Workbook

Sheet DETAILS
A1: STUDENT'S DETAIL
A2: SR NO | B2: NAME | C2: MOTHER'S NAME | D2: FATHER'S NAME | E2: DOB | F2: CLASS & SEC
A3: 1944 | B3: AARUSH YADUVANSHI | C3: ANTIMA YADAV | D3: MANMOHAN YADAV | E3: 22.08.2022 | F3: NURSERY
A4: 1940 | B4: ADITRI CHAUDHARI | C4: KIRAN BHARTI | D4: CHAUDHARI KARAMVEER | E4: 01.01.2022 | F4: NURSERY
A5: 1948 | B5: AHEM | C5: RAJWANTI | D5: LAVKUSH KUMAR | E5: 26.03.2020 | F5: NURSERY
A6: 1868 | B6: ANUSHKA RAJ | C6: BRIJRANI | D6: SUSHEEL KUMAR | E6: 20.08.2020 | F6: NURSERY
A7: 1939 | B7: ARNAV SINGH | C7: REKHA RAJPOOT | D7: ANIL KUMAR | E7: 02.02.2022 | F7: NURSERY
A8: 1956 | B8: ATHARV UPADHYAY | C8: PRIYA UPADHAYAY | D8: PANKAJ UPADHAYAY | E8: 14.01.2021 | F8: NURSERY
A9: 1882 | B9: ATHRAV SINGH | C9: JYOTIMA | D9: SHIV RAM SINGH | E9: 02.04.2021 | F9: NURSERY
A10: 1954 | B10: AVANTIKA | C10: SHIVANI | D10: SATESH KUMAR | E10: 07.08.2021 | F10: NURSERY
A11: 1923 | B11: AVIKA MAURYA | C11: SUMAN MAURYA | D11: RAHUL KUMAR MAURYA | E11: 29.05.2022 | F11: NURSERY
A12: 1893 | B12: DAKSH | C12: MAMTA | D12: ABHISHEK KUMAR | E12: 22.04.2021 | F12: NURSERY
A13: 1843 | B13: DEV MISHRA | C13: LAXMI MISHRA | D13: KRISHNA KUMAR MISHRA | E13: 31.03.2022 | F13: NURSERY
A14: 1858 | B14: DEVESH RAJPOOT | C14: NEHA | D14: DIWAKAR SINGH | E14: 07.11.2021 | F14: NURSERY
... A19: 1874 | B19: SEHRISH | C19: BUSHRA KHATOON | D19: MOHD SHAMEEM | E19: 09.06.2020 | F19: NURSERY

Sheet UT-I
A1: UNIT TEST-I (2025-26) CLASS - NUR
A2: SR. NO. | B2: NAME | C2: ENGLISH WRITTEN | D2: ENGLISH ORAL | E2: ENGLISH DICTATION | F2: HINDI WRITTEN | G2: HINDI ORAL | H2: HINDI DICTATION | I2: MATHS WRITTEN | J2: MATHS ORAL | K2: EVS | L2: CONVERSATION | M2: GK | N2: DRAWING | O2: RHYMES | P2: P.T. & GAMES | Q2: TOTAL | R2: PERCENTAGE | S2: TOTAL PRESENT | T2: TOTAL WORKING DAY | U2: RANK IN CLASS | V2: PARENT'S SIGNATURE
A3: =DETAILS!A3 -> 1944 | B3: =DETAILS!B3 -> AARUSH YADUVANSHI | C3: NA | D3: 17 | E3: NA | F3: NA | G3: 17 | H3: NA | I3: NA | J3: 17 | K3: 17 | L3: 17 | M3: AB | N3: NA | O3: B | P3: B | Q3: =SUM(C3:P3) -> 85 | R3: =Q3/5&" %" -> 17 % | S3: 2 | T3: 7
A4: =DETAILS!A4 -> 1940 | B4: =DETAILS!B4 -> ADITRI CHAUDHARI | C4: NA | D4: 17 | E4: NA | F4: NA | G4: 17 | H4: NA | I4: NA | J4: 17 | K4: 17 | L4: 17 | M4: D | N4: NA | O4: D | P4: D | Q4: =SUM(C4:P4) -> 85 | R4: =Q4/5&" %" -> 17 % | S4: 12 | T4: 12
A5: =DETAILS!A5 -> 1948 | B5: =DETAILS!B5 -> AHEM | C5: NA | D5: NA | E5: 50 | F5: NA | G5: NA | H5: NA | I5: NA | J5: NA | K5: NA | L5: NA | M5: NA | N5: NA | O5: NA | P5: NA | Q5: =SUM(C5:P5) -> 50 | R5: =Q5/5&" %" -> 10 % | S5: 2 | T5: 2
A6: =DETAILS!A6 -> 1868 | B6: =DETAILS!B6 -> ANUSHKA RAJ | C6: 43 | D6: 40 | E6: 30 | F6: 43 | G6: 40 | H6: 30 | I6: 39 | J6: 50 | K6: 50 | L6: 40 | M6: B | N6: A | O6: B | P6: B | Q6: =SUM(C6:P6) -> 405 | R6: =Q6/5&" %" -> 81 % | S6: 32 | T6: 55
A7: =DETAILS!A7 -> 1939 | B7: =DETAILS!B7 -> ARNAV SINGH | C7: 47 | D7: 50 | E7: 45 | F7: 46 | G7: 50 | H7: 45 | I7: 46 | J7: 50 | K7: 50 | L7: 50 | M7: A | N7: A | O7: A | P7: A | Q7: =SUM(C7:P7) -> 479 | R7: =Q7/5&" %" -> 95.8 % | S7: 15 | T7: 17
A8: =DETAILS!A8 -> 1956 | B8: =DETAILS!B8 -> ATHARV UPADHYAY | C8: NA | D8: NA | E8: NA | F8: NA | G8: NA | H8: NA | I8: NA | J8: NA | K8: NA | L8: NA | M8: NA | N8: NA | O8: NA | P8: NA | Q8: NA | R8: NA | S8: NA | T8: NA | U8: NA | V8: NA
A9: =DETAILS!A9 -> 1882 | B9: =DETAILS!B9 -> ATHRAV SINGH | C9: 49 | D9: 50 | E9: 48 | F9: 50 | G9: 50 | H9: 48 | I9: 48 | J9: 50 | K9: 50 | L9: 50 | M9: A | N9: A | O9: A | P9: A | Q9: =SUM(C9:P9) -> 493 | R9: =Q9/5&" %" -> 98.6 % | S9: 37 | T9: 55
A10: =DETAILS!A10 -> 1954 | B10: =DETAILS!B10 -> AVANTIKA | C10: NA | D10: NA | E10: NA | F10: NA | G10: NA | H10: NA | I10: NA | J10: NA | K10: NA | L10: NA | M10: NA | N10: NA | O10: NA | P10: NA | Q10: =SUM(C10:P10) -> 0 | R10: =Q10/5&" %" -> 0 % | S10: NA | T10: NA
A11: =DETAILS!A11 -> 1923 | B11: =DETAILS!B11 -> AVIKA MAURYA | C11: 39 | D11: 40 | E11: 30 | F11: 40 | G11: 40 | H11: 30 | I11: 39 | J11: 40 | K11: 50 | L11: 40 | M11: B | N11: A | O11: B | P11: B | Q11: =SUM(C11:P11) -> 388 | R11: =Q11/5&" %" -> 77.6 % | S11: 13 | T11: 17
A12: =DETAILS!A12 -> 1893 | B12: =DETAILS!B12 -> DAKSH | C12: 28 | D12: 17 | E12: 20 | F12: 28 | G12: 17 | H12: 25 | I12: 31 | J12: 17 | K12: 25 | L12: 17 | M12: D | N12: B | O12: D | P12: C | Q12: =SUM(C12:P12) -> 225 | R12: =Q12/5&" %" -> 45 % | S12: 26 | T12: 55
A13: =DETAILS!A13 -> 1843 | B13: =DETAILS!B13 -> DEV MISHRA | C13: 42 | D13: 40 | E13: 30 | F13: 38 | G13: 30 | H13: 30 | I13: 36 | J13: 50 | K13: 50 | L13: 40 | M13: B | N13: B | O13: A | P13: A | Q13: =SUM(C13:P13) -> 386 | R13: =Q13/5&" %" -> 77.2 % | S13: 45 | T13: 55
A14: =DETAILS!A14 -> 1858 | B14: =DETAILS!B14 -> DEVESH RAJPOOT | C14: 46 | D14: 45 | E14: 40 | F14: 44 | G14: 50 | H14: 40 | I14: 40 | J14: 40 | K14: 40 | L14: 40 | M14: A | N14: A | O14: A | P14: A | Q14: =SUM(C14:P14) -> 425 | R14: =Q14/5&" %" -> 85 % | S14: 42 | T14: 55
A15: =DETAILS!A15 -> 1877 | B15: =DETAILS!B15 -> INDRABH YADAV | C15: 43 | D15: 50 | E15: 40 | F15: 41 | G15: 45 | H15: 40 | I15: 45 | J15: 45 | K15: 50 | L15: 50 | M15: A | N15: A | O15: A | P15: A | Q15: =SUM(C15:P15) -> 449 | R15: =Q15/5&" %" -> 89.8 % | S15: 41 | T15: 55
A16: =DETAILS!A16 -> 1851 | B16: =DETAILS!B16 -> KARTIKEY SINGH | C16: 47 | D16: 45 | E16: 47 | F16: 40 | G16: 50 | H16: 47 | I16: 47 | J16: 50 | K16: 50 | L16: 50 | M16: A | N16: A | O16: A | P16: A | Q16: =SUM(C16:P16) -> 473 | R16: =Q16/5&" %" -> 94.6 % | S16: 41 | T16: 55
A17: =DETAILS!A17 -> 1889 | B17: =DETAILS!B17 -> MOHD. ARIZ | C17: 44 | D17: 45 | E17: 30 | F17: 46 | G17: 50 | H17: 30 | I17: 46 | J17: 50 | K17: 45 | L17: 50 | M17: A | N17: A | O17: A | P17: A | Q17: =SUM(C17:P17) -> 436 | R17: =Q17/5&" %" -> 87.2 % | S17: 29 | T17: 55
A18: =DETAILS!A18 -> 1905 | B18: =DETAILS!B18 -> RAVNOOR KAUR | C18: AB | D18: AB | E18: 48 | F18: 40 | G18: 50 | H18: 48 | I18: 49 | J18: 50 | K18: AB | L18: 40 | M18: A | N18: AB | O18: A | P18: A | Q18: =SUM(C18:P18) -> 325 | R18: =Q18/5&" %" -> 65 % | S18: 21 | T18: 55
A19: =DETAILS!A19 -> 1874 | B19: =DETAILS!B19 -> SEHRISH | C19: 47 | D19: 50 | E19: 45 | F19: 40 | G19: 45 | H19: 45 | I19: 40 | J19: 50 | K19: 50 | L19: 50 | M19: AB | N19: A | O19: A | P19: A | Q19: =SUM(C19:P19) -> 462 | R19: =Q19/5&" %" -> 92.4 % | S19: 41 | T19: 55
B23: CLASS TEACHER'S SIGNATURE | S23: PRINCIPAL'S SIGNATURE

Sheet HALF YEARLY
A1: HALF YEARLY EXAMINATION (2025-26) CLASS - NURSERY-B
A2: SR. NO. | B2: NAME | C2: ENGLISH WRITTEN | D2: ENGLISH ORAL | E2: ENGLISH DICTATION | F2: HINDI WRITTEN | G2: HINDI ORAL | H2: HINDI DICTATION | I2: MATHS WRITTEN | J2: MATHS ORAL | K2: EVS | L2: CONVERSATION | M2: GK | N2: DRAWING | O2: RHYMES | P2: P.T. & GAMES | Q2: TOTAL (500) | R2: PERCENTAGE | S2: TOTAL PRESENT | T2: TOTAL WORKING DAY | U2: RANK IN CLASS | V2: PARENT'S SIGNATURE
A3: =DETAILS!A3 -> 1944 | B3: =DETAILS!B3 -> AARUSH YADUVANSHI | C3: AB | D3: AB | E3: AB | F3: AB | G3: AB | H3: AB | I3: AB | J3: AB | K3: AB | L3: AB | M3: AB | N3: AB | O3: AB | P3: AB | Q3: =SUM(C3:P3) -> 0 | R3: =Q3/5&" %" -> 0 % | S3: 4 | T3: 64
A4: =DETAILS!A4 -> 1940 | B4: =DETAILS!B4 -> ADITRI CHAUDHARI | C4: 41 | D4: 30 | E4: 21 | F4: 43 | G4: 30 | H4: 25 | I4: 37 | J4: 20 | K4: 20 | L4: 20 | M4: D | N4: C | O4: A | P4: B | Q4: =SUM(C4:P4) -> 287 | R4: =Q4/5&" %" -> 57.4 % | S4: 64 | T4: 69
A5: =DETAILS!A5 -> 1948 | B5: =DETAILS!B5 -> AHEM | C5: 46 | D5: 35 | E5: 48 | F5: 48 | G5: 45 | H5: 49 | I5: 42 | J5: 35 | K5: 30 | L5: 40 | M5: A | N5: A | O5: A | P5: A | Q5: =SUM(C5:P5) -> 418 | R5: =Q5/5&" %" -> 83.6 % | S5: 55 | T5: 59
A6: =DETAILS!A6 -> 1868 | B6: =DETAILS!B6 -> ANUSHKA RAJ | C6: 47 | D6: 45 | E6: 49 | F6: 43 | G6: 40 | H6: AB | I6: 36 | J6: 35 | K6: 30 | L6: AB | M6: C | N6: A | O6: A | P6: A | Q6: =SUM(C6:P6) -> 325 | R6: =Q6/5&" %" -> 65 % | S6: 85 | T6: 102
A7: =DETAILS!A7 -> 1939 | B7: =DETAILS!B7 -> ARNAV SINGH | C7: 46 | D7: 50 | E7: 44 | F7: 49 | G7: 50 | H7: 46 | I7: 45 | J7: 50 | K7: 45 | L7: 50 | M7: A | N7: A | O7: A | P7: A | Q7: =SUM(C7:P7) -> 475 | R7: =Q7/5&" %" -> 95 % | S7: 70 | T7: 72 | U7: II
A8: =DETAILS!A8 -> 1956 | B8: =DETAILS!B8 -> ATHARV UPADHYAY | C8: 34 | D8: 25 | E8: 35 | F8: 42 | G8: 20 | H8: 38 | I8: 34 | J8: 20 | K8: 20 | L8: 30 | M8: D | N8: A | O8: C | P8: A | Q8: =SUM(C8:P8) -> 298 | R8: =Q8/5&" %" -> 59.6 % | S8: 36 | T8: 41
A9: =DETAILS!A9 -> 1882 | B9: =DETAILS!B9 -> ATHRAV SINGH | C9: 50 | D9: 50 | E9: 47 | F9: 50 | G9: 50 | H9: 49 | I9: 50 | J9: 50 | K9: 50 | L9: 50 | M9: A | N9: A | O9: A | P9: A | Q9: =SUM(C9:P9) -> 496 | R9: =Q9/5&" %" -> 99.2 % | S9: 93 | T9: 96 | U9: I
A10: =DETAILS!A10 -> 1954 | B10: =DETAILS!B10 -> AVANTIKA | C10: 44 | D10: 20 | E10: 42 | F10: 40 | G10: 30 | H10: 40 | I10: 33 | J10: 20 | K10: 20 | L10: 30 | M10: D | N10: A | O10: B | P10: A | Q10: =SUM(C10:P10) -> 319 | R10: =Q10/5&" %" -> 63.8 % | S10: 52 | T10: 56
A11: =DETAILS!A11 -> 1923 | B11: =DETAILS!B11 -> AVIKA MAURYA | C11: 41 | D11: 45 | E11: 31 | F11: 36 | G11: 30 | H11: AB | I11: 35 | J11: 30 | K11: 40 | L11: AB | M11: A | N11: B | O11: B | P11: A | Q11: =SUM(C11:P11) -> 288 | R11: =Q11/5&" %" -> 57.6 % | S11: 64 | T11: 72
A12: =DETAILS!A12 -> 1893 | B12: =DETAILS!B12 -> DAKSH | C12: 30 | D12: 17 | E12: 41 | F12: 34 | G12: 20 | H12: 22 | I12: 27 | J12: 20 | K12: 17 | L12: 17 | M12: D | N12: B | O12: D | P12: A | Q12: =SUM(C12:P12) -> 245 | R12: =Q12/5&" %" -> 49 % | S12: 74 | T12: 94
A13: =DETAILS!A13 -> 1843 | B13: =DETAILS!B13 -> DEV MISHRA | C13: 39 | D13: 35 | E13: AB | F13: 35 | G13: 25 | H13: 30 | I13: 33 | J13: 30 | K13: 30 | L13: 27 | M13: AB | N13: B | O13: C | P13: A | Q13: =SUM(C13:P13) -> 284 | R13: =Q13/5&" %" -> 56.8 % | S13: 98 | T13: 107
A14: =DETAILS!A14 -> 1858 | B14: =DETAILS!B14 -> DEVESH RAJPOOT | C14: 34 | D14: 25 | E14: 38 | F14: 37 | G14: 20 | H14: 41 | I14: 27 | J14: 20 | K14: 30 | L14: 27 | M14: D | N14: A | O14: B | P14: A | Q14: =SUM(C14:P14) -> 299 | R14: =Q14/5&" %" -> 59.8 % | S14: 83 | T14: 104
A15: =DETAILS!A15 -> 1877 | B15: =DETAILS!B15 -> INDRABH YADAV | C15: 25 | D15: 25 | E15: 41 | F15: 40 | G15: 35 | H15: 25 | I15: 39 | J15: 45 | K15: 45 | L15: 25 | M15: A | N15: C | O15: A | P15: A | Q15: =SUM(C15:P15) -> 345 | R15: =Q15/5&" %" -> 69 % | S15: 87 | T15: 100
A16: =DETAILS!A16 -> 1851 | B16: =DETAILS!B16 -> KARTIKEY SINGH | C16: 46 | D16: 30 | E16: 44 | F16: 45 | G16: 48 | H16: 46 | I16: 32 | J16: 45 | K16: 40 | L16: 45 | M16: B | N16: A | O16: A | P16: A | Q16: =SUM(C16:P16) -> 421 | R16: =Q16/5&" %" -> 84.2 % | S16: 88 | T16: 108 | U16: III
A17: =DETAILS!A17 -> 1889 | B17: =DETAILS!B17 -> MOHD. ARIZ | C17: 48 | D17: 35 | E17: 31 | F17: 40 | G17: 35 | H17: 36 | I17: 32 | J17: 20 | K17: 30 | L17: 17 | M17: C | N17: B | O17: C | P17: A | Q17: =SUM(C17:P17) -> 324 | R17: =Q17/5&" %" -> 64.8 % | S17: 75 | T17: 92
A18: =DETAILS!A18 -> 1905 | B18: =DETAILS!B18 -> RAVNOOR KAUR | C18: 44 | D18: 40 | E18: 40 | F18: 42 | G18: 20 | H18: 37 | I18: 39 | J18: 30 | K18: 30 | L18: 35 | M18: D | N18: A | O18: A | P18: A | Q18: =SUM(C18:P18) -> 357 | R18: =Q18/5&" %" -> 71.4 % | S18: 62 | T18: 89
A19: =DETAILS!A19 -> 1874 | B19: =DETAILS!B19 -> SEHRISH | C19: 43 | D19: 30 | E19: 36 | F19: 41 | G19: 25 | H19: 47 | I19: 41 | J19: 30 | K19: 20 | L19: 25 | M19: D | N19: A | O19: B | P19: A | Q19: =SUM(C19:P19) -> 338 | R19: =Q19/5&" %" -> 67.6 % | S19: 87 | T19: 106
B23: CLASS TEACHER'S SIGNATURE | S23: PRINCIPAL'S SIGNATURE

Sheet UT-II
A1: UNIT TEST -II (2024-25) CLASS - NUR
A2: SR. NO. | B2: NAME | C2: ENGLISH WRITTEN | D2: ENGLISH ORAL | E2: ENGLISH DICTATION | F2: HINDI WRITTEN | G2: HINDI ORAL | H2: HINDI DICTATION | I2: MATHS WRITTEN | J2: MATHS ORAL | K2: EVS | L2: CONVERSATION | M2: GK | N2: DRAWING | O2: RHYMES | P2: P.T. & GAMES | Q2: MORAL VALUES | R2: TOTAL
A3: =DETAILS!A3 -> 1944 | B3: =DETAILS!B3 -> AARUSH YADUVANSHI | R3: =SUM(C3:Q3) -> 0
A4: =DETAILS!#REF! -> #REF! | B4: =DETAILS!#REF! -> #REF! | R4: =SUM(C4:Q4) -> 0
A5: =DETAILS!#REF! -> #REF! | B5: =DETAILS!#REF! -> #REF! | R5: =SUM(C5:Q5) -> 0
A6: =DETAILS!A4 -> 1940 | B6: =DETAILS!B4 -> ADITRI CHAUDHARI | R6: =SUM(C6:Q6) -> 0
A7: =DETAILS!A5 -> 1948 | B7: =DETAILS!B5 -> AHEM | R7: =SUM(C7:Q7) -> 0
A8: =DETAILS!#REF! -> #REF! | B8: =DETAILS!#REF! -> #REF! | R8: =SUM(C8:Q8) -> 0
A9: =DETAILS!#REF! -> #REF! | B9: =DETAILS!#REF! -> #REF! | R9: =SUM(C9:Q9) -> 0
A10: =DETAILS!#REF! -> #REF! | B10: =DETAILS!#REF! -> #REF! | R10: =SUM(C10:Q10) -> 0
A11: =DETAILS!#REF! -> #REF! | B11: =DETAILS!#REF! -> #REF! | R11: =SUM(C11:Q11) -> 0
A12: =DETAILS!A6 -> 1868 | B12: =DETAILS!B6 -> ANUSHKA RAJ | R12: =SUM(C12:Q12) -> 0
A13: =DETAILS!A7 -> 1939 | B13: =DETAILS!B7 -> ARNAV SINGH | R13: =SUM(C13:Q13) -> 0
A14: =DETAILS!A8 -> 1956 | B14: =DETAILS!B8 -> ATHARV UPADHYAY | R14: =SUM(C14:Q14) -> 0
A15: =DETAILS!A9 -> 1882 | B15: =DETAILS!B9 -> ATHRAV SINGH | R15: =SUM(C15:Q15) -> 0
A16: =DETAILS!A10 -> 1954 | B16: =DETAILS!B10 -> AVANTIKA | R16: =SUM(C16:Q16) -> 0
A17: =DETAILS!#REF! -> #REF! | B17: =DETAILS!#REF! -> #REF! | R17: =SUM(C17:Q17) -> 0
A18: =DETAILS!#REF! -> #REF! | B18: =DETAILS!#REF! -> #REF! | R18: =SUM(C18:Q18) -> 0
A19: =DETAILS!A11 -> 1923 | B19: =DETAILS!B11 -> AVIKA MAURYA | R19: =SUM(C19:Q19) -> 0
A20: =DETAILS!A12 -> 1893 | B20: =DETAILS!B12 -> DAKSH | R20: =SUM(C20:Q20) -> 0
A21: =DETAILS!#REF! -> #REF! | B21: =DETAILS!#REF! -> #REF! | R21: =SUM(C21:Q21) -> 0
A22: =DETAILS!A13 -> 1843 | B22: =DETAILS!B13 -> DEV MISHRA | R22: =SUM(C22:Q22) -> 0
A23: =DETAILS!#REF! -> #REF! | B23: =DETAILS!#REF! -> #REF! | R23: =SUM(C23:Q23) -> 0
A24: =DETAILS!#REF! -> #REF! | B24: =DETAILS!#REF! -> #REF! | R24: =SUM(C24:Q24) -> 0
A25: =DETAILS!#REF! -> #REF! | B25: =DETAILS!#REF! -> #REF! | R25: =SUM(C25:Q25) -> 0
A26: =DETAILS!A14 -> 1858 | B26: =DETAILS!B14 -> DEVESH RAJPOOT | R26: =SUM(C26:Q26) -> 0
A27: =DETAILS!A15 -> 1877 | B27: =DETAILS!B15 -> INDRABH YADAV | R27: =SUM(C27:Q27) -> 0
A28: =DETAILS!A16 -> 1851 | B28: =DETAILS!B16 -> KARTIKEY SINGH | R28: =SUM(C28:Q28) -> 0
A29: =DETAILS!#REF! -> #REF! | B29: =DETAILS!#REF! -> #REF! | R29: =SUM(C29:Q29) -> 0
A30: =DETAILS!A17 -> 1889 | B30: =DETAILS!B17 -> MOHD. ARIZ | R30: =SUM(C30:Q30) -> 0
A31: =DETAILS!#REF! -> #REF! | B31: =DETAILS!#REF! -> #REF! | R31: =SUM(C31:Q31) -> 0
A32: =DETAILS!#REF! -> #REF! | B32: =DETAILS!#REF! -> #REF! | R32: =SUM(C32:Q32) -> 0
A33: =DETAILS!#REF! -> #REF! | B33: =DETAILS!#REF! -> #REF! | R33: =SUM(C33:Q33) -> 0
A34: =DETAILS!#REF! -> #REF! | B34: =DETAILS!#REF! -> #REF! | R34: =SUM(C34:Q34) -> 0
A35: =DETAILS!A18 -> 1905 | B35: =DETAILS!B18 -> RAVNOOR KAUR | R35: =SUM(C35:Q35) -> 0
A36: =DETAILS!#REF! -> #REF! | B36: =DETAILS!#REF! -> #REF! | R36: =SUM(C36:Q36) -> 0
A37: =DETAILS!#REF! -> #REF! | B37: =DETAILS!#REF! -> #REF! | R37: =SUM(C37:Q37) -> 0
A38: =DETAILS!#REF! -> #REF! | B38: =DETAILS!#REF! -> #REF! | R38: =SUM(C38:Q38) -> 0
A39: =DETAILS!A19 -> 1874 | B39: =DETAILS!B19 -> SEHRISH | R39: =SUM(C39:Q39) -> 0
A40: =DETAILS!A20 -> 0 | B40: =DETAILS!B20 -> 0 | R40: =SUM(C40:Q40) -> 0
...

Sheet ANNUAL
A1: ANNUAL EXAMINATION (2024-25) CLASS -NUR
A2: SR. NO. | B2: NAME | C2: ENGLISH WRITTEN | D2: ENGLISH ORAL | E2: ENGLISH DICTATION | F2: HINDI WRITTEN | G2: HINDI ORAL | H2: HINDI DICTATION | I2: MATHS WRITTEN | J2: MATHS ORAL | K2: EVS | L2: CONVERSATION | M2: GK | N2: DRAWING | O2: RHYMES | P2: P.T. & GAMES | Q2: MORAL VALUES | R2: TOTAL ATTENDACE | S2: TOTAL WORKING DAY | T2: REMARKS | U2: TOTAL
A3: =DETAILS!A3 -> 1944 | B3: =DETAILS!B3 -> AARUSH YADUVANSHI | C3: 48 | D3: 50 | E3: 50 | F3: 49 | G3: 50 | H3: 49 | I3: 47 | J3: 45 | K3: 45 | L3: 50 | M3: A | N3: A | O3: A | P3: A | Q3: A | R3: 159 | S3: 214 | T3: Great Potential- Stay Focused! | U3: =SUM(C3:L3) -> 483
A4: =DETAILS!#REF! -> #REF! | B4: =DETAILS!#REF! -> #REF! | C4: 50 | D4: 48 | E4: 50 | F4: 44 | G4: 50 | H4: 48 | I4: 50 | J4: 50 | K4: 50 | L4: 50 | M4: A | N4: A | O4: A | P4: A | Q4: A | R4: 152 | S4: 214 | T4: Outstanding effort all year. | U4: =SUM(C4:L4) -> 490
A5: =DETAILS!#REF! -> #REF! | B5: =DETAILS!#REF! -> #REF! | C5: 29 | D5: 23 | E5: 20 | F5: 28 | G5: 40 | H5: 20 | I5: 46 | J5: 45 | K5: 35 | L5: 30 | M5: B | N5: A | O5: A | P5: A | Q5: A | R5: 105 | S5: 160 | T5: Needs improvement. | U5: =SUM(C5:L5) -> 316
A6: =DETAILS!A4 -> 1940 | B6: =DETAILS!B4 -> ADITRI CHAUDHARI | C6: 35 | D6: 40 | E6: 30 | F6: 34 | G6: 40 | H6: 42 | I6: 46 | J6: 35 | K6: 40 | L6: 30 | M6: A | N6: A | O6: A | P6: A | Q6: A | R6: 129 | S6: 153 | T6: Needs improvement. | U6: =SUM(C6:L6) -> 372
A7: =DETAILS!A5 -> 1948 | B7: =DETAILS!B5 -> AHEM | C7: 47 | D7: 50 | E7: 47 | F7: 50 | G7: 50 | H7: 50 | I7: 50 | J7: 50 | K7: 50 | L7: 45 | M7: A | N7: A | O7: A | P7: A | Q7: A | R7: 174 | S7: 214 | T7: Excellent progress this year! | U7: =SUM(C7:L7) -> 489
A8: =DETAILS!#REF! -> #REF! | B8: =DETAILS!#REF! -> #REF! | C8: 17 | D8: 17 | E8: 17 | F8: 17 | G8: 17 | H8: 17 | I8: 17 | J8: 17 | K8: 17 | L8: 17 | M8: B | N8: B | O8: B | P8: A | Q8: A | R8: 78 | S8: 214 | T8: Needs improvement. | U8: =SUM(C8:L8) -> 170
A9: =DETAILS!#REF! -> #REF! | B9: =DETAILS!#REF! -> #REF! | C9: 44 | D9: 50 | E9: 48 | F9: 45 | G9: 50 | H9: 37 | I9: 48 | J9: 49 | K9: 50 | L9: 48 | M9: A | N9: A | O9: A | P9: A | Q9: A | R9: 184 | S9: 214 | T9: Great Potential- Stay Focused! | U9: =SUM(C9:L9) -> 469
A10: =DETAILS!#REF! -> #REF! | B10: =DETAILS!#REF! -> #REF! | C10: 44 | D10: 45 | E10: 48 | F10: 47 | G10: 48 | H10: 45 | I10: 41 | J10: 45 | K10: 40 | L10: 40 | M10: A | N10: A | O10: A | P10: A | Q10: A | R10: 206 | S10: 214 | T10: Keep up the great work ! | U10: =SUM(C10:L10) -> 443
A11: =DETAILS!#REF! -> #REF! | B11: =DETAILS!#REF! -> #REF! | C11: 40 | D11: 45 | E11: 45 | F11: 42 | G11: 48 | H11: 48 | I11: 48 | J11: 48 | K11: 45 | L11: 45 | M11: A | N11: A | O11: A | P11: A | Q11: A | R11: 167 | S11: 214 | T11: Keep up the great work ! | U11: =SUM(C11:L11) -> 454
A12: =DETAILS!A6 -> 1868 | B12: =DETAILS!B6 -> ANUSHKA RAJ | C12: 46 | D12: 50 | E12: 30 | F12: 46 | G12: 48 | H12: 43 | I12: 50 | J12: 50 | K12: 45 | L12: 45 | M12: A | N12: A | O12: A | P12: A | Q12: A | R12: 161 | S12: 204 | T12: Good. Can do better. | U12: =SUM(C12:L12) -> 453
A13: =DETAILS!A7 -> 1939 | B13: =DETAILS!B7 -> ARNAV SINGH | C13: 39 | D13: 40 | E13: 30 | F13: 38 | G13: 45 | H13: 30 | I13: 40 | J13: 40 | K13: 40 | L13: 35 | M13: A | N13: A | O13: A | P13: A | Q13: A | R13: 122 | S13: 176 | T13: Good. Can do better. | U13: =SUM(C13:L13) -> 377
A14: =DETAILS!A8 -> 1956 | B14: =DETAILS!B8 -> ATHARV UPADHYAY | C14: 33 | D14: 40 | E14: 30 | F14: 33 | G14: 40 | H14: 30 | I14: 45 | J14: 45 | K14: 50 | L14: 40 | M14: A | N14: A | O14: A | P14: A | Q14: A | R14: 107 | S14: 167 | T14: Great Potential- Stay Focused! | U14: =SUM(C14:L14) -> 386
A15: =DETAILS!A9 -> 1882 | B15: =DETAILS!B9 -> ATHRAV SINGH | U15: =SUM(C15:L15) -> 0
A16: =DETAILS!A10 -> 1954 | B16: =DETAILS!B10 -> AVANTIKA | C16: 49 | D16: 50 | E16: 43 | F16: 48 | G16: 49 | H16: 48 | I16: 48 | J16: 48 | K16: 40 | L16: 50 | M16: A | N16: A | O16: A | P16: A | Q16: A | R16: 160 | S16: 214 | T16: Excellent progress this year! | U16: =SUM(C16:L16) -> 473
A17: =DETAILS!#REF! -> #REF! | B17: =DETAILS!#REF! -> #REF! | C17: 45 | D17: 50 | E17: 39 | F17: 46 | G17: 48 | H17: 50 | I17: 50 | J17: 50 | K17: 50 | L17: 50 | M17: A | N17: A | O17: A | P17: A | Q17: A | R17: 177 | S17: 214 | T17: Excellent progress this year! | U17: =SUM(C17:L17) -> 478
A18: =DETAILS!#REF! -> #REF! | B18: =DETAILS!#REF! -> #REF! | C18: 50 | D18: 50 | E18: 50 | F18: 50 | G18: 50 | H18: 50 | I18: 50 | J18: 50 | K18: 50 | L18: 50 | M18: A | N18: A | O18: A | P18: A | Q18: A | R18: 175 | S18: 214 | T18: Out standing effort all year. | U18: =SUM(C18:L18) -> 500
A19: =DETAILS!A11 -> 1923 | B19: =DETAILS!B11 -> AVIKA MAURYA | C19: 50 | D19: 48 | E19: 48 | F19: 40 | G19: 48 | H19: 48 | I19: 48 | J19: 50 | K19: 48 | L19: 48 | M19: A | N19: A | O19: A | P19: A | Q19: A | R19: 163 | S19: 214 | T19: Excellent progress this year! | U19: =SUM(C19:L19) -> 476
A20: =DETAILS!A12 -> 1893 | B20: =DETAILS!B12 -> DAKSH | C20: 50 | D20: 50 | E20: 48 | F20: 50 | G20: 48 | H20: 48 | I20: 50 | J20: 50 | K20: 50 | L20: 50 | M20: A | N20: A | O20: A | P20: A | Q20: A | R20: 110 | S20: 174 | T20: Great Potential- Stay Focused! | U20: =SUM(C20:L20) -> 494
A21: =DETAILS!#REF! -> #REF! | B21: =DETAILS!#REF! -> #REF! | C21: 40 | D21: 48 | E21: 38 | F21: 40 | G21: 45 | H21: 45 | I21: 45 | J21: 45 | K21: 48 | L21: 49 | M21: A | N21: A | O21: A | P21: A | Q21: A | R21: 135 | S21: 179 | T21: Great Potential- Stay Focused! | U21: =SUM(C21:L21) -> 443
A22: =DETAILS!A13 -> 1843 | B22: =DETAILS!B13 -> DEV MISHRA | C22: 46 | D22: 50 | E22: 50 | F22: 49 | G22: 45 | H22: 42 | I22: 47 | J22: 48 | K22: 50 | L22: 50 | M22: A | N22: A | O22: A | P22: A | Q22: A | R22: 170 | S22: 214 | T22: Good. Can do better. | U22: =SUM(C22:L22) -> 477
A23: =DETAILS!#REF! -> #REF! | B23: =DETAILS!#REF! -> #REF! | C23: 35 | D23: 50 | E23: 35 | F23: 43 | G23: 45 | H23: 40 | I23: 49 | J23: 48 | K23: 50 | L23: 50 | M23: A | N23: A | O23: A | P23: A | Q23: A | R23: 166 | S23: 214 | T23: Great Potential- Stay Focused! | U23: =SUM(C23:L23) -> 445
A24: =DETAILS!#REF! -> #REF! | B24: =DETAILS!#REF! -> #REF! | C24: 41 | D24: 50 | E24: 50 | F24: 49 | G24: 45 | H24: 50 | I24: 49 | J24: 48 | K24: 48 | L24: 50 | M24: A | N24: A | O24: A | P24: A | Q24: A | R24: 165 | S24: 214 | T24: Excellent progress this year! | U24: =SUM(C24:L24) -> 480
A25: =DETAILS!#REF! -> #REF! | B25: =DETAILS!#REF! -> #REF! | C25: 43 | D25: 50 | E25: 40 | F25: 44 | G25: 48 | H25: 46 | I25: 49 | J25: 48 | K25: 50 | L25: 48 | M25: A | N25: B | O25: A | P25: A | Q25: A | R25: 153 | S25: 169 | T25: Good. Can do better. | U25: =SUM(C25:L25) -> 466
A26: =DETAILS!A14 -> 1858 | B26: =DETAILS!B14 -> DEVESH RAJPOOT | C26: 44 | D26: 48 | E26: 42 | F26: 50 | G26: 48 | H26: 45 | I26: 50 | J26: 45 | K26: 48 | L26: 50 | M26: A | N26: B | O26: A | P26: A | Q26: A | R26: 153 | S26: 169 | T26: Great Potential- Stay Focused! | U26: =SUM(C26:L26) -> 470
A27: =DETAILS!A15 -> 1877 | B27: =DETAILS!B15 -> INDRABH YADAV | C27: 17 | D27: 17 | E27: 17 | F27: 35 | G27: 40 | H27: 17 | I27: 42 | J27: 40 | K27: 17 | L27: 17 | M27: B | N27: B | O27: B | P27: A | Q27: A | R27: 136 | S27: 174 | T27: Good. Can do better. | U27: =SUM(C27:L27) -> 259
A28: =DETAILS!A16 -> 1851 | B28: =DETAILS!B16 -> KARTIKEY SINGH | C28: 44 | D28: 50 | E28: 36 | F28: 45 | G28: 45 | H28: 45 | I28: 50 | J28: 45 | K28: 50 | L28: 50 | M28: A | N28: A | O28: A | P28: A | Q28: A | R28: 140 | S28: 155 | T28: Great Potential- Stay Focused! | U28: =SUM(C28:L28) -> 460
A29: =DETAILS!#REF! -> #REF! | B29: =DETAILS!#REF! -> #REF! | C29: 50 | D29: 50 | E29: 50 | F29: 50 | G29: 45 | H29: 50 | I29: 50 | J29: 50 | K29: 50 | L29: 50 | M29: A | N29: A | O29: A | P29: A | Q29: A | R29: 159 | S29: 214 | T29: Excellent progress this year! | U29: =SUM(C29:L29) -> 495
A30: =DETAILS!A17 -> 1889 | B30: =DETAILS!B17 -> MOHD. ARIZ | C30: 48 | D30: 50 | E30: 50 | F30: 48 | G30: 49 | H30: 50 | I30: 50 | J30: 50 | K30: 50 | L30: 50 | M30: A | N30: A | O30: A | P30: A | Q30: A | R30: 174 | S30: 201 | T30: Outstanding effort all year. | U30: =SUM(C30:L30) -> 495
A31: =DETAILS!#REF! -> #REF! | B31: =DETAILS!#REF! -> #REF! | U31: =SUM(C31:L31) -> 0
A32: =DETAILS!#REF! -> #REF! | B32: =DETAILS!#REF! -> #REF! | U32: =SUM(C32:L32) -> 0
A33: =DETAILS!#REF! -> #REF! | B33: =DETAILS!#REF! -> #REF! | U33: =SUM(C33:L33) -> 0
A34: =DETAILS!#REF! -> #REF! | B34: =DETAILS!#REF! -> #REF! | U34: =SUM(C34:L34) -> 0
A35: =DETAILS!A18 -> 1905 | B35: =DETAILS!B18 -> RAVNOOR KAUR | U35: =SUM(C35:L35) -> 0
A36: =DETAILS!#REF! -> #REF! | B36: =DETAILS!#REF! -> #REF! | U36: =SUM(C36:L36) -> 0
A37: =DETAILS!#REF! -> #REF! | B37: =DETAILS!#REF! -> #REF! | U37: =SUM(C37:L37) -> 0
A38: =DETAILS!#REF! -> #REF! | B38: =DETAILS!#REF! -> #REF! | U38: =SUM(C38:L38) -> 0
A39: =DETAILS!A19 -> 1874 | B39: =DETAILS!B19 -> SEHRISH | U39: =SUM(C39:L39) -> 0
A40: =DETAILS!A20 -> 0 | B40: =DETAILS!B20 -> 0 | U40: =SUM(C40:L40) -> 0
...

Sheet COMIPLE RESULT
A1: COMPILE TABULATION(2024-25) CLASS -NUR
A2: SR. NO. | B2: NAME | C2: ENGLISH WRITTEN | G2: ENGLISH ORAL | K2: ENGLISH DICTATION | O2: HINDI WRITTEN | S2: HINDI ORAL | W2: HINDI DICTATION | AA2: MATHS WRITTEN | AE2: MATHS ORAL | AI2: EVS | AM2: CONVERSATION | AQ2: GK | AU2: DRAWING | AY2: RHYMES | BC2: PT. & GAMES | BG2: MORAL VALUES | BK2: ATTENDANCE | BM2: REMARKS
C3: UT-I | D3: HY | E3: UT-II | F3: ANNUAL | G3: UT-I | H3: HY | I3: UT-II | J3: ANNUAL | K3: UT-I | L3: HY | M3: UT-II | N3: ANNUAL | O3: UT-I | P3: HY | Q3: UT-II | R3: ANNUAL | S3: UT-I | T3: HY | U3: UT-II | V3: ANNUAL | W3: UT-I | X3: HY | Y3: UT-II | Z3: ANNUAL | AA3: UT-I | AB3: HY | AC3: UT-II | AD3: ANNUAL | AE3: UT-I | AF3: HY | AG3: UT-II | AH3: ANNUAL | AI3: UT-I | AJ3: HY | AK3: UT-II | AL3: ANNUAL | AM3: UT-I | AN3: HY | AO3: UT-II | AP3: ANNUAL | AQ3: UT-I | AR3: HY | AS3: UT-II | AT3: ANNUAL | AU3: UT-I | AV3: HY | AW3: UT-II | AX3: ANNUAL | AY3: UT-I | AZ3: HY | BA3: UT-II | BB3: ANNUAL | BC3: UT-I | BD3: HY | BE3: UT-II | BF3: ANNUAL | BG3: UT-I | BH3: HY | BI3: UT-II | BJ3: ANNUAL | BK3: PRESENT | BL3: WORKING DAYS
A4: =DETAILS!A3 -> 1944 | B4: =DETAILS!B3 -> AARUSH YADUVANSHI | C4: =VLOOKUP(A4,'UT-I'!$A$1:$EA$1758,3,0) -> NA | D4: =VLOOKUP($A4,'HALF YEARLY'!$1:$1048576,3,0) -> AB | E4: =VLOOKUP($A4,'UT-II'!$1:$1048576,3,0) -> 0 | F4: =VLOOKUP($A4,ANNUAL!$1:$1048576,3,0) -> 48 | G4: =VLOOKUP($A$4,'UT-I'!$A$1:$EA$1758,4,0) -> 17 | H4: =VLOOKUP($A4,'HALF YEARLY'!$1:$1048576,4,0) -> AB | I4: =VLOOKUP($A4,'UT-II'!$1:$1048576,4,0) -> 0 | J4: =VLOOKUP($A4,ANNUAL!$1:$1048576,4,0) -> 50 | K4: =VLOOKUP(A4,'UT-I'!$A$1:$EA$1758,5,0) -> NA | L4: =VLOOKUP($A4,'HALF YEARLY'!$1:$1048576,5,0) -> AB | M4: =VLOOKUP($A4,'UT-II'!$1:$1048576,5,0) -> 0 | N4: =VLOOKUP($A4,ANNUAL!$1:$1048576,5,0) -> 50 | O4: =VLOOKUP(A4,'UT-I'!$A$1:$EA$1758,6,0) -> NA | P4: =VLOOKUP($A4,'HALF YEARLY'!$1:$1048576,6,0) -> AB | Q4: =VLOOKUP($A4,'UT-II'!$1:$1048576,6,0) -> 0 | R4: =VLOOKUP($A4,ANNUAL!$1:$1048576,6,0) -> 49 | S4: =VLOOKUP(A4,'UT-I'!$A$1:$EA$1758,7,0) -> 17 | T4: =VLOOKUP($A4,'HALF YEARLY'!$1:$1048576,7,0) -> AB | U4: =VLOOKUP($A4,'UT-II'!$1:$1048576,7,0) -> 0 | V4: =VLOOKUP($A4,ANNUAL!$1:$1048576,7,0) -> 50 | W4: =VLOOKUP(A4,'UT-I'!$A$1:$EA$1758,8,0) -> NA | X4: =VLOOKUP($A4,'HALF YEARLY'!$1:$1048576,8,0) -> AB | Y4: =VLOOKUP($A4,'UT-II'!$1:$1048576,8,0) -> 0 | Z4: =VLOOKUP($A4,ANNUAL!$1:$1048576,8,0) -> 49 | AA4: =VLOOKUP(A4,'UT-I'!$A$1:$EA$1758,9,0) -> NA | AB4: =VLOOKUP($A4,'HALF YEARLY'!$1:$1048576,9,0) -> AB | AC4: =VLOOKUP($A4,'UT-II'!$1:$1048576,9,0) -> 0 | AD4: =VLOOKUP($A4,ANNUAL!$1:$1048576,9,0) -> 47 | AE4: =VLOOKUP(A4,'UT-I'!$A$1:$EA$1758,10,0) -> 17 | AF4: =VLOOKUP($A4,'HALF YEARLY'!$1:$1048576,10,0) -> AB | AG4: =VLOOKUP($A4,'UT-II'!$1:$1048576,10,0) -> 0 | AH4: =VLOOKUP($A4,ANNUAL!$1:$1048576,10,0) -> 45 | AI4: =VLOOKUP(A4,'UT-I'!$A$1:$EA$1758,11,0) -> 17 | AJ4: =VLOOKUP($A4,'HALF YEARLY'!$1:$1048576,11,0) -> AB | AK4: =VLOOKUP($A4,'UT-II'!$1:$1048576,11,0) -> 0 | AL4: =VLOOKUP($A4,ANNUAL!$1:$1048576,11,0) -> 45 | AM4: =VLOOKUP(A4,'UT-I'!$A$1:$EA$1758,12,0) -> 17 | AN4: =VLOOKUP($A4,'HALF YEARLY'!$1:$1048576,12,0) -> AB | AO4: =VLOOKUP($A4,'UT-II'!$1:$1048576,12,0) -> 0 | AP4: =VLOOKUP($A4,ANNUAL!$1:$1048576,12,0) -> 50 | AQ4: =VLOOKUP(A4,'UT-I'!$A$1:$EA$1758,13,0) -> AB | AR4: =VLOOKUP($A4,'HALF YEARLY'!$1:$1048576,13,0) -> AB | AS4: =VLOOKUP($A4,'UT-II'!$1:$1048576,13,0) -> 0 | AT4: =VLOOKUP($A4,ANNUAL!$1:$1048576,13,0) -> A | AU4: =VLOOKUP(A4,'UT-I'!$A$1:$EA$1758,14,0) -> NA | AV4: =VLOOKUP($A4,'HALF YEARLY'!$1:$1048576,14,0) -> AB | AW4: =VLOOKUP($A4,'UT-II'!$1:$1048576,14,0) -> 0 | AX4: =VLOOKUP($A4,ANNUAL!$1:$1048576,14,0) -> A | AY4: =VLOOKUP(A4,'UT-I'!$A$1:$EA$1758,15,0) -> B | AZ4: =VLOOKUP($A4,'HALF YEARLY'!$1:$1048576,15,0) -> AB | BA4: =VLOOKUP($A4,'UT-II'!$1:$1048576,15,0) -> 0 | BB4: =VLOOKUP($A4,ANNUAL!$1:$1048576,15,0) -> A | BC4: =VLOOKUP(A4,'UT-I'!$A$1:$EA$1758,16,0) -> B | BD4: =VLOOKUP($A4,'HALF YEARLY'!$1:$1048576,16,0) -> AB | BE4: =VLOOKUP($A4,'UT-II'!$1:$1048576,16,0) -> 0 | BF4: =VLOOKUP($A4,ANNUAL!$1:$1048576,16,0) -> A | BG4: =VLOOKUP(A4,'UT-I'!$A$1:$EA$1758,17,0) -> 85 | BH4: =VLOOKUP($A4,'HALF YEARLY'!$1:$1048576,17,0) -> 0 | BI4: =VLOOKUP($A4,'UT-II'!$1:$1048576,17,0) -> 0 | BJ4: =VLOOKUP($A4,ANNUAL!$1:$1048576,17,0) -> A | BK4: =VLOOKUP($A4,ANNUAL!$1:$1048576,18,0) -> 159 | BL4: =VLOOKUP($A4,ANNUAL!$1:$1048576,19,0) -> 214 | BM4: =VLOOKUP($A4,ANNUAL!$1:$1048576,20,0) -> Great Potential- Stay Focused!
A5: =DETAILS!#REF! -> #REF! | B5: =DETAILS!#REF! -> #REF! | C5: =VLOOKUP(A5,'UT-I'!$A$1:$EA$1758,3,0) -> #REF! | D5: =VLOOKUP($A5,'HALF YEARLY'!$1:$1048576,3,0) -> #REF! | E5: =VLOOKUP($A5,'UT-II'!$1:$1048576,3,0) -> #REF! | F5: =VLOOKUP($A5,ANNUAL!$1:$1048576,3,0) -> #REF! | G5: =VLOOKUP(A5,'UT-I'!$A$1:$EA$1758,4,0) -> #REF! | H5: =VLOOKUP($A5,'HALF YEARLY'!$1:$1048576,4,0) -> #REF! | I5: =VLOOKUP($A5,'UT-II'!$1:$1048576,4,0) -> #REF! | J5: =VLOOKUP($A5,ANNUAL!$1:$1048576,4,0) -> #REF! | K5: =VLOOKUP(A5,'UT-I'!$A$1:$EA$1758,5,0) -> #REF! | L5: =VLOOKUP($A5,'HALF YEARLY'!$1:$1048576,5,0) -> #REF! | M5: =VLOOKUP($A5,'UT-II'!$1:$1048576,5,0) -> #REF! | N5: =VLOOKUP($A5,ANNUAL!$1:$1048576,5,0) -> #REF! | O5: =VLOOKUP(A5,'UT-I'!$A$1:$EA$1758,6,0) -> #REF! | P5: =VLOOKUP($A5,'HALF YEARLY'!$1:$1048576,6,0) -> #REF! | Q5: =VLOOKUP($A5,'UT-II'!$1:$1048576,6,0) -> #REF! | R5: =VLOOKUP($A5,ANNUAL!$1:$1048576,6,0) -> #REF! | S5: =VLOOKUP(A5,'UT-I'!$A$1:$EA$1758,7,0) -> #REF! | T5: =VLOOKUP($A5,'HALF YEARLY'!$1:$1048576,7,0) -> #REF! | U5: =VLOOKUP($A5,'UT-II'!$1:$1048576,7,0) -> #REF! | V5: =VLOOKUP($A5,ANNUAL!$1:$1048576,7,0) -> #REF! | W5: =VLOOKUP(A5,'UT-I'!$A$1:$EA$1758,8,0) -> #REF! | X5: =VLOOKUP($A5,'HALF YEARLY'!$1:$1048576,8,0) -> #REF! | Y5: =VLOOKUP($A5,'UT-II'!$1:$1048576,8,0) -> #REF! | Z5: =VLOOKUP($A5,ANNUAL!$1:$1048576,8,0) -> #REF! | AA5: =VLOOKUP(A5,'UT-I'!$A$1:$EA$1758,9,0) -> #REF! | AB5: =VLOOKUP($A5,'HALF YEARLY'!$1:$1048576,9,0) -> #REF! | AC5: =VLOOKUP($A5,'UT-II'!$1:$1048576,9,0) -> #REF! | AD5: =VLOOKUP($A5,ANNUAL!$1:$1048576,9,0) -> #REF! | AE5: =VLOOKUP(A5,'UT-I'!$A$1:$EA$1758,10,0) -> #REF! | AF5: =VLOOKUP($A5,'HALF YEARLY'!$1:$1048576,10,0) -> #REF! | AG5: =VLOOKUP($A5,'UT-II'!$1:$1048576,10,0) -> #REF! | AH5: =VLOOKUP($A5,ANNUAL!$1:$1048576,10,0) -> #REF! | AI5: =VLOOKUP(A5,'UT-I'!$A$1:$EA$1758,11,0) -> #REF! | AJ5: =VLOOKUP($A5,'HALF YEARLY'!$1:$1048576,11,0) -> #REF! | AK5: =VLOOKUP($A5,'UT-II'!$1:$1048576,11,0) -> #REF! | AL5: =VLOOKUP($A5,ANNUAL!$1:$1048576,11,0) -> #REF! | AM5: =VLOOKUP(A5,'UT-I'!$A$1:$EA$1758,12,0) -> #REF! | AN5: =VLOOKUP($A5,'HALF YEARLY'!$1:$1048576,12,0) -> #REF! | AO5: =VLOOKUP($A5,'UT-II'!$1:$1048576,12,0) -> #REF! | AP5: =VLOOKUP($A5,ANNUAL!$1:$1048576,12,0) -> #REF! | AQ5: =VLOOKUP(A5,'UT-I'!$A$1:$EA$1758,13,0) -> #REF! | AR5: =VLOOKUP($A5,'HALF YEARLY'!$1:$1048576,13,0) -> #REF! | AS5: =VLOOKUP($A5,'UT-II'!$1:$1048576,13,0) -> #REF! | AT5: =VLOOKUP($A5,ANNUAL!$1:$1048576,13,0) -> #REF! | AU5: =VLOOKUP(A5,'UT-I'!$A$1:$EA$1758,14,0) -> #REF! | AV5: =VLOOKUP($A5,'HALF YEARLY'!$1:$1048576,14,0) -> #REF! | AW5: =VLOOKUP($A5,'UT-II'!$1:$1048576,14,0) -> #REF! | AX5: =VLOOKUP($A5,ANNUAL!$1:$1048576,14,0) -> #REF! | AY5: =VLOOKUP(A5,'UT-I'!$A$1:$EA$1758,15,0) -> #REF! | AZ5: =VLOOKUP($A5,'HALF YEARLY'!$1:$1048576,15,0) -> #REF! | BA5: =VLOOKUP($A5,'UT-II'!$1:$1048576,15,0) -> #REF! | BB5: =VLOOKUP($A5,ANNUAL!$1:$1048576,15,0) -> #REF! | BC5: =VLOOKUP(A5,'UT-I'!$A$1:$EA$1758,16,0) -> #REF! | BD5: =VLOOKUP($A5,'HALF YEARLY'!$1:$1048576,16,0) -> #REF! | BE5: =VLOOKUP($A5,'UT-II'!$1:$1048576,16,0) -> #REF! | BF5: =VLOOKUP($A5,ANNUAL!$1:$1048576,16,0) -> #REF! | BG5: =VLOOKUP(A5,'UT-I'!$A$1:$EA$1758,17,0) -> #REF! | BH5: =VLOOKUP($A5,'HALF YEARLY'!$1:$1048576,17,0) -> #REF! | BI5: =VLOOKUP($A5,'UT-II'!$1:$1048576,17,0) -> #REF! | BJ5: =VLOOKUP($A5,ANNUAL!$1:$1048576,17,0) -> #REF! | BK5: =VLOOKUP($A5,ANNUAL!$1:$1048576,18,0) -> #REF! | BL5: =VLOOKUP($A5,ANNUAL!$1:$1048576,19,0) -> #REF! | BM5: =VLOOKUP($A5,ANNUAL!$1:$1048576,20,0) -> #REF!
A6: =DETAILS!#REF! -> #REF! | B6: =DETAILS!#REF! -> #REF! | C6: =VLOOKUP(A6,'UT-I'!$A$1:$EA$1758,3,0) -> #REF! | D6: =VLOOKUP($A6,'HALF YEARLY'!$1:$1048576,3,0) -> #REF! | E6: =VLOOKUP($A6,'UT-II'!$1:$1048576,3,0) -> #REF! | F6: =VLOOKUP($A6,ANNUAL!$1:$1048576,3,0) -> #REF! | G6: =VLOOKUP(A6,'UT-I'!$A$1:$EA$1758,4,0) -> #REF! | H6: =VLOOKUP($A6,'HALF YEARLY'!$1:$1048576,4,0) -> #REF! | I6: =VLOOKUP($A6,'UT-II'!$1:$1048576,4,0) -> #REF! | J6: =VLOOKUP($A6,ANNUAL!$1:$1048576,4,0) -> #REF! | K6: =VLOOKUP(A6,'UT-I'!$A$1:$EA$1758,5,0) -> #REF! | L6: =VLOOKUP($A6,'HALF YEARLY'!$1:$1048576,5,0) -> #REF! | M6: =VLOOKUP($A6,'UT-II'!$1:$1048576,5,0) -> #REF! | N6: =VLOOKUP($A6,ANNUAL!$1:$1048576,5,0) -> #REF! | O6: =VLOOKUP(A6,'UT-I'!$A$1:$EA$1758,6,0) -> #REF! | P6: =VLOOKUP($A6,'HALF YEARLY'!$1:$1048576,6,0) -> #REF! | Q6: =VLOOKUP($A6,'UT-II'!$1:$1048576,6,0) -> #REF! | R6: =VLOOKUP($A6,ANNUAL!$1:$1048576,6,0) -> #REF! | S6: =VLOOKUP(A6,'UT-I'!$A$1:$EA$1758,7,0) -> #REF! | T6: =VLOOKUP($A6,'HALF YEARLY'!$1:$1048576,7,0) -> #REF! | U6: =VLOOKUP($A6,'UT-II'!$1:$1048576,7,0) -> #REF! | V6: =VLOOKUP($A6,ANNUAL!$1:$1048576,7,0) -> #REF! | W6: =VLOOKUP(A6,'UT-I'!$A$1:$EA$1758,8,0) -> #REF! | X6: =VLOOKUP($A6,'HALF YEARLY'!$1:$1048576,8,0) -> #REF! | Y6: =VLOOKUP($A6,'UT-II'!$1:$1048576,8,0) -> #REF! | Z6: =VLOOKUP($A6,ANNUAL!$1:$1048576,8,0) -> #REF! | AA6: =VLOOKUP(A6,'UT-I'!$A$1:$EA$1758,9,0) -> #REF! | AB6: =VLOOKUP($A6,'HALF YEARLY'!$1:$1048576,9,0) -> #REF! | AC6: =VLOOKUP($A6,'UT-II'!$1:$1048576,9,0) -> #REF! | AD6: =VLOOKUP($A6,ANNUAL!$1:$1048576,9,0) -> #REF! | AE6: =VLOOKUP(A6,'UT-I'!$A$1:$EA$1758,10,0) -> #REF! | AF6: =VLOOKUP($A6,'HALF YEARLY'!$1:$1048576,10,0) -> #REF! | AG6: =VLOOKUP($A6,'UT-II'!$1:$1048576,10,0) -> #REF! | AH6: =VLOOKUP($A6,ANNUAL!$1:$1048576,10,0) -> #REF! | AI6: =VLOOKUP(A6,'UT-I'!$A$1:$EA$1758,11,0) -> #REF! | AJ6: =VLOOKUP($A6,'HALF YEARLY'!$1:$1048576,11,0) -> #REF! | AK6: =VLOOKUP($A6,'UT-II'!$1:$1048576,11,0) -> #REF! | AL6: =VLOOKUP($A6,ANNUAL!$1:$1048576,11,0) -> #REF! | AM6: =VLOOKUP(A6,'UT-I'!$A$1:$EA$1758,12,0) -> #REF! | AN6: =VLOOKUP($A6,'HALF YEARLY'!$1:$1048576,12,0) -> #REF! | AO6: =VLOOKUP($A6,'UT-II'!$1:$1048576,12,0) -> #REF! | AP6: =VLOOKUP($A6,ANNUAL!$1:$1048576,12,0) -> #REF! | AQ6: =VLOOKUP(A6,'UT-I'!$A$1:$EA$1758,13,0) -> #REF! | AR6: =VLOOKUP($A6,'HALF YEARLY'!$1:$1048576,13,0) -> #REF! | AS6: =VLOOKUP($A6,'UT-II'!$1:$1048576,13,0) -> #REF! | AT6: =VLOOKUP($A6,ANNUAL!$1:$1048576,13,0) -> #REF! | AU6: =VLOOKUP(A6,'UT-I'!$A$1:$EA$1758,14,0) -> #REF! | AV6: =VLOOKUP($A6,'HALF YEARLY'!$1:$1048576,14,0) -> #REF! | AW6: =VLOOKUP($A6,'UT-II'!$1:$1048576,14,0) -> #REF! | AX6: =VLOOKUP($A6,ANNUAL!$1:$1048576,14,0) -> #REF! | AY6: =VLOOKUP(A6,'UT-I'!$A$1:$EA$1758,15,0) -> #REF! | AZ6: =VLOOKUP($A6,'HALF YEARLY'!$1:$1048576,15,0) -> #REF! | BA6: =VLOOKUP($A6,'UT-II'!$1:$1048576,15,0) -> #REF! | BB6: =VLOOKUP($A6,ANNUAL!$1:$1048576,15,0) -> #REF! | BC6: =VLOOKUP(A6,'UT-I'!$A$1:$EA$1758,16,0) -> #REF! | BD6: =VLOOKUP($A6,'HALF YEARLY'!$1:$1048576,16,0) -> #REF! | BE6: =VLOOKUP($A6,'UT-II'!$1:$1048576,16,0) -> #REF! | BF6: =VLOOKUP($A6,ANNUAL!$1:$1048576,16,0) -> #REF! | BG6: =VLOOKUP(A6,'UT-I'!$A$1:$EA$1758,17,0) -> #REF! | BH6: =VLOOKUP($A6,'HALF YEARLY'!$1:$1048576,17,0) -> #REF! | BI6: =VLOOKUP($A6,'UT-II'!$1:$1048576,17,0) -> #REF! | BJ6: =VLOOKUP($A6,ANNUAL!$1:$1048576,17,0) -> #REF! | BK6: =VLOOKUP($A6,ANNUAL!$1:$1048576,18,0) -> #REF! | BL6: =VLOOKUP($A6,ANNUAL!$1:$1048576,19,0) -> #REF! | BM6: =VLOOKUP($A6,ANNUAL!$1:$1048576,20,0) -> #REF!
A7: =DETAILS!A4 -> 1940 | B7: =DETAILS!B4 -> ADITRI CHAUDHARI | C7: =VLOOKUP(A7,'UT-I'!$A$1:$EA$1758,3,0) -> NA | D7: =VLOOKUP($A7,'HALF YEARLY'!$1:$1048576,3,0) -> 41 | E7: =VLOOKUP($A7,'UT-II'!$1:$1048576,3,0) -> 0 | F7: =VLOOKUP($A7,ANNUAL!$1:$1048576,3,0) -> 35 | G7: =VLOOKUP(A7,'UT-I'!$A$1:$EA$1758,4,0) -> 17 | H7: =VLOOKUP($A7,'HALF YEARLY'!$1:$1048576,4,0) -> 30 | I7: =VLOOKUP($A7,'UT-II'!$1:$1048576,4,0) -> 0 | J7: =VLOOKUP($A7,ANNUAL!$1:$1048576,4,0) -> 40 | K7: =VLOOKUP(A7,'UT-I'!$A$1:$EA$1758,5,0) -> NA | L7: =VLOOKUP($A7,'HALF YEARLY'!$1:$1048576,5,0) -> 21 | M7: =VLOOKUP($A7,'UT-II'!$1:$1048576,5,0) -> 0 | N7: =VLOOKUP($A7,ANNUAL!$1:$1048576,5,0) -> 30 | O7: =VLOOKUP(A7,'UT-I'!$A$1:$EA$1758,6,0) -> NA | P7: =VLOOKUP($A7,'HALF YEARLY'!$1:$1048576,6,0) -> 43 | Q7: =VLOOKUP($A7,'UT-II'!$1:$1048576,6,0) -> 0 | R7: =VLOOKUP($A7,ANNUAL!$1:$1048576,6,0) -> 34 | S7: =VLOOKUP(A7,'UT-I'!$A$1:$EA$1758,7,0) -> 17 | T7: =VLOOKUP($A7,'HALF YEARLY'!$1:$1048576,7,0) -> 30 | U7: =VLOOKUP($A7,'UT-II'!$1:$1048576,7,0) -> 0 | V7: =VLOOKUP($A7,ANNUAL!$1:$1048576,7,0) -> 40 | W7: =VLOOKUP(A7,'UT-I'!$A$1:$EA$1758,8,0) -> NA | X7: =VLOOKUP($A7,'HALF YEARLY'!$1:$1048576,8,0) -> 25 | Y7: =VLOOKUP($A7,'UT-II'!$1:$1048576,8,0) -> 0 | Z7: =VLOOKUP($A7,ANNUAL!$1:$1048576,8,0) -> 42 | AA7: =VLOOKUP(A7,'UT-I'!$A$1:$EA$1758,9,0) -> NA | AB7: =VLOOKUP($A7,'HALF YEARLY'!$1:$1048576,9,0) -> 37 | AC7: =VLOOKUP($A7,'UT-II'!$1:$1048576,9,0) -> 0 | AD7: =VLOOKUP($A7,ANNUAL!$1:$1048576,9,0) -> 46 | AE7: =VLOOKUP(A7,'UT-I'!$A$1:$EA$1758,10,0) -> 17 | AF7: =VLOOKUP($A7,'HALF YEARLY'!$1:$1048576,10,0) -> 20 | AG7: =VLOOKUP($A7,'UT-II'!$1:$1048576,10,0) -> 0 | AH7: =VLOOKUP($A7,ANNUAL!$1:$1048576,10,0) -> 35 | AI7: =VLOOKUP(A7,'UT-I'!$A$1:$EA$1758,11,0) -> 17 | AJ7: =VLOOKUP($A7,'HALF YEARLY'!$1:$1048576,11,0) -> 20 | AK7: =VLOOKUP($A7,'UT-II'!$1:$1048576,11,0) -> 0 | AL7: =VLOOKUP($A7,ANNUAL!$1:$1048576,11,0) -> 40 | AM7: =VLOOKUP(A7,'UT-I'!$A$1:$EA$1758,12,0) -> 17 | AN7: =VLOOKUP($A7,'HALF YEARLY'!$1:$1048576,12,0) -> 20 | AO7: =VLOOKUP($A7,'UT-II'!$1:$1048576,12,0) -> 0 | AP7: =VLOOKUP($A7,ANNUAL!$1:$1048576,12,0) -> 30 | AQ7: =VLOOKUP(A7,'UT-I'!$A$1:$EA$1758,13,0) -> D | AR7: =VLOOKUP($A7,'HALF YEARLY'!$1:$1048576,13,0) -> D | AS7: =VLOOKUP($A7,'UT-II'!$1:$1048576,13,0) -> 0 | AT7: =VLOOKUP($A7,ANNUAL!$1:$1048576,13,0) -> A | AU7: =VLOOKUP(A7,'UT-I'!$A$1:$EA$1758,14,0) -> NA | AV7: =VLOOKUP($A7,'HALF YEARLY'!$1:$1048576,14,0) -> C | AW7: =VLOOKUP($A7,'UT-II'!$1:$1048576,14,0) -> 0 | AX7: =VLOOKUP($A7,ANNUAL!$1:$1048576,14,0) -> A | AY7: =VLOOKUP(A7,'UT-I'!$A$1:$EA$1758,15,0) -> D | AZ7: =VLOOKUP($A7,'HALF YEARLY'!$1:$1048576,15,0) -> A | BA7: =VLOOKUP($A7,'UT-II'!$1:$1048576,15,0) -> 0 | BB7: =VLOOKUP($A7,ANNUAL!$1:$1048576,15,0) -> A | BC7: =VLOOKUP(A7,'UT-I'!$A$1:$EA$1758,16,0) -> D | BD7: =VLOOKUP($A7,'HALF YEARLY'!$1:$1048576,16,0) -> B | BE7: =VLOOKUP($A7,'UT-II'!$1:$1048576,16,0) -> 0 | BF7: =VLOOKUP($A7,ANNUAL!$1:$1048576,16,0) -> A | BG7: =VLOOKUP(A7,'UT-I'!$A$1:$EA$1758,17,0) -> 85 | BH7: =VLOOKUP($A7,'HALF YEARLY'!$1:$1048576,17,0) -> 287 | BI7: =VLOOKUP($A7,'UT-II'!$1:$1048576,17,0) -> 0 | BJ7: =VLOOKUP($A7,ANNUAL!$1:$1048576,17,0) -> A | BK7: =VLOOKUP($A7,ANNUAL!$1:$1048576,18,0) -> 129 | BL7: =VLOOKUP($A7,ANNUAL!$1:$1048576,19,0) -> 153 | BM7: =VLOOKUP($A7,ANNUAL!$1:$1048576,20,0) -> Needs improvement.
A8: =DETAILS!A5 -> 1948 | B8: =DETAILS!B5 -> AHEM | C8: =VLOOKUP(A8,'UT-I'!$A$1:$EA$1758,3,0) -> NA | D8: =VLOOKUP($A8,'HALF YEARLY'!$1:$1048576,3,0) -> 46 | E8: =VLOOKUP($A8,'UT-II'!$1:$1048576,3,0) -> 0 | F8: =VLOOKUP($A8,ANNUAL!$1:$1048576,3,0) -> 47 | G8: =VLOOKUP(A8,'UT-I'!$A$1:$EA$1758,4,0) -> NA | H8: =VLOOKUP($A8,'HALF YEARLY'!$1:$1048576,4,0) -> 35 | I8: =VLOOKUP($A8,'UT-II'!$1:$1048576,4,0) -> 0 | J8: =VLOOKUP($A8,ANNUAL!$1:$1048576,4,0) -> 50 | K8: =VLOOKUP(A8,'UT-I'!$A$1:$EA$1758,5,0) -> 50 | L8: =VLOOKUP($A8,'HALF YEARLY'!$1:$1048576,5,0) -> 48 | M8: =VLOOKUP($A8,'UT-II'!$1:$1048576,5,0) -> 0 | N8: =VLOOKUP($A8,ANNUAL!$1:$1048576,5,0) -> 47 | O8: =VLOOKUP(A8,'UT-I'!$A$1:$EA$1758,6,0) -> NA | P8: =VLOOKUP($A8,'HALF YEARLY'!$1:$1048576,6,0) -> 48 | Q8: =VLOOKUP($A8,'UT-II'!$1:$1048576,6,0) -> 0 | R8: =VLOOKUP($A8,ANNUAL!$1:$1048576,6,0) -> 50 | S8: =VLOOKUP(A8,'UT-I'!$A$1:$EA$1758,7,0) -> NA | T8: =VLOOKUP($A8,'HALF YEARLY'!$1:$1048576,7,0) -> 45 | U8: =VLOOKUP($A8,'UT-II'!$1:$1048576,7,0) -> 0 | V8: =VLOOKUP($A8,ANNUAL!$1:$1048576,7,0) -> 50 | W8: =VLOOKUP(A8,'UT-I'!$A$1:$EA$1758,8,0) -> NA | X8: =VLOOKUP($A8,'HALF YEARLY'!$1:$1048576,8,0) -> 49 | Y8: =VLOOKUP($A8,'UT-II'!$1:$1048576,8,0) -> 0 | Z8: =VLOOKUP($A8,ANNUAL!$1:$1048576,8,0) -> 50 | AA8: =VLOOKUP(A8,'UT-I'!$A$1:$EA$1758,9,0) -> NA | AB8: =VLOOKUP($A8,'HALF YEARLY'!$1:$1048576,9,0) -> 42 | AC8: =VLOOKUP($A8,'UT-II'!$1:$1048576,9,0) -> 0 | AD8: =VLOOKUP($A8,ANNUAL!$1:$1048576,9,0) -> 50 | AE8: =VLOOKUP(A8,'UT-I'!$A$1:$EA$1758,10,0) -> NA | AF8: =VLOOKUP($A8,'HALF YEARLY'!$1:$1048576,10,0) -> 35 | AG8: =VLOOKUP($A8,'UT-II'!$1:$1048576,10,0) -> 0 | AH8: =VLOOKUP($A8,ANNUAL!$1:$1048576,10,0) -> 50 | AI8: =VLOOKUP(A8,'UT-I'!$A$1:$EA$1758,11,0) -> NA | AJ8: =VLOOKUP($A8,'HALF YEARLY'!$1:$1048576,11,0) -> 30 | AK8: =VLOOKUP($A8,'UT-II'!$1:$1048576,11,0) -> 0 | AL8: =VLOOKUP($A8,ANNUAL!$1:$1048576,11,0) -> 50 | AM8: =VLOOKUP(A8,'UT-I'!$A$1:$EA$1758,12,0) -> NA | AN8: =VLOOKUP($A8,'HALF YEARLY'!$1:$1048576,12,0) -> 40 | AO8: =VLOOKUP($A8,'UT-II'!$1:$1048576,12,0) -> 0 | AP8: =VLOOKUP($A8,ANNUAL!$1:$1048576,12,0) -> 45 | AQ8: =VLOOKUP(A8,'UT-I'!$A$1:$EA$1758,13,0) -> NA | AR8: =VLOOKUP($A8,'HALF YEARLY'!$1:$1048576,13,0) -> A | AS8: =VLOOKUP($A8,'UT-II'!$1:$1048576,13,0) -> 0 | AT8: =VLOOKUP($A8,ANNUAL!$1:$1048576,13,0) -> A | AU8: =VLOOKUP(A8,'UT-I'!$A$1:$EA$1758,14,0) -> NA | AV8: =VLOOKUP($A8,'HALF YEARLY'!$1:$1048576,14,0) -> A | AW8: =VLOOKUP($A8,'UT-II'!$1:$1048576,14,0) -> 0 | AX8: =VLOOKUP($A8,ANNUAL!$1:$1048576,14,0) -> A | AY8: =VLOOKUP(A8,'UT-I'!$A$1:$EA$1758,15,0) -> NA | AZ8: =VLOOKUP($A8,'HALF YEARLY'!$1:$1048576,15,0) -> A | BA8: =VLOOKUP($A8,'UT-II'!$1:$1048576,15,0) -> 0 | BB8: =VLOOKUP($A8,ANNUAL!$1:$1048576,15,0) -> A | BC8: =VLOOKUP(A8,'UT-I'!$A$1:$EA$1758,16,0) -> NA | BD8: =VLOOKUP($A8,'HALF YEARLY'!$1:$1048576,16,0) -> A | BE8: =VLOOKUP($A8,'UT-II'!$1:$1048576,16,0) -> 0 | BF8: =VLOOKUP($A8,ANNUAL!$1:$1048576,16,0) -> A | BG8: =VLOOKUP(A8,'UT-I'!$A$1:$EA$1758,17,0) -> 50 | BH8: =VLOOKUP($A8,'HALF YEARLY'!$1:$1048576,17,0) -> 418 | BI8: =VLOOKUP($A8,'UT-II'!$1:$1048576,17,0) -> 0 | BJ8: =VLOOKUP($A8,ANNUAL!$1:$1048576,17,0) -> A | BK8: =VLOOKUP($A8,ANNUAL!$1:$1048576,18,0) -> 174 | BL8: =VLOOKUP($A8,ANNUAL!$1:$1048576,19,0) -> 214 | BM8: =VLOOKUP($A8,ANNUAL!$1:$1048576,20,0) -> Excellent progress this year!
A9: =DETAILS!#REF! -> #REF! | B9: =DETAILS!#REF! -> #REF! | C9: =VLOOKUP(A9,'UT-I'!$A$1:$EA$1758,3,0) -> #REF! | D9: =VLOOKUP($A9,'HALF YEARLY'!$1:$1048576,3,0) -> #REF! | E9: =VLOOKUP($A9,'UT-II'!$1:$1048576,3,0) -> #REF! | F9: =VLOOKUP($A9,ANNUAL!$1:$1048576,3,0) -> #REF! | G9: =VLOOKUP(A9,'UT-I'!$A$1:$EA$1758,4,0) -> #REF! | H9: =VLOOKUP($A9,'HALF YEARLY'!$1:$1048576,4,0) -> #REF! | I9: =VLOOKUP($A9,'UT-II'!$1:$1048576,4,0) -> #REF! | J9: =VLOOKUP($A9,ANNUAL!$1:$1048576,4,0) -> #REF! | K9: =VLOOKUP(A9,'UT-I'!$A$1:$EA$1758,5,0) -> #REF! | L9: =VLOOKUP($A9,'HALF YEARLY'!$1:$1048576,5,0) -> #REF! | M9: =VLOOKUP($A9,'UT-II'!$1:$1048576,5,0) -> #REF! | N9: =VLOOKUP($A9,ANNUAL!$1:$1048576,5,0) -> #REF! | O9: =VLOOKUP(A9,'UT-I'!$A$1:$EA$1758,6,0) -> #REF! | P9: =VLOOKUP($A9,'HALF YEARLY'!$1:$1048576,6,0) -> #REF! | Q9: =VLOOKUP($A9,'UT-II'!$1:$1048576,6,0) -> #REF! | R9: =VLOOKUP($A9,ANNUAL!$1:$1048576,6,0) -> #REF! | S9: =VLOOKUP(A9,'UT-I'!$A$1:$EA$1758,7,0) -> #REF! | T9: =VLOOKUP($A9,'HALF YEARLY'!$1:$1048576,7,0) -> #REF! | U9: =VLOOKUP($A9,'UT-II'!$1:$1048576,7,0) -> #REF! | V9: =VLOOKUP($A9,ANNUAL!$1:$1048576,7,0) -> #REF! | W9: =VLOOKUP(A9,'UT-I'!$A$1:$EA$1758,8,0) -> #REF! | X9: =VLOOKUP($A9,'HALF YEARLY'!$1:$1048576,8,0) -> #REF! | Y9: =VLOOKUP($A9,'UT-II'!$1:$1048576,8,0) -> #REF! | Z9: =VLOOKUP($A9,ANNUAL!$1:$1048576,8,0) -> #REF! | AA9: =VLOOKUP(A9,'UT-I'!$A$1:$EA$1758,9,0) -> #REF! | AB9: =VLOOKUP($A9,'HALF YEARLY'!$1:$1048576,9,0) -> #REF! | AC9: =VLOOKUP($A9,'UT-II'!$1:$1048576,9,0) -> #REF! | AD9: =VLOOKUP($A9,ANNUAL!$1:$1048576,9,0) -> #REF! | AE9: =VLOOKUP(A9,'UT-I'!$A$1:$EA$1758,10,0) -> #REF! | AF9: =VLOOKUP($A9,'HALF YEARLY'!$1:$1048576,10,0) -> #REF! | AG9: =VLOOKUP($A9,'UT-II'!$1:$1048576,10,0) -> #REF! | AH9: =VLOOKUP($A9,ANNUAL!$1:$1048576,10,0) -> #REF! | AI9: =VLOOKUP(A9,'UT-I'!$A$1:$EA$1758,11,0) -> #REF! | AJ9: =VLOOKUP($A9,'HALF YEARLY'!$1:$1048576,11,0) -> #REF! | AK9: =VLOOKUP($A9,'UT-II'!$1:$1048576,11,0) -> #REF! | AL9: =VLOOKUP($A9,ANNUAL!$1:$1048576,11,0) -> #REF! | AM9: =VLOOKUP(A9,'UT-I'!$A$1:$EA$1758,12,0) -> #REF! | AN9: =VLOOKUP($A9,'HALF YEARLY'!$1:$1048576,12,0) -> #REF! | AO9: =VLOOKUP($A9,'UT-II'!$1:$1048576,12,0) -> #REF! | AP9: =VLOOKUP($A9,ANNUAL!$1:$1048576,12,0) -> #REF! | AQ9: =VLOOKUP(A9,'UT-I'!$A$1:$EA$1758,13,0) -> #REF! | AR9: =VLOOKUP($A9,'HALF YEARLY'!$1:$1048576,13,0) -> #REF! | AS9: =VLOOKUP($A9,'UT-II'!$1:$1048576,13,0) -> #REF! | AT9: =VLOOKUP($A9,ANNUAL!$1:$1048576,13,0) -> #REF! | AU9: =VLOOKUP(A9,'UT-I'!$A$1:$EA$1758,14,0) -> #REF! | AV9: =VLOOKUP($A9,'HALF YEARLY'!$1:$1048576,14,0) -> #REF! | AW9: =VLOOKUP($A9,'UT-II'!$1:$1048576,14,0) -> #REF! | AX9: =VLOOKUP($A9,ANNUAL!$1:$1048576,14,0) -> #REF! | AY9: =VLOOKUP(A9,'UT-I'!$A$1:$EA$1758,15,0) -> #REF! | AZ9: =VLOOKUP($A9,'HALF YEARLY'!$1:$1048576,15,0) -> #REF! | BA9: =VLOOKUP($A9,'UT-II'!$1:$1048576,15,0) -> #REF! | BB9: =VLOOKUP($A9,ANNUAL!$1:$1048576,15,0) -> #REF! | BC9: =VLOOKUP(A9,'UT-I'!$A$1:$EA$1758,16,0) -> #REF! | BD9: =VLOOKUP($A9,'HALF YEARLY'!$1:$1048576,16,0) -> #REF! | BE9: =VLOOKUP($A9,'UT-II'!$1:$1048576,16,0) -> #REF! | BF9: =VLOOKUP($A9,ANNUAL!$1:$1048576,16,0) -> #REF! | BG9: =VLOOKUP(A9,'UT-I'!$A$1:$EA$1758,17,0) -> #REF! | BH9: =VLOOKUP($A9,'HALF YEARLY'!$1:$1048576,17,0) -> #REF! | BI9: =VLOOKUP($A9,'UT-II'!$1:$1048576,17,0) -> #REF! | BJ9: =VLOOKUP($A9,ANNUAL!$1:$1048576,17,0) -> #REF! | BK9: =VLOOKUP($A9,ANNUAL!$1:$1048576,18,0) -> #REF! | BL9: =VLOOKUP($A9,ANNUAL!$1:$1048576,19,0) -> #REF! | BM9: =VLOOKUP($A9,ANNUAL!$1:$1048576,20,0) -> #REF!
A10: =DETAILS!#REF! -> #REF! | B10: =DETAILS!#REF! -> #REF! | C10: =VLOOKUP(A10,'UT-I'!$A$1:$EA$1758,3,0) -> #REF! | D10: =VLOOKUP($A10,'HALF YEARLY'!$1:$1048576,3,0) -> #REF! | E10: =VLOOKUP($A10,'UT-II'!$1:$1048576,3,0) -> #REF! | F10: =VLOOKUP($A10,ANNUAL!$1:$1048576,3,0) -> #REF! | G10: =VLOOKUP(A10,'UT-I'!$A$1:$EA$1758,4,0) -> #REF! | H10: =VLOOKUP($A10,'HALF YEARLY'!$1:$1048576,4,0) -> #REF! | I10: =VLOOKUP($A10,'UT-II'!$1:$1048576,4,0) -> #REF! | J10: =VLOOKUP($A10,ANNUAL!$1:$1048576,4,0) -> #REF! | K10: =VLOOKUP(A10,'UT-I'!$A$1:$EA$1758,5,0) -> #REF! | L10: =VLOOKUP($A10,'HALF YEARLY'!$1:$1048576,5,0) -> #REF! | M10: =VLOOKUP($A10,'UT-II'!$1:$1048576,5,0) -> #REF! | N10: =VLOOKUP($A10,ANNUAL!$1:$1048576,5,0) -> #REF! | O10: =VLOOKUP(A10,'UT-I'!$A$1:$EA$1758,6,0) -> #REF! | P10: =VLOOKUP($A10,'HALF YEARLY'!$1:$1048576,6,0) -> #REF! | Q10: =VLOOKUP($A10,'UT-II'!$1:$1048576,6,0) -> #REF! | R10: =VLOOKUP($A10,ANNUAL!$1:$1048576,6,0) -> #REF! | S10: =VLOOKUP(A10,'UT-I'!$A$1:$EA$1758,7,0) -> #REF! | T10: =VLOOKUP($A10,'HALF YEARLY'!$1:$1048576,7,0) -> #REF! | U10: =VLOOKUP($A10,'UT-II'!$1:$1048576,7,0) -> #REF! | V10: =VLOOKUP($A10,ANNUAL!$1:$1048576,7,0) -> #REF! | W10: =VLOOKUP(A10,'UT-I'!$A$1:$EA$1758,8,0) -> #REF! | X10: =VLOOKUP($A10,'HALF YEARLY'!$1:$1048576,8,0) -> #REF! | Y10: =VLOOKUP($A10,'UT-II'!$1:$1048576,8,0) -> #REF! | Z10: =VLOOKUP($A10,ANNUAL!$1:$1048576,8,0) -> #REF! | AA10: =VLOOKUP(A10,'UT-I'!$A$1:$EA$1758,9,0) -> #REF! | AB10: =VLOOKUP($A10,'HALF YEARLY'!$1:$1048576,9,0) -> #REF! | AC10: =VLOOKUP($A10,'UT-II'!$1:$1048576,9,0) -> #REF! | AD10: =VLOOKUP($A10,ANNUAL!$1:$1048576,9,0) -> #REF! | AE10: =VLOOKUP(A10,'UT-I'!$A$1:$EA$1758,10,0) -> #REF! | AF10: =VLOOKUP($A10,'HALF YEARLY'!$1:$1048576,10,0) -> #REF! | AG10: =VLOOKUP($A10,'UT-II'!$1:$1048576,10,0) -> #REF! | AH10: =VLOOKUP($A10,ANNUAL!$1:$1048576,10,0) -> #REF! | AI10: =VLOOKUP(A10,'UT-I'!$A$1:$EA$1758,11,0) -> #REF! | AJ10: =VLOOKUP($A10,'HALF YEARLY'!$1:$1048576,11,0) -> #REF! | AK10: =VLOOKUP($A10,'UT-II'!$1:$1048576,11,0) -> #REF! | AL10: =VLOOKUP($A10,ANNUAL!$1:$1048576,11,0) -> #REF! | AM10: =VLOOKUP(A10,'UT-I'!$A$1:$EA$1758,12,0) -> #REF! | AN10: =VLOOKUP($A10,'HALF YEARLY'!$1:$1048576,12,0) -> #REF! | AO10: =VLOOKUP($A10,'UT-II'!$1:$1048576,12,0) -> #REF! | AP10: =VLOOKUP($A10,ANNUAL!$1:$1048576,12,0) -> #REF! | AQ10: =VLOOKUP(A10,'UT-I'!$A$1:$EA$1758,13,0) -> #REF! | AR10: =VLOOKUP($A10,'HALF YEARLY'!$1:$1048576,13,0) -> #REF! | AS10: =VLOOKUP($A10,'UT-II'!$1:$1048576,13,0) -> #REF! | AT10: =VLOOKUP($A10,ANNUAL!$1:$1048576,13,0) -> #REF! | AU10: =VLOOKUP(A10,'UT-I'!$A$1:$EA$1758,14,0) -> #REF! | AV10: =VLOOKUP($A10,'HALF YEARLY'!$1:$1048576,14,0) -> #REF! | AW10: =VLOOKUP($A10,'UT-II'!$1:$1048576,14,0) -> #REF! | AX10: =VLOOKUP($A10,ANNUAL!$1:$1048576,14,0) -> #REF! | AY10: =VLOOKUP(A10,'UT-I'!$A$1:$EA$1758,15,0) -> #REF! | AZ10: =VLOOKUP($A10,'HALF YEARLY'!$1:$1048576,15,0) -> #REF! | BA10: =VLOOKUP($A10,'UT-II'!$1:$1048576,15,0) -> #REF! | BB10: =VLOOKUP($A10,ANNUAL!$1:$1048576,15,0) -> #REF! | BC10: =VLOOKUP(A10,'UT-I'!$A$1:$EA$1758,16,0) -> #REF! | BD10: =VLOOKUP($A10,'HALF YEARLY'!$1:$1048576,16,0) -> #REF! | BE10: =VLOOKUP($A10,'UT-II'!$1:$1048576,16,0) -> #REF! | BF10: =VLOOKUP($A10,ANNUAL!$1:$1048576,16,0) -> #REF! | BG10: =VLOOKUP(A10,'UT-I'!$A$1:$EA$1758,17,0) -> #REF! | BH10: =VLOOKUP($A10,'HALF YEARLY'!$1:$1048576,17,0) -> #REF! | BI10: =VLOOKUP($A10,'UT-II'!$1:$1048576,17,0) -> #REF! | BJ10: =VLOOKUP($A10,ANNUAL!$1:$1048576,17,0) -> #REF! | BK10: =VLOOKUP($A10,ANNUAL!$1:$1048576,18,0) -> #REF! | BL10: =VLOOKUP($A10,ANNUAL!$1:$1048576,19,0) -> #REF! | BM10: =VLOOKUP($A10,ANNUAL!$1:$1048576,20,0) -> #REF!
A11: =DETAILS!#REF! -> #REF! | B11: =DETAILS!#REF! -> #REF! | C11: =VLOOKUP(A11,'UT-I'!$A$1:$EA$1758,3,0) -> #REF! | D11: =VLOOKUP($A11,'HALF YEARLY'!$1:$1048576,3,0) -> #REF! | E11: =VLOOKUP($A11,'UT-II'!$1:$1048576,3,0) -> #REF! | F11: =VLOOKUP($A11,ANNUAL!$1:$1048576,3,0) -> #REF! | G11: =VLOOKUP(A11,'UT-I'!$A$1:$EA$1758,4,0) -> #REF! | H11: =VLOOKUP($A11,'HALF YEARLY'!$1:$1048576,4,0) -> #REF! | I11: =VLOOKUP($A11,'UT-II'!$1:$1048576,4,0) -> #REF! | J11: =VLOOKUP($A11,ANNUAL!$1:$1048576,4,0) -> #REF! | K11: =VLOOKUP(A11,'UT-I'!$A$1:$EA$1758,5,0) -> #REF! | L11: =VLOOKUP($A11,'HALF YEARLY'!$1:$1048576,5,0) -> #REF! | M11: =VLOOKUP($A11,'UT-II'!$1:$1048576,5,0) -> #REF! | N11: =VLOOKUP($A11,ANNUAL!$1:$1048576,5,0) -> #REF! | O11: =VLOOKUP(A11,'UT-I'!$A$1:$EA$1758,6,0) -> #REF! | P11: =VLOOKUP($A11,'HALF YEARLY'!$1:$1048576,6,0) -> #REF! | Q11: =VLOOKUP($A11,'UT-II'!$1:$1048576,6,0) -> #REF! | R11: =VLOOKUP($A11,ANNUAL!$1:$1048576,6,0) -> #REF! | S11: =VLOOKUP(A11,'UT-I'!$A$1:$EA$1758,7,0) -> #REF! | T11: =VLOOKUP($A11,'HALF YEARLY'!$1:$1048576,7,0) -> #REF! | U11: =VLOOKUP($A11,'UT-II'!$1:$1048576,7,0) -> #REF! | V11: =VLOOKUP($A11,ANNUAL!$1:$1048576,7,0) -> #REF! | W11: =VLOOKUP(A11,'UT-I'!$A$1:$EA$1758,8,0) -> #REF! | X11: =VLOOKUP($A11,'HALF YEARLY'!$1:$1048576,8,0) -> #REF! | Y11: =VLOOKUP($A11,'UT-II'!$1:$1048576,8,0) -> #REF! | Z11: =VLOOKUP($A11,ANNUAL!$1:$1048576,8,0) -> #REF! | AA11: =VLOOKUP(A11,'UT-I'!$A$1:$EA$1758,9,0) -> #REF! | AB11: =VLOOKUP($A11,'HALF YEARLY'!$1:$1048576,9,0) -> #REF! | AC11: =VLOOKUP($A11,'UT-II'!$1:$1048576,9,0) -> #REF! | AD11: =VLOOKUP($A11,ANNUAL!$1:$1048576,9,0) -> #REF! | AE11: =VLOOKUP(A11,'UT-I'!$A$1:$EA$1758,10,0) -> #REF! | AF11: =VLOOKUP($A11,'HALF YEARLY'!$1:$1048576,10,0) -> #REF! | AG11: =VLOOKUP($A11,'UT-II'!$1:$1048576,10,0) -> #REF! | AH11: =VLOOKUP($A11,ANNUAL!$1:$1048576,10,0) -> #REF! | AI11: =VLOOKUP(A11,'UT-I'!$A$1:$EA$1758,11,0) -> #REF! | AJ11: =VLOOKUP($A11,'HALF YEARLY'!$1:$1048576,11,0) -> #REF! | AK11: =VLOOKUP($A11,'UT-II'!$1:$1048576,11,0) -> #REF! | AL11: =VLOOKUP($A11,ANNUAL!$1:$1048576,11,0) -> #REF! | AM11: =VLOOKUP(A11,'UT-I'!$A$1:$EA$1758,12,0) -> #REF! | AN11: =VLOOKUP($A11,'HALF YEARLY'!$1:$1048576,12,0) -> #REF! | AO11: =VLOOKUP($A11,'UT-II'!$1:$1048576,12,0) -> #REF! | AP11: =VLOOKUP($A11,ANNUAL!$1:$1048576,12,0) -> #REF! | AQ11: =VLOOKUP(A11,'UT-I'!$A$1:$EA$1758,13,0) -> #REF! | AR11: =VLOOKUP($A11,'HALF YEARLY'!$1:$1048576,13,0) -> #REF! | AS11: =VLOOKUP($A11,'UT-II'!$1:$1048576,13,0) -> #REF! | AT11: =VLOOKUP($A11,ANNUAL!$1:$1048576,13,0) -> #REF! | AU11: =VLOOKUP(A11,'UT-I'!$A$1:$EA$1758,14,0) -> #REF! | AV11: =VLOOKUP($A11,'HALF YEARLY'!$1:$1048576,14,0) -> #REF! | AW11: =VLOOKUP($A11,'UT-II'!$1:$1048576,14,0) -> #REF! | AX11: =VLOOKUP($A11,ANNUAL!$1:$1048576,14,0) -> #REF! | AY11: =VLOOKUP(A11,'UT-I'!$A$1:$EA$1758,15,0) -> #REF! | AZ11: =VLOOKUP($A11,'HALF YEARLY'!$1:$1048576,15,0) -> #REF! | BA11: =VLOOKUP($A11,'UT-II'!$1:$1048576,15,0) -> #REF! | BB11: =VLOOKUP($A11,ANNUAL!$1:$1048576,15,0) -> #REF! | BC11: =VLOOKUP(A11,'UT-I'!$A$1:$EA$1758,16,0) -> #REF! | BD11: =VLOOKUP($A11,'HALF YEARLY'!$1:$1048576,16,0) -> #REF! | BE11: =VLOOKUP($A11,'UT-II'!$1:$1048576,16,0) -> #REF! | BF11: =VLOOKUP($A11,ANNUAL!$1:$1048576,16,0) -> #REF! | BG11: =VLOOKUP(A11,'UT-I'!$A$1:$EA$1758,17,0) -> #REF! | BH11: =VLOOKUP($A11,'HALF YEARLY'!$1:$1048576,17,0) -> #REF! | BI11: =VLOOKUP($A11,'UT-II'!$1:$1048576,17,0) -> #REF! | BJ11: =VLOOKUP($A11,ANNUAL!$1:$1048576,17,0) -> #REF! | BK11: =VLOOKUP($A11,ANNUAL!$1:$1048576,18,0) -> #REF! | BL11: =VLOOKUP($A11,ANNUAL!$1:$1048576,19,0) -> #REF! | BM11: =VLOOKUP($A11,ANNUAL!$1:$1048576,20,0) -> #REF!
A12: =DETAILS!#REF! -> #REF! | B12: =DETAILS!#REF! -> #REF! | C12: =VLOOKUP(A12,'UT-I'!$A$1:$EA$1758,3,0) -> #REF! | D12: =VLOOKUP($A12,'HALF YEARLY'!$1:$1048576,3,0) -> #REF! | E12: =VLOOKUP($A12,'UT-II'!$1:$1048576,3,0) -> #REF! | F12: =VLOOKUP($A12,ANNUAL!$1:$1048576,3,0) -> #REF! | G12: =VLOOKUP(A12,'UT-I'!$A$1:$EA$1758,4,0) -> #REF! | H12: =VLOOKUP($A12,'HALF YEARLY'!$1:$1048576,4,0) -> #REF! | I12: =VLOOKUP($A12,'UT-II'!$1:$1048576,4,0) -> #REF! | J12: =VLOOKUP($A12,ANNUAL!$1:$1048576,4,0) -> #REF! | K12: =VLOOKUP(A12,'UT-I'!$A$1:$EA$1758,5,0) -> #REF! | L12: =VLOOKUP($A12,'HALF YEARLY'!$1:$1048576,5,0) -> #REF! | M12: =VLOOKUP($A12,'UT-II'!$1:$1048576,5,0) -> #REF! | N12: =VLOOKUP($A12,ANNUAL!$1:$1048576,5,0) -> #REF! | O12: =VLOOKUP(A12,'UT-I'!$A$1:$EA$1758,6,0) -> #REF! | P12: =VLOOKUP($A12,'HALF YEARLY'!$1:$1048576,6,0) -> #REF! | Q12: =VLOOKUP($A12,'UT-II'!$1:$1048576,6,0) -> #REF! | R12: =VLOOKUP($A12,ANNUAL!$1:$1048576,6,0) -> #REF! | S12: =VLOOKUP(A12,'UT-I'!$A$1:$EA$1758,7,0) -> #REF! | T12: =VLOOKUP($A12,'HALF YEARLY'!$1:$1048576,7,0) -> #REF! | U12: =VLOOKUP($A12,'UT-II'!$1:$1048576,7,0) -> #REF! | V12: =VLOOKUP($A12,ANNUAL!$1:$1048576,7,0) -> #REF! | W12: =VLOOKUP(A12,'UT-I'!$A$1:$EA$1758,8,0) -> #REF! | X12: =VLOOKUP($A12,'HALF YEARLY'!$1:$1048576,8,0) -> #REF! | Y12: =VLOOKUP($A12,'UT-II'!$1:$1048576,8,0) -> #REF! | Z12: =VLOOKUP($A12,ANNUAL!$1:$1048576,8,0) -> #REF! | AA12: =VLOOKUP(A12,'UT-I'!$A$1:$EA$1758,9,0) -> #REF! | AB12: =VLOOKUP($A12,'HALF YEARLY'!$1:$1048576,9,0) -> #REF! | AC12: =VLOOKUP($A12,'UT-II'!$1:$1048576,9,0) -> #REF! | AD12: =VLOOKUP($A12,ANNUAL!$1:$1048576,9,0) -> #REF! | AE12: =VLOOKUP(A12,'UT-I'!$A$1:$EA$1758,10,0) -> #REF! | AF12: =VLOOKUP($A12,'HALF YEARLY'!$1:$1048576,10,0) -> #REF! | AG12: =VLOOKUP($A12,'UT-II'!$1:$1048576,10,0) -> #REF! | AH12: =VLOOKUP($A12,ANNUAL!$1:$1048576,10,0) -> #REF! | AI12: =VLOOKUP(A12,'UT-I'!$A$1:$EA$1758,11,0) -> #REF! | AJ12: =VLOOKUP($A12,'HALF YEARLY'!$1:$1048576,11,0) -> #REF! | AK12: =VLOOKUP($A12,'UT-II'!$1:$1048576,11,0) -> #REF! | AL12: =VLOOKUP($A12,ANNUAL!$1:$1048576,11,0) -> #REF! | AM12: =VLOOKUP(A12,'UT-I'!$A$1:$EA$1758,12,0) -> #REF! | AN12: =VLOOKUP($A12,'HALF YEARLY'!$1:$1048576,12,0) -> #REF! | AO12: =VLOOKUP($A12,'UT-II'!$1:$1048576,12,0) -> #REF! | AP12: =VLOOKUP($A12,ANNUAL!$1:$1048576,12,0) -> #REF! | AQ12: =VLOOKUP(A12,'UT-I'!$A$1:$EA$1758,13,0) -> #REF! | AR12: =VLOOKUP($A12,'HALF YEARLY'!$1:$1048576,13,0) -> #REF! | AS12: =VLOOKUP($A12,'UT-II'!$1:$1048576,13,0) -> #REF! | AT12: =VLOOKUP($A12,ANNUAL!$1:$1048576,13,0) -> #REF! | AU12: =VLOOKUP(A12,'UT-I'!$A$1:$EA$1758,14,0) -> #REF! | AV12: =VLOOKUP($A12,'HALF YEARLY'!$1:$1048576,14,0) -> #REF! | AW12: =VLOOKUP($A12,'UT-II'!$1:$1048576,14,0) -> #REF! | AX12: =VLOOKUP($A12,ANNUAL!$1:$1048576,14,0) -> #REF! | AY12: =VLOOKUP(A12,'UT-I'!$A$1:$EA$1758,15,0) -> #REF! | AZ12: =VLOOKUP($A12,'HALF YEARLY'!$1:$1048576,15,0) -> #REF! | BA12: =VLOOKUP($A12,'UT-II'!$1:$1048576,15,0) -> #REF! | BB12: =VLOOKUP($A12,ANNUAL!$1:$1048576,15,0) -> #REF! | BC12: =VLOOKUP(A12,'UT-I'!$A$1:$EA$1758,16,0) -> #REF! | BD12: =VLOOKUP($A12,'HALF YEARLY'!$1:$1048576,16,0) -> #REF! | BE12: =VLOOKUP($A12,'UT-II'!$1:$1048576,16,0) -> #REF! | BF12: =VLOOKUP($A12,ANNUAL!$1:$1048576,16,0) -> #REF! | BG12: =VLOOKUP(A12,'UT-I'!$A$1:$EA$1758,17,0) -> #REF! | BH12: =VLOOKUP($A12,'HALF YEARLY'!$1:$1048576,17,0) -> #REF! | BI12: =VLOOKUP($A12,'UT-II'!$1:$1048576,17,0) -> #REF! | BJ12: =VLOOKUP($A12,ANNUAL!$1:$1048576,17,0) -> #REF! | BK12: =VLOOKUP($A12,ANNUAL!$1:$1048576,18,0) -> #REF! | BL12: =VLOOKUP($A12,ANNUAL!$1:$1048576,19,0) -> #REF! | BM12: =VLOOKUP($A12,ANNUAL!$1:$1048576,20,0) -> #REF!
