Workbook

Sheet DETAILS
A1: STUDENT'S DETAIL
A2: SR NO | B2: NAME | C2: MOTHER'S NAME | D2: FATHER'S NAME | E2: DOB | F2: CLASS & SEC | G2: Elective1 | H2: Elective1 Code
A3: 688 | B3: AMINUDDIN | C3: RAFIYA BANO | D3: ANSAR AHMAD | E3: 13.09.2008 | F3: XI-COM | G3: HINDI CORE | H3: 302 | K3: 83
A4: 1011 | B4: ARPIT VERMA | C4: SUNITA VERMA | D4: MANISH KUMAR VERMA | E4: 12.12.2008 | F4: XI-COM | H4: 83
A5: 692 | B5: ATUL VERMA | C5: SUSHEELA DEVI | D5: RAVI SHANKAR | E5: 31.10.2010 | F5: XI-COM | H5: 83
A6: 1931 | B6: GAURAV GAUTAM | C6: SUSHMA GAUTAM | D6: SUNIL KUMAR | E6: 09.05.2011 | F6: XI-COM | H6: 241
A7: 1509 | B7: HIMANSHU | C7: ANITA | D7: ANIL KUMAR | E7: 06.03.2008 | F7: XI-COM | H7: 83
A8: 694 | B8: JYOTIRADITYA DAS | C8: NEELAM DAS | D8: AJAY BAX DAS | E8: 31.08.2009 | F8: XI-COM | H8: 83
A9: 1873 | B9: MASIRA AKHTAR | C9: BABY TABASSUM | D9: SHAMSUL ARFEEN | E9: 12.04.2009 | F9: XI-COM | H9: 83
A10: 1491 | B10: SIDDHARTH | C10: PUSHPA GAUTAM | D10: JAGDISH KUMAR | E10: 19.09.2007 | F10: XI-COM | H10: 83
A11: 701 | B11: YASH SONI | C11: ARTI SONI | D11: ASHEESH KUMAR | E11: 15.08.2010 | F11: XI-COM | H11: 83

Sheet UT-I(Entry)
A1: UNIT TEST-I (2025-26) CLASS - XI-Comm
A2: SR. NO. | B2: NAME | C2: ENGLISH | D2: HINDI/CS/App. Maths | E2: ACCOUNTACNY | F2: BUSINESS STUDIES | G2: ECONOMICS | H2: PHYSICAL EDUCATION | I2: Attendance
I3: Present | J3: Working Day
A4: =DETAILS!A3 -> 688 | B4: =DETAILS!B3 -> AMINUDDIN | C4: AB | D4: AB | E4: AB | F4: AB | G4: AB | H4: AB | I4: 47 | J4: 71
A5: =DETAILS!A4 -> 1011 | B5: =DETAILS!B4 -> ARPIT VERMA | C5: 12 | D5: 12 | E5: 13 | F5: 9 | G5: 2 | H5: 10 | I5: 32 | J5: 71
A6: =DETAILS!A5 -> 692 | B6: =DETAILS!B5 -> ATUL VERMA | C6: 26 | D6: 36 | E6: 33 | F6: 38 | G6: 24 | H6: 33 | I6: 65 | J6: 71
A7: =DETAILS!A6 -> 1931 | B7: =DETAILS!B6 -> GAURAV GAUTAM | C7: 30 | D7: 40 | E7: 33 | F7: 39 | G7: 25 | H7: 29 | I7: 15 | J7: 18
A8: =DETAILS!A7 -> 1509 | B8: =DETAILS!B7 -> HIMANSHU | C8: 26 | D8: 24 | E8: 26 | F8: 32 | G8: 16 | H8: 23 | I8: 43 | J8: 71
A9: =DETAILS!A8 -> 694 | B9: =DETAILS!B8 -> JYOTIRADITYA DAS | C9: 17 | D9: 18 | E9: 25 | F9: 26 | G9: 10 | H9: 19 | I9: 33 | J9: 71
A10: =DETAILS!A9 -> 1873 | B10: =DETAILS!B9 -> MASIRA AKHTAR | C10: 26 | D10: 32 | E10: 31 | F10: 34 | G10: 28 | H10: 29 | I10: 42 | J10: 33
A11: =DETAILS!A10 -> 1491 | B11: =DETAILS!B10 -> SIDDHARTH | C11: 21 | D11: 17 | E11: 22 | F11: 31 | G11: 15 | H11: 26 | I11: 39 | J11: 71
A12: =DETAILS!A11 -> 701 | B12: =DETAILS!B11 -> YASH SONI | C12: AB | D12: AB | E12: AB | F12: AB | G12: AB | H12: AB | I12: 21 | J12: 71

Sheet UT-I 
A1: UNIT TEST-I (2025-26) CLASS - XI-Comm.
A2: SR. NO. | B2: NAME | C2: ENGLISH | D2: HINDI/CS | E2: ACCOUNTACNY | F2: BUSINESS STUDIES | G2: ECONOMICS | H2: PHYSICAL EDUCATION | I2: TOTAL | J2: PERCENTAGE | K2: Attendance | M2: RANK IN CLASS | N2: PARENT'S SIGNATURE
K3: Present | L3: Working Day
A4: =DETAILS!A3 -> 688 | B4: =DETAILS!B3 -> AMINUDDIN | C4: =IFERROR(ROUND((VLOOKUP(A4,'UT-I(Entry)'!$1:$1048576,3,0))/2,0),VLOOKUP(A4,'UT-I(Entry)'!$1:$1048576,3,0)) -> AB | D4: =IF(VLOOKUP($A4,DETAILS!$1:$1048576,8,0)=DETAILS!$K$3,IFERROR(ROUND((VLOOKUP($A4,'UT-I(Entry)'!$1:$1048576,4,0))/2.5,0),VLOOKUP($A4,'UT-I(Entry)'!$1:$1048576,4,0)),IFERROR(ROUND((VLOOKUP($A4,'UT-I(Entry)'!$1:$1048576,4,0))/2,0),VLOOKUP($A4,'UT-I(Entry)'!$1:$1048576,4,0))) -> AB | E4: =IFERROR(ROUND((VLOOKUP(A4,'UT-I(Entry)'!$1:$1048576,5,0))/2,0),VLOOKUP(A4,'UT-I(Entry)'!$1:$1048576,5,0)) -> AB | F4: =IFERROR(ROUND((VLOOKUP(A4,'UT-I(Entry)'!$1:$1048576,6,0))/2,0),VLOOKUP(A4,'UT-I(Entry)'!$1:$1048576,6,0)) -> AB | G4: =IFERROR(ROUND((VLOOKUP($A4,'UT-I(Entry)'!$1:$1048576,7,0))/2,0),VLOOKUP($A4,'UT-I(Entry)'!$1:$1048576,7,0)) -> AB | H4: =IFERROR(ROUND((VLOOKUP($A4,'UT-I(Entry)'!$1:$1048576,8,0))/1.75,0),VLOOKUP($A4,'UT-I(Entry)'!$1:$1048576,8,0)) -> AB | I4: =SUM(C4:H4) -> 0 | J4: =ROUND(I4/1.2,2)&" %" -> 0 % | K4: =VLOOKUP(A4,'UT-I(Entry)'!$1:$1048576,9,0) -> 47 | L4: =VLOOKUP(A4,'UT-I(Entry)'!$1:$1048576,10,0) -> 71
A5: =DETAILS!A4 -> 1011 | B5: =DETAILS!B4 -> ARPIT VERMA | C5: =IFERROR(ROUND((VLOOKUP(A5,'UT-I(Entry)'!$1:$1048576,3,0))/2,0),VLOOKUP(A5,'UT-I(Entry)'!$1:$1048576,3,0)) -> 6 | D5: =IF(VLOOKUP($A5,DETAILS!$1:$1048576,8,0)=DETAILS!$K$3,IFERROR(ROUND((VLOOKUP($A5,'UT-I(Entry)'!$1:$1048576,4,0))/2.5,0),VLOOKUP($A5,'UT-I(Entry)'!$1:$1048576,4,0)),IFERROR(ROUND((VLOOKUP($A5,'UT-I(Entry)'!$1:$1048576,4,0))/2,0),VLOOKUP($A5,'UT-I(Entry)'!$1:$1048576,4,0))) -> 5 | E5: =IFERROR(ROUND((VLOOKUP(A5,'UT-I(Entry)'!$1:$1048576,5,0))/2,0),VLOOKUP(A5,'UT-I(Entry)'!$1:$1048576,5,0)) -> 7 | F5: =IFERROR(ROUND((VLOOKUP(A5,'UT-I(Entry)'!$1:$1048576,6,0))/2,0),VLOOKUP(A5,'UT-I(Entry)'!$1:$1048576,6,0)) -> 5 | G5: =IFERROR(ROUND((VLOOKUP($A5,'UT-I(Entry)'!$1:$1048576,7,0))/2,0),VLOOKUP($A5,'UT-I(Entry)'!$1:$1048576,7,0)) -> 1 | H5: =IFERROR(ROUND((VLOOKUP($A5,'UT-I(Entry)'!$1:$1048576,8,0))/1.75,0),VLOOKUP($A5,'UT-I(Entry)'!$1:$1048576,8,0)) -> 6 | I5: =SUM(C5:H5) -> 30 | J5: =ROUND(I5/1.2,2)&" %" -> 25 % | K5: =VLOOKUP(A5,'UT-I(Entry)'!$1:$1048576,9,0) -> 32 | L5: =VLOOKUP(A5,'UT-I(Entry)'!$1:$1048576,10,0) -> 71
A6: =DETAILS!A5 -> 692 | B6: =DETAILS!B5 -> ATUL VERMA | C6: =IFERROR(ROUND((VLOOKUP(A6,'UT-I(Entry)'!$1:$1048576,3,0))/2,0),VLOOKUP(A6,'UT-I(Entry)'!$1:$1048576,3,0)) -> 13 | D6: =IF(VLOOKUP($A6,DETAILS!$1:$1048576,8,0)=DETAILS!$K$3,IFERROR(ROUND((VLOOKUP($A6,'UT-I(Entry)'!$1:$1048576,4,0))/2.5,0),VLOOKUP($A6,'UT-I(Entry)'!$1:$1048576,4,0)),IFERROR(ROUND((VLOOKUP($A6,'UT-I(Entry)'!$1:$1048576,4,0))/2,0),VLOOKUP($A6,'UT-I(Entry)'!$1:$1048576,4,0))) -> 14 | E6: =IFERROR(ROUND((VLOOKUP(A6,'UT-I(Entry)'!$1:$1048576,5,0))/2,0),VLOOKUP(A6,'UT-I(Entry)'!$1:$1048576,5,0)) -> 17 | F6: =IFERROR(ROUND((VLOOKUP(A6,'UT-I(Entry)'!$1:$1048576,6,0))/2,0),VLOOKUP(A6,'UT-I(Entry)'!$1:$1048576,6,0)) -> 19 | G6: =IFERROR(ROUND((VLOOKUP($A6,'UT-I(Entry)'!$1:$1048576,7,0))/2,0),VLOOKUP($A6,'UT-I(Entry)'!$1:$1048576,7,0)) -> 12 | H6: =IFERROR(ROUND((VLOOKUP($A6,'UT-I(Entry)'!$1:$1048576,8,0))/1.75,0),VLOOKUP($A6,'UT-I(Entry)'!$1:$1048576,8,0)) -> 19 | I6: =SUM(C6:H6) -> 94 | J6: =ROUND(I6/1.2,2)&" %" -> 78.33 % | K6: =VLOOKUP(A6,'UT-I(Entry)'!$1:$1048576,9,0) -> 65 | L6: =VLOOKUP(A6,'UT-I(Entry)'!$1:$1048576,10,0) -> 71 | M6: II
A7: =DETAILS!A6 -> 1931 | B7: =DETAILS!B6 -> GAURAV GAUTAM | C7: =IFERROR(ROUND((VLOOKUP(A7,'UT-I(Entry)'!$1:$1048576,3,0))/2,0),VLOOKUP(A7,'UT-I(Entry)'!$1:$1048576,3,0)) -> 15 | D7: =IF(VLOOKUP($A7,DETAILS!$1:$1048576,8,0)=DETAILS!$K$3,IFERROR(ROUND((VLOOKUP($A7,'UT-I(Entry)'!$1:$1048576,4,0))/2.5,0),VLOOKUP($A7,'UT-I(Entry)'!$1:$1048576,4,0)),IFERROR(ROUND((VLOOKUP($A7,'UT-I(Entry)'!$1:$1048576,4,0))/2,0),VLOOKUP($A7,'UT-I(Entry)'!$1:$1048576,4,0))) -> 20 | E7: =IFERROR(ROUND((VLOOKUP(A7,'UT-I(Entry)'!$1:$1048576,5,0))/2,0),VLOOKUP(A7,'UT-I(Entry)'!$1:$1048576,5,0)) -> 17 | F7: =IFERROR(ROUND((VLOOKUP(A7,'UT-I(Entry)'!$1:$1048576,6,0))/2,0),VLOOKUP(A7,'UT-I(Entry)'!$1:$1048576,6,0)) -> 20 | G7: =IFERROR(ROUND((VLOOKUP($A7,'UT-I(Entry)'!$1:$1048576,7,0))/2,0),VLOOKUP($A7,'UT-I(Entry)'!$1:$1048576,7,0)) -> 13 | H7: =IFERROR(ROUND((VLOOKUP($A7,'UT-I(Entry)'!$1:$1048576,8,0))/1.75,0),VLOOKUP($A7,'UT-I(Entry)'!$1:$1048576,8,0)) -> 17 | I7: =SUM(C7:H7) -> 102 | J7: =ROUND(I7/1.2,2)&" %" -> 85 % | K7: =VLOOKUP(A7,'UT-I(Entry)'!$1:$1048576,9,0) -> 15 | L7: =VLOOKUP(A7,'UT-I(Entry)'!$1:$1048576,10,0) -> 18 | M7: I
A8: =DETAILS!A7 -> 1509 | B8: =DETAILS!B7 -> HIMANSHU | C8: =IFERROR(ROUND((VLOOKUP(A8,'UT-I(Entry)'!$1:$1048576,3,0))/2,0),VLOOKUP(A8,'UT-I(Entry)'!$1:$1048576,3,0)) -> 13 | D8: =IF(VLOOKUP($A8,DETAILS!$1:$1048576,8,0)=DETAILS!$K$3,IFERROR(ROUND((VLOOKUP($A8,'UT-I(Entry)'!$1:$1048576,4,0))/2.5,0),VLOOKUP($A8,'UT-I(Entry)'!$1:$1048576,4,0)),IFERROR(ROUND((VLOOKUP($A8,'UT-I(Entry)'!$1:$1048576,4,0))/2,0),VLOOKUP($A8,'UT-I(Entry)'!$1:$1048576,4,0))) -> 10 | E8: =IFERROR(ROUND((VLOOKUP(A8,'UT-I(Entry)'!$1:$1048576,5,0))/2,0),VLOOKUP(A8,'UT-I(Entry)'!$1:$1048576,5,0)) -> 13 | F8: =IFERROR(ROUND((VLOOKUP(A8,'UT-I(Entry)'!$1:$1048576,6,0))/2,0),VLOOKUP(A8,'UT-I(Entry)'!$1:$1048576,6,0)) -> 16 | G8: =IFERROR(ROUND((VLOOKUP($A8,'UT-I(Entry)'!$1:$1048576,7,0))/2,0),VLOOKUP($A8,'UT-I(Entry)'!$1:$1048576,7,0)) -> 8 | H8: =IFERROR(ROUND((VLOOKUP($A8,'UT-I(Entry)'!$1:$1048576,8,0))/1.75,0),VLOOKUP($A8,'UT-I(Entry)'!$1:$1048576,8,0)) -> 13 | I8: =SUM(C8:H8) -> 73 | J8: =ROUND(I8/1.2,2)&" %" -> 60.83 % | K8: =VLOOKUP(A8,'UT-I(Entry)'!$1:$1048576,9,0) -> 43 | L8: =VLOOKUP(A8,'UT-I(Entry)'!$1:$1048576,10,0) -> 71
A9: =DETAILS!A8 -> 694 | B9: =DETAILS!B8 -> JYOTIRADITYA DAS | C9: =IFERROR(ROUND((VLOOKUP(A9,'UT-I(Entry)'!$1:$1048576,3,0))/2,0),VLOOKUP(A9,'UT-I(Entry)'!$1:$1048576,3,0)) -> 9 | D9: =IF(VLOOKUP($A9,DETAILS!$1:$1048576,8,0)=DETAILS!$K$3,IFERROR(ROUND((VLOOKUP($A9,'UT-I(Entry)'!$1:$1048576,4,0))/2.5,0),VLOOKUP($A9,'UT-I(Entry)'!$1:$1048576,4,0)),IFERROR(ROUND((VLOOKUP($A9,'UT-I(Entry)'!$1:$1048576,4,0))/2,0),VLOOKUP($A9,'UT-I(Entry)'!$1:$1048576,4,0))) -> 7 | E9: =IFERROR(ROUND((VLOOKUP(A9,'UT-I(Entry)'!$1:$1048576,5,0))/2,0),VLOOKUP(A9,'UT-I(Entry)'!$1:$1048576,5,0)) -> 13 | F9: =IFERROR(ROUND((VLOOKUP(A9,'UT-I(Entry)'!$1:$1048576,6,0))/2,0),VLOOKUP(A9,'UT-I(Entry)'!$1:$1048576,6,0)) -> 13 | G9: =IFERROR(ROUND((VLOOKUP($A9,'UT-I(Entry)'!$1:$1048576,7,0))/2,0),VLOOKUP($A9,'UT-I(Entry)'!$1:$1048576,7,0)) -> 5 | H9: =IFERROR(ROUND((VLOOKUP($A9,'UT-I(Entry)'!$1:$1048576,8,0))/1.75,0),VLOOKUP($A9,'UT-I(Entry)'!$1:$1048576,8,0)) -> 11 | I9: =SUM(C9:H9) -> 58 | J9: =ROUND(I9/1.2,2)&" %" -> 48.33 % | K9: =VLOOKUP(A9,'UT-I(Entry)'!$1:$1048576,9,0) -> 33 | L9: =VLOOKUP(A9,'UT-I(Entry)'!$1:$1048576,10,0) -> 71
A10: =DETAILS!A9 -> 1873 | B10: =DETAILS!B9 -> MASIRA AKHTAR | C10: =IFERROR(ROUND((VLOOKUP(A10,'UT-I(Entry)'!$1:$1048576,3,0))/2,0),VLOOKUP(A10,'UT-I(Entry)'!$1:$1048576,3,0)) -> 13 | D10: =IF(VLOOKUP($A10,DETAILS!$1:$1048576,8,0)=DETAILS!$K$3,IFERROR(ROUND((VLOOKUP($A10,'UT-I(Entry)'!$1:$1048576,4,0))/2.5,0),VLOOKUP($A10,'UT-I(Entry)'!$1:$1048576,4,0)),IFERROR(ROUND((VLOOKUP($A10,'UT-I(Entry)'!$1:$1048576,4,0))/2,0),VLOOKUP($A10,'UT-I(Entry)'!$1:$1048576,4,0))) -> 13 | E10: =IFERROR(ROUND((VLOOKUP(A10,'UT-I(Entry)'!$1:$1048576,5,0))/2,0),VLOOKUP(A10,'UT-I(Entry)'!$1:$1048576,5,0)) -> 16 | F10: =IFERROR(ROUND((VLOOKUP(A10,'UT-I(Entry)'!$1:$1048576,6,0))/2,0),VLOOKUP(A10,'UT-I(Entry)'!$1:$1048576,6,0)) -> 17 | G10: =IFERROR(ROUND((VLOOKUP($A10,'UT-I(Entry)'!$1:$1048576,7,0))/2,0),VLOOKUP($A10,'UT-I(Entry)'!$1:$1048576,7,0)) -> 14 | H10: =IFERROR(ROUND((VLOOKUP($A10,'UT-I(Entry)'!$1:$1048576,8,0))/1.75,0),VLOOKUP($A10,'UT-I(Entry)'!$1:$1048576,8,0)) -> 17 | I10: =SUM(C10:H10) -> 90 | J10: =ROUND(I10/1.2,2)&" %" -> 75 % | K10: =VLOOKUP(A10,'UT-I(Entry)'!$1:$1048576,9,0) -> 42 | L10: =VLOOKUP(A10,'UT-I(Entry)'!$1:$1048576,10,0) -> 33 | M10: III
A11: =DETAILS!A10 -> 1491 | B11: =DETAILS!B10 -> SIDDHARTH | C11: =IFERROR(ROUND((VLOOKUP(A11,'UT-I(Entry)'!$1:$1048576,3,0))/2,0),VLOOKUP(A11,'UT-I(Entry)'!$1:$1048576,3,0)) -> 11 | D11: =IF(VLOOKUP($A11,DETAILS!$1:$1048576,8,0)=DETAILS!$K$3,IFERROR(ROUND((VLOOKUP($A11,'UT-I(Entry)'!$1:$1048576,4,0))/2.5,0),VLOOKUP($A11,'UT-I(Entry)'!$1:$1048576,4,0)),IFERROR(ROUND((VLOOKUP($A11,'UT-I(Entry)'!$1:$1048576,4,0))/2,0),VLOOKUP($A11,'UT-I(Entry)'!$1:$1048576,4,0))) -> 7 | E11: =IFERROR(ROUND((VLOOKUP(A11,'UT-I(Entry)'!$1:$1048576,5,0))/2,0),VLOOKUP(A11,'UT-I(Entry)'!$1:$1048576,5,0)) -> 11 | F11: =IFERROR(ROUND((VLOOKUP(A11,'UT-I(Entry)'!$1:$1048576,6,0))/2,0),VLOOKUP(A11,'UT-I(Entry)'!$1:$1048576,6,0)) -> 16 | G11: =IFERROR(ROUND((VLOOKUP($A11,'UT-I(Entry)'!$1:$1048576,7,0))/2,0),VLOOKUP($A11,'UT-I(Entry)'!$1:$1048576,7,0)) -> 8 | H11: =IFERROR(ROUND((VLOOKUP($A11,'UT-I(Entry)'!$1:$1048576,8,0))/1.75,0),VLOOKUP($A11,'UT-I(Entry)'!$1:$1048576,8,0)) -> 15 | I11: =SUM(C11:H11) -> 68 | J11: =ROUND(I11/1.2,2)&" %" -> 56.67 % | K11: =VLOOKUP(A11,'UT-I(Entry)'!$1:$1048576,9,0) -> 39 | L11: =VLOOKUP(A11,'UT-I(Entry)'!$1:$1048576,10,0) -> 71
A12: =DETAILS!A11 -> 701 | B12: =DETAILS!B11 -> YASH SONI | C12: =IFERROR(ROUND((VLOOKUP(A12,'UT-I(Entry)'!$1:$1048576,3,0))/2,0),VLOOKUP(A12,'UT-I(Entry)'!$1:$1048576,3,0)) -> AB | D12: =IF(VLOOKUP($A12,DETAILS!$1:$1048576,8,0)=DETAILS!$K$3,IFERROR(ROUND((VLOOKUP($A12,'UT-I(Entry)'!$1:$1048576,4,0))/2.5,0),VLOOKUP($A12,'UT-I(Entry)'!$1:$1048576,4,0)),IFERROR(ROUND((VLOOKUP($A12,'UT-I(Entry)'!$1:$1048576,4,0))/2,0),VLOOKUP($A12,'UT-I(Entry)'!$1:$1048576,4,0))) -> AB | E12: =IFERROR(ROUND((VLOOKUP(A12,'UT-I(Entry)'!$1:$1048576,5,0))/2,0),VLOOKUP(A12,'UT-I(Entry)'!$1:$1048576,5,0)) -> AB | F12: =IFERROR(ROUND((VLOOKUP(A12,'UT-I(Entry)'!$1:$1048576,6,0))/2,0),VLOOKUP(A12,'UT-I(Entry)'!$1:$1048576,6,0)) -> AB | G12: =IFERROR(ROUND((VLOOKUP($A12,'UT-I(Entry)'!$1:$1048576,7,0))/2,0),VLOOKUP($A12,'UT-I(Entry)'!$1:$1048576,7,0)) -> AB | H12: =IFERROR(ROUND((VLOOKUP($A12,'UT-I(Entry)'!$1:$1048576,8,0))/1.75,0),VLOOKUP($A12,'UT-I(Entry)'!$1:$1048576,8,0)) -> AB | I12: =SUM(C12:H12) -> 0 | J12: =ROUND(I12/1.2,2)&" %" -> 0 % | K12: =VLOOKUP(A12,'UT-I(Entry)'!$1:$1048576,9,0) -> 21 | L12: =VLOOKUP(A12,'UT-I(Entry)'!$1:$1048576,10,0) -> 71

Sheet Grade(40)
A2: 40 | B2: A
A3: 39 | B3: A
A4: 38 | B4: A
A5: 37 | B5: A
A6: 36 | B6: A
A7: 35 | B7: A
A8: 34 | B8: A
A9: 33 | B9: A
A10: 32 | B10: B
A11: 31 | B11: B
A12: 30 | B12: B
A13: 29 | B13: B
... A42: 0 | B42: E

Sheet HALF YEARLY(Entry)
A1: HALF YEARLY EXAMINATION (2025-26) CLASS - XI-Comm
A2: SR. NO. | B2: NAME | C2: ENGLISH | D2: HINDI/CS | E2: ACCOUNTACNY | F2: BUSINESS STUDIES | G2: ECONOMICS | H2: PHYSICAL EDUCATION | I2: WORK EDUCATION | J2: ART EDUCATION | K2: HEALTH & PHYSICAL EDUCATION | L2: DISCIPLINE | M2: Total Present | N2: Total Working | O2: Class Teacher's Remark | P2: TOTAL | Q2: Percentage
A3: =DETAILS!A3 -> 688 | B3: =DETAILS!B3 -> AMINUDDIN | P3: =SUM(C3:H3) -> 0 | Q3: =ROUND(P3/6,2)&" %" -> 0 %
A4: =DETAILS!A4 -> 1011 | B4: =DETAILS!B4 -> ARPIT VERMA | P4: =SUM(C4:H4) -> 0 | Q4: =ROUND(P4/6,2)&" %" -> 0 %
A5: =DETAILS!A5 -> 692 | B5: =DETAILS!B5 -> ATUL VERMA | P5: =SUM(C5:H5) -> 0 | Q5: =ROUND(P5/6,2)&" %" -> 0 %
A6: =DETAILS!A6 -> 1931 | B6: =DETAILS!B6 -> GAURAV GAUTAM | P6: =SUM(C6:H6) -> 0 | Q6: =ROUND(P6/6,2)&" %" -> 0 %
A7: =DETAILS!A7 -> 1509 | B7: =DETAILS!B7 -> HIMANSHU | P7: =SUM(C7:H7) -> 0 | Q7: =ROUND(P7/6,2)&" %" -> 0 %
A8: =DETAILS!A8 -> 694 | B8: =DETAILS!B8 -> JYOTIRADITYA DAS | P8: =SUM(C8:H8) -> 0 | Q8: =ROUND(P8/6,2)&" %" -> 0 %
A9: =DETAILS!A9 -> 1873 | B9: =DETAILS!B9 -> MASIRA AKHTAR | P9: =SUM(C9:H9) -> 0 | Q9: =ROUND(P9/6,2)&" %" -> 0 %
A10: =DETAILS!A10 -> 1491 | B10: =DETAILS!B10 -> SIDDHARTH | P10: =SUM(C10:H10) -> 0 | Q10: =ROUND(P10/6,2)&" %" -> 0 %
A11: =DETAILS!A11 -> 701 | B11: =DETAILS!B11 -> YASH SONI | P11: =SUM(C11:H11) -> 0 | Q11: =ROUND(P11/6,2)&" %" -> 0 %
A12: =DETAILS!#REF! -> #REF! | B12: =DETAILS!#REF! -> #REF! | P12: =SUM(C12:H12) -> 0 | Q12: =ROUND(P12/6,2)&" %" -> 0 %
A13: =DETAILS!#REF! -> #REF! | B13: =DETAILS!#REF! -> #REF! | P13: =SUM(C13:H13) -> 0 | Q13: =ROUND(P13/6,2)&" %" -> 0 %
A14: =DETAILS!#REF! -> #REF! | B14: =DETAILS!#REF! -> #REF! | P14: =SUM(C14:H14) -> 0 | Q14: =ROUND(P14/6,2)&" %" -> 0 %
A15: =DETAILS!#REF! -> #REF! | B15: =DETAILS!#REF! -> #REF! | P15: =SUM(C15:H15) -> 0 | Q15: =ROUND(P15/6,2)&" %" -> 0 %
A16: =DETAILS!#REF! -> #REF! | B16: =DETAILS!#REF! -> #REF! | P16: =SUM(C16:H16) -> 0 | Q16: =ROUND(P16/6,2)&" %" -> 0 %
A17: =DETAILS!#REF! -> #REF! | B17: =DETAILS!#REF! -> #REF! | P17: =SUM(C17:H17) -> 0 | Q17: =ROUND(P17/6,2)&" %" -> 0 %
A18: =DETAILS!#REF! -> #REF! | B18: =DETAILS!#REF! -> #REF! | P18: =SUM(C18:H18) -> 0 | Q18: =ROUND(P18/6,2)&" %" -> 0 %
A19: =DETAILS!#REF! -> #REF! | B19: =DETAILS!#REF! -> #REF! | P19: =SUM(C19:H19) -> 0 | Q19: =ROUND(P19/6,2)&" %" -> 0 %
A20: =DETAILS!#REF! -> #REF! | B20: =DETAILS!#REF! -> #REF! | P20: =SUM(C20:H20) -> 0 | Q20: =ROUND(P20/6,2)&" %" -> 0 %
A21: =DETAILS!#REF! -> #REF! | B21: =DETAILS!#REF! -> #REF! | P21: =SUM(C21:H21) -> 0 | Q21: =ROUND(P21/6,2)&" %" -> 0 %
A22: =DETAILS!#REF! -> #REF! | B22: =DETAILS!#REF! -> #REF! | P22: =SUM(C22:H22) -> 0 | Q22: =ROUND(P22/6,2)&" %" -> 0 %
A23: =DETAILS!#REF! -> #REF! | B23: =DETAILS!#REF! -> #REF! | P23: =SUM(C23:H23) -> 0 | Q23: =ROUND(P23/6,2)&" %" -> 0 %
... A41: =DETAILS!#REF! -> #REF! | B41: =DETAILS!#REF! -> #REF! | P41: =SUM(C41:H41) -> 0 | Q41: =ROUND(P41/6,2)&" %" -> 0 %

Sheet HALF YEARLY
A1: HALF YEARLY EXAMINATION (2025-26) CLASS - XI-Comm
A2: SR. NO. | B2: NAME | C2: ENGLISH | D2: HINDI/CS | E2: ACCOUNTACNY | F2: BUSINESS STUDIES | G2: ECONOMICS | H2: PHYSICAL EDUCATION | I2: WORK EDUCATION | J2: ART EDUCATION | K2: HEALTH & PHYSICAL EDUCATION | L2: DISCIPLINE | M2: Total Present | N2: Total Working | O2: Class Teacher's Remark | P2: TOTAL | Q2: Percentage
A3: =DETAILS!A3 -> 688 | B3: =DETAILS!B3 -> AMINUDDIN | C3: =VLOOKUP($A3,'HALF YEARLY(Entry)'!$1:$1048576,3,0) -> 0 | D3: =VLOOKUP($A3,'HALF YEARLY(Entry)'!$1:$1048576,4,0) -> 0 | E3: =VLOOKUP($A3,'HALF YEARLY(Entry)'!$1:$1048576,5,0) -> 0 | F3: =VLOOKUP($A3,'HALF YEARLY(Entry)'!$1:$1048576,6,0) -> 0 | G3: =VLOOKUP($A3,'HALF YEARLY(Entry)'!$1:$1048576,7,0) -> 0 | H3: =VLOOKUP($A3,'HALF YEARLY(Entry)'!$1:$1048576,8,0) -> 0 | I3: =VLOOKUP($A3,'HALF YEARLY(Entry)'!$1:$1048576,9,0) -> 0 | J3: =VLOOKUP($A3,'HALF YEARLY(Entry)'!$1:$1048576,10,0) -> 0 | K3: =VLOOKUP($A3,'HALF YEARLY(Entry)'!$1:$1048576,11,0) -> 0 | L3: =VLOOKUP($A3,'HALF YEARLY(Entry)'!$1:$1048576,12,0) -> 0 | M3: =VLOOKUP($A3,'HALF YEARLY(Entry)'!$1:$1048576,13,0) -> 0 | N3: =VLOOKUP($A3,'HALF YEARLY(Entry)'!$1:$1048576,14,0) -> 0 | O3: =VLOOKUP($A3,'HALF YEARLY(Entry)'!$1:$1048576,15,0) -> 0 | P3: =SUM(C3:H3) -> 0 | Q3: =ROUND(P3/6,2)&" %" -> 0 %
A4: =DETAILS!A4 -> 1011 | B4: =DETAILS!B4 -> ARPIT VERMA | C4: =VLOOKUP($A4,'HALF YEARLY(Entry)'!$1:$1048576,3,0) -> 0 | D4: =VLOOKUP($A4,'HALF YEARLY(Entry)'!$1:$1048576,4,0) -> 0 | E4: =VLOOKUP($A4,'HALF YEARLY(Entry)'!$1:$1048576,5,0) -> 0 | F4: =VLOOKUP($A4,'HALF YEARLY(Entry)'!$1:$1048576,6,0) -> 0 | G4: =VLOOKUP($A4,'HALF YEARLY(Entry)'!$1:$1048576,7,0) -> 0 | H4: =VLOOKUP($A4,'HALF YEARLY(Entry)'!$1:$1048576,8,0) -> 0 | I4: =VLOOKUP($A4,'HALF YEARLY(Entry)'!$1:$1048576,9,0) -> 0 | J4: =VLOOKUP($A4,'HALF YEARLY(Entry)'!$1:$1048576,10,0) -> 0 | K4: =VLOOKUP($A4,'HALF YEARLY(Entry)'!$1:$1048576,11,0) -> 0 | L4: =VLOOKUP($A4,'HALF YEARLY(Entry)'!$1:$1048576,12,0) -> 0 | M4: =VLOOKUP($A4,'HALF YEARLY(Entry)'!$1:$1048576,13,0) -> 0 | N4: =VLOOKUP($A4,'HALF YEARLY(Entry)'!$1:$1048576,14,0) -> 0 | O4: =VLOOKUP($A4,'HALF YEARLY(Entry)'!$1:$1048576,15,0) -> 0 | P4: =SUM(C4:H4) -> 0 | Q4: =ROUND(P4/6,2)&" %" -> 0 %
A5: =DETAILS!A5 -> 692 | B5: =DETAILS!B5 -> ATUL VERMA | C5: =VLOOKUP($A5,'HALF YEARLY(Entry)'!$1:$1048576,3,0) -> 0 | D5: =VLOOKUP($A5,'HALF YEARLY(Entry)'!$1:$1048576,4,0) -> 0 | E5: =VLOOKUP($A5,'HALF YEARLY(Entry)'!$1:$1048576,5,0) -> 0 | F5: =VLOOKUP($A5,'HALF YEARLY(Entry)'!$1:$1048576,6,0) -> 0 | G5: =VLOOKUP($A5,'HALF YEARLY(Entry)'!$1:$1048576,7,0) -> 0 | H5: =VLOOKUP($A5,'HALF YEARLY(Entry)'!$1:$1048576,8,0) -> 0 | I5: =VLOOKUP($A5,'HALF YEARLY(Entry)'!$1:$1048576,9,0) -> 0 | J5: =VLOOKUP($A5,'HALF YEARLY(Entry)'!$1:$1048576,10,0) -> 0 | K5: =VLOOKUP($A5,'HALF YEARLY(Entry)'!$1:$1048576,11,0) -> 0 | L5: =VLOOKUP($A5,'HALF YEARLY(Entry)'!$1:$1048576,12,0) -> 0 | M5: =VLOOKUP($A5,'HALF YEARLY(Entry)'!$1:$1048576,13,0) -> 0 | N5: =VLOOKUP($A5,'HALF YEARLY(Entry)'!$1:$1048576,14,0) -> 0 | O5: =VLOOKUP($A5,'HALF YEARLY(Entry)'!$1:$1048576,15,0) -> 0 | P5: =SUM(C5:H5) -> 0 | Q5: =ROUND(P5/6,2)&" %" -> 0 %
A6: =DETAILS!A6 -> 1931 | B6: =DETAILS!B6 -> GAURAV GAUTAM | C6: =VLOOKUP($A6,'HALF YEARLY(Entry)'!$1:$1048576,3,0) -> 0 | D6: =VLOOKUP($A6,'HALF YEARLY(Entry)'!$1:$1048576,4,0) -> 0 | E6: =VLOOKUP($A6,'HALF YEARLY(Entry)'!$1:$1048576,5,0) -> 0 | F6: =VLOOKUP($A6,'HALF YEARLY(Entry)'!$1:$1048576,6,0) -> 0 | G6: =VLOOKUP($A6,'HALF YEARLY(Entry)'!$1:$1048576,7,0) -> 0 | H6: =VLOOKUP($A6,'HALF YEARLY(Entry)'!$1:$1048576,8,0) -> 0 | I6: =VLOOKUP($A6,'HALF YEARLY(Entry)'!$1:$1048576,9,0) -> 0 | J6: =VLOOKUP($A6,'HALF YEARLY(Entry)'!$1:$1048576,10,0) -> 0 | K6: =VLOOKUP($A6,'HALF YEARLY(Entry)'!$1:$1048576,11,0) -> 0 | L6: =VLOOKUP($A6,'HALF YEARLY(Entry)'!$1:$1048576,12,0) -> 0 | M6: =VLOOKUP($A6,'HALF YEARLY(Entry)'!$1:$1048576,13,0) -> 0 | N6: =VLOOKUP($A6,'HALF YEARLY(Entry)'!$1:$1048576,14,0) -> 0 | O6: =VLOOKUP($A6,'HALF YEARLY(Entry)'!$1:$1048576,15,0) -> 0 | P6: =SUM(C6:H6) -> 0 | Q6: =ROUND(P6/6,2)&" %" -> 0 %
A7: =DETAILS!A7 -> 1509 | B7: =DETAILS!B7 -> HIMANSHU | C7: =VLOOKUP($A7,'HALF YEARLY(Entry)'!$1:$1048576,3,0) -> 0 | D7: =VLOOKUP($A7,'HALF YEARLY(Entry)'!$1:$1048576,4,0) -> 0 | E7: =VLOOKUP($A7,'HALF YEARLY(Entry)'!$1:$1048576,5,0) -> 0 | F7: =VLOOKUP($A7,'HALF YEARLY(Entry)'!$1:$1048576,6,0) -> 0 | G7: =VLOOKUP($A7,'HALF YEARLY(Entry)'!$1:$1048576,7,0) -> 0 | H7: =VLOOKUP($A7,'HALF YEARLY(Entry)'!$1:$1048576,8,0) -> 0 | I7: =VLOOKUP($A7,'HALF YEARLY(Entry)'!$1:$1048576,9,0) -> 0 | J7: =VLOOKUP($A7,'HALF YEARLY(Entry)'!$1:$1048576,10,0) -> 0 | K7: =VLOOKUP($A7,'HALF YEARLY(Entry)'!$1:$1048576,11,0) -> 0 | L7: =VLOOKUP($A7,'HALF YEARLY(Entry)'!$1:$1048576,12,0) -> 0 | M7: =VLOOKUP($A7,'HALF YEARLY(Entry)'!$1:$1048576,13,0) -> 0 | N7: =VLOOKUP($A7,'HALF YEARLY(Entry)'!$1:$1048576,14,0) -> 0 | O7: =VLOOKUP($A7,'HALF YEARLY(Entry)'!$1:$1048576,15,0) -> 0 | P7: =SUM(C7:H7) -> 0 | Q7: =ROUND(P7/6,2)&" %" -> 0 %
A8: =DETAILS!A8 -> 694 | B8: =DETAILS!B8 -> JYOTIRADITYA DAS | C8: =VLOOKUP($A8,'HALF YEARLY(Entry)'!$1:$1048576,3,0) -> 0 | D8: =VLOOKUP($A8,'HALF YEARLY(Entry)'!$1:$1048576,4,0) -> 0 | E8: =VLOOKUP($A8,'HALF YEARLY(Entry)'!$1:$1048576,5,0) -> 0 | F8: =VLOOKUP($A8,'HALF YEARLY(Entry)'!$1:$1048576,6,0) -> 0 | G8: =VLOOKUP($A8,'HALF YEARLY(Entry)'!$1:$1048576,7,0) -> 0 | H8: =VLOOKUP($A8,'HALF YEARLY(Entry)'!$1:$1048576,8,0) -> 0 | I8: =VLOOKUP($A8,'HALF YEARLY(Entry)'!$1:$1048576,9,0) -> 0 | J8: =VLOOKUP($A8,'HALF YEARLY(Entry)'!$1:$1048576,10,0) -> 0 | K8: =VLOOKUP($A8,'HALF YEARLY(Entry)'!$1:$1048576,11,0) -> 0 | L8: =VLOOKUP($A8,'HALF YEARLY(Entry)'!$1:$1048576,12,0) -> 0 | M8: =VLOOKUP($A8,'HALF YEARLY(Entry)'!$1:$1048576,13,0) -> 0 | N8: =VLOOKUP($A8,'HALF YEARLY(Entry)'!$1:$1048576,14,0) -> 0 | O8: =VLOOKUP($A8,'HALF YEARLY(Entry)'!$1:$1048576,15,0) -> 0 | P8: =SUM(C8:H8) -> 0 | Q8: =ROUND(P8/6,2)&" %" -> 0 %
A9: =DETAILS!A9 -> 1873 | B9: =DETAILS!B9 -> MASIRA AKHTAR | C9: =VLOOKUP($A9,'HALF YEARLY(Entry)'!$1:$1048576,3,0) -> 0 | D9: =VLOOKUP($A9,'HALF YEARLY(Entry)'!$1:$1048576,4,0) -> 0 | E9: =VLOOKUP($A9,'HALF YEARLY(Entry)'!$1:$1048576,5,0) -> 0 | F9: =VLOOKUP($A9,'HALF YEARLY(Entry)'!$1:$1048576,6,0) -> 0 | G9: =VLOOKUP($A9,'HALF YEARLY(Entry)'!$1:$1048576,7,0) -> 0 | H9: =VLOOKUP($A9,'HALF YEARLY(Entry)'!$1:$1048576,8,0) -> 0 | I9: =VLOOKUP($A9,'HALF YEARLY(Entry)'!$1:$1048576,9,0) -> 0 | J9: =VLOOKUP($A9,'HALF YEARLY(Entry)'!$1:$1048576,10,0) -> 0 | K9: =VLOOKUP($A9,'HALF YEARLY(Entry)'!$1:$1048576,11,0) -> 0 | L9: =VLOOKUP($A9,'HALF YEARLY(Entry)'!$1:$1048576,12,0) -> 0 | M9: =VLOOKUP($A9,'HALF YEARLY(Entry)'!$1:$1048576,13,0) -> 0 | N9: =VLOOKUP($A9,'HALF YEARLY(Entry)'!$1:$1048576,14,0) -> 0 | O9: =VLOOKUP($A9,'HALF YEARLY(Entry)'!$1:$1048576,15,0) -> 0 | P9: =SUM(C9:H9) -> 0 | Q9: =ROUND(P9/6,2)&" %" -> 0 %
A10: =DETAILS!A10 -> 1491 | B10: =DETAILS!B10 -> SIDDHARTH | C10: =VLOOKUP($A10,'HALF YEARLY(Entry)'!$1:$1048576,3,0) -> 0 | D10: =VLOOKUP($A10,'HALF YEARLY(Entry)'!$1:$1048576,4,0) -> 0 | E10: =VLOOKUP($A10,'HALF YEARLY(Entry)'!$1:$1048576,5,0) -> 0 | F10: =VLOOKUP($A10,'HALF YEARLY(Entry)'!$1:$1048576,6,0) -> 0 | G10: =VLOOKUP($A10,'HALF YEARLY(Entry)'!$1:$1048576,7,0) -> 0 | H10: =VLOOKUP($A10,'HALF YEARLY(Entry)'!$1:$1048576,8,0) -> 0 | I10: =VLOOKUP($A10,'HALF YEARLY(Entry)'!$1:$1048576,9,0) -> 0 | J10: =VLOOKUP($A10,'HALF YEARLY(Entry)'!$1:$1048576,10,0) -> 0 | K10: =VLOOKUP($A10,'HALF YEARLY(Entry)'!$1:$1048576,11,0) -> 0 | L10: =VLOOKUP($A10,'HALF YEARLY(Entry)'!$1:$1048576,12,0) -> 0 | M10: =VLOOKUP($A10,'HALF YEARLY(Entry)'!$1:$1048576,13,0) -> 0 | N10: =VLOOKUP($A10,'HALF YEARLY(Entry)'!$1:$1048576,14,0) -> 0 | O10: =VLOOKUP($A10,'HALF YEARLY(Entry)'!$1:$1048576,15,0) -> 0 | P10: =SUM(C10:H10) -> 0 | Q10: =ROUND(P10/6,2)&" %" -> 0 %
A11: =DETAILS!A11 -> 701 | B11: =DETAILS!B11 -> YASH SONI | C11: =VLOOKUP($A11,'HALF YEARLY(Entry)'!$1:$1048576,3,0) -> 0 | D11: =VLOOKUP($A11,'HALF YEARLY(Entry)'!$1:$1048576,4,0) -> 0 | E11: =VLOOKUP($A11,'HALF YEARLY(Entry)'!$1:$1048576,5,0) -> 0 | F11: =VLOOKUP($A11,'HALF YEARLY(Entry)'!$1:$1048576,6,0) -> 0 | G11: =VLOOKUP($A11,'HALF YEARLY(Entry)'!$1:$1048576,7,0) -> 0 | H11: =VLOOKUP($A11,'HALF YEARLY(Entry)'!$1:$1048576,8,0) -> 0 | I11: =VLOOKUP($A11,'HALF YEARLY(Entry)'!$1:$1048576,9,0) -> 0 | J11: =VLOOKUP($A11,'HALF YEARLY(Entry)'!$1:$1048576,10,0) -> 0 | K11: =VLOOKUP($A11,'HALF YEARLY(Entry)'!$1:$1048576,11,0) -> 0 | L11: =VLOOKUP($A11,'HALF YEARLY(Entry)'!$1:$1048576,12,0) -> 0 | M11: =VLOOKUP($A11,'HALF YEARLY(Entry)'!$1:$1048576,13,0) -> 0 | N11: =VLOOKUP($A11,'HALF YEARLY(Entry)'!$1:$1048576,14,0) -> 0 | O11: =VLOOKUP($A11,'HALF YEARLY(Entry)'!$1:$1048576,15,0) -> 0 | P11: =SUM(C11:H11) -> 0 | Q11: =ROUND(P11/6,2)&" %" -> 0 %
A12: =DETAILS!#REF! -> #REF! | B12: =DETAILS!#REF! -> #REF! | C12: =VLOOKUP($A12,'HALF YEARLY(Entry)'!$1:$1048576,3,0) -> #REF! | D12: =VLOOKUP($A12,'HALF YEARLY(Entry)'!$1:$1048576,4,0) -> #REF! | E12: =VLOOKUP($A12,'HALF YEARLY(Entry)'!$1:$1048576,5,0) -> #REF! | F12: =VLOOKUP($A12,'HALF YEARLY(Entry)'!$1:$1048576,6,0) -> #REF! | G12: =VLOOKUP($A12,'HALF YEARLY(Entry)'!$1:$1048576,7,0) -> #REF! | H12: =VLOOKUP($A12,'HALF YEARLY(Entry)'!$1:$1048576,8,0) -> #REF! | I12: =VLOOKUP($A12,'HALF YEARLY(Entry)'!$1:$1048576,9,0) -> #REF! | J12: =VLOOKUP($A12,'HALF YEARLY(Entry)'!$1:$1048576,10,0) -> #REF! | K12: =VLOOKUP($A12,'HALF YEARLY(Entry)'!$1:$1048576,11,0) -> #REF! | L12: =VLOOKUP($A12,'HALF YEARLY(Entry)'!$1:$1048576,12,0) -> #REF! | M12: =VLOOKUP($A12,'HALF YEARLY(Entry)'!$1:$1048576,13,0) -> #REF! | N12: =VLOOKUP($A12,'HALF YEARLY(Entry)'!$1:$1048576,14,0) -> #REF! | O12: =VLOOKUP($A12,'HALF YEARLY(Entry)'!$1:$1048576,15,0) -> #REF! | P12: =SUM(C12:H12) -> #REF! | Q12: =ROUND(P12/6,2)&" %" -> #REF!
A13: =DETAILS!#REF! -> #REF! | B13: =DETAILS!#REF! -> #REF! | C13: =VLOOKUP($A13,'HALF YEARLY(Entry)'!$1:$1048576,3,0) -> #REF! | D13: =VLOOKUP($A13,'HALF YEARLY(Entry)'!$1:$1048576,4,0) -> #REF! | E13: =VLOOKUP($A13,'HALF YEARLY(Entry)'!$1:$1048576,5,0) -> #REF! | F13: =VLOOKUP($A13,'HALF YEARLY(Entry)'!$1:$1048576,6,0) -> #REF! | G13: =VLOOKUP($A13,'HALF YEARLY(Entry)'!$1:$1048576,7,0) -> #REF! | H13: =VLOOKUP($A13,'HALF YEARLY(Entry)'!$1:$1048576,8,0) -> #REF! | I13: =VLOOKUP($A13,'HALF YEARLY(Entry)'!$1:$1048576,9,0) -> #REF! | J13: =VLOOKUP($A13,'HALF YEARLY(Entry)'!$1:$1048576,10,0) -> #REF! | K13: =VLOOKUP($A13,'HALF YEARLY(Entry)'!$1:$1048576,11,0) -> #REF! | L13: =VLOOKUP($A13,'HALF YEARLY(Entry)'!$1:$1048576,12,0) -> #REF! | M13: =VLOOKUP($A13,'HALF YEARLY(Entry)'!$1:$1048576,13,0) -> #REF! | N13: =VLOOKUP($A13,'HALF YEARLY(Entry)'!$1:$1048576,14,0) -> #REF! | O13: =VLOOKUP($A13,'HALF YEARLY(Entry)'!$1:$1048576,15,0) -> #REF! | P13: =SUM(C13:H13) -> #REF! | Q13: =ROUND(P13/6,2)&" %" -> #REF!
A14: =DETAILS!#REF! -> #REF! | B14: =DETAILS!#REF! -> #REF! | C14: =VLOOKUP($A14,'HALF YEARLY(Entry)'!$1:$1048576,3,0) -> #REF! | D14: =VLOOKUP($A14,'HALF YEARLY(Entry)'!$1:$1048576,4,0) -> #REF! | E14: =VLOOKUP($A14,'HALF YEARLY(Entry)'!$1:$1048576,5,0) -> #REF! | F14: =VLOOKUP($A14,'HALF YEARLY(Entry)'!$1:$1048576,6,0) -> #REF! | G14: =VLOOKUP($A14,'HALF YEARLY(Entry)'!$1:$1048576,7,0) -> #REF! | H14: =VLOOKUP($A14,'HALF YEARLY(Entry)'!$1:$1048576,8,0) -> #REF! | I14: =VLOOKUP($A14,'HALF YEARLY(Entry)'!$1:$1048576,9,0) -> #REF! | J14: =VLOOKUP($A14,'HALF YEARLY(Entry)'!$1:$1048576,10,0) -> #REF! | K14: =VLOOKUP($A14,'HALF YEARLY(Entry)'!$1:$1048576,11,0) -> #REF! | L14: =VLOOKUP($A14,'HALF YEARLY(Entry)'!$1:$1048576,12,0) -> #REF! | M14: =VLOOKUP($A14,'HALF YEARLY(Entry)'!$1:$1048576,13,0) -> #REF! | N14: =VLOOKUP($A14,'HALF YEARLY(Entry)'!$1:$1048576,14,0) -> #REF! | O14: =VLOOKUP($A14,'HALF YEARLY(Entry)'!$1:$1048576,15,0) -> #REF! | P14: =SUM(C14:H14) -> #REF! | Q14: =ROUND(P14/6,2)&" %" -> #REF!
A15: =DETAILS!#REF! -> #REF! | B15: =DETAILS!#REF! -> #REF! | C15: =VLOOKUP($A15,'HALF YEARLY(Entry)'!$1:$1048576,3,0) -> #REF! | D15: =VLOOKUP($A15,'HALF YEARLY(Entry)'!$1:$1048576,4,0) -> #REF! | E15: =VLOOKUP($A15,'HALF YEARLY(Entry)'!$1:$1048576,5,0) -> #REF! | F15: =VLOOKUP($A15,'HALF YEARLY(Entry)'!$1:$1048576,6,0) -> #REF! | G15: =VLOOKUP($A15,'HALF YEARLY(Entry)'!$1:$1048576,7,0) -> #REF! | H15: =VLOOKUP($A15,'HALF YEARLY(Entry)'!$1:$1048576,8,0) -> #REF! | I15: =VLOOKUP($A15,'HALF YEARLY(Entry)'!$1:$1048576,9,0) -> #REF! | J15: =VLOOKUP($A15,'HALF YEARLY(Entry)'!$1:$1048576,10,0) -> #REF! | K15: =VLOOKUP($A15,'HALF YEARLY(Entry)'!$1:$1048576,11,0) -> #REF! | L15: =VLOOKUP($A15,'HALF YEARLY(Entry)'!$1:$1048576,12,0) -> #REF! | M15: =VLOOKUP($A15,'HALF YEARLY(Entry)'!$1:$1048576,13,0) -> #REF! | N15: =VLOOKUP($A15,'HALF YEARLY(Entry)'!$1:$1048576,14,0) -> #REF! | O15: =VLOOKUP($A15,'HALF YEARLY(Entry)'!$1:$1048576,15,0) -> #REF! | P15: =SUM(C15:H15) -> #REF! | Q15: =ROUND(P15/6,2)&" %" -> #REF!
A16: =DETAILS!#REF! -> #REF! | B16: =DETAILS!#REF! -> #REF! | C16: =VLOOKUP($A16,'HALF YEARLY(Entry)'!$1:$1048576,3,0) -> #REF! | D16: =VLOOKUP($A16,'HALF YEARLY(Entry)'!$1:$1048576,4,0) -> #REF! | E16: =VLOOKUP($A16,'HALF YEARLY(Entry)'!$1:$1048576,5,0) -> #REF! | F16: =VLOOKUP($A16,'HALF YEARLY(Entry)'!$1:$1048576,6,0) -> #REF! | G16: =VLOOKUP($A16,'HALF YEARLY(Entry)'!$1:$1048576,7,0) -> #REF! | H16: =VLOOKUP($A16,'HALF YEARLY(Entry)'!$1:$1048576,8,0) -> #REF! | I16: =VLOOKUP($A16,'HALF YEARLY(Entry)'!$1:$1048576,9,0) -> #REF! | J16: =VLOOKUP($A16,'HALF YEARLY(Entry)'!$1:$1048576,10,0) -> #REF! | K16: =VLOOKUP($A16,'HALF YEARLY(Entry)'!$1:$1048576,11,0) -> #REF! | L16: =VLOOKUP($A16,'HALF YEARLY(Entry)'!$1:$1048576,12,0) -> #REF! | M16: =VLOOKUP($A16,'HALF YEARLY(Entry)'!$1:$1048576,13,0) -> #REF! | N16: =VLOOKUP($A16,'HALF YEARLY(Entry)'!$1:$1048576,14,0) -> #REF! | O16: =VLOOKUP($A16,'HALF YEARLY(Entry)'!$1:$1048576,15,0) -> #REF! | P16: =SUM(C16:H16) -> #REF! | Q16: =ROUND(P16/6,2)&" %" -> #REF!
A17: =DETAILS!#REF! -> #REF! | B17: =DETAILS!#REF! -> #REF! | C17: =VLOOKUP($A17,'HALF YEARLY(Entry)'!$1:$1048576,3,0) -> #REF! | D17: =VLOOKUP($A17,'HALF YEARLY(Entry)'!$1:$1048576,4,0) -> #REF! | E17: =VLOOKUP($A17,'HALF YEARLY(Entry)'!$1:$1048576,5,0) -> #REF! | F17: =VLOOKUP($A17,'HALF YEARLY(Entry)'!$1:$1048576,6,0) -> #REF! | G17: =VLOOKUP($A17,'HALF YEARLY(Entry)'!$1:$1048576,7,0) -> #REF! | H17: =VLOOKUP($A17,'HALF YEARLY(Entry)'!$1:$1048576,8,0) -> #REF! | I17: =VLOOKUP($A17,'HALF YEARLY(Entry)'!$1:$1048576,9,0) -> #REF! | J17: =VLOOKUP($A17,'HALF YEARLY(Entry)'!$1:$1048576,10,0) -> #REF! | K17: =VLOOKUP($A17,'HALF YEARLY(Entry)'!$1:$1048576,11,0) -> #REF! | L17: =VLOOKUP($A17,'HALF YEARLY(Entry)'!$1:$1048576,12,0) -> #REF! | M17: =VLOOKUP($A17,'HALF YEARLY(Entry)'!$1:$1048576,13,0) -> #REF! | N17: =VLOOKUP($A17,'HALF YEARLY(Entry)'!$1:$1048576,14,0) -> #REF! | O17: =VLOOKUP($A17,'HALF YEARLY(Entry)'!$1:$1048576,15,0) -> #REF! | P17: =SUM(C17:H17) -> #REF! | Q17: =ROUND(P17/6,2)&" %" -> #REF!
A18: =DETAILS!#REF! -> #REF! | B18: =DETAILS!#REF! -> #REF! | C18: =VLOOKUP($A18,'HALF YEARLY(Entry)'!$1:$1048576,3,0) -> #REF! | D18: =VLOOKUP($A18,'HALF YEARLY(Entry)'!$1:$1048576,4,0) -> #REF! | E18: =VLOOKUP($A18,'HALF YEARLY(Entry)'!$1:$1048576,5,0) -> #REF! | F18: =VLOOKUP($A18,'HALF YEARLY(Entry)'!$1:$1048576,6,0) -> #REF! | G18: =VLOOKUP($A18,'HALF YEARLY(Entry)'!$1:$1048576,7,0) -> #REF! | H18: =VLOOKUP($A18,'HALF YEARLY(Entry)'!$1:$1048576,8,0) -> #REF! | I18: =VLOOKUP($A18,'HALF YEARLY(Entry)'!$1:$1048576,9,0) -> #REF! | J18: =VLOOKUP($A18,'HALF YEARLY(Entry)'!$1:$1048576,10,0) -> #REF! | K18: =VLOOKUP($A18,'HALF YEARLY(Entry)'!$1:$1048576,11,0) -> #REF! | L18: =VLOOKUP($A18,'HALF YEARLY(Entry)'!$1:$1048576,12,0) -> #REF! | M18: =VLOOKUP($A18,'HALF YEARLY(Entry)'!$1:$1048576,13,0) -> #REF! | N18: =VLOOKUP($A18,'HALF YEARLY(Entry)'!$1:$1048576,14,0) -> #REF! | O18: =VLOOKUP($A18,'HALF YEARLY(Entry)'!$1:$1048576,15,0) -> #REF! | P18: =SUM(C18:H18) -> #REF! | Q18: =ROUND(P18/6,2)&" %" -> #REF!
A19: =DETAILS!#REF! -> #REF! | B19: =DETAILS!#REF! -> #REF! | C19: =VLOOKUP($A19,'HALF YEARLY(Entry)'!$1:$1048576,3,0) -> #REF! | D19: =VLOOKUP($A19,'HALF YEARLY(Entry)'!$1:$1048576,4,0) -> #REF! | E19: =VLOOKUP($A19,'HALF YEARLY(Entry)'!$1:$1048576,5,0) -> #REF! | F19: =VLOOKUP($A19,'HALF YEARLY(Entry)'!$1:$1048576,6,0) -> #REF! | G19: =VLOOKUP($A19,'HALF YEARLY(Entry)'!$1:$1048576,7,0) -> #REF! | H19: =VLOOKUP($A19,'HALF YEARLY(Entry)'!$1:$1048576,8,0) -> #REF! | I19: =VLOOKUP($A19,'HALF YEARLY(Entry)'!$1:$1048576,9,0) -> #REF! | J19: =VLOOKUP($A19,'HALF YEARLY(Entry)'!$1:$1048576,10,0) -> #REF! | K19: =VLOOKUP($A19,'HALF YEARLY(Entry)'!$1:$1048576,11,0) -> #REF! | L19: =VLOOKUP($A19,'HALF YEARLY(Entry)'!$1:$1048576,12,0) -> #REF! | M19: =VLOOKUP($A19,'HALF YEARLY(Entry)'!$1:$1048576,13,0) -> #REF! | N19: =VLOOKUP($A19,'HALF YEARLY(Entry)'!$1:$1048576,14,0) -> #REF! | O19: =VLOOKUP($A19,'HALF YEARLY(Entry)'!$1:$1048576,15,0) -> #REF! | P19: =SUM(C19:H19) -> #REF! | Q19: =ROUND(P19/6,2)&" %" -> #REF!
A20: =DETAILS!#REF! -> #REF! | B20: =DETAILS!#REF! -> #REF! | C20: =VLOOKUP($A20,'HALF YEARLY(Entry)'!$1:$1048576,3,0) -> #REF! | D20: =VLOOKUP($A20,'HALF YEARLY(Entry)'!$1:$1048576,4,0) -> #REF! | E20: =VLOOKUP($A20,'HALF YEARLY(Entry)'!$1:$1048576,5,0) -> #REF! | F20: =VLOOKUP($A20,'HALF YEARLY(Entry)'!$1:$1048576,6,0) -> #REF! | G20: =VLOOKUP($A20,'HALF YEARLY(Entry)'!$1:$1048576,7,0) -> #REF! | H20: =VLOOKUP($A20,'HALF YEARLY(Entry)'!$1:$1048576,8,0) -> #REF! | I20: =VLOOKUP($A20,'HALF YEARLY(Entry)'!$1:$1048576,9,0) -> #REF! | J20: =VLOOKUP($A20,'HALF YEARLY(Entry)'!$1:$1048576,10,0) -> #REF! | K20: =VLOOKUP($A20,'HALF YEARLY(Entry)'!$1:$1048576,11,0) -> #REF! | L20: =VLOOKUP($A20,'HALF YEARLY(Entry)'!$1:$1048576,12,0) -> #REF! | M20: =VLOOKUP($A20,'HALF YEARLY(Entry)'!$1:$1048576,13,0) -> #REF! | N20: =VLOOKUP($A20,'HALF YEARLY(Entry)'!$1:$1048576,14,0) -> #REF! | O20: =VLOOKUP($A20,'HALF YEARLY(Entry)'!$1:$1048576,15,0) -> #REF! | P20: =SUM(C20:H20) -> #REF! | Q20: =ROUND(P20/6,2)&" %" -> #REF!
A21: =DETAILS!#REF! -> #REF! | B21: =DETAILS!#REF! -> #REF! | C21: =VLOOKUP($A21,'HALF YEARLY(Entry)'!$1:$1048576,3,0) -> #REF! | D21: =VLOOKUP($A21,'HALF YEARLY(Entry)'!$1:$1048576,4,0) -> #REF! | E21: =VLOOKUP($A21,'HALF YEARLY(Entry)'!$1:$1048576,5,0) -> #REF! | F21: =VLOOKUP($A21,'HALF YEARLY(Entry)'!$1:$1048576,6,0) -> #REF! | G21: =VLOOKUP($A21,'HALF YEARLY(Entry)'!$1:$1048576,7,0) -> #REF! | H21: =VLOOKUP($A21,'HALF YEARLY(Entry)'!$1:$1048576,8,0) -> #REF! | I21: =VLOOKUP($A21,'HALF YEARLY(Entry)'!$1:$1048576,9,0) -> #REF! | J21: =VLOOKUP($A21,'HALF YEARLY(Entry)'!$1:$1048576,10,0) -> #REF! | K21: =VLOOKUP($A21,'HALF YEARLY(Entry)'!$1:$1048576,11,0) -> #REF! | L21: =VLOOKUP($A21,'HALF YEARLY(Entry)'!$1:$1048576,12,0) -> #REF! | M21: =VLOOKUP($A21,'HALF YEARLY(Entry)'!$1:$1048576,13,0) -> #REF! | N21: =VLOOKUP($A21,'HALF YEARLY(Entry)'!$1:$1048576,14,0) -> #REF! | O21: =VLOOKUP($A21,'HALF YEARLY(Entry)'!$1:$1048576,15,0) -> #REF! | P21: =SUM(C21:H21) -> #REF! | Q21: =ROUND(P21/6,2)&" %" -> #REF!
A22: =DETAILS!#REF! -> #REF! | B22: =DETAILS!#REF! -> #REF! | C22: =VLOOKUP($A22,'HALF YEARLY(Entry)'!$1:$1048576,3,0) -> #REF! | D22: =VLOOKUP($A22,'HALF YEARLY(Entry)'!$1:$1048576,4,0) -> #REF! | E22: =VLOOKUP($A22,'HALF YEARLY(Entry)'!$1:$1048576,5,0) -> #REF! | F22: =VLOOKUP($A22,'HALF YEARLY(Entry)'!$1:$1048576,6,0) -> #REF! | G22: =VLOOKUP($A22,'HALF YEARLY(Entry)'!$1:$1048576,7,0) -> #REF! | H22: =VLOOKUP($A22,'HALF YEARLY(Entry)'!$1:$1048576,8,0) -> #REF! | I22: =VLOOKUP($A22,'HALF YEARLY(Entry)'!$1:$1048576,9,0) -> #REF! | J22: =VLOOKUP($A22,'HALF YEARLY(Entry)'!$1:$1048576,10,0) -> #REF! | K22: =VLOOKUP($A22,'HALF YEARLY(Entry)'!$1:$1048576,11,0) -> #REF! | L22: =VLOOKUP($A22,'HALF YEARLY(Entry)'!$1:$1048576,12,0) -> #REF! | M22: =VLOOKUP($A22,'HALF YEARLY(Entry)'!$1:$1048576,13,0) -> #REF! | N22: =VLOOKUP($A22,'HALF YEARLY(Entry)'!$1:$1048576,14,0) -> #REF! | O22: =VLOOKUP($A22,'HALF YEARLY(Entry)'!$1:$1048576,15,0) -> #REF! | P22: =SUM(C22:H22) -> #REF! | Q22: =ROUND(P22/6,2)&" %" -> #REF!
A23: =DETAILS!#REF! -> #REF! | B23: =DETAILS!#REF! -> #REF! | C23: =VLOOKUP($A23,'HALF YEARLY(Entry)'!$1:$1048576,3,0) -> #REF! | D23: =VLOOKUP($A23,'HALF YEARLY(Entry)'!$1:$1048576,4,0) -> #REF! | E23: =VLOOKUP($A23,'HALF YEARLY(Entry)'!$1:$1048576,5,0) -> #REF! | F23: =VLOOKUP($A23,'HALF YEARLY(Entry)'!$1:$1048576,6,0) -> #REF! | G23: =VLOOKUP($A23,'HALF YEARLY(Entry)'!$1:$1048576,7,0) -> #REF! | H23: =VLOOKUP($A23,'HALF YEARLY(Entry)'!$1:$1048576,8,0) -> #REF! | I23: =VLOOKUP($A23,'HALF YEARLY(Entry)'!$1:$1048576,9,0) -> #REF! | J23: =VLOOKUP($A23,'HALF YEARLY(Entry)'!$1:$1048576,10,0) -> #REF! | K23: =VLOOKUP($A23,'HALF YEARLY(Entry)'!$1:$1048576,11,0) -> #REF! | L23: =VLOOKUP($A23,'HALF YEARLY(Entry)'!$1:$1048576,12,0) -> #REF! | M23: =VLOOKUP($A23,'HALF YEARLY(Entry)'!$1:$1048576,13,0) -> #REF! | N23: =VLOOKUP($A23,'HALF YEARLY(Entry)'!$1:$1048576,14,0) -> #REF! | O23: =VLOOKUP($A23,'HALF YEARLY(Entry)'!$1:$1048576,15,0) -> #REF! | P23: =SUM(C23:H23) -> #REF! | Q23: =ROUND(P23/6,2)&" %" -> #REF!
... A41: =DETAILS!#REF! -> #REF! | B41: =DETAILS!#REF! -> #REF! | C41: =VLOOKUP($A41,'HALF YEARLY(Entry)'!$1:$1048576,3,0) -> #REF! | D41: =VLOOKUP($A41,'HALF YEARLY(Entry)'!$1:$1048576,4,0) -> #REF! | E41: =VLOOKUP($A41,'HALF YEARLY(Entry)'!$1:$1048576,5,0) -> #REF! | F41: =VLOOKUP($A41,'HALF YEARLY(Entry)'!$1:$1048576,6,0) -> #REF! | G41: =VLOOKUP($A41,'HALF YEARLY(Entry)'!$1:$1048576,7,0) -> #REF! | H41: =VLOOKUP($A41,'HALF YEARLY(Entry)'!$1:$1048576,8,0) -> #REF! | I41: =VLOOKUP($A41,'HALF YEARLY(Entry)'!$1:$1048576,9,0) -> #REF! | J41: =VLOOKUP($A41,'HALF YEARLY(Entry)'!$1:$1048576,10,0) -> #REF! | K41: =VLOOKUP($A41,'HALF YEARLY(Entry)'!$1:$1048576,11,0) -> #REF! | L41: =VLOOKUP($A41,'HALF YEARLY(Entry)'!$1:$1048576,12,0) -> #REF! | M41: =VLOOKUP($A41,'HALF YEARLY(Entry)'!$1:$1048576,13,0) -> #REF! | N41: =VLOOKUP($A41,'HALF YEARLY(Entry)'!$1:$1048576,14,0) -> #REF! | O41: =VLOOKUP($A41,'HALF YEARLY(Entry)'!$1:$1048576,15,0) -> #REF! | P41: =SUM(C41:H41) -> #REF! | Q41: =ROUND(P41/6,2)&" %" -> #REF!

Sheet Grade 50
A2: 50 | B2: A
A3: 49 | B3: A
A4: 48 | B4: A
A5: 47 | B5: A
A6: 46 | B6: A
A7: 45 | B7: A
A8: 44 | B8: A
A9: 43 | B9: A
A10: 42 | B10: A
A11: 41 | B11: A
A12: 40 | B12: B
A13: 39 | B13: B
... A52: 0 | B52: E

Sheet HY Compile
A1: Half Yearly Compile Report (2025-26) Class - XI-Comm
A2: S.R. No. | B2: Student's Name | C2: ENGLISH | F2: HINDI/CS | I2: ACCOUNTACNY | L2: BUSINESS STUDIES | O2: ECONOMICS | R2: PHYSICAL EDUCATION | U2: WORK EDUCATION | V2: ART EDUCATION | W2: HEALTH & PHYSICAL EDUCATION | X2: DISCIPLINE | Y2: TOTAL PRESENT | Z2: TORAL WORKING DAY | AA2: CLASS TEACHER'S REAMRK
C3: UT-I | D3: HY | E3: Total | F3: UT-I | G3: HY | H3: Total | I3: UT-I | J3: HY | K3: Total | L3: UT-I | M3: HY | N3: Total | O3: UT-I | P3: HY | Q3: Total | R3: UT-I | S3: HY | T3: Total
A4: =DETAILS!A3 -> 688 | B4: =DETAILS!B3 -> AMINUDDIN | C4: =VLOOKUP($A4,'UT-I '!$1:$1048576,3,0) -> AB | D4: =IFERROR(ROUND(VLOOKUP($A4,'HALF YEARLY'!$1:$1048576,3,0)*0.8,0),VLOOKUP($A4,'HALF YEARLY'!$1:$1048576,3,0)) -> 0 | E4: =SUM(C4:D4) -> 0 | F4: =VLOOKUP($A4,'UT-I '!$1:$1048576,4,0) -> AB | G4: =IFERROR(ROUND(VLOOKUP($A4,'HALF YEARLY'!$1:$1048576,4,0)*0.8,0),VLOOKUP($A4,'HALF YEARLY'!$1:$1048576,4,0)) -> 0 | H4: =SUM(F4:G4) -> 0 | I4: =VLOOKUP($A4,'UT-I '!$1:$1048576,5,0) -> AB | J4: =IFERROR(ROUND(VLOOKUP($A4,'HALF YEARLY'!$1:$1048576,5,0)*0.8,0),VLOOKUP($A4,'HALF YEARLY'!$1:$1048576,5,0)) -> 0 | K4: =SUM(I4:J4) -> 0 | L4: =VLOOKUP($A4,'UT-I '!$1:$1048576,6,0) -> AB | M4: =IFERROR(ROUND(VLOOKUP($A4,'HALF YEARLY'!$1:$1048576,6,0)*0.8,0),VLOOKUP($A4,'HALF YEARLY'!$1:$1048576,6,0)) -> 0 | N4: =SUM(L4:M4) -> 0 | O4: =VLOOKUP($A4,'UT-I '!$1:$1048576,7,0) -> AB | P4: =IFERROR(ROUND(VLOOKUP($A4,'HALF YEARLY'!$1:$1048576,7,0)*0.8,0),VLOOKUP($A4,'HALF YEARLY'!$1:$1048576,7,0)) -> 0 | Q4: =SUM(O4:P4) -> 0 | R4: =VLOOKUP($A4,'UT-I '!$1:$1048576,8,0) -> AB | S4: =IFERROR(ROUND(VLOOKUP($A4,'HALF YEARLY'!$1:$1048576,8,0)*0.8,0),VLOOKUP($A4,'HALF YEARLY'!$1:$1048576,8,0)) -> 0 | T4: =SUM(R4:S4) -> 0 | U4: =VLOOKUP($A4,'HALF YEARLY'!$1:$1048576,9,0) -> 0 | V4: =VLOOKUP($A4,'HALF YEARLY'!$1:$1048576,10,0) -> 0 | W4: =VLOOKUP($A4,'HALF YEARLY'!$1:$1048576,11,0) -> 0 | X4: =VLOOKUP($A4,'HALF YEARLY'!$1:$1048576,12,0) -> 0 | Y4: =VLOOKUP($A4,'HALF YEARLY'!$1:$1048576,13,0) -> 0 | Z4: =VLOOKUP($A4,'HALF YEARLY'!$1:$1048576,14,0) -> 0 | AA4: =VLOOKUP($A4,'HALF YEARLY'!$1:$1048576,15,0) -> 0
A5: =DETAILS!A4 -> 1011 | B5: =DETAILS!B4 -> ARPIT VERMA | C5: =VLOOKUP($A5,'UT-I '!$1:$1048576,3,0) -> 6 | D5: =IFERROR(ROUND(VLOOKUP($A5,'HALF YEARLY'!$1:$1048576,3,0)*0.8,0),VLOOKUP($A5,'HALF YEARLY'!$1:$1048576,3,0)) -> 0 | E5: =SUM(C5:D5) -> 6 | F5: =VLOOKUP($A5,'UT-I '!$1:$1048576,4,0) -> 5 | G5: =IFERROR(ROUND(VLOOKUP($A5,'HALF YEARLY'!$1:$1048576,4,0)*0.8,0),VLOOKUP($A5,'HALF YEARLY'!$1:$1048576,4,0)) -> 0 | H5: =SUM(F5:G5) -> 5 | I5: =VLOOKUP($A5,'UT-I '!$1:$1048576,5,0) -> 7 | J5: =IFERROR(ROUND(VLOOKUP($A5,'HALF YEARLY'!$1:$1048576,5,0)*0.8,0),VLOOKUP($A5,'HALF YEARLY'!$1:$1048576,5,0)) -> 0 | K5: =SUM(I5:J5) -> 7 | L5: =VLOOKUP($A5,'UT-I '!$1:$1048576,6,0) -> 5 | M5: =IFERROR(ROUND(VLOOKUP($A5,'HALF YEARLY'!$1:$1048576,6,0)*0.8,0),VLOOKUP($A5,'HALF YEARLY'!$1:$1048576,6,0)) -> 0 | N5: =SUM(L5:M5) -> 5 | O5: =VLOOKUP($A5,'UT-I '!$1:$1048576,7,0) -> 1 | P5: =IFERROR(ROUND(VLOOKUP($A5,'HALF YEARLY'!$1:$1048576,7,0)*0.8,0),VLOOKUP($A5,'HALF YEARLY'!$1:$1048576,7,0)) -> 0 | Q5: =SUM(O5:P5) -> 1 | R5: =VLOOKUP($A5,'UT-I '!$1:$1048576,8,0) -> 6 | S5: =IFERROR(ROUND(VLOOKUP($A5,'HALF YEARLY'!$1:$1048576,8,0)*0.8,0),VLOOKUP($A5,'HALF YEARLY'!$1:$1048576,8,0)) -> 0 | T5: =SUM(R5:S5) -> 6 | U5: =VLOOKUP($A5,'HALF YEARLY'!$1:$1048576,9,0) -> 0 | V5: =VLOOKUP($A5,'HALF YEARLY'!$1:$1048576,10,0) -> 0 | W5: =VLOOKUP($A5,'HALF YEARLY'!$1:$1048576,11,0) -> 0 | X5: =VLOOKUP($A5,'HALF YEARLY'!$1:$1048576,12,0) -> 0 | Y5: =VLOOKUP($A5,'HALF YEARLY'!$1:$1048576,13,0) -> 0 | Z5: =VLOOKUP($A5,'HALF YEARLY'!$1:$1048576,14,0) -> 0 | AA5: =VLOOKUP($A5,'HALF YEARLY'!$1:$1048576,15,0) -> 0
A6: =DETAILS!A5 -> 692 | B6: =DETAILS!B5 -> ATUL VERMA | C6: =VLOOKUP($A6,'UT-I '!$1:$1048576,3,0) -> 13 | D6: =IFERROR(ROUND(VLOOKUP($A6,'HALF YEARLY'!$1:$1048576,3,0)*0.8,0),VLOOKUP($A6,'HALF YEARLY'!$1:$1048576,3,0)) -> 0 | E6: =SUM(C6:D6) -> 13 | F6: =VLOOKUP($A6,'UT-I '!$1:$1048576,4,0) -> 14 | G6: =IFERROR(ROUND(VLOOKUP($A6,'HALF YEARLY'!$1:$1048576,4,0)*0.8,0),VLOOKUP($A6,'HALF YEARLY'!$1:$1048576,4,0)) -> 0 | H6: =SUM(F6:G6) -> 14 | I6: =VLOOKUP($A6,'UT-I '!$1:$1048576,5,0) -> 17 | J6: =IFERROR(ROUND(VLOOKUP($A6,'HALF YEARLY'!$1:$1048576,5,0)*0.8,0),VLOOKUP($A6,'HALF YEARLY'!$1:$1048576,5,0)) -> 0 | K6: =SUM(I6:J6) -> 17 | L6: =VLOOKUP($A6,'UT-I '!$1:$1048576,6,0) -> 19 | M6: =IFERROR(ROUND(VLOOKUP($A6,'HALF YEARLY'!$1:$1048576,6,0)*0.8,0),VLOOKUP($A6,'HALF YEARLY'!$1:$1048576,6,0)) -> 0 | N6: =SUM(L6:M6) -> 19 | O6: =VLOOKUP($A6,'UT-I '!$1:$1048576,7,0) -> 12 | P6: =IFERROR(ROUND(VLOOKUP($A6,'HALF YEARLY'!$1:$1048576,7,0)*0.8,0),VLOOKUP($A6,'HALF YEARLY'!$1:$1048576,7,0)) -> 0 | Q6: =SUM(O6:P6) -> 12 | R6: =VLOOKUP($A6,'UT-I '!$1:$1048576,8,0) -> 19 | S6: =IFERROR(ROUND(VLOOKUP($A6,'HALF YEARLY'!$1:$1048576,8,0)*0.8,0),VLOOKUP($A6,'HALF YEARLY'!$1:$1048576,8,0)) -> 0 | T6: =SUM(R6:S6) -> 19 | U6: =VLOOKUP($A6,'HALF YEARLY'!$1:$1048576,9,0) -> 0 | V6: =VLOOKUP($A6,'HALF YEARLY'!$1:$1048576,10,0) -> 0 | W6: =VLOOKUP($A6,'HALF YEARLY'!$1:$1048576,11,0) -> 0 | X6: =VLOOKUP($A6,'HALF YEARLY'!$1:$1048576,12,0) -> 0 | Y6: =VLOOKUP($A6,'HALF YEARLY'!$1:$1048576,13,0) -> 0 | Z6: =VLOOKUP($A6,'HALF YEARLY'!$1:$1048576,14,0) -> 0 | AA6: =VLOOKUP($A6,'HALF YEARLY'!$1:$1048576,15,0) -> 0
A7: =DETAILS!A6 -> 1931 | B7: =DETAILS!B6 -> GAURAV GAUTAM | C7: =VLOOKUP($A7,'UT-I '!$1:$1048576,3,0) -> 15 | D7: =IFERROR(ROUND(VLOOKUP($A7,'HALF YEARLY'!$1:$1048576,3,0)*0.8,0),VLOOKUP($A7,'HALF YEARLY'!$1:$1048576,3,0)) -> 0 | E7: =SUM(C7:D7) -> 15 | F7: =VLOOKUP($A7,'UT-I '!$1:$1048576,4,0) -> 20 | G7: =IFERROR(ROUND(VLOOKUP($A7,'HALF YEARLY'!$1:$1048576,4,0)*0.8,0),VLOOKUP($A7,'HALF YEARLY'!$1:$1048576,4,0)) -> 0 | H7: =SUM(F7:G7) -> 20 | I7: =VLOOKUP($A7,'UT-I '!$1:$1048576,5,0) -> 17 | J7: =IFERROR(ROUND(VLOOKUP($A7,'HALF YEARLY'!$1:$1048576,5,0)*0.8,0),VLOOKUP($A7,'HALF YEARLY'!$1:$1048576,5,0)) -> 0 | K7: =SUM(I7:J7) -> 17 | L7: =VLOOKUP($A7,'UT-I '!$1:$1048576,6,0) -> 20 | M7: =IFERROR(ROUND(VLOOKUP($A7,'HALF YEARLY'!$1:$1048576,6,0)*0.8,0),VLOOKUP($A7,'HALF YEARLY'!$1:$1048576,6,0)) -> 0 | N7: =SUM(L7:M7) -> 20 | O7: =VLOOKUP($A7,'UT-I '!$1:$1048576,7,0) -> 13 | P7: =IFERROR(ROUND(VLOOKUP($A7,'HALF YEARLY'!$1:$1048576,7,0)*0.8,0),VLOOKUP($A7,'HALF YEARLY'!$1:$1048576,7,0)) -> 0 | Q7: =SUM(O7:P7) -> 13 | R7: =VLOOKUP($A7,'UT-I '!$1:$1048576,8,0) -> 17 | S7: =IFERROR(ROUND(VLOOKUP($A7,'HALF YEARLY'!$1:$1048576,8,0)*0.8,0),VLOOKUP($A7,'HALF YEARLY'!$1:$1048576,8,0)) -> 0 | T7: =SUM(R7:S7) -> 17 | U7: =VLOOKUP($A7,'HALF YEARLY'!$1:$1048576,9,0) -> 0 | V7: =VLOOKUP($A7,'HALF YEARLY'!$1:$1048576,10,0) -> 0 | W7: =VLOOKUP($A7,'HALF YEARLY'!$1:$1048576,11,0) -> 0 | X7: =VLOOKUP($A7,'HALF YEARLY'!$1:$1048576,12,0) -> 0 | Y7: =VLOOKUP($A7,'HALF YEARLY'!$1:$1048576,13,0) -> 0 | Z7: =VLOOKUP($A7,'HALF YEARLY'!$1:$1048576,14,0) -> 0 | AA7: =VLOOKUP($A7,'HALF YEARLY'!$1:$1048576,15,0) -> 0
A8: =DETAILS!A7 -> 1509 | B8: =DETAILS!B7 -> HIMANSHU | C8: =VLOOKUP($A8,'UT-I '!$1:$1048576,3,0) -> 13 | D8: =IFERROR(ROUND(VLOOKUP($A8,'HALF YEARLY'!$1:$1048576,3,0)*0.8,0),VLOOKUP($A8,'HALF YEARLY'!$1:$1048576,3,0)) -> 0 | E8: =SUM(C8:D8) -> 13 | F8: =VLOOKUP($A8,'UT-I '!$1:$1048576,4,0) -> 10 | G8: =IFERROR(ROUND(VLOOKUP($A8,'HALF YEARLY'!$1:$1048576,4,0)*0.8,0),VLOOKUP($A8,'HALF YEARLY'!$1:$1048576,4,0)) -> 0 | H8: =SUM(F8:G8) -> 10 | I8: =VLOOKUP($A8,'UT-I '!$1:$1048576,5,0) -> 13 | J8: =IFERROR(ROUND(VLOOKUP($A8,'HALF YEARLY'!$1:$1048576,5,0)*0.8,0),VLOOKUP($A8,'HALF YEARLY'!$1:$1048576,5,0)) -> 0 | K8: =SUM(I8:J8) -> 13 | L8: =VLOOKUP($A8,'UT-I '!$1:$1048576,6,0) -> 16 | M8: =IFERROR(ROUND(VLOOKUP($A8,'HALF YEARLY'!$1:$1048576,6,0)*0.8,0),VLOOKUP($A8,'HALF YEARLY'!$1:$1048576,6,0)) -> 0 | N8: =SUM(L8:M8) -> 16 | O8: =VLOOKUP($A8,'UT-I '!$1:$1048576,7,0) -> 8 | P8: =IFERROR(ROUND(VLOOKUP($A8,'HALF YEARLY'!$1:$1048576,7,0)*0.8,0),VLOOKUP($A8,'HALF YEARLY'!$1:$1048576,7,0)) -> 0 | Q8: =SUM(O8:P8) -> 8 | R8: =VLOOKUP($A8,'UT-I '!$1:$1048576,8,0) -> 13 | S8: =IFERROR(ROUND(VLOOKUP($A8,'HALF YEARLY'!$1:$1048576,8,0)*0.8,0),VLOOKUP($A8,'HALF YEARLY'!$1:$1048576,8,0)) -> 0 | T8: =SUM(R8:S8) -> 13 | U8: =VLOOKUP($A8,'HALF YEARLY'!$1:$1048576,9,0) -> 0 | V8: =VLOOKUP($A8,'HALF YEARLY'!$1:$1048576,10,0) -> 0 | W8: =VLOOKUP($A8,'HALF YEARLY'!$1:$1048576,11,0) -> 0 | X8: =VLOOKUP($A8,'HALF YEARLY'!$1:$1048576,12,0) -> 0 | Y8: =VLOOKUP($A8,'HALF YEARLY'!$1:$1048576,13,0) -> 0 | Z8: =VLOOKUP($A8,'HALF YEARLY'!$1:$1048576,14,0) -> 0 | AA8: =VLOOKUP($A8,'HALF YEARLY'!$1:$1048576,15,0) -> 0
A9: =DETAILS!A8 -> 694 | B9: =DETAILS!B8 -> JYOTIRADITYA DAS | C9: =VLOOKUP($A9,'UT-I '!$1:$1048576,3,0) -> 9 | D9: =IFERROR(ROUND(VLOOKUP($A9,'HALF YEARLY'!$1:$1048576,3,0)*0.8,0),VLOOKUP($A9,'HALF YEARLY'!$1:$1048576,3,0)) -> 0 | E9: =SUM(C9:D9) -> 9 | F9: =VLOOKUP($A9,'UT-I '!$1:$1048576,4,0) -> 7 | G9: =IFERROR(ROUND(VLOOKUP($A9,'HALF YEARLY'!$1:$1048576,4,0)*0.8,0),VLOOKUP($A9,'HALF YEARLY'!$1:$1048576,4,0)) -> 0 | H9: =SUM(F9:G9) -> 7 | I9: =VLOOKUP($A9,'UT-I '!$1:$1048576,5,0) -> 13 | J9: =IFERROR(ROUND(VLOOKUP($A9,'HALF YEARLY'!$1:$1048576,5,0)*0.8,0),VLOOKUP($A9,'HALF YEARLY'!$1:$1048576,5,0)) -> 0 | K9: =SUM(I9:J9) -> 13 | L9: =VLOOKUP($A9,'UT-I '!$1:$1048576,6,0) -> 13 | M9: =IFERROR(ROUND(VLOOKUP($A9,'HALF YEARLY'!$1:$1048576,6,0)*0.8,0),VLOOKUP($A9,'HALF YEARLY'!$1:$1048576,6,0)) -> 0 | N9: =SUM(L9:M9) -> 13 | O9: =VLOOKUP($A9,'UT-I '!$1:$1048576,7,0) -> 5 | P9: =IFERROR(ROUND(VLOOKUP($A9,'HALF YEARLY'!$1:$1048576,7,0)*0.8,0),VLOOKUP($A9,'HALF YEARLY'!$1:$1048576,7,0)) -> 0 | Q9: =SUM(O9:P9) -> 5 | R9: =VLOOKUP($A9,'UT-I '!$1:$1048576,8,0) -> 11 | S9: =IFERROR(ROUND(VLOOKUP($A9,'HALF YEARLY'!$1:$1048576,8,0)*0.8,0),VLOOKUP($A9,'HALF YEARLY'!$1:$1048576,8,0)) -> 0 | T9: =SUM(R9:S9) -> 11 | U9: =VLOOKUP($A9,'HALF YEARLY'!$1:$1048576,9,0) -> 0 | V9: =VLOOKUP($A9,'HALF YEARLY'!$1:$1048576,10,0) -> 0 | W9: =VLOOKUP($A9,'HALF YEARLY'!$1:$1048576,11,0) -> 0 | X9: =VLOOKUP($A9,'HALF YEARLY'!$1:$1048576,12,0) -> 0 | Y9: =VLOOKUP($A9,'HALF YEARLY'!$1:$1048576,13,0) -> 0 | Z9: =VLOOKUP($A9,'HALF YEARLY'!$1:$1048576,14,0) -> 0 | AA9: =VLOOKUP($A9,'HALF YEARLY'!$1:$1048576,15,0) -> 0
A10: =DETAILS!A9 -> 1873 | B10: =DETAILS!B9 -> MASIRA AKHTAR | C10: =VLOOKUP($A10,'UT-I '!$1:$1048576,3,0) -> 13 | D10: =IFERROR(ROUND(VLOOKUP($A10,'HALF YEARLY'!$1:$1048576,3,0)*0.8,0),VLOOKUP($A10,'HALF YEARLY'!$1:$1048576,3,0)) -> 0 | E10: =SUM(C10:D10) -> 13 | F10: =VLOOKUP($A10,'UT-I '!$1:$1048576,4,0) -> 13 | G10: =IFERROR(ROUND(VLOOKUP($A10,'HALF YEARLY'!$1:$1048576,4,0)*0.8,0),VLOOKUP($A10,'HALF YEARLY'!$1:$1048576,4,0)) -> 0 | H10: =SUM(F10:G10) -> 13 | I10: =VLOOKUP($A10,'UT-I '!$1:$1048576,5,0) -> 16 | J10: =IFERROR(ROUND(VLOOKUP($A10,'HALF YEARLY'!$1:$1048576,5,0)*0.8,0),VLOOKUP($A10,'HALF YEARLY'!$1:$1048576,5,0)) -> 0 | K10: =SUM(I10:J10) -> 16 | L10: =VLOOKUP($A10,'UT-I '!$1:$1048576,6,0) -> 17 | M10: =IFERROR(ROUND(VLOOKUP($A10,'HALF YEARLY'!$1:$1048576,6,0)*0.8,0),VLOOKUP($A10,'HALF YEARLY'!$1:$1048576,6,0)) -> 0 | N10: =SUM(L10:M10) -> 17 | O10: =VLOOKUP($A10,'UT-I '!$1:$1048576,7,0) -> 14 | P10: =IFERROR(ROUND(VLOOKUP($A10,'HALF YEARLY'!$1:$1048576,7,0)*0.8,0),VLOOKUP($A10,'HALF YEARLY'!$1:$1048576,7,0)) -> 0 | Q10: =SUM(O10:P10) -> 14 | R10: =VLOOKUP($A10,'UT-I '!$1:$1048576,8,0) -> 17 | S10: =IFERROR(ROUND(VLOOKUP($A10,'HALF YEARLY'!$1:$1048576,8,0)*0.8,0),VLOOKUP($A10,'HALF YEARLY'!$1:$1048576,8,0)) -> 0 | T10: =SUM(R10:S10) -> 17 | U10: =VLOOKUP($A10,'HALF YEARLY'!$1:$1048576,9,0) -> 0 | V10: =VLOOKUP($A10,'HALF YEARLY'!$1:$1048576,10,0) -> 0 | W10: =VLOOKUP($A10,'HALF YEARLY'!$1:$1048576,11,0) -> 0 | X10: =VLOOKUP($A10,'HALF YEARLY'!$1:$1048576,12,0) -> 0 | Y10: =VLOOKUP($A10,'HALF YEARLY'!$1:$1048576,13,0) -> 0 | Z10: =VLOOKUP($A10,'HALF YEARLY'!$1:$1048576,14,0) -> 0 | AA10: =VLOOKUP($A10,'HALF YEARLY'!$1:$1048576,15,0) -> 0
A11: =DETAILS!A10 -> 1491 | B11: =DETAILS!B10 -> SIDDHARTH | C11: =VLOOKUP($A11,'UT-I '!$1:$1048576,3,0) -> 11 | D11: =IFERROR(ROUND(VLOOKUP($A11,'HALF YEARLY'!$1:$1048576,3,0)*0.8,0),VLOOKUP($A11,'HALF YEARLY'!$1:$1048576,3,0)) -> 0 | E11: =SUM(C11:D11) -> 11 | F11: =VLOOKUP($A11,'UT-I '!$1:$1048576,4,0) -> 7 | G11: =IFERROR(ROUND(VLOOKUP($A11,'HALF YEARLY'!$1:$1048576,4,0)*0.8,0),VLOOKUP($A11,'HALF YEARLY'!$1:$1048576,4,0)) -> 0 | H11: =SUM(F11:G11) -> 7 | I11: =VLOOKUP($A11,'UT-I '!$1:$1048576,5,0) -> 11 | J11: =IFERROR(ROUND(VLOOKUP($A11,'HALF YEARLY'!$1:$1048576,5,0)*0.8,0),VLOOKUP($A11,'HALF YEARLY'!$1:$1048576,5,0)) -> 0 | K11: =SUM(I11:J11) -> 11 | L11: =VLOOKUP($A11,'UT-I '!$1:$1048576,6,0) -> 16 | M11: =IFERROR(ROUND(VLOOKUP($A11,'HALF YEARLY'!$1:$1048576,6,0)*0.8,0),VLOOKUP($A11,'HALF YEARLY'!$1:$1048576,6,0)) -> 0 | N11: =SUM(L11:M11) -> 16 | O11: =VLOOKUP($A11,'UT-I '!$1:$1048576,7,0) -> 8 | P11: =IFERROR(ROUND(VLOOKUP($A11,'HALF YEARLY'!$1:$1048576,7,0)*0.8,0),VLOOKUP($A11,'HALF YEARLY'!$1:$1048576,7,0)) -> 0 | Q11: =SUM(O11:P11) -> 8 | R11: =VLOOKUP($A11,'UT-I '!$1:$1048576,8,0) -> 15 | S11: =IFERROR(ROUND(VLOOKUP($A11,'HALF YEARLY'!$1:$1048576,8,0)*0.8,0),VLOOKUP($A11,'HALF YEARLY'!$1:$1048576,8,0)) -> 0 | T11: =SUM(R11:S11) -> 15 | U11: =VLOOKUP($A11,'HALF YEARLY'!$1:$1048576,9,0) -> 0 | V11: =VLOOKUP($A11,'HALF YEARLY'!$1:$1048576,10,0) -> 0 | W11: =VLOOKUP($A11,'HALF YEARLY'!$1:$1048576,11,0) -> 0 | X11: =VLOOKUP($A11,'HALF YEARLY'!$1:$1048576,12,0) -> 0 | Y11: =VLOOKUP($A11,'HALF YEARLY'!$1:$1048576,13,0) -> 0 | Z11: =VLOOKUP($A11,'HALF YEARLY'!$1:$1048576,14,0) -> 0 | AA11: =VLOOKUP($A11,'HALF YEARLY'!$1:$1048576,15,0) -> 0
A12: =DETAILS!A11 -> 701 | B12: =DETAILS!B11 -> YASH SONI | C12: =VLOOKUP($A12,'UT-I '!$1:$1048576,3,0) -> AB | D12: =IFERROR(ROUND(VLOOKUP($A12,'HALF YEARLY'!$1:$1048576,3,0)*0.8,0),VLOOKUP($A12,'HALF YEARLY'!$1:$1048576,3,0)) -> 0 | E12: =SUM(C12:D12) -> 0 | F12: =VLOOKUP($A12,'UT-I '!$1:$1048576,4,0) -> AB | G12: =IFERROR(ROUND(VLOOKUP($A12,'HALF YEARLY'!$1:$1048576,4,0)*0.8,0),VLOOKUP($A12,'HALF YEARLY'!$1:$1048576,4,0)) -> 0 | H12: =SUM(F12:G12) -> 0 | I12: =VLOOKUP($A12,'UT-I '!$1:$1048576,5,0) -> AB | J12: =IFERROR(ROUND(VLOOKUP($A12,'HALF YEARLY'!$1:$1048576,5,0)*0.8,0),VLOOKUP($A12,'HALF YEARLY'!$1:$1048576,5,0)) -> 0 | K12: =SUM(I12:J12) -> 0 | L12: =VLOOKUP($A12,'UT-I '!$1:$1048576,6,0) -> AB | M12: =IFERROR(ROUND(VLOOKUP($A12,'HALF YEARLY'!$1:$1048576,6,0)*0.8,0),VLOOKUP($A12,'HALF YEARLY'!$1:$1048576,6,0)) -> 0 | N12: =SUM(L12:M12) -> 0 | O12: =VLOOKUP($A12,'UT-I '!$1:$1048576,7,0) -> AB | P12: =IFERROR(ROUND(VLOOKUP($A12,'HALF YEARLY'!$1:$1048576,7,0)*0.8,0),VLOOKUP($A12,'HALF YEARLY'!$1:$1048576,7,0)) -> 0 | Q12: =SUM(O12:P12) -> 0 | R12: =VLOOKUP($A12,'UT-I '!$1:$1048576,8,0) -> AB | S12: =IFERROR(ROUND(VLOOKUP($A12,'HALF YEARLY'!$1:$1048576,8,0)*0.8,0),VLOOKUP($A12,'HALF YEARLY'!$1:$1048576,8,0)) -> 0 | T12: =SUM(R12:S12) -> 0 | U12: =VLOOKUP($A12,'HALF YEARLY'!$1:$1048576,9,0) -> 0 | V12: =VLOOKUP($A12,'HALF YEARLY'!$1:$1048576,10,0) -> 0 | W12: =VLOOKUP($A12,'HALF YEARLY'!$1:$1048576,11,0) -> 0 | X12: =VLOOKUP($A12,'HALF YEARLY'!$1:$1048576,12,0) -> 0 | Y12: =VLOOKUP($A12,'HALF YEARLY'!$1:$1048576,13,0) -> 0 | Z12: =VLOOKUP($A12,'HALF YEARLY'!$1:$1048576,14,0) -> 0 | AA12: =VLOOKUP($A12,'HALF YEARLY'!$1:$1048576,15,0) -> 0
A13: =DETAILS!#REF! -> #REF! | B13: =DETAILS!#REF! -> #REF! | C13: =VLOOKUP($A13,'UT-I '!$1:$1048576,3,0) -> #REF! | D13: =IFERROR(ROUND(VLOOKUP($A13,'HALF YEARLY'!$1:$1048576,3,0)*0.8,0),VLOOKUP($A13,'HALF YEARLY'!$1:$1048576,3,0)) -> #REF! | E13: =SUM(C13:D13) -> #REF! | F13: =VLOOKUP($A13,'UT-I '!$1:$1048576,4,0) -> #REF! | G13: =IFERROR(ROUND(VLOOKUP($A13,'HALF YEARLY'!$1:$1048576,4,0)*0.8,0),VLOOKUP($A13,'HALF YEARLY'!$1:$1048576,4,0)) -> #REF! | H13: =SUM(F13:G13) -> #REF! | I13: =VLOOKUP($A13,'UT-I '!$1:$1048576,5,0) -> #REF! | J13: =IFERROR(ROUND(VLOOKUP($A13,'HALF YEARLY'!$1:$1048576,5,0)*0.8,0),VLOOKUP($A13,'HALF YEARLY'!$1:$1048576,5,0)) -> #REF! | K13: =SUM(I13:J13) -> #REF! | L13: =VLOOKUP($A13,'UT-I '!$1:$1048576,6,0) -> #REF! | M13: =IFERROR(ROUND(VLOOKUP($A13,'HALF YEARLY'!$1:$1048576,6,0)*0.8,0),VLOOKUP($A13,'HALF YEARLY'!$1:$1048576,6,0)) -> #REF! | N13: =SUM(L13:M13) -> #REF! | O13: =VLOOKUP($A13,'UT-I '!$1:$1048576,7,0) -> #REF! | P13: =IFERROR(ROUND(VLOOKUP($A13,'HALF YEARLY'!$1:$1048576,7,0)*0.8,0),VLOOKUP($A13,'HALF YEARLY'!$1:$1048576,7,0)) -> #REF! | Q13: =SUM(O13:P13) -> #REF! | R13: =VLOOKUP($A13,'UT-I '!$1:$1048576,8,0) -> #REF! | S13: =IFERROR(ROUND(VLOOKUP($A13,'HALF YEARLY'!$1:$1048576,8,0)*0.8,0),VLOOKUP($A13,'HALF YEARLY'!$1:$1048576,8,0)) -> #REF! | T13: =SUM(R13:S13) -> #REF! | U13: =VLOOKUP($A13,'HALF YEARLY'!$1:$1048576,9,0) -> #REF! | V13: =VLOOKUP($A13,'HALF YEARLY'!$1:$1048576,10,0) -> #REF! | W13: =VLOOKUP($A13,'HALF YEARLY'!$1:$1048576,11,0) -> #REF! | X13: =VLOOKUP($A13,'HALF YEARLY'!$1:$1048576,12,0) -> #REF! | Y13: =VLOOKUP($A13,'HALF YEARLY'!$1:$1048576,13,0) -> #REF! | Z13: =VLOOKUP($A13,'HALF YEARLY'!$1:$1048576,14,0) -> #REF! | AA13: =VLOOKUP($A13,'HALF YEARLY'!$1:$1048576,15,0) -> #REF!
A14: =DETAILS!#REF! -> #REF! | B14: =DETAILS!#REF! -> #REF! | C14: =VLOOKUP($A14,'UT-I '!$1:$1048576,3,0) -> #REF! | D14: =IFERROR(ROUND(VLOOKUP($A14,'HALF YEARLY'!$1:$1048576,3,0)*0.8,0),VLOOKUP($A14,'HALF YEARLY'!$1:$1048576,3,0)) -> #REF! | E14: =SUM(C14:D14) -> #REF! | F14: =VLOOKUP($A14,'UT-I '!$1:$1048576,4,0) -> #REF! | G14: =IFERROR(ROUND(VLOOKUP($A14,'HALF YEARLY'!$1:$1048576,4,0)*0.8,0),VLOOKUP($A14,'HALF YEARLY'!$1:$1048576,4,0)) -> #REF! | H14: =SUM(F14:G14) -> #REF! | I14: =VLOOKUP($A14,'UT-I '!$1:$1048576,5,0) -> #REF! | J14: =IFERROR(ROUND(VLOOKUP($A14,'HALF YEARLY'!$1:$1048576,5,0)*0.8,0),VLOOKUP($A14,'HALF YEARLY'!$1:$1048576,5,0)) -> #REF! | K14: =SUM(I14:J14) -> #REF! | L14: =VLOOKUP($A14,'UT-I '!$1:$1048576,6,0) -> #REF! | M14: =IFERROR(ROUND(VLOOKUP($A14,'HALF YEARLY'!$1:$1048576,6,0)*0.8,0),VLOOKUP($A14,'HALF YEARLY'!$1:$1048576,6,0)) -> #REF! | N14: =SUM(L14:M14) -> #REF! | O14: =VLOOKUP($A14,'UT-I '!$1:$1048576,7,0) -> #REF! | P14: =IFERROR(ROUND(VLOOKUP($A14,'HALF YEARLY'!$1:$1048576,7,0)*0.8,0),VLOOKUP($A14,'HALF YEARLY'!$1:$1048576,7,0)) -> #REF! | Q14: =SUM(O14:P14) -> #REF! | R14: =VLOOKUP($A14,'UT-I '!$1:$1048576,8,0) -> #REF! | S14: =IFERROR(ROUND(VLOOKUP($A14,'HALF YEARLY'!$1:$1048576,8,0)*0.8,0),VLOOKUP($A14,'HALF YEARLY'!$1:$1048576,8,0)) -> #REF! | T14: =SUM(R14:S14) -> #REF! | U14: =VLOOKUP($A14,'HALF YEARLY'!$1:$1048576,9,0) -> #REF! | V14: =VLOOKUP($A14,'HALF YEARLY'!$1:$1048576,10,0) -> #REF! | W14: =VLOOKUP($A14,'HALF YEARLY'!$1:$1048576,11,0) -> #REF! | X14: =VLOOKUP($A14,'HALF YEARLY'!$1:$1048576,12,0) -> #REF! | Y14: =VLOOKUP($A14,'HALF YEARLY'!$1:$1048576,13,0) -> #REF! | Z14: =VLOOKUP($A14,'HALF YEARLY'!$1:$1048576,14,0) -> #REF! | AA14: =VLOOKUP($A14,'HALF YEARLY'!$1:$1048576,15,0) -> #REF!
A15: =DETAILS!#REF! -> #REF! | B15: =DETAILS!#REF! -> #REF! | C15: =VLOOKUP($A15,'UT-I '!$1:$1048576,3,0) -> #REF! | D15: =IFERROR(ROUND(VLOOKUP($A15,'HALF YEARLY'!$1:$1048576,3,0)*0.8,0),VLOOKUP($A15,'HALF YEARLY'!$1:$1048576,3,0)) -> #REF! | E15: =SUM(C15:D15) -> #REF! | F15: =VLOOKUP($A15,'UT-I '!$1:$1048576,4,0) -> #REF! | G15: =IFERROR(ROUND(VLOOKUP($A15,'HALF YEARLY'!$1:$1048576,4,0)*0.8,0),VLOOKUP($A15,'HALF YEARLY'!$1:$1048576,4,0)) -> #REF! | H15: =SUM(F15:G15) -> #REF! | I15: =VLOOKUP($A15,'UT-I '!$1:$1048576,5,0) -> #REF! | J15: =IFERROR(ROUND(VLOOKUP($A15,'HALF YEARLY'!$1:$1048576,5,0)*0.8,0),VLOOKUP($A15,'HALF YEARLY'!$1:$1048576,5,0)) -> #REF! | K15: =SUM(I15:J15) -> #REF! | L15: =VLOOKUP($A15,'UT-I '!$1:$1048576,6,0) -> #REF! | M15: =IFERROR(ROUND(VLOOKUP($A15,'HALF YEARLY'!$1:$1048576,6,0)*0.8,0),VLOOKUP($A15,'HALF YEARLY'!$1:$1048576,6,0)) -> #REF! | N15: =SUM(L15:M15) -> #REF! | O15: =VLOOKUP($A15,'UT-I '!$1:$1048576,7,0) -> #REF! | P15: =IFERROR(ROUND(VLOOKUP($A15,'HALF YEARLY'!$1:$1048576,7,0)*0.8,0),VLOOKUP($A15,'HALF YEARLY'!$1:$1048576,7,0)) -> #REF! | Q15: =SUM(O15:P15) -> #REF! | R15: =VLOOKUP($A15,'UT-I '!$1:$1048576,8,0) -> #REF! | S15: =IFERROR(ROUND(VLOOKUP($A15,'HALF YEARLY'!$1:$1048576,8,0)*0.8,0),VLOOKUP($A15,'HALF YEARLY'!$1:$1048576,8,0)) -> #REF! | T15: =SUM(R15:S15) -> #REF! | U15: =VLOOKUP($A15,'HALF YEARLY'!$1:$1048576,9,0) -> #REF! | V15: =VLOOKUP($A15,'HALF YEARLY'!$1:$1048576,10,0) -> #REF! | W15: =VLOOKUP($A15,'HALF YEARLY'!$1:$1048576,11,0) -> #REF! | X15: =VLOOKUP($A15,'HALF YEARLY'!$1:$1048576,12,0) -> #REF! | Y15: =VLOOKUP($A15,'HALF YEARLY'!$1:$1048576,13,0) -> #REF! | Z15: =VLOOKUP($A15,'HALF YEARLY'!$1:$1048576,14,0) -> #REF! | AA15: =VLOOKUP($A15,'HALF YEARLY'!$1:$1048576,15,0) -> #REF!
