Workbook

Sheet DETAILS
A1: STUDENT'S DETAIL
A2: SR NO | B2: NAME | C2: MOTHER'S NAME | D2: FATHER'S NAME | E2: DOB | F2: CLASS & SEC
A3: 1804 | B3: AAKRITI SINGH | C3: CHHAYA SINGH | D3: SUJEET KUMAR SINGH | E3: 17.09.2020 | F3: I-A
A4: 1571 | B4: ABHIJEET PATEL | C4: NEHA VERMA | D4: ASHISH KUMAR VERMA | E4: 01.07.2019 | F4: I-A
A5: 1881 | B5: ADITI | C5: JYOTIMA | D5: SHIVRAM SINGH | E5: 24.01.2019 | F5: I-A
A6: 1559 | B6: ADITYA VERMA | C6: LAXMI VERMA | D6: SUNIL KUMAR | E6: 12.08.2017 | F6: I-A
A7: 1548 | B7: ADVIK BAJPAI | C7: SEEMA BAJPAI | D7: VIVEK BAJPAI | E7: 22.04.2019 | F7: I-A
A8: 1549 | B8: AHEM SHARMA | C8: PARUL SHARMA | D8: KULDEEP KUMAR | E8: 23.02.2018 | F8: I-A
A9: 1556 | B9: AKRATI VISHWAKARMA | C9: VINEETA VISHWAKARAMA | D9: RUPENDRA KUMAR | E9: 01.07.2018 | F9: I-A
A10: 1915 | B10: AKRITI SHUKLA | C10: RITU SHUKLA | D10: ARUNESH KUMAR | E10: 30.10.2019 | F10: I-A
A11: 1563 | B11: ANANYA | C11: BARKHA RAJPOOT | D11: SONU | E11: 14.06.2018 | F11: I-A
A12: 1562 | B12: ANKITA RAJPOOT | C12: NEHA | D12: DIWAKAR SINGH | E12: 06.02.2019 | F12: I-A
A13: 1547 | B13: ANSHIKA PANDEY | C13: SIMA DEVI | D13: RAJU PRASAD | E13: 25.05.2018 | F13: I-A
A14: 1644 | B14: ARADHYA SINGH | C14: POOJA SINGH | D14: ANJANI KUMAR SINGH | E14: 14.08.2017 | F14: I-A
... A19: 1569 | B19: AVNI VERMA | C19: SHILPI VERMA | D19: AMRENDRA KUMAR VERMA | E19: 18.02.2019 | F19: I-A
A20: 1789 | B20: AYUSHI YADAV | D20: SHIV JATAN YADAV | E20: 14.10.2016 | F20: I-A
A21: 1673 | B21: DEVANSH SINGH | C21: POOJA SINGH | D21: AMAN SINGH | E21: 23.11.2018 | F21: I-A
A22: 1649 | B22: DEVISHA TIWARI | C22: JYOTI | D22: MUKESH KUMAR | E22: 28.04.2019 | F22: I-A
A23: 1791 | B23: DIPANSH SRIVASTAVA | C23: SAPNA SRIVASTAVA | D23: DURGA KANT SRIVASTAVA | E23: 27.03.2019 | F23: I-A
A24: 1564 | B24: GAURAV YADAV | C24: KUSUM YADAV | D24: ARVIND KUMAR | E24: 09.08.2018 | F24: I-A
A25: 1573 | B25: HARIOM MISHRA | C25: CHITRA MISHRA | D25: ASHISH KUMAR MISHRA | E25: 02.06.2019 | F25: I-A
A26: 1561 | B26: HARSHITA MEENA | C26: MAMTA MEENA | D26: HARI RAM MEENA | E26: 07.09.2018 | F26: I-A
A27: 1565 | B27: JANVI SINGH | C27: RADHA RANI | D27: HANS RAJ | E27: 27.03.2018 | F27: I-A
A28: 1870 | B28: JANVI SINGH SENGAR | C28: VIJAY LAXMI | D28: RAM PRATAP SINGH | E28: 30.07.2018 | F28: I-A
A29: 1657 | B29: KARNIKA VERMA | C29: NISHA VERMA | D29: SANDEEP KUMAR | E29: 15.09.2019 | F29: I-A
A30: 1558 | B30: KAVYA TIWARI | C30: PREETI TIWARI | D30: RAM KUMAR TIWARI | E30: 16.01.2018 | F30: I-A
A31: 1906 | B31: KHUSHI PATEL | C31: SHEELA CHAUDHARY | D31: RAVINDRA KUMAR CHAUDHARY | E31: 14.11.2018 | F31: I-A
A32: 1865 | B32: MOHD SAIF | C32: ZAREENA KHATOON | D32: MODH. SAMEER | E32: 26.06.2017 | F32: I-A
... A41: 1937 | B41: VIVAAN PAL | C41: ROMA PAL | D41: VIJAY PAL | E41: 29.07.2016 | F41: I-A

Sheet UT-I(Entry)
A1: UNIT TEST-I (2025-26) CLASS - I
A2: SR. NO. | B2: NAME | C2: ENGLISH | D2: HINDI | E2: MATHS | F2: EVS | G2: COMPUTER | H2: G.K. | I2: ART | J2: Attendance
J3: Present | K3: Working Day
A4: =DETAILS!A3 -> 1804 | B4: =DETAILS!B3 -> AAKRITI SINGH
A5: =DETAILS!A4 -> 1571 | B5: =DETAILS!B4 -> ABHIJEET PATEL
A6: =DETAILS!A5 -> 1881 | B6: =DETAILS!B5 -> ADITI
A7: =DETAILS!A6 -> 1559 | B7: =DETAILS!B6 -> ADITYA VERMA
A8: =DETAILS!A7 -> 1548 | B8: =DETAILS!B7 -> ADVIK BAJPAI
A9: =DETAILS!A8 -> 1549 | B9: =DETAILS!B8 -> AHEM SHARMA
A10: =DETAILS!A9 -> 1556 | B10: =DETAILS!B9 -> AKRATI VISHWAKARMA
A11: =DETAILS!A10 -> 1915 | B11: =DETAILS!B10 -> AKRITI SHUKLA
A12: =DETAILS!A11 -> 1563 | B12: =DETAILS!B11 -> ANANYA
A13: =DETAILS!A12 -> 1562 | B13: =DETAILS!B12 -> ANKITA RAJPOOT
A14: =DETAILS!A13 -> 1547 | B14: =DETAILS!B13 -> ANSHIKA PANDEY
A15: =DETAILS!A14 -> 1644 | B15: =DETAILS!B14 -> ARADHYA SINGH
... A42: =DETAILS!A41 -> 1937 | B42: =DETAILS!B41 -> VIVAAN PAL

Sheet UT-I 
A1: UNIT TEST-I (2025-26) CLASS - I
A2: SR. NO. | B2: NAME | C2: ENGLISH | D2: HINDI | E2: MATHS | F2: EVS | G2: COMPUTER | H2: G.K. | I2: ART | J2: TOTAL | K2: PERCENTAGE | L2: Attendance
L3: Present | M3: Working Day
A4: =DETAILS!A3 -> 1804 | B4: =DETAILS!B3 -> AAKRITI SINGH | C4: =IFERROR(ROUND((VLOOKUP(A4,'UT-I(Entry)'!$1:$1048576,3,0))/2,0),VLOOKUP(A4,'UT-I(Entry)'!$1:$1048576,3,0)) -> 0 | D4: =IFERROR(ROUND((VLOOKUP(A4,'UT-I(Entry)'!$1:$1048576,4,0))/2,0),VLOOKUP(A4,'UT-I(Entry)'!$1:$1048576,4,0)) -> 0 | E4: =IFERROR(ROUND((VLOOKUP(A4,'UT-I(Entry)'!$1:$1048576,5,0))/2,0),VLOOKUP(A4,'UT-I(Entry)'!$1:$1048576,5,0)) -> 0 | F4: =IFERROR(ROUND((VLOOKUP(A4,'UT-I(Entry)'!$1:$1048576,6,0))/2,0),VLOOKUP(A4,'UT-I(Entry)'!$1:$1048576,6,0)) -> 0 | G4: =IFERROR(ROUND((VLOOKUP(A4,'UT-I(Entry)'!$1:$1048576,7,0))/2,0),VLOOKUP(A4,'UT-I(Entry)'!$1:$1048576,7,0)) -> 0 | H4: =IFERROR(VLOOKUP(VLOOKUP(A4,'UT-I(Entry)'!$1:$1048576,8,0),'Grade(40)'!$1:$1048576,2,0),VLOOKUP(A4,'UT-I(Entry)'!$1:$1048576,8,0)) -> E | I4: =IFERROR(VLOOKUP(VLOOKUP(A4,'UT-I(Entry)'!$1:$1048576,9,0),'Grade(40)'!$1:$1048576,2,0),VLOOKUP(A4,'UT-I(Entry)'!$1:$1048576,9,0)) -> E | J4: =SUM(C4:G4) -> 0 | K4: =ROUND(J4/1,2)&" %" -> 0 % | L4: =VLOOKUP(A4,'UT-I(Entry)'!$1:$1048576,10,0) -> 0 | M4: =VLOOKUP(A4,'UT-I(Entry)'!$1:$1048576,11,0) -> 0
A5: =DETAILS!A4 -> 1571 | B5: =DETAILS!B4 -> ABHIJEET PATEL | C5: =IFERROR(ROUND((VLOOKUP(A5,'UT-I(Entry)'!$1:$1048576,3,0))/2,0),VLOOKUP(A5,'UT-I(Entry)'!$1:$1048576,3,0)) -> 0 | D5: =IFERROR(ROUND((VLOOKUP(A5,'UT-I(Entry)'!$1:$1048576,4,0))/2,0),VLOOKUP(A5,'UT-I(Entry)'!$1:$1048576,4,0)) -> 0 | E5: =IFERROR(ROUND((VLOOKUP(A5,'UT-I(Entry)'!$1:$1048576,5,0))/2,0),VLOOKUP(A5,'UT-I(Entry)'!$1:$1048576,5,0)) -> 0 | F5: =IFERROR(ROUND((VLOOKUP(A5,'UT-I(Entry)'!$1:$1048576,6,0))/2,0),VLOOKUP(A5,'UT-I(Entry)'!$1:$1048576,6,0)) -> 0 | G5: =IFERROR(ROUND((VLOOKUP(A5,'UT-I(Entry)'!$1:$1048576,7,0))/2,0),VLOOKUP(A5,'UT-I(Entry)'!$1:$1048576,7,0)) -> 0 | H5: =IFERROR(VLOOKUP(VLOOKUP(A5,'UT-I(Entry)'!$1:$1048576,8,0),'Grade(40)'!$1:$1048576,2,0),VLOOKUP(A5,'UT-I(Entry)'!$1:$1048576,8,0)) -> E | I5: =IFERROR(VLOOKUP(VLOOKUP(A5,'UT-I(Entry)'!$1:$1048576,9,0),'Grade(40)'!$1:$1048576,2,0),VLOOKUP(A5,'UT-I(Entry)'!$1:$1048576,9,0)) -> E | J5: =SUM(C5:G5) -> 0 | K5: =ROUND(J5/1,2)&" %" -> 0 % | L5: =VLOOKUP(A5,'UT-I(Entry)'!$1:$1048576,10,0) -> 0 | M5: =VLOOKUP(A5,'UT-I(Entry)'!$1:$1048576,11,0) -> 0
A6: =DETAILS!A5 -> 1881 | B6: =DETAILS!B5 -> ADITI | C6: =IFERROR(ROUND((VLOOKUP(A6,'UT-I(Entry)'!$1:$1048576,3,0))/2,0),VLOOKUP(A6,'UT-I(Entry)'!$1:$1048576,3,0)) -> 0 | D6: =IFERROR(ROUND((VLOOKUP(A6,'UT-I(Entry)'!$1:$1048576,4,0))/2,0),VLOOKUP(A6,'UT-I(Entry)'!$1:$1048576,4,0)) -> 0 | E6: =IFERROR(ROUND((VLOOKUP(A6,'UT-I(Entry)'!$1:$1048576,5,0))/2,0),VLOOKUP(A6,'UT-I(Entry)'!$1:$1048576,5,0)) -> 0 | F6: =IFERROR(ROUND((VLOOKUP(A6,'UT-I(Entry)'!$1:$1048576,6,0))/2,0),VLOOKUP(A6,'UT-I(Entry)'!$1:$1048576,6,0)) -> 0 | G6: =IFERROR(ROUND((VLOOKUP(A6,'UT-I(Entry)'!$1:$1048576,7,0))/2,0),VLOOKUP(A6,'UT-I(Entry)'!$1:$1048576,7,0)) -> 0 | H6: =IFERROR(VLOOKUP(VLOOKUP(A6,'UT-I(Entry)'!$1:$1048576,8,0),'Grade(40)'!$1:$1048576,2,0),VLOOKUP(A6,'UT-I(Entry)'!$1:$1048576,8,0)) -> E | I6: =IFERROR(VLOOKUP(VLOOKUP(A6,'UT-I(Entry)'!$1:$1048576,9,0),'Grade(40)'!$1:$1048576,2,0),VLOOKUP(A6,'UT-I(Entry)'!$1:$1048576,9,0)) -> E | J6: =SUM(C6:G6) -> 0 | K6: =ROUND(J6/1,2)&" %" -> 0 % | L6: =VLOOKUP(A6,'UT-I(Entry)'!$1:$1048576,10,0) -> 0 | M6: =VLOOKUP(A6,'UT-I(Entry)'!$1:$1048576,11,0) -> 0
A7: =DETAILS!A6 -> 1559 | B7: =DETAILS!B6 -> ADITYA VERMA | C7: =IFERROR(ROUND((VLOOKUP(A7,'UT-I(Entry)'!$1:$1048576,3,0))/2,0),VLOOKUP(A7,'UT-I(Entry)'!$1:$1048576,3,0)) -> 0 | D7: =IFERROR(ROUND((VLOOKUP(A7,'UT-I(Entry)'!$1:$1048576,4,0))/2,0),VLOOKUP(A7,'UT-I(Entry)'!$1:$1048576,4,0)) -> 0 | E7: =IFERROR(ROUND((VLOOKUP(A7,'UT-I(Entry)'!$1:$1048576,5,0))/2,0),VLOOKUP(A7,'UT-I(Entry)'!$1:$1048576,5,0)) -> 0 | F7: =IFERROR(ROUND((VLOOKUP(A7,'UT-I(Entry)'!$1:$1048576,6,0))/2,0),VLOOKUP(A7,'UT-I(Entry)'!$1:$1048576,6,0)) -> 0 | G7: =IFERROR(ROUND((VLOOKUP(A7,'UT-I(Entry)'!$1:$1048576,7,0))/2,0),VLOOKUP(A7,'UT-I(Entry)'!$1:$1048576,7,0)) -> 0 | H7: =IFERROR(VLOOKUP(VLOOKUP(A7,'UT-I(Entry)'!$1:$1048576,8,0),'Grade(40)'!$1:$1048576,2,0),VLOOKUP(A7,'UT-I(Entry)'!$1:$1048576,8,0)) -> E | I7: =IFERROR(VLOOKUP(VLOOKUP(A7,'UT-I(Entry)'!$1:$1048576,9,0),'Grade(40)'!$1:$1048576,2,0),VLOOKUP(A7,'UT-I(Entry)'!$1:$1048576,9,0)) -> E | J7: =SUM(C7:G7) -> 0 | K7: =ROUND(J7/1,2)&" %" -> 0 % | L7: =VLOOKUP(A7,'UT-I(Entry)'!$1:$1048576,10,0) -> 0 | M7: =VLOOKUP(A7,'UT-I(Entry)'!$1:$1048576,11,0) -> 0
A8: =DETAILS!A7 -> 1548 | B8: =DETAILS!B7 -> ADVIK BAJPAI | C8: =IFERROR(ROUND((VLOOKUP(A8,'UT-I(Entry)'!$1:$1048576,3,0))/2,0),VLOOKUP(A8,'UT-I(Entry)'!$1:$1048576,3,0)) -> 0 | D8: =IFERROR(ROUND((VLOOKUP(A8,'UT-I(Entry)'!$1:$1048576,4,0))/2,0),VLOOKUP(A8,'UT-I(Entry)'!$1:$1048576,4,0)) -> 0 | E8: =IFERROR(ROUND((VLOOKUP(A8,'UT-I(Entry)'!$1:$1048576,5,0))/2,0),VLOOKUP(A8,'UT-I(Entry)'!$1:$1048576,5,0)) -> 0 | F8: =IFERROR(ROUND((VLOOKUP(A8,'UT-I(Entry)'!$1:$1048576,6,0))/2,0),VLOOKUP(A8,'UT-I(Entry)'!$1:$1048576,6,0)) -> 0 | G8: =IFERROR(ROUND((VLOOKUP(A8,'UT-I(Entry)'!$1:$1048576,7,0))/2,0),VLOOKUP(A8,'UT-I(Entry)'!$1:$1048576,7,0)) -> 0 | H8: =IFERROR(VLOOKUP(VLOOKUP(A8,'UT-I(Entry)'!$1:$1048576,8,0),'Grade(40)'!$1:$1048576,2,0),VLOOKUP(A8,'UT-I(Entry)'!$1:$1048576,8,0)) -> E | I8: =IFERROR(VLOOKUP(VLOOKUP(A8,'UT-I(Entry)'!$1:$1048576,9,0),'Grade(40)'!$1:$1048576,2,0),VLOOKUP(A8,'UT-I(Entry)'!$1:$1048576,9,0)) -> E | J8: =SUM(C8:G8) -> 0 | K8: =ROUND(J8/1,2)&" %" -> 0 % | L8: =VLOOKUP(A8,'UT-I(Entry)'!$1:$1048576,10,0) -> 0 | M8: =VLOOKUP(A8,'UT-I(Entry)'!$1:$1048576,11,0) -> 0
A9: =DETAILS!A8 -> 1549 | B9: =DETAILS!B8 -> AHEM SHARMA | C9: =IFERROR(ROUND((VLOOKUP(A9,'UT-I(Entry)'!$1:$1048576,3,0))/2,0),VLOOKUP(A9,'UT-I(Entry)'!$1:$1048576,3,0)) -> 0 | D9: =IFERROR(ROUND((VLOOKUP(A9,'UT-I(Entry)'!$1:$1048576,4,0))/2,0),VLOOKUP(A9,'UT-I(Entry)'!$1:$1048576,4,0)) -> 0 | E9: =IFERROR(ROUND((VLOOKUP(A9,'UT-I(Entry)'!$1:$1048576,5,0))/2,0),VLOOKUP(A9,'UT-I(Entry)'!$1:$1048576,5,0)) -> 0 | F9: =IFERROR(ROUND((VLOOKUP(A9,'UT-I(Entry)'!$1:$1048576,6,0))/2,0),VLOOKUP(A9,'UT-I(Entry)'!$1:$1048576,6,0)) -> 0 | G9: =IFERROR(ROUND((VLOOKUP(A9,'UT-I(Entry)'!$1:$1048576,7,0))/2,0),VLOOKUP(A9,'UT-I(Entry)'!$1:$1048576,7,0)) -> 0 | H9: =IFERROR(VLOOKUP(VLOOKUP(A9,'UT-I(Entry)'!$1:$1048576,8,0),'Grade(40)'!$1:$1048576,2,0),VLOOKUP(A9,'UT-I(Entry)'!$1:$1048576,8,0)) -> E | I9: =IFERROR(VLOOKUP(VLOOKUP(A9,'UT-I(Entry)'!$1:$1048576,9,0),'Grade(40)'!$1:$1048576,2,0),VLOOKUP(A9,'UT-I(Entry)'!$1:$1048576,9,0)) -> E | J9: =SUM(C9:G9) -> 0 | K9: =ROUND(J9/1,2)&" %" -> 0 % | L9: =VLOOKUP(A9,'UT-I(Entry)'!$1:$1048576,10,0) -> 0 | M9: =VLOOKUP(A9,'UT-I(Entry)'!$1:$1048576,11,0) -> 0
A10: =DETAILS!A9 -> 1556 | B10: =DETAILS!B9 -> AKRATI VISHWAKARMA | C10: =IFERROR(ROUND((VLOOKUP(A10,'UT-I(Entry)'!$1:$1048576,3,0))/2,0),VLOOKUP(A10,'UT-I(Entry)'!$1:$1048576,3,0)) -> 0 | D10: =IFERROR(ROUND((VLOOKUP(A10,'UT-I(Entry)'!$1:$1048576,4,0))/2,0),VLOOKUP(A10,'UT-I(Entry)'!$1:$1048576,4,0)) -> 0 | E10: =IFERROR(ROUND((VLOOKUP(A10,'UT-I(Entry)'!$1:$1048576,5,0))/2,0),VLOOKUP(A10,'UT-I(Entry)'!$1:$1048576,5,0)) -> 0 | F10: =IFERROR(ROUND((VLOOKUP(A10,'UT-I(Entry)'!$1:$1048576,6,0))/2,0),VLOOKUP(A10,'UT-I(Entry)'!$1:$1048576,6,0)) -> 0 | G10: =IFERROR(ROUND((VLOOKUP(A10,'UT-I(Entry)'!$1:$1048576,7,0))/2,0),VLOOKUP(A10,'UT-I(Entry)'!$1:$1048576,7,0)) -> 0 | H10: =IFERROR(VLOOKUP(VLOOKUP(A10,'UT-I(Entry)'!$1:$1048576,8,0),'Grade(40)'!$1:$1048576,2,0),VLOOKUP(A10,'UT-I(Entry)'!$1:$1048576,8,0)) -> E | I10: =IFERROR(VLOOKUP(VLOOKUP(A10,'UT-I(Entry)'!$1:$1048576,9,0),'Grade(40)'!$1:$1048576,2,0),VLOOKUP(A10,'UT-I(Entry)'!$1:$1048576,9,0)) -> E | J10: =SUM(C10:G10) -> 0 | K10: =ROUND(J10/1,2)&" %" -> 0 % | L10: =VLOOKUP(A10,'UT-I(Entry)'!$1:$1048576,10,0) -> 0 | M10: =VLOOKUP(A10,'UT-I(Entry)'!$1:$1048576,11,0) -> 0
A11: =DETAILS!A10 -> 1915 | B11: =DETAILS!B10 -> AKRITI SHUKLA | C11: =IFERROR(ROUND((VLOOKUP(A11,'UT-I(Entry)'!$1:$1048576,3,0))/2,0),VLOOKUP(A11,'UT-I(Entry)'!$1:$1048576,3,0)) -> 0 | D11: =IFERROR(ROUND((VLOOKUP(A11,'UT-I(Entry)'!$1:$1048576,4,0))/2,0),VLOOKUP(A11,'UT-I(Entry)'!$1:$1048576,4,0)) -> 0 | E11: =IFERROR(ROUND((VLOOKUP(A11,'UT-I(Entry)'!$1:$1048576,5,0))/2,0),VLOOKUP(A11,'UT-I(Entry)'!$1:$1048576,5,0)) -> 0 | F11: =IFERROR(ROUND((VLOOKUP(A11,'UT-I(Entry)'!$1:$1048576,6,0))/2,0),VLOOKUP(A11,'UT-I(Entry)'!$1:$1048576,6,0)) -> 0 | G11: =IFERROR(ROUND((VLOOKUP(A11,'UT-I(Entry)'!$1:$1048576,7,0))/2,0),VLOOKUP(A11,'UT-I(Entry)'!$1:$1048576,7,0)) -> 0 | H11: =IFERROR(VLOOKUP(VLOOKUP(A11,'UT-I(Entry)'!$1:$1048576,8,0),'Grade(40)'!$1:$1048576,2,0),VLOOKUP(A11,'UT-I(Entry)'!$1:$1048576,8,0)) -> E | I11: =IFERROR(VLOOKUP(VLOOKUP(A11,'UT-I(Entry)'!$1:$1048576,9,0),'Grade(40)'!$1:$1048576,2,0),VLOOKUP(A11,'UT-I(Entry)'!$1:$1048576,9,0)) -> E | J11: =SUM(C11:G11) -> 0 | K11: =ROUND(J11/1,2)&" %" -> 0 % | L11: =VLOOKUP(A11,'UT-I(Entry)'!$1:$1048576,10,0) -> 0 | M11: =VLOOKUP(A11,'UT-I(Entry)'!$1:$1048576,11,0) -> 0
A12: =DETAILS!A11 -> 1563 | B12: =DETAILS!B11 -> ANANYA | C12: =IFERROR(ROUND((VLOOKUP(A12,'UT-I(Entry)'!$1:$1048576,3,0))/2,0),VLOOKUP(A12,'UT-I(Entry)'!$1:$1048576,3,0)) -> 0 | D12: =IFERROR(ROUND((VLOOKUP(A12,'UT-I(Entry)'!$1:$1048576,4,0))/2,0),VLOOKUP(A12,'UT-I(Entry)'!$1:$1048576,4,0)) -> 0 | E12: =IFERROR(ROUND((VLOOKUP(A12,'UT-I(Entry)'!$1:$1048576,5,0))/2,0),VLOOKUP(A12,'UT-I(Entry)'!$1:$1048576,5,0)) -> 0 | F12: =IFERROR(ROUND((VLOOKUP(A12,'UT-I(Entry)'!$1:$1048576,6,0))/2,0),VLOOKUP(A12,'UT-I(Entry)'!$1:$1048576,6,0)) -> 0 | G12: =IFERROR(ROUND((VLOOKUP(A12,'UT-I(Entry)'!$1:$1048576,7,0))/2,0),VLOOKUP(A12,'UT-I(Entry)'!$1:$1048576,7,0)) -> 0 | H12: =IFERROR(VLOOKUP(VLOOKUP(A12,'UT-I(Entry)'!$1:$1048576,8,0),'Grade(40)'!$1:$1048576,2,0),VLOOKUP(A12,'UT-I(Entry)'!$1:$1048576,8,0)) -> E | I12: =IFERROR(VLOOKUP(VLOOKUP(A12,'UT-I(Entry)'!$1:$1048576,9,0),'Grade(40)'!$1:$1048576,2,0),VLOOKUP(A12,'UT-I(Entry)'!$1:$1048576,9,0)) -> E | J12: =SUM(C12:G12) -> 0 | K12: =ROUND(J12/1,2)&" %" -> 0 % | L12: =VLOOKUP(A12,'UT-I(Entry)'!$1:$1048576,10,0) -> 0 | M12: =VLOOKUP(A12,'UT-I(Entry)'!$1:$1048576,11,0) -> 0
A13: =DETAILS!A12 -> 1562 | B13: =DETAILS!B12 -> ANKITA RAJPOOT | C13: =IFERROR(ROUND((VLOOKUP(A13,'UT-I(Entry)'!$1:$1048576,3,0))/2,0),VLOOKUP(A13,'UT-I(Entry)'!$1:$1048576,3,0)) -> 0 | D13: =IFERROR(ROUND((VLOOKUP(A13,'UT-I(Entry)'!$1:$1048576,4,0))/2,0),VLOOKUP(A13,'UT-I(Entry)'!$1:$1048576,4,0)) -> 0 | E13: =IFERROR(ROUND((VLOOKUP(A13,'UT-I(Entry)'!$1:$1048576,5,0))/2,0),VLOOKUP(A13,'UT-I(Entry)'!$1:$1048576,5,0)) -> 0 | F13: =IFERROR(ROUND((VLOOKUP(A13,'UT-I(Entry)'!$1:$1048576,6,0))/2,0),VLOOKUP(A13,'UT-I(Entry)'!$1:$1048576,6,0)) -> 0 | G13: =IFERROR(ROUND((VLOOKUP(A13,'UT-I(Entry)'!$1:$1048576,7,0))/2,0),VLOOKUP(A13,'UT-I(Entry)'!$1:$1048576,7,0)) -> 0 | H13: =IFERROR(VLOOKUP(VLOOKUP(A13,'UT-I(Entry)'!$1:$1048576,8,0),'Grade(40)'!$1:$1048576,2,0),VLOOKUP(A13,'UT-I(Entry)'!$1:$1048576,8,0)) -> E | I13: =IFERROR(VLOOKUP(VLOOKUP(A13,'UT-I(Entry)'!$1:$1048576,9,0),'Grade(40)'!$1:$1048576,2,0),VLOOKUP(A13,'UT-I(Entry)'!$1:$1048576,9,0)) -> E | J13: =SUM(C13:G13) -> 0 | K13: =ROUND(J13/1,2)&" %" -> 0 % | L13: =VLOOKUP(A13,'UT-I(Entry)'!$1:$1048576,10,0) -> 0 | M13: =VLOOKUP(A13,'UT-I(Entry)'!$1:$1048576,11,0) -> 0
A14: =DETAILS!A13 -> 1547 | B14: =DETAILS!B13 -> ANSHIKA PANDEY | C14: =IFERROR(ROUND((VLOOKUP(A14,'UT-I(Entry)'!$1:$1048576,3,0))/2,0),VLOOKUP(A14,'UT-I(Entry)'!$1:$1048576,3,0)) -> 0 | D14: =IFERROR(ROUND((VLOOKUP(A14,'UT-I(Entry)'!$1:$1048576,4,0))/2,0),VLOOKUP(A14,'UT-I(Entry)'!$1:$1048576,4,0)) -> 0 | E14: =IFERROR(ROUND((VLOOKUP(A14,'UT-I(Entry)'!$1:$1048576,5,0))/2,0),VLOOKUP(A14,'UT-I(Entry)'!$1:$1048576,5,0)) -> 0 | F14: =IFERROR(ROUND((VLOOKUP(A14,'UT-I(Entry)'!$1:$1048576,6,0))/2,0),VLOOKUP(A14,'UT-I(Entry)'!$1:$1048576,6,0)) -> 0 | G14: =IFERROR(ROUND((VLOOKUP(A14,'UT-I(Entry)'!$1:$1048576,7,0))/2,0),VLOOKUP(A14,'UT-I(Entry)'!$1:$1048576,7,0)) -> 0 | H14: =IFERROR(VLOOKUP(VLOOKUP(A14,'UT-I(Entry)'!$1:$1048576,8,0),'Grade(40)'!$1:$1048576,2,0),VLOOKUP(A14,'UT-I(Entry)'!$1:$1048576,8,0)) -> E | I14: =IFERROR(VLOOKUP(VLOOKUP(A14,'UT-I(Entry)'!$1:$1048576,9,0),'Grade(40)'!$1:$1048576,2,0),VLOOKUP(A14,'UT-I(Entry)'!$1:$1048576,9,0)) -> E | J14: =SUM(C14:G14) -> 0 | K14: =ROUND(J14/1,2)&" %" -> 0 % | L14: =VLOOKUP(A14,'UT-I(Entry)'!$1:$1048576,10,0) -> 0 | M14: =VLOOKUP(A14,'UT-I(Entry)'!$1:$1048576,11,0) -> 0
A15: =DETAILS!A14 -> 1644 | B15: =DETAILS!B14 -> ARADHYA SINGH | C15: =IFERROR(ROUND((VLOOKUP(A15,'UT-I(Entry)'!$1:$1048576,3,0))/2,0),VLOOKUP(A15,'UT-I(Entry)'!$1:$1048576,3,0)) -> 0 | D15: =IFERROR(ROUND((VLOOKUP(A15,'UT-I(Entry)'!$1:$1048576,4,0))/2,0),VLOOKUP(A15,'UT-I(Entry)'!$1:$1048576,4,0)) -> 0 | E15: =IFERROR(ROUND((VLOOKUP(A15,'UT-I(Entry)'!$1:$1048576,5,0))/2,0),VLOOKUP(A15,'UT-I(Entry)'!$1:$1048576,5,0)) -> 0 | F15: =IFERROR(ROUND((VLOOKUP(A15,'UT-I(Entry)'!$1:$1048576,6,0))/2,0),VLOOKUP(A15,'UT-I(Entry)'!$1:$1048576,6,0)) -> 0 | G15: =IFERROR(ROUND((VLOOKUP(A15,'UT-I(Entry)'!$1:$1048576,7,0))/2,0),VLOOKUP(A15,'UT-I(Entry)'!$1:$1048576,7,0)) -> 0 | H15: =IFERROR(VLOOKUP(VLOOKUP(A15,'UT-I(Entry)'!$1:$1048576,8,0),'Grade(40)'!$1:$1048576,2,0),VLOOKUP(A15,'UT-I(Entry)'!$1:$1048576,8,0)) -> E | I15: =IFERROR(VLOOKUP(VLOOKUP(A15,'UT-I(Entry)'!$1:$1048576,9,0),'Grade(40)'!$1:$1048576,2,0),VLOOKUP(A15,'UT-I(Entry)'!$1:$1048576,9,0)) -> E | J15: =SUM(C15:G15) -> 0 | K15: =ROUND(J15/1,2)&" %" -> 0 % | L15: =VLOOKUP(A15,'UT-I(Entry)'!$1:$1048576,10,0) -> 0 | M15: =VLOOKUP(A15,'UT-I(Entry)'!$1:$1048576,11,0) -> 0
... A42: =DETAILS!A41 -> 1937 | B42: =DETAILS!B41 -> VIVAAN PAL | C42: =IFERROR(ROUND((VLOOKUP(A42,'UT-I(Entry)'!$1:$1048576,3,0))/2,0),VLOOKUP(A42,'UT-I(Entry)'!$1:$1048576,3,0)) -> 0 | D42: =IFERROR(ROUND((VLOOKUP(A42,'UT-I(Entry)'!$1:$1048576,4,0))/2,0),VLOOKUP(A42,'UT-I(Entry)'!$1:$1048576,4,0)) -> 0 | E42: =IFERROR(ROUND((VLOOKUP(A42,'UT-I(Entry)'!$1:$1048576,5,0))/2,0),VLOOKUP(A42,'UT-I(Entry)'!$1:$1048576,5,0)) -> 0 | F42: =IFERROR(ROUND((VLOOKUP(A42,'UT-I(Entry)'!$1:$1048576,6,0))/2,0),VLOOKUP(A42,'UT-I(Entry)'!$1:$1048576,6,0)) -> 0 | G42: =IFERROR(ROUND((VLOOKUP(A42,'UT-I(Entry)'!$1:$1048576,7,0))/2,0),VLOOKUP(A42,'UT-I(Entry)'!$1:$1048576,7,0)) -> 0 | H42: =IFERROR(VLOOKUP(VLOOKUP(A42,'UT-I(Entry)'!$1:$1048576,8,0),'Grade(40)'!$1:$1048576,2,0),VLOOKUP(A42,'UT-I(Entry)'!$1:$1048576,8,0)) -> E | I42: =IFERROR(VLOOKUP(VLOOKUP(A42,'UT-I(Entry)'!$1:$1048576,9,0),'Grade(40)'!$1:$1048576,2,0),VLOOKUP(A42,'UT-I(Entry)'!$1:$1048576,9,0)) -> E | J42: =SUM(C42:G42) -> 0 | K42: =ROUND(J42/1,2)&" %" -> 0 % | L42: =VLOOKUP(A42,'UT-I(Entry)'!$1:$1048576,10,0) -> 0 | M42: =VLOOKUP(A42,'UT-I(Entry)'!$1:$1048576,11,0) -> 0

Sheet Grade(40)
A2: 40 | B2: A
A3: 39 | B3: A
A4: 38 | B4: A
A5: 37 | B5: A
A6: 36 | B6: A
A7: 35 | B7: A
A8: 34 | B8: A
A9: 33 | B9: A
A10: 32 | B10: B
A11: 31 | B11: B
A12: 30 | B12: B
A13: 29 | B13: B
... A42: 0 | B42: E

Sheet NOTEBOOK-1 (Entry)
A1: NOTEBOOK-1 (2025-26) CLASS -I
A2: SR. NO. | B2: NAME | C2: ENGLISH | D2: HINDI | E2: MATHS | F2: EVS | G2: COMPUTER
A3: =DETAILS!A3 -> 1804 | B3: =DETAILS!B3 -> AAKRITI SINGH
A4: =DETAILS!A4 -> 1571 | B4: =DETAILS!B4 -> ABHIJEET PATEL
A5: =DETAILS!A5 -> 1881 | B5: =DETAILS!B5 -> ADITI
A6: =DETAILS!A6 -> 1559 | B6: =DETAILS!B6 -> ADITYA VERMA
A7: =DETAILS!A7 -> 1548 | B7: =DETAILS!B7 -> ADVIK BAJPAI
A8: =DETAILS!A8 -> 1549 | B8: =DETAILS!B8 -> AHEM SHARMA
A9: =DETAILS!A9 -> 1556 | B9: =DETAILS!B9 -> AKRATI VISHWAKARMA
A10: =DETAILS!A10 -> 1915 | B10: =DETAILS!B10 -> AKRITI SHUKLA
A11: =DETAILS!A11 -> 1563 | B11: =DETAILS!B11 -> ANANYA
A12: =DETAILS!A12 -> 1562 | B12: =DETAILS!B12 -> ANKITA RAJPOOT
A13: =DETAILS!A13 -> 1547 | B13: =DETAILS!B13 -> ANSHIKA PANDEY
A14: =DETAILS!A14 -> 1644 | B14: =DETAILS!B14 -> ARADHYA SINGH
... A27: =DETAILS!A27 -> 1565 | B27: =DETAILS!B27 -> JANVI SINGH
A28: =DETAILS!A28 -> 1870 | B28: =DETAILS!B28 -> JANVI SINGH SENGAR | G28: =SUM(C28:F28) -> 0
A29: =DETAILS!A29 -> 1657 | B29: =DETAILS!B29 -> KARNIKA VERMA | G29: =SUM(C29:F29) -> 0
A30: =DETAILS!A30 -> 1558 | B30: =DETAILS!B30 -> KAVYA TIWARI | G30: =SUM(C30:F30) -> 0
A31: =DETAILS!A31 -> 1906 | B31: =DETAILS!B31 -> KHUSHI PATEL | G31: =SUM(C31:F31) -> 0
A32: =DETAILS!A32 -> 1865 | B32: =DETAILS!B32 -> MOHD SAIF | G32: =SUM(C32:F32) -> 0
A33: =DETAILS!A33 -> 1735 | B33: =DETAILS!B33 -> PRAGATI SINGH | G33: =SUM(C33:F33) -> 0
A34: =DETAILS!A34 -> 1557 | B34: =DETAILS!B34 -> PRISHA JAISWAL | G34: =SUM(C34:F34) -> 0
A35: =DETAILS!A35 -> 1560 | B35: =DETAILS!B35 -> SHANTANU YADAV | G35: =SUM(C35:F35) -> 0
A36: =DETAILS!A36 -> 1890 | B36: =DETAILS!B36 -> SHIVA YADAV | G36: =SUM(C36:F36) -> 0
A37: =DETAILS!A37 -> 1575 | B37: =DETAILS!B37 -> SHIVIKA VERMA | G37: =SUM(C37:F37) -> 0
A38: =DETAILS!A38 -> 1732 | B38: =DETAILS!B38 -> SUHAN ALI | G38: =SUM(C38:F38) -> 0
A39: =DETAILS!A39 -> 1706 | B39: =DETAILS!B39 -> UTKARSH | G39: =SUM(C39:F39) -> 0
... A41: =DETAILS!A41 -> 1937 | B41: =DETAILS!B41 -> VIVAAN PAL | G41: =SUM(C41:F41) -> 0

Sheet ENRICH-1(Entry)
A1: SUBJECT ENRICHMENT -1 (2025-26) CLASS -I
A2: SR. NO. | B2: NAME | C2: ENGLISH | D2: HINDI | E2: MATHS | F2: EVS | G2: COMPUTER
A3: =DETAILS!A3 -> 1804 | B3: =DETAILS!B3 -> AAKRITI SINGH
A4: =DETAILS!A4 -> 1571 | B4: =DETAILS!B4 -> ABHIJEET PATEL
A5: =DETAILS!A5 -> 1881 | B5: =DETAILS!B5 -> ADITI
A6: =DETAILS!A6 -> 1559 | B6: =DETAILS!B6 -> ADITYA VERMA
A7: =DETAILS!A7 -> 1548 | B7: =DETAILS!B7 -> ADVIK BAJPAI
A8: =DETAILS!A8 -> 1549 | B8: =DETAILS!B8 -> AHEM SHARMA
A9: =DETAILS!A9 -> 1556 | B9: =DETAILS!B9 -> AKRATI VISHWAKARMA
A10: =DETAILS!A10 -> 1915 | B10: =DETAILS!B10 -> AKRITI SHUKLA
A11: =DETAILS!A11 -> 1563 | B11: =DETAILS!B11 -> ANANYA
A12: =DETAILS!A12 -> 1562 | B12: =DETAILS!B12 -> ANKITA RAJPOOT
A13: =DETAILS!A13 -> 1547 | B13: =DETAILS!B13 -> ANSHIKA PANDEY
A14: =DETAILS!A14 -> 1644 | B14: =DETAILS!B14 -> ARADHYA SINGH
... A27: =DETAILS!A27 -> 1565 | B27: =DETAILS!B27 -> JANVI SINGH
A28: =DETAILS!A28 -> 1870 | B28: =DETAILS!B28 -> JANVI SINGH SENGAR | G28: =SUM(C28:F28) -> 0
A29: =DETAILS!A29 -> 1657 | B29: =DETAILS!B29 -> KARNIKA VERMA | G29: =SUM(C29:F29) -> 0
A30: =DETAILS!A30 -> 1558 | B30: =DETAILS!B30 -> KAVYA TIWARI | G30: =SUM(C30:F30) -> 0
A31: =DETAILS!A31 -> 1906 | B31: =DETAILS!B31 -> KHUSHI PATEL | G31: =SUM(C31:F31) -> 0
A32: =DETAILS!A32 -> 1865 | B32: =DETAILS!B32 -> MOHD SAIF | G32: =SUM(C32:F32) -> 0
A33: =DETAILS!A33 -> 1735 | B33: =DETAILS!B33 -> PRAGATI SINGH | G33: =SUM(C33:F33) -> 0
A34: =DETAILS!A34 -> 1557 | B34: =DETAILS!B34 -> PRISHA JAISWAL | G34: =SUM(C34:F34) -> 0
A35: =DETAILS!A35 -> 1560 | B35: =DETAILS!B35 -> SHANTANU YADAV | G35: =SUM(C35:F35) -> 0
A36: =DETAILS!A36 -> 1890 | B36: =DETAILS!B36 -> SHIVA YADAV | G36: =SUM(C36:F36) -> 0
A37: =DETAILS!A37 -> 1575 | B37: =DETAILS!B37 -> SHIVIKA VERMA | G37: =SUM(C37:F37) -> 0
A38: =DETAILS!A38 -> 1732 | B38: =DETAILS!B38 -> SUHAN ALI | G38: =SUM(C38:F38) -> 0
A39: =DETAILS!A39 -> 1706 | B39: =DETAILS!B39 -> UTKARSH | G39: =SUM(C39:F39) -> 0
... A41: =DETAILS!A41 -> 1937 | B41: =DETAILS!B41 -> VIVAAN PAL | G41: =SUM(C41:F41) -> 0

Sheet HALF YEARLY(Entry)
A1: HALF YEARLY EXAMINATION (2025-26) CLASS - I
A2: SR. NO. | B2: NAME | C2: ENGLISH | D2: HINDI | E2: MATHS | F2: EVS | G2: COMPUTER | H2: WORK EDUCATION | I2: ART EDUCATION | J2: GENERAL KNOWLEDGE | K2: HEALTH & PHYSICAL EDUCATION | L2: DISCIPLINE | M2: Total Present | N2: Total Working | O2: Class Teacher's Remark | P2: TOTAL | Q2: Percentage
A3: =DETAILS!A3 -> 1804 | B3: =DETAILS!B3 -> AAKRITI SINGH | P3: =SUM(C3:G3) -> 0 | Q3: =ROUND(P3/4,2)&" %" -> 0 %
A4: =DETAILS!A4 -> 1571 | B4: =DETAILS!B4 -> ABHIJEET PATEL | P4: =SUM(C4:G4) -> 0 | Q4: =ROUND(P4/4,2)&" %" -> 0 %
A5: =DETAILS!A5 -> 1881 | B5: =DETAILS!B5 -> ADITI | P5: =SUM(C5:G5) -> 0 | Q5: =ROUND(P5/4,2)&" %" -> 0 %
A6: =DETAILS!A6 -> 1559 | B6: =DETAILS!B6 -> ADITYA VERMA | P6: =SUM(C6:G6) -> 0 | Q6: =ROUND(P6/4,2)&" %" -> 0 %
A7: =DETAILS!A7 -> 1548 | B7: =DETAILS!B7 -> ADVIK BAJPAI | P7: =SUM(C7:G7) -> 0 | Q7: =ROUND(P7/4,2)&" %" -> 0 %
A8: =DETAILS!A8 -> 1549 | B8: =DETAILS!B8 -> AHEM SHARMA | P8: =SUM(C8:G8) -> 0 | Q8: =ROUND(P8/4,2)&" %" -> 0 %
A9: =DETAILS!A9 -> 1556 | B9: =DETAILS!B9 -> AKRATI VISHWAKARMA | P9: =SUM(C9:G9) -> 0 | Q9: =ROUND(P9/4,2)&" %" -> 0 %
A10: =DETAILS!A10 -> 1915 | B10: =DETAILS!B10 -> AKRITI SHUKLA | P10: =SUM(C10:G10) -> 0 | Q10: =ROUND(P10/4,2)&" %" -> 0 %
A11: =DETAILS!A11 -> 1563 | B11: =DETAILS!B11 -> ANANYA | P11: =SUM(C11:G11) -> 0 | Q11: =ROUND(P11/4,2)&" %" -> 0 %
A12: =DETAILS!A12 -> 1562 | B12: =DETAILS!B12 -> ANKITA RAJPOOT | P12: =SUM(C12:G12) -> 0 | Q12: =ROUND(P12/4,2)&" %" -> 0 %
A13: =DETAILS!A13 -> 1547 | B13: =DETAILS!B13 -> ANSHIKA PANDEY | P13: =SUM(C13:G13) -> 0 | Q13: =ROUND(P13/4,2)&" %" -> 0 %
A14: =DETAILS!A14 -> 1644 | B14: =DETAILS!B14 -> ARADHYA SINGH | P14: =SUM(C14:G14) -> 0 | Q14: =ROUND(P14/4,2)&" %" -> 0 %
... A41: =DETAILS!A41 -> 1937 | B41: =DETAILS!B41 -> VIVAAN PAL | P41: =SUM(C41:G41) -> 0 | Q41: =ROUND(P41/4,2)&" %" -> 0 %

Sheet HALF YEARLY
A1: HALF YEARLY EXAMINATION (2025-26) CLASS - I
A2: SR. NO. | B2: NAME | C2: ENGLISH | D2: HINDI | E2: MATHS | F2: EVS | G2: COMPUTER | H2: WORK EDUCATION | I2: ART EDUCATION | J2: GENERAL KNOWLEDGE | K2: HEALTH & PHYSICAL EDUCATION | L2: DISCIPLINE | M2: Total Present | N2: Total Working | O2: Class Teacher's Remark | P2: TOTAL | Q2: Percentage
A3: =DETAILS!A3 -> 1804 | B3: =DETAILS!B3 -> AAKRITI SINGH | C3: =VLOOKUP($A3,'HALF YEARLY(Entry)'!$1:$1048576,3,0) -> 0 | D3: =VLOOKUP($A3,'HALF YEARLY(Entry)'!$1:$1048576,4,0) -> 0 | E3: =VLOOKUP($A3,'HALF YEARLY(Entry)'!$1:$1048576,5,0) -> 0 | F3: =VLOOKUP($A3,'HALF YEARLY(Entry)'!$1:$1048576,6,0) -> 0 | G3: =VLOOKUP($A3,'HALF YEARLY(Entry)'!$1:$1048576,7,0) -> 0 | H3: =VLOOKUP($A3,'HALF YEARLY(Entry)'!$1:$1048576,8,0) -> 0 | I3: =IFERROR(VLOOKUP(VLOOKUP($A3,'HALF YEARLY(Entry)'!$1:$1048576,9,0),'Grade 50'!$1:$1048576,2,0),VLOOKUP($A3,'HALF YEARLY(Entry)'!$1:$1048576,9,0)) -> E | J3: =IFERROR(VLOOKUP(VLOOKUP($A3,'HALF YEARLY(Entry)'!$1:$1048576,10,0),'Grade 50'!$1:$1048576,2,0),VLOOKUP($A3,'HALF YEARLY(Entry)'!$1:$1048576,10,0)) -> E | K3: =VLOOKUP($A3,'HALF YEARLY(Entry)'!$1:$1048576,11,0) -> 0 | L3: =VLOOKUP($A3,'HALF YEARLY(Entry)'!$1:$1048576,12,0) -> 0 | M3: =VLOOKUP($A3,'HALF YEARLY(Entry)'!$1:$1048576,13,0) -> 0 | N3: =VLOOKUP($A3,'HALF YEARLY(Entry)'!$1:$1048576,14,0) -> 0 | O3: =VLOOKUP($A3,'HALF YEARLY(Entry)'!$1:$1048576,15,0) -> 0 | P3: =SUM(C3:G3) -> 0 | Q3: =ROUND(P3/4,2)&" %" -> 0 %
A4: =DETAILS!A4 -> 1571 | B4: =DETAILS!B4 -> ABHIJEET PATEL | C4: =VLOOKUP($A4,'HALF YEARLY(Entry)'!$1:$1048576,3,0) -> 0 | D4: =VLOOKUP($A4,'HALF YEARLY(Entry)'!$1:$1048576,4,0) -> 0 | E4: =VLOOKUP($A4,'HALF YEARLY(Entry)'!$1:$1048576,5,0) -> 0 | F4: =VLOOKUP($A4,'HALF YEARLY(Entry)'!$1:$1048576,6,0) -> 0 | G4: =VLOOKUP($A4,'HALF YEARLY(Entry)'!$1:$1048576,7,0) -> 0 | H4: =VLOOKUP($A4,'HALF YEARLY(Entry)'!$1:$1048576,8,0) -> 0 | I4: =IFERROR(VLOOKUP(VLOOKUP($A4,'HALF YEARLY(Entry)'!$1:$1048576,9,0),'Grade 50'!$1:$1048576,2,0),VLOOKUP($A4,'HALF YEARLY(Entry)'!$1:$1048576,9,0)) -> E | J4: =IFERROR(VLOOKUP(VLOOKUP(A4,'HALF YEARLY(Entry)'!$1:$1048576,10,0),'Grade 50'!$1:$1048576,2,0),VLOOKUP(A4,'HALF YEARLY(Entry)'!$1:$1048576,10,0)) -> E | K4: =VLOOKUP($A4,'HALF YEARLY(Entry)'!$1:$1048576,11,0) -> 0 | L4: =VLOOKUP($A4,'HALF YEARLY(Entry)'!$1:$1048576,12,0) -> 0 | M4: =VLOOKUP($A4,'HALF YEARLY(Entry)'!$1:$1048576,13,0) -> 0 | N4: =VLOOKUP($A4,'HALF YEARLY(Entry)'!$1:$1048576,14,0) -> 0 | O4: =VLOOKUP($A4,'HALF YEARLY(Entry)'!$1:$1048576,15,0) -> 0 | P4: =SUM(C4:G4) -> 0 | Q4: =ROUND(P4/4,2)&" %" -> 0 %
A5: =DETAILS!A5 -> 1881 | B5: =DETAILS!B5 -> ADITI | C5: =VLOOKUP($A5,'HALF YEARLY(Entry)'!$1:$1048576,3,0) -> 0 | D5: =VLOOKUP($A5,'HALF YEARLY(Entry)'!$1:$1048576,4,0) -> 0 | E5: =VLOOKUP($A5,'HALF YEARLY(Entry)'!$1:$1048576,5,0) -> 0 | F5: =VLOOKUP($A5,'HALF YEARLY(Entry)'!$1:$1048576,6,0) -> 0 | G5: =VLOOKUP($A5,'HALF YEARLY(Entry)'!$1:$1048576,7,0) -> 0 | H5: =VLOOKUP($A5,'HALF YEARLY(Entry)'!$1:$1048576,8,0) -> 0 | I5: =IFERROR(VLOOKUP(VLOOKUP($A5,'HALF YEARLY(Entry)'!$1:$1048576,9,0),'Grade 50'!$1:$1048576,2,0),VLOOKUP($A5,'HALF YEARLY(Entry)'!$1:$1048576,9,0)) -> E | J5: =IFERROR(VLOOKUP(VLOOKUP(A5,'HALF YEARLY(Entry)'!$1:$1048576,10,0),'Grade 50'!$1:$1048576,2,0),VLOOKUP(A5,'HALF YEARLY(Entry)'!$1:$1048576,10,0)) -> E | K5: =VLOOKUP($A5,'HALF YEARLY(Entry)'!$1:$1048576,11,0) -> 0 | L5: =VLOOKUP($A5,'HALF YEARLY(Entry)'!$1:$1048576,12,0) -> 0 | M5: =VLOOKUP($A5,'HALF YEARLY(Entry)'!$1:$1048576,13,0) -> 0 | N5: =VLOOKUP($A5,'HALF YEARLY(Entry)'!$1:$1048576,14,0) -> 0 | O5: =VLOOKUP($A5,'HALF YEARLY(Entry)'!$1:$1048576,15,0) -> 0 | P5: =SUM(C5:G5) -> 0 | Q5: =ROUND(P5/4,2)&" %" -> 0 %
A6: =DETAILS!A6 -> 1559 | B6: =DETAILS!B6 -> ADITYA VERMA | C6: =VLOOKUP($A6,'HALF YEARLY(Entry)'!$1:$1048576,3,0) -> 0 | D6: =VLOOKUP($A6,'HALF YEARLY(Entry)'!$1:$1048576,4,0) -> 0 | E6: =VLOOKUP($A6,'HALF YEARLY(Entry)'!$1:$1048576,5,0) -> 0 | F6: =VLOOKUP($A6,'HALF YEARLY(Entry)'!$1:$1048576,6,0) -> 0 | G6: =VLOOKUP($A6,'HALF YEARLY(Entry)'!$1:$1048576,7,0) -> 0 | H6: =VLOOKUP($A6,'HALF YEARLY(Entry)'!$1:$1048576,8,0) -> 0 | I6: =IFERROR(VLOOKUP(VLOOKUP($A6,'HALF YEARLY(Entry)'!$1:$1048576,9,0),'Grade 50'!$1:$1048576,2,0),VLOOKUP($A6,'HALF YEARLY(Entry)'!$1:$1048576,9,0)) -> E | J6: =IFERROR(VLOOKUP(VLOOKUP(A6,'HALF YEARLY(Entry)'!$1:$1048576,10,0),'Grade 50'!$1:$1048576,2,0),VLOOKUP(A6,'HALF YEARLY(Entry)'!$1:$1048576,10,0)) -> E | K6: =VLOOKUP($A6,'HALF YEARLY(Entry)'!$1:$1048576,11,0) -> 0 | L6: =VLOOKUP($A6,'HALF YEARLY(Entry)'!$1:$1048576,12,0) -> 0 | M6: =VLOOKUP($A6,'HALF YEARLY(Entry)'!$1:$1048576,13,0) -> 0 | N6: =VLOOKUP($A6,'HALF YEARLY(Entry)'!$1:$1048576,14,0) -> 0 | O6: =VLOOKUP($A6,'HALF YEARLY(Entry)'!$1:$1048576,15,0) -> 0 | P6: =SUM(C6:G6) -> 0 | Q6: =ROUND(P6/4,2)&" %" -> 0 %
A7: =DETAILS!A7 -> 1548 | B7: =DETAILS!B7 -> ADVIK BAJPAI | C7: =VLOOKUP($A7,'HALF YEARLY(Entry)'!$1:$1048576,3,0) -> 0 | D7: =VLOOKUP($A7,'HALF YEARLY(Entry)'!$1:$1048576,4,0) -> 0 | E7: =VLOOKUP($A7,'HALF YEARLY(Entry)'!$1:$1048576,5,0) -> 0 | F7: =VLOOKUP($A7,'HALF YEARLY(Entry)'!$1:$1048576,6,0) -> 0 | G7: =VLOOKUP($A7,'HALF YEARLY(Entry)'!$1:$1048576,7,0) -> 0 | H7: =VLOOKUP($A7,'HALF YEARLY(Entry)'!$1:$1048576,8,0) -> 0 | I7: =IFERROR(VLOOKUP(VLOOKUP($A7,'HALF YEARLY(Entry)'!$1:$1048576,9,0),'Grade 50'!$1:$1048576,2,0),VLOOKUP($A7,'HALF YEARLY(Entry)'!$1:$1048576,9,0)) -> E | J7: =IFERROR(VLOOKUP(VLOOKUP(A7,'HALF YEARLY(Entry)'!$1:$1048576,10,0),'Grade 50'!$1:$1048576,2,0),VLOOKUP(A7,'HALF YEARLY(Entry)'!$1:$1048576,10,0)) -> E | K7: =VLOOKUP($A7,'HALF YEARLY(Entry)'!$1:$1048576,11,0) -> 0 | L7: =VLOOKUP($A7,'HALF YEARLY(Entry)'!$1:$1048576,12,0) -> 0 | M7: =VLOOKUP($A7,'HALF YEARLY(Entry)'!$1:$1048576,13,0) -> 0 | N7: =VLOOKUP($A7,'HALF YEARLY(Entry)'!$1:$1048576,14,0) -> 0 | O7: =VLOOKUP($A7,'HALF YEARLY(Entry)'!$1:$1048576,15,0) -> 0 | P7: =SUM(C7:G7) -> 0 | Q7: =ROUND(P7/4,2)&" %" -> 0 %
A8: =DETAILS!A8 -> 1549 | B8: =DETAILS!B8 -> AHEM SHARMA | C8: =VLOOKUP($A8,'HALF YEARLY(Entry)'!$1:$1048576,3,0) -> 0 | D8: =VLOOKUP($A8,'HALF YEARLY(Entry)'!$1:$1048576,4,0) -> 0 | E8: =VLOOKUP($A8,'HALF YEARLY(Entry)'!$1:$1048576,5,0) -> 0 | F8: =VLOOKUP($A8,'HALF YEARLY(Entry)'!$1:$1048576,6,0) -> 0 | G8: =VLOOKUP($A8,'HALF YEARLY(Entry)'!$1:$1048576,7,0) -> 0 | H8: =VLOOKUP($A8,'HALF YEARLY(Entry)'!$1:$1048576,8,0) -> 0 | I8: =IFERROR(VLOOKUP(VLOOKUP($A8,'HALF YEARLY(Entry)'!$1:$1048576,9,0),'Grade 50'!$1:$1048576,2,0),VLOOKUP($A8,'HALF YEARLY(Entry)'!$1:$1048576,9,0)) -> E | J8: =IFERROR(VLOOKUP(VLOOKUP(A8,'HALF YEARLY(Entry)'!$1:$1048576,10,0),'Grade 50'!$1:$1048576,2,0),VLOOKUP(A8,'HALF YEARLY(Entry)'!$1:$1048576,10,0)) -> E | K8: =VLOOKUP($A8,'HALF YEARLY(Entry)'!$1:$1048576,11,0) -> 0 | L8: =VLOOKUP($A8,'HALF YEARLY(Entry)'!$1:$1048576,12,0) -> 0 | M8: =VLOOKUP($A8,'HALF YEARLY(Entry)'!$1:$1048576,13,0) -> 0 | N8: =VLOOKUP($A8,'HALF YEARLY(Entry)'!$1:$1048576,14,0) -> 0 | O8: =VLOOKUP($A8,'HALF YEARLY(Entry)'!$1:$1048576,15,0) -> 0 | P8: =SUM(C8:G8) -> 0 | Q8: =ROUND(P8/4,2)&" %" -> 0 %
A9: =DETAILS!A9 -> 1556 | B9: =DETAILS!B9 -> AKRATI VISHWAKARMA | C9: =VLOOKUP($A9,'HALF YEARLY(Entry)'!$1:$1048576,3,0) -> 0 | D9: =VLOOKUP($A9,'HALF YEARLY(Entry)'!$1:$1048576,4,0) -> 0 | E9: =VLOOKUP($A9,'HALF YEARLY(Entry)'!$1:$1048576,5,0) -> 0 | F9: =VLOOKUP($A9,'HALF YEARLY(Entry)'!$1:$1048576,6,0) -> 0 | G9: =VLOOKUP($A9,'HALF YEARLY(Entry)'!$1:$1048576,7,0) -> 0 | H9: =VLOOKUP($A9,'HALF YEARLY(Entry)'!$1:$1048576,8,0) -> 0 | I9: =IFERROR(VLOOKUP(VLOOKUP($A9,'HALF YEARLY(Entry)'!$1:$1048576,9,0),'Grade 50'!$1:$1048576,2,0),VLOOKUP($A9,'HALF YEARLY(Entry)'!$1:$1048576,9,0)) -> E | J9: =IFERROR(VLOOKUP(VLOOKUP(A9,'HALF YEARLY(Entry)'!$1:$1048576,10,0),'Grade 50'!$1:$1048576,2,0),VLOOKUP(A9,'HALF YEARLY(Entry)'!$1:$1048576,10,0)) -> E | K9: =VLOOKUP($A9,'HALF YEARLY(Entry)'!$1:$1048576,11,0) -> 0 | L9: =VLOOKUP($A9,'HALF YEARLY(Entry)'!$1:$1048576,12,0) -> 0 | M9: =VLOOKUP($A9,'HALF YEARLY(Entry)'!$1:$1048576,13,0) -> 0 | N9: =VLOOKUP($A9,'HALF YEARLY(Entry)'!$1:$1048576,14,0) -> 0 | O9: =VLOOKUP($A9,'HALF YEARLY(Entry)'!$1:$1048576,15,0) -> 0 | P9: =SUM(C9:G9) -> 0 | Q9: =ROUND(P9/4,2)&" %" -> 0 %
A10: =DETAILS!A10 -> 1915 | B10: =DETAILS!B10 -> AKRITI SHUKLA | C10: =VLOOKUP($A10,'HALF YEARLY(Entry)'!$1:$1048576,3,0) -> 0 | D10: =VLOOKUP($A10,'HALF YEARLY(Entry)'!$1:$1048576,4,0) -> 0 | E10: =VLOOKUP($A10,'HALF YEARLY(Entry)'!$1:$1048576,5,0) -> 0 | F10: =VLOOKUP($A10,'HALF YEARLY(Entry)'!$1:$1048576,6,0) -> 0 | G10: =VLOOKUP($A10,'HALF YEARLY(Entry)'!$1:$1048576,7,0) -> 0 | H10: =VLOOKUP($A10,'HALF YEARLY(Entry)'!$1:$1048576,8,0) -> 0 | I10: =IFERROR(VLOOKUP(VLOOKUP($A10,'HALF YEARLY(Entry)'!$1:$1048576,9,0),'Grade 50'!$1:$1048576,2,0),VLOOKUP($A10,'HALF YEARLY(Entry)'!$1:$1048576,9,0)) -> E | J10: =IFERROR(VLOOKUP(VLOOKUP(A10,'HALF YEARLY(Entry)'!$1:$1048576,10,0),'Grade 50'!$1:$1048576,2,0),VLOOKUP(A10,'HALF YEARLY(Entry)'!$1:$1048576,10,0)) -> E | K10: =VLOOKUP($A10,'HALF YEARLY(Entry)'!$1:$1048576,11,0) -> 0 | L10: =VLOOKUP($A10,'HALF YEARLY(Entry)'!$1:$1048576,12,0) -> 0 | M10: =VLOOKUP($A10,'HALF YEARLY(Entry)'!$1:$1048576,13,0) -> 0 | N10: =VLOOKUP($A10,'HALF YEARLY(Entry)'!$1:$1048576,14,0) -> 0 | O10: =VLOOKUP($A10,'HALF YEARLY(Entry)'!$1:$1048576,15,0) -> 0 | P10: =SUM(C10:G10) -> 0 | Q10: =ROUND(P10/4,2)&" %" -> 0 %
A11: =DETAILS!A11 -> 1563 | B11: =DETAILS!B11 -> ANANYA | C11: =VLOOKUP($A11,'HALF YEARLY(Entry)'!$1:$1048576,3,0) -> 0 | D11: =VLOOKUP($A11,'HALF YEARLY(Entry)'!$1:$1048576,4,0) -> 0 | E11: =VLOOKUP($A11,'HALF YEARLY(Entry)'!$1:$1048576,5,0) -> 0 | F11: =VLOOKUP($A11,'HALF YEARLY(Entry)'!$1:$1048576,6,0) -> 0 | G11: =VLOOKUP($A11,'HALF YEARLY(Entry)'!$1:$1048576,7,0) -> 0 | H11: =VLOOKUP($A11,'HALF YEARLY(Entry)'!$1:$1048576,8,0) -> 0 | I11: =IFERROR(VLOOKUP(VLOOKUP($A11,'HALF YEARLY(Entry)'!$1:$1048576,9,0),'Grade 50'!$1:$1048576,2,0),VLOOKUP($A11,'HALF YEARLY(Entry)'!$1:$1048576,9,0)) -> E | J11: =IFERROR(VLOOKUP(VLOOKUP(A11,'HALF YEARLY(Entry)'!$1:$1048576,10,0),'Grade 50'!$1:$1048576,2,0),VLOOKUP(A11,'HALF YEARLY(Entry)'!$1:$1048576,10,0)) -> E | K11: =VLOOKUP($A11,'HALF YEARLY(Entry)'!$1:$1048576,11,0) -> 0 | L11: =VLOOKUP($A11,'HALF YEARLY(Entry)'!$1:$1048576,12,0) -> 0 | M11: =VLOOKUP($A11,'HALF YEARLY(Entry)'!$1:$1048576,13,0) -> 0 | N11: =VLOOKUP($A11,'HALF YEARLY(Entry)'!$1:$1048576,14,0) -> 0 | O11: =VLOOKUP($A11,'HALF YEARLY(Entry)'!$1:$1048576,15,0) -> 0 | P11: =SUM(C11:G11) -> 0 | Q11: =ROUND(P11/4,2)&" %" -> 0 %
A12: =DETAILS!A12 -> 1562 | B12: =DETAILS!B12 -> ANKITA RAJPOOT | C12: =VLOOKUP($A12,'HALF YEARLY(Entry)'!$1:$1048576,3,0) -> 0 | D12: =VLOOKUP($A12,'HALF YEARLY(Entry)'!$1:$1048576,4,0) -> 0 | E12: =VLOOKUP($A12,'HALF YEARLY(Entry)'!$1:$1048576,5,0) -> 0 | F12: =VLOOKUP($A12,'HALF YEARLY(Entry)'!$1:$1048576,6,0) -> 0 | G12: =VLOOKUP($A12,'HALF YEARLY(Entry)'!$1:$1048576,7,0) -> 0 | H12: =VLOOKUP($A12,'HALF YEARLY(Entry)'!$1:$1048576,8,0) -> 0 | I12: =IFERROR(VLOOKUP(VLOOKUP($A12,'HALF YEARLY(Entry)'!$1:$1048576,9,0),'Grade 50'!$1:$1048576,2,0),VLOOKUP($A12,'HALF YEARLY(Entry)'!$1:$1048576,9,0)) -> E | J12: =IFERROR(VLOOKUP(VLOOKUP(A12,'HALF YEARLY(Entry)'!$1:$1048576,10,0),'Grade 50'!$1:$1048576,2,0),VLOOKUP(A12,'HALF YEARLY(Entry)'!$1:$1048576,10,0)) -> E | K12: =VLOOKUP($A12,'HALF YEARLY(Entry)'!$1:$1048576,11,0) -> 0 | L12: =VLOOKUP($A12,'HALF YEARLY(Entry)'!$1:$1048576,12,0) -> 0 | M12: =VLOOKUP($A12,'HALF YEARLY(Entry)'!$1:$1048576,13,0) -> 0 | N12: =VLOOKUP($A12,'HALF YEARLY(Entry)'!$1:$1048576,14,0) -> 0 | O12: =VLOOKUP($A12,'HALF YEARLY(Entry)'!$1:$1048576,15,0) -> 0 | P12: =SUM(C12:G12) -> 0 | Q12: =ROUND(P12/4,2)&" %" -> 0 %
A13: =DETAILS!A13 -> 1547 | B13: =DETAILS!B13 -> ANSHIKA PANDEY | C13: =VLOOKUP($A13,'HALF YEARLY(Entry)'!$1:$1048576,3,0) -> 0 | D13: =VLOOKUP($A13,'HALF YEARLY(Entry)'!$1:$1048576,4,0) -> 0 | E13: =VLOOKUP($A13,'HALF YEARLY(Entry)'!$1:$1048576,5,0) -> 0 | F13: =VLOOKUP($A13,'HALF YEARLY(Entry)'!$1:$1048576,6,0) -> 0 | G13: =VLOOKUP($A13,'HALF YEARLY(Entry)'!$1:$1048576,7,0) -> 0 | H13: =VLOOKUP($A13,'HALF YEARLY(Entry)'!$1:$1048576,8,0) -> 0 | I13: =IFERROR(VLOOKUP(VLOOKUP($A13,'HALF YEARLY(Entry)'!$1:$1048576,9,0),'Grade 50'!$1:$1048576,2,0),VLOOKUP($A13,'HALF YEARLY(Entry)'!$1:$1048576,9,0)) -> E | J13: =IFERROR(VLOOKUP(VLOOKUP(A13,'HALF YEARLY(Entry)'!$1:$1048576,10,0),'Grade 50'!$1:$1048576,2,0),VLOOKUP(A13,'HALF YEARLY(Entry)'!$1:$1048576,10,0)) -> E | K13: =VLOOKUP($A13,'HALF YEARLY(Entry)'!$1:$1048576,11,0) -> 0 | L13: =VLOOKUP($A13,'HALF YEARLY(Entry)'!$1:$1048576,12,0) -> 0 | M13: =VLOOKUP($A13,'HALF YEARLY(Entry)'!$1:$1048576,13,0) -> 0 | N13: =VLOOKUP($A13,'HALF YEARLY(Entry)'!$1:$1048576,14,0) -> 0 | O13: =VLOOKUP($A13,'HALF YEARLY(Entry)'!$1:$1048576,15,0) -> 0 | P13: =SUM(C13:G13) -> 0 | Q13: =ROUND(P13/4,2)&" %" -> 0 %
A14: =DETAILS!A14 -> 1644 | B14: =DETAILS!B14 -> ARADHYA SINGH | C14: =VLOOKUP($A14,'HALF YEARLY(Entry)'!$1:$1048576,3,0) -> 0 | D14: =VLOOKUP($A14,'HALF YEARLY(Entry)'!$1:$1048576,4,0) -> 0 | E14: =VLOOKUP($A14,'HALF YEARLY(Entry)'!$1:$1048576,5,0) -> 0 | F14: =VLOOKUP($A14,'HALF YEARLY(Entry)'!$1:$1048576,6,0) -> 0 | G14: =VLOOKUP($A14,'HALF YEARLY(Entry)'!$1:$1048576,7,0) -> 0 | H14: =VLOOKUP($A14,'HALF YEARLY(Entry)'!$1:$1048576,8,0) -> 0 | I14: =IFERROR(VLOOKUP(VLOOKUP($A14,'HALF YEARLY(Entry)'!$1:$1048576,9,0),'Grade 50'!$1:$1048576,2,0),VLOOKUP($A14,'HALF YEARLY(Entry)'!$1:$1048576,9,0)) -> E | J14: =IFERROR(VLOOKUP(VLOOKUP(A14,'HALF YEARLY(Entry)'!$1:$1048576,10,0),'Grade 50'!$1:$1048576,2,0),VLOOKUP(A14,'HALF YEARLY(Entry)'!$1:$1048576,10,0)) -> E | K14: =VLOOKUP($A14,'HALF YEARLY(Entry)'!$1:$1048576,11,0) -> 0 | L14: =VLOOKUP($A14,'HALF YEARLY(Entry)'!$1:$1048576,12,0) -> 0 | M14: =VLOOKUP($A14,'HALF YEARLY(Entry)'!$1:$1048576,13,0) -> 0 | N14: =VLOOKUP($A14,'HALF YEARLY(Entry)'!$1:$1048576,14,0) -> 0 | O14: =VLOOKUP($A14,'HALF YEARLY(Entry)'!$1:$1048576,15,0) -> 0 | P14: =SUM(C14:G14) -> 0 | Q14: =ROUND(P14/4,2)&" %" -> 0 %
A15: =DETAILS!A15 -> 1566 | B15: =DETAILS!B15 -> ARIYAN PAL | C15: =VLOOKUP($A15,'HALF YEARLY(Entry)'!$1:$1048576,3,0) -> 0 | D15: =VLOOKUP($A15,'HALF YEARLY(Entry)'!$1:$1048576,4,0) -> 0 | E15: =VLOOKUP($A15,'HALF YEARLY(Entry)'!$1:$1048576,5,0) -> 0 | F15: =VLOOKUP($A15,'HALF YEARLY(Entry)'!$1:$1048576,6,0) -> 0 | G15: =VLOOKUP($A15,'HALF YEARLY(Entry)'!$1:$1048576,7,0) -> 0 | H15: =VLOOKUP($A15,'HALF YEARLY(Entry)'!$1:$1048576,8,0) -> 0 | I15: =IFERROR(VLOOKUP(VLOOKUP($A15,'HALF YEARLY(Entry)'!$1:$1048576,9,0),'Grade 50'!$1:$1048576,2,0),VLOOKUP($A15,'HALF YEARLY(Entry)'!$1:$1048576,9,0)) -> E | J15: =IFERROR(VLOOKUP(VLOOKUP(A15,'HALF YEARLY(Entry)'!$1:$1048576,10,0),'Grade 50'!$1:$1048576,2,0),VLOOKUP(A15,'HALF YEARLY(Entry)'!$1:$1048576,10,0)) -> E | K15: =VLOOKUP($A15,'HALF YEARLY(Entry)'!$1:$1048576,11,0) -> 0 | L15: =VLOOKUP($A15,'HALF YEARLY(Entry)'!$1:$1048576,12,0) -> 0 | M15: =VLOOKUP($A15,'HALF YEARLY(Entry)'!$1:$1048576,13,0) -> 0 | N15: =VLOOKUP($A15,'HALF YEARLY(Entry)'!$1:$1048576,14,0) -> 0 | O15: =VLOOKUP($A15,'HALF YEARLY(Entry)'!$1:$1048576,15,0) -> 0 | P15: =SUM(C15:G15) -> 0 | Q15: =ROUND(P15/4,2)&" %" -> 0 %
... A41: =DETAILS!A41 -> 1937 | B41: =DETAILS!B41 -> VIVAAN PAL | C41: =VLOOKUP($A41,'HALF YEARLY(Entry)'!$1:$1048576,3,0) -> 0 | D41: =VLOOKUP($A41,'HALF YEARLY(Entry)'!$1:$1048576,4,0) -> 0 | E41: =VLOOKUP($A41,'HALF YEARLY(Entry)'!$1:$1048576,5,0) -> 0 | F41: =VLOOKUP($A41,'HALF YEARLY(Entry)'!$1:$1048576,6,0) -> 0 | G41: =VLOOKUP($A41,'HALF YEARLY(Entry)'!$1:$1048576,7,0) -> 0 | H41: =VLOOKUP($A41,'HALF YEARLY(Entry)'!$1:$1048576,8,0) -> 0 | I41: =IFERROR(VLOOKUP(VLOOKUP($A41,'HALF YEARLY(Entry)'!$1:$1048576,9,0),'Grade 50'!$1:$1048576,2,0),VLOOKUP($A41,'HALF YEARLY(Entry)'!$1:$1048576,9,0)) -> E | J41: =IFERROR(VLOOKUP(VLOOKUP(A41,'HALF YEARLY(Entry)'!$1:$1048576,10,0),'Grade 50'!$1:$1048576,2,0),VLOOKUP(A41,'HALF YEARLY(Entry)'!$1:$1048576,10,0)) -> E | K41: =VLOOKUP($A41,'HALF YEARLY(Entry)'!$1:$1048576,11,0) -> 0 | L41: =VLOOKUP($A41,'HALF YEARLY(Entry)'!$1:$1048576,12,0) -> 0 | M41: =VLOOKUP($A41,'HALF YEARLY(Entry)'!$1:$1048576,13,0) -> 0 | N41: =VLOOKUP($A41,'HALF YEARLY(Entry)'!$1:$1048576,14,0) -> 0 | O41: =VLOOKUP($A41,'HALF YEARLY(Entry)'!$1:$1048576,15,0) -> 0 | P41: =SUM(C41:G41) -> 0 | Q41: =ROUND(P41/4,2)&" %" -> 0 %

Sheet Grade 50
A2: 50 | B2: A
A3: 49 | B3: A
A4: 48 | B4: A
A5: 47 | B5: A
A6: 46 | B6: A
A7: 45 | B7: A
A8: 44 | B8: A
A9: 43 | B9: A
A10: 42 | B10: A
A11: 41 | B11: A
A12: 40 | B12: B
A13: 39 | B13: B
... A52: 0 | B52: E

Sheet HY Compile
A1: Half Yearly Compile Report (2025-26)
A2: S.R. No. | B2: Student's Name | C2: ENGLISH | H2: HINDI | M2: MATHEMATICS | R2: EVS | W2: COMPUTER | AB2: WORK EDUCATION | AC2: ART EDUCATION | AD2: GENERAL KNOWLEDGE | AE2: HEALTH & PHYSICAL EDUCATION | AF2: DISCIPLINE | AG2: TOTAL PRESENT | AH2: TORAL WORKING DAY | AI2: CLASS TEACHER'S REAMRK
C3: UT-I | D3: NB-I | E3: SE-I | F3: HY | G3: Total | H3: UT-I | I3: NB-I | J3: SE-I | K3: HY | L3: Total | M3: UT-I | N3: NB-I | O3: SE-I | P3: HY | Q3: Total | R3: UT-I | S3: NB-I | T3: SE-I | U3: HY | V3: Total | W3: UT-I | X3: NB-I | Y3: SE-I | Z3: HY | AA3: Total
A4: =DETAILS!A3 -> 1804 | B4: =DETAILS!B3 -> AAKRITI SINGH | C4: =IFERROR(ROUND(VLOOKUP($A4,'UT-I '!$1:$1048576,3,0)/2,0),VLOOKUP($A4,'UT-I '!$1:$1048576,3,0)) -> 0 | D4: =VLOOKUP($A4,'NOTEBOOK-1 (Entry)'!$1:$1048576,3,0) -> 0 | E4: =VLOOKUP($A4,'ENRICH-1(Entry)'!$1:$1048576,3,0) -> 0 | F4: =VLOOKUP(A4,'HALF YEARLY'!$1:$1048576,3,0) -> 0 | G4: =SUM(C4:F4) -> 0 | H4: =IFERROR(ROUND(VLOOKUP($A4,'UT-I '!$1:$1048576,4,0)/2,0),VLOOKUP($A4,'UT-I '!$1:$1048576,4,0)) -> 0 | I4: =VLOOKUP($A4,'NOTEBOOK-1 (Entry)'!$1:$1048576,4,0) -> 0 | J4: =VLOOKUP($A4,'ENRICH-1(Entry)'!$1:$1048576,4,0) -> 0 | K4: =VLOOKUP($A4,'HALF YEARLY'!$1:$1048576,4,0) -> 0 | L4: =SUM(H4:K4) -> 0 | M4: =IFERROR(ROUND(VLOOKUP($A4,'UT-I '!$1:$1048576,5,0)/2,0),VLOOKUP($A4,'UT-I '!$1:$1048576,5,0)) -> 0 | N4: =VLOOKUP($A4,'NOTEBOOK-1 (Entry)'!$1:$1048576,5,0) -> 0 | O4: =VLOOKUP($A4,'ENRICH-1(Entry)'!$1:$1048576,5,0) -> 0 | P4: =VLOOKUP($A4,'HALF YEARLY'!$1:$1048576,5,0) -> 0 | Q4: =SUM(M4:P4) -> 0 | R4: =IFERROR(ROUND(VLOOKUP($A4,'UT-I '!$1:$1048576,6,0)/2,0),VLOOKUP($A4,'UT-I '!$1:$1048576,6,0)) -> 0 | S4: =VLOOKUP($A4,'NOTEBOOK-1 (Entry)'!$1:$1048576,6,0) -> 0 | T4: =VLOOKUP($A4,'ENRICH-1(Entry)'!$1:$1048576,6,0) -> 0 | U4: =VLOOKUP($A4,'HALF YEARLY'!$1:$1048576,6,0) -> 0 | V4: =SUM(R4:U4) -> 0 | W4: =IFERROR(ROUND(VLOOKUP($A4,'UT-I '!$1:$1048576,7,0)/2,0),VLOOKUP($A4,'UT-I '!$1:$1048576,7,0)) -> 0 | X4: =VLOOKUP($A4,'NOTEBOOK-1 (Entry)'!$1:$1048576,7,0) -> 0 | Y4: =VLOOKUP($A4,'ENRICH-1(Entry)'!$1:$1048576,7,0) -> 0 | Z4: =VLOOKUP($A4,'HALF YEARLY'!$1:$1048576,7,0) -> 0 | AA4: =SUM(W4:Z4) -> 0 | AB4: =VLOOKUP($A4,'HALF YEARLY'!$1:$1048576,8,0) -> 0 | AC4: =VLOOKUP($A4,'HALF YEARLY'!$1:$1048576,9,0) -> E | AD4: =VLOOKUP($A4,'HALF YEARLY'!$1:$1048576,10,0) -> E | AE4: =VLOOKUP($A4,'HALF YEARLY'!$1:$1048576,11,0) -> 0 | AF4: =VLOOKUP($A4,'HALF YEARLY'!$1:$1048576,12,0) -> 0 | AG4: =VLOOKUP($A4,'HALF YEARLY'!$1:$1048576,13,0) -> 0 | AH4: =VLOOKUP($A4,'HALF YEARLY'!$1:$1048576,14,0) -> 0 | AI4: =VLOOKUP($A4,'HALF YEARLY'!$1:$1048576,15,0) -> 0
A5: =DETAILS!A4 -> 1571 | B5: =DETAILS!B4 -> ABHIJEET PATEL | C5: =IFERROR(ROUND(VLOOKUP($A5,'UT-I '!$1:$1048576,3,0)/2,0),VLOOKUP($A5,'UT-I '!$1:$1048576,3,0)) -> 0 | D5: =VLOOKUP($A5,'NOTEBOOK-1 (Entry)'!$1:$1048576,3,0) -> 0 | E5: =VLOOKUP($A5,'ENRICH-1(Entry)'!$1:$1048576,3,0) -> 0 | F5: =VLOOKUP(A5,'HALF YEARLY'!$1:$1048576,3,0) -> 0 | G5: =SUM(C5:F5) -> 0 | H5: =IFERROR(ROUND(VLOOKUP($A5,'UT-I '!$1:$1048576,4,0)/2,0),VLOOKUP($A5,'UT-I '!$1:$1048576,4,0)) -> 0 | I5: =VLOOKUP($A5,'NOTEBOOK-1 (Entry)'!$1:$1048576,4,0) -> 0 | J5: =VLOOKUP($A5,'ENRICH-1(Entry)'!$1:$1048576,4,0) -> 0 | K5: =VLOOKUP($A5,'HALF YEARLY'!$1:$1048576,4,0) -> 0 | L5: =SUM(H5:K5) -> 0 | M5: =IFERROR(ROUND(VLOOKUP($A5,'UT-I '!$1:$1048576,5,0)/2,0),VLOOKUP($A5,'UT-I '!$1:$1048576,5,0)) -> 0 | N5: =VLOOKUP($A5,'NOTEBOOK-1 (Entry)'!$1:$1048576,5,0) -> 0 | O5: =VLOOKUP($A5,'ENRICH-1(Entry)'!$1:$1048576,5,0) -> 0 | P5: =VLOOKUP($A5,'HALF YEARLY'!$1:$1048576,5,0) -> 0 | Q5: =SUM(M5:P5) -> 0 | R5: =IFERROR(ROUND(VLOOKUP($A5,'UT-I '!$1:$1048576,6,0)/2,0),VLOOKUP($A5,'UT-I '!$1:$1048576,6,0)) -> 0 | S5: =VLOOKUP($A5,'NOTEBOOK-1 (Entry)'!$1:$1048576,6,0) -> 0 | T5: =VLOOKUP($A5,'ENRICH-1(Entry)'!$1:$1048576,6,0) -> 0 | U5: =VLOOKUP($A5,'HALF YEARLY'!$1:$1048576,6,0) -> 0 | V5: =SUM(R5:U5) -> 0 | W5: =IFERROR(ROUND(VLOOKUP($A5,'UT-I '!$1:$1048576,7,0)/2,0),VLOOKUP($A5,'UT-I '!$1:$1048576,7,0)) -> 0 | X5: =VLOOKUP($A5,'NOTEBOOK-1 (Entry)'!$1:$1048576,7,0) -> 0 | Y5: =VLOOKUP($A5,'ENRICH-1(Entry)'!$1:$1048576,7,0) -> 0 | Z5: =VLOOKUP($A5,'HALF YEARLY'!$1:$1048576,7,0) -> 0 | AA5: =SUM(W5:Z5) -> 0 | AB5: =VLOOKUP($A5,'HALF YEARLY'!$1:$1048576,8,0) -> 0 | AC5: =VLOOKUP($A5,'HALF YEARLY'!$1:$1048576,9,0) -> E | AD5: =VLOOKUP($A5,'HALF YEARLY'!$1:$1048576,10,0) -> E | AE5: =VLOOKUP($A5,'HALF YEARLY'!$1:$1048576,11,0) -> 0 | AF5: =VLOOKUP($A5,'HALF YEARLY'!$1:$1048576,12,0) -> 0 | AG5: =VLOOKUP($A5,'HALF YEARLY'!$1:$1048576,13,0) -> 0 | AH5: =VLOOKUP($A5,'HALF YEARLY'!$1:$1048576,14,0) -> 0 | AI5: =VLOOKUP($A5,'HALF YEARLY'!$1:$1048576,15,0) -> 0
A6: =DETAILS!A5 -> 1881 | B6: =DETAILS!B5 -> ADITI | C6: =IFERROR(ROUND(VLOOKUP($A6,'UT-I '!$1:$1048576,3,0)/2,0),VLOOKUP($A6,'UT-I '!$1:$1048576,3,0)) -> 0 | D6: =VLOOKUP($A6,'NOTEBOOK-1 (Entry)'!$1:$1048576,3,0) -> 0 | E6: =VLOOKUP($A6,'ENRICH-1(Entry)'!$1:$1048576,3,0) -> 0 | F6: =VLOOKUP(A6,'HALF YEARLY'!$1:$1048576,3,0) -> 0 | G6: =SUM(C6:F6) -> 0 | H6: =IFERROR(ROUND(VLOOKUP($A6,'UT-I '!$1:$1048576,4,0)/2,0),VLOOKUP($A6,'UT-I '!$1:$1048576,4,0)) -> 0 | I6: =VLOOKUP($A6,'NOTEBOOK-1 (Entry)'!$1:$1048576,4,0) -> 0 | J6: =VLOOKUP($A6,'ENRICH-1(Entry)'!$1:$1048576,4,0) -> 0 | K6: =VLOOKUP($A6,'HALF YEARLY'!$1:$1048576,4,0) -> 0 | L6: =SUM(H6:K6) -> 0 | M6: =IFERROR(ROUND(VLOOKUP($A6,'UT-I '!$1:$1048576,5,0)/2,0),VLOOKUP($A6,'UT-I '!$1:$1048576,5,0)) -> 0 | N6: =VLOOKUP($A6,'NOTEBOOK-1 (Entry)'!$1:$1048576,5,0) -> 0 | O6: =VLOOKUP($A6,'ENRICH-1(Entry)'!$1:$1048576,5,0) -> 0 | P6: =VLOOKUP($A6,'HALF YEARLY'!$1:$1048576,5,0) -> 0 | Q6: =SUM(M6:P6) -> 0 | R6: =IFERROR(ROUND(VLOOKUP($A6,'UT-I '!$1:$1048576,6,0)/2,0),VLOOKUP($A6,'UT-I '!$1:$1048576,6,0)) -> 0 | S6: =VLOOKUP($A6,'NOTEBOOK-1 (Entry)'!$1:$1048576,6,0) -> 0 | T6: =VLOOKUP($A6,'ENRICH-1(Entry)'!$1:$1048576,6,0) -> 0 | U6: =VLOOKUP($A6,'HALF YEARLY'!$1:$1048576,6,0) -> 0 | V6: =SUM(R6:U6) -> 0 | W6: =IFERROR(ROUND(VLOOKUP($A6,'UT-I '!$1:$1048576,7,0)/2,0),VLOOKUP($A6,'UT-I '!$1:$1048576,7,0)) -> 0 | X6: =VLOOKUP($A6,'NOTEBOOK-1 (Entry)'!$1:$1048576,7,0) -> 0 | Y6: =VLOOKUP($A6,'ENRICH-1(Entry)'!$1:$1048576,7,0) -> 0 | Z6: =VLOOKUP($A6,'HALF YEARLY'!$1:$1048576,7,0) -> 0 | AA6: =SUM(W6:Z6) -> 0 | AB6: =VLOOKUP($A6,'HALF YEARLY'!$1:$1048576,8,0) -> 0 | AC6: =VLOOKUP($A6,'HALF YEARLY'!$1:$1048576,9,0) -> E | AD6: =VLOOKUP($A6,'HALF YEARLY'!$1:$1048576,10,0) -> E | AE6: =VLOOKUP($A6,'HALF YEARLY'!$1:$1048576,11,0) -> 0 | AF6: =VLOOKUP($A6,'HALF YEARLY'!$1:$1048576,12,0) -> 0 | AG6: =VLOOKUP($A6,'HALF YEARLY'!$1:$1048576,13,0) -> 0 | AH6: =VLOOKUP($A6,'HALF YEARLY'!$1:$1048576,14,0) -> 0 | AI6: =VLOOKUP($A6,'HALF YEARLY'!$1:$1048576,15,0) -> 0
A7: =DETAILS!A6 -> 1559 | B7: =DETAILS!B6 -> ADITYA VERMA | C7: =IFERROR(ROUND(VLOOKUP($A7,'UT-I '!$1:$1048576,3,0)/2,0),VLOOKUP($A7,'UT-I '!$1:$1048576,3,0)) -> 0 | D7: =VLOOKUP($A7,'NOTEBOOK-1 (Entry)'!$1:$1048576,3,0) -> 0 | E7: =VLOOKUP($A7,'ENRICH-1(Entry)'!$1:$1048576,3,0) -> 0 | F7: =VLOOKUP(A7,'HALF YEARLY'!$1:$1048576,3,0) -> 0 | G7: =SUM(C7:F7) -> 0 | H7: =IFERROR(ROUND(VLOOKUP($A7,'UT-I '!$1:$1048576,4,0)/2,0),VLOOKUP($A7,'UT-I '!$1:$1048576,4,0)) -> 0 | I7: =VLOOKUP($A7,'NOTEBOOK-1 (Entry)'!$1:$1048576,4,0) -> 0 | J7: =VLOOKUP($A7,'ENRICH-1(Entry)'!$1:$1048576,4,0) -> 0 | K7: =VLOOKUP($A7,'HALF YEARLY'!$1:$1048576,4,0) -> 0 | L7: =SUM(H7:K7) -> 0 | M7: =IFERROR(ROUND(VLOOKUP($A7,'UT-I '!$1:$1048576,5,0)/2,0),VLOOKUP($A7,'UT-I '!$1:$1048576,5,0)) -> 0 | N7: =VLOOKUP($A7,'NOTEBOOK-1 (Entry)'!$1:$1048576,5,0) -> 0 | O7: =VLOOKUP($A7,'ENRICH-1(Entry)'!$1:$1048576,5,0) -> 0 | P7: =VLOOKUP($A7,'HALF YEARLY'!$1:$1048576,5,0) -> 0 | Q7: =SUM(M7:P7) -> 0 | R7: =IFERROR(ROUND(VLOOKUP($A7,'UT-I '!$1:$1048576,6,0)/2,0),VLOOKUP($A7,'UT-I '!$1:$1048576,6,0)) -> 0 | S7: =VLOOKUP($A7,'NOTEBOOK-1 (Entry)'!$1:$1048576,6,0) -> 0 | T7: =VLOOKUP($A7,'ENRICH-1(Entry)'!$1:$1048576,6,0) -> 0 | U7: =VLOOKUP($A7,'HALF YEARLY'!$1:$1048576,6,0) -> 0 | V7: =SUM(R7:U7) -> 0 | W7: =IFERROR(ROUND(VLOOKUP($A7,'UT-I '!$1:$1048576,7,0)/2,0),VLOOKUP($A7,'UT-I '!$1:$1048576,7,0)) -> 0 | X7: =VLOOKUP($A7,'NOTEBOOK-1 (Entry)'!$1:$1048576,7,0) -> 0 | Y7: =VLOOKUP($A7,'ENRICH-1(Entry)'!$1:$1048576,7,0) -> 0 | Z7: =VLOOKUP($A7,'HALF YEARLY'!$1:$1048576,7,0) -> 0 | AA7: =SUM(W7:Z7) -> 0 | AB7: =VLOOKUP($A7,'HALF YEARLY'!$1:$1048576,8,0) -> 0 | AC7: =VLOOKUP($A7,'HALF YEARLY'!$1:$1048576,9,0) -> E | AD7: =VLOOKUP($A7,'HALF YEARLY'!$1:$1048576,10,0) -> E | AE7: =VLOOKUP($A7,'HALF YEARLY'!$1:$1048576,11,0) -> 0 | AF7: =VLOOKUP($A7,'HALF YEARLY'!$1:$1048576,12,0) -> 0 | AG7: =VLOOKUP($A7,'HALF YEARLY'!$1:$1048576,13,0) -> 0 | AH7: =VLOOKUP($A7,'HALF YEARLY'!$1:$1048576,14,0) -> 0 | AI7: =VLOOKUP($A7,'HALF YEARLY'!$1:$1048576,15,0) -> 0
A8: =DETAILS!A7 -> 1548 | B8: =DETAILS!B7 -> ADVIK BAJPAI | C8: =IFERROR(ROUND(VLOOKUP($A8,'UT-I '!$1:$1048576,3,0)/2,0),VLOOKUP($A8,'UT-I '!$1:$1048576,3,0)) -> 0 | D8: =VLOOKUP($A8,'NOTEBOOK-1 (Entry)'!$1:$1048576,3,0) -> 0 | E8: =VLOOKUP($A8,'ENRICH-1(Entry)'!$1:$1048576,3,0) -> 0 | F8: =VLOOKUP(A8,'HALF YEARLY'!$1:$1048576,3,0) -> 0 | G8: =SUM(C8:F8) -> 0 | H8: =IFERROR(ROUND(VLOOKUP($A8,'UT-I '!$1:$1048576,4,0)/2,0),VLOOKUP($A8,'UT-I '!$1:$1048576,4,0)) -> 0 | I8: =VLOOKUP($A8,'NOTEBOOK-1 (Entry)'!$1:$1048576,4,0) -> 0 | J8: =VLOOKUP($A8,'ENRICH-1(Entry)'!$1:$1048576,4,0) -> 0 | K8: =VLOOKUP($A8,'HALF YEARLY'!$1:$1048576,4,0) -> 0 | L8: =SUM(H8:K8) -> 0 | M8: =IFERROR(ROUND(VLOOKUP($A8,'UT-I '!$1:$1048576,5,0)/2,0),VLOOKUP($A8,'UT-I '!$1:$1048576,5,0)) -> 0 | N8: =VLOOKUP($A8,'NOTEBOOK-1 (Entry)'!$1:$1048576,5,0) -> 0 | O8: =VLOOKUP($A8,'ENRICH-1(Entry)'!$1:$1048576,5,0) -> 0 | P8: =VLOOKUP($A8,'HALF YEARLY'!$1:$1048576,5,0) -> 0 | Q8: =SUM(M8:P8) -> 0 | R8: =IFERROR(ROUND(VLOOKUP($A8,'UT-I '!$1:$1048576,6,0)/2,0),VLOOKUP($A8,'UT-I '!$1:$1048576,6,0)) -> 0 | S8: =VLOOKUP($A8,'NOTEBOOK-1 (Entry)'!$1:$1048576,6,0) -> 0 | T8: =VLOOKUP($A8,'ENRICH-1(Entry)'!$1:$1048576,6,0) -> 0 | U8: =VLOOKUP($A8,'HALF YEARLY'!$1:$1048576,6,0) -> 0 | V8: =SUM(R8:U8) -> 0 | W8: =IFERROR(ROUND(VLOOKUP($A8,'UT-I '!$1:$1048576,7,0)/2,0),VLOOKUP($A8,'UT-I '!$1:$1048576,7,0)) -> 0 | X8: =VLOOKUP($A8,'NOTEBOOK-1 (Entry)'!$1:$1048576,7,0) -> 0 | Y8: =VLOOKUP($A8,'ENRICH-1(Entry)'!$1:$1048576,7,0) -> 0 | Z8: =VLOOKUP($A8,'HALF YEARLY'!$1:$1048576,7,0) -> 0 | AA8: =SUM(W8:Z8) -> 0 | AB8: =VLOOKUP($A8,'HALF YEARLY'!$1:$1048576,8,0) -> 0 | AC8: =VLOOKUP($A8,'HALF YEARLY'!$1:$1048576,9,0) -> E | AD8: =VLOOKUP($A8,'HALF YEARLY'!$1:$1048576,10,0) -> E | AE8: =VLOOKUP($A8,'HALF YEARLY'!$1:$1048576,11,0) -> 0 | AF8: =VLOOKUP($A8,'HALF YEARLY'!$1:$1048576,12,0) -> 0 | AG8: =VLOOKUP($A8,'HALF YEARLY'!$1:$1048576,13,0) -> 0 | AH8: =VLOOKUP($A8,'HALF YEARLY'!$1:$1048576,14,0) -> 0 | AI8: =VLOOKUP($A8,'HALF YEARLY'!$1:$1048576,15,0) -> 0
A9: =DETAILS!A8 -> 1549 | B9: =DETAILS!B8 -> AHEM SHARMA | C9: =IFERROR(ROUND(VLOOKUP($A9,'UT-I '!$1:$1048576,3,0)/2,0),VLOOKUP($A9,'UT-I '!$1:$1048576,3,0)) -> 0 | D9: =VLOOKUP($A9,'NOTEBOOK-1 (Entry)'!$1:$1048576,3,0) -> 0 | E9: =VLOOKUP($A9,'ENRICH-1(Entry)'!$1:$1048576,3,0) -> 0 | F9: =VLOOKUP(A9,'HALF YEARLY'!$1:$1048576,3,0) -> 0 | G9: =SUM(C9:F9) -> 0 | H9: =IFERROR(ROUND(VLOOKUP($A9,'UT-I '!$1:$1048576,4,0)/2,0),VLOOKUP($A9,'UT-I '!$1:$1048576,4,0)) -> 0 | I9: =VLOOKUP($A9,'NOTEBOOK-1 (Entry)'!$1:$1048576,4,0) -> 0 | J9: =VLOOKUP($A9,'ENRICH-1(Entry)'!$1:$1048576,4,0) -> 0 | K9: =VLOOKUP($A9,'HALF YEARLY'!$1:$1048576,4,0) -> 0 | L9: =SUM(H9:K9) -> 0 | M9: =IFERROR(ROUND(VLOOKUP($A9,'UT-I '!$1:$1048576,5,0)/2,0),VLOOKUP($A9,'UT-I '!$1:$1048576,5,0)) -> 0 | N9: =VLOOKUP($A9,'NOTEBOOK-1 (Entry)'!$1:$1048576,5,0) -> 0 | O9: =VLOOKUP($A9,'ENRICH-1(Entry)'!$1:$1048576,5,0) -> 0 | P9: =VLOOKUP($A9,'HALF YEARLY'!$1:$1048576,5,0) -> 0 | Q9: =SUM(M9:P9) -> 0 | R9: =IFERROR(ROUND(VLOOKUP($A9,'UT-I '!$1:$1048576,6,0)/2,0),VLOOKUP($A9,'UT-I '!$1:$1048576,6,0)) -> 0 | S9: =VLOOKUP($A9,'NOTEBOOK-1 (Entry)'!$1:$1048576,6,0) -> 0 | T9: =VLOOKUP($A9,'ENRICH-1(Entry)'!$1:$1048576,6,0) -> 0 | U9: =VLOOKUP($A9,'HALF YEARLY'!$1:$1048576,6,0) -> 0 | V9: =SUM(R9:U9) -> 0 | W9: =IFERROR(ROUND(VLOOKUP($A9,'UT-I '!$1:$1048576,7,0)/2,0),VLOOKUP($A9,'UT-I '!$1:$1048576,7,0)) -> 0 | X9: =VLOOKUP($A9,'NOTEBOOK-1 (Entry)'!$1:$1048576,7,0) -> 0 | Y9: =VLOOKUP($A9,'ENRICH-1(Entry)'!$1:$1048576,7,0) -> 0 | Z9: =VLOOKUP($A9,'HALF YEARLY'!$1:$1048576,7,0) -> 0 | AA9: =SUM(W9:Z9) -> 0 | AB9: =VLOOKUP($A9,'HALF YEARLY'!$1:$1048576,8,0) -> 0 | AC9: =VLOOKUP($A9,'HALF YEARLY'!$1:$1048576,9,0) -> E | AD9: =VLOOKUP($A9,'HALF YEARLY'!$1:$1048576,10,0) -> E | AE9: =VLOOKUP($A9,'HALF YEARLY'!$1:$1048576,11,0) -> 0 | AF9: =VLOOKUP($A9,'HALF YEARLY'!$1:$1048576,12,0) -> 0 | AG9: =VLOOKUP($A9,'HALF YEARLY'!$1:$1048576,13,0) -> 0 | AH9: =VLOOKUP($A9,'HALF YEARLY'!$1:$1048576,14,0) -> 0 | AI9: =VLOOKUP($A9,'HALF YEARLY'!$1:$1048576,15,0) -> 0
A10: =DETAILS!A9 -> 1556 | B10: =DETAILS!B9 -> AKRATI VISHWAKARMA | C10: =IFERROR(ROUND(VLOOKUP($A10,'UT-I '!$1:$1048576,3,0)/2,0),VLOOKUP($A10,'UT-I '!$1:$1048576,3,0)) -> 0 | D10: =VLOOKUP($A10,'NOTEBOOK-1 (Entry)'!$1:$1048576,3,0) -> 0 | E10: =VLOOKUP($A10,'ENRICH-1(Entry)'!$1:$1048576,3,0) -> 0 | F10: =VLOOKUP(A10,'HALF YEARLY'!$1:$1048576,3,0) -> 0 | G10: =SUM(C10:F10) -> 0 | H10: =IFERROR(ROUND(VLOOKUP($A10,'UT-I '!$1:$1048576,4,0)/2,0),VLOOKUP($A10,'UT-I '!$1:$1048576,4,0)) -> 0 | I10: =VLOOKUP($A10,'NOTEBOOK-1 (Entry)'!$1:$1048576,4,0) -> 0 | J10: =VLOOKUP($A10,'ENRICH-1(Entry)'!$1:$1048576,4,0) -> 0 | K10: =VLOOKUP($A10,'HALF YEARLY'!$1:$1048576,4,0) -> 0 | L10: =SUM(H10:K10) -> 0 | M10: =IFERROR(ROUND(VLOOKUP($A10,'UT-I '!$1:$1048576,5,0)/2,0),VLOOKUP($A10,'UT-I '!$1:$1048576,5,0)) -> 0 | N10: =VLOOKUP($A10,'NOTEBOOK-1 (Entry)'!$1:$1048576,5,0) -> 0 | O10: =VLOOKUP($A10,'ENRICH-1(Entry)'!$1:$1048576,5,0) -> 0 | P10: =VLOOKUP($A10,'HALF YEARLY'!$1:$1048576,5,0) -> 0 | Q10: =SUM(M10:P10) -> 0 | R10: =IFERROR(ROUND(VLOOKUP($A10,'UT-I '!$1:$1048576,6,0)/2,0),VLOOKUP($A10,'UT-I '!$1:$1048576,6,0)) -> 0 | S10: =VLOOKUP($A10,'NOTEBOOK-1 (Entry)'!$1:$1048576,6,0) -> 0 | T10: =VLOOKUP($A10,'ENRICH-1(Entry)'!$1:$1048576,6,0) -> 0 | U10: =VLOOKUP($A10,'HALF YEARLY'!$1:$1048576,6,0) -> 0 | V10: =SUM(R10:U10) -> 0 | W10: =IFERROR(ROUND(VLOOKUP($A10,'UT-I '!$1:$1048576,7,0)/2,0),VLOOKUP($A10,'UT-I '!$1:$1048576,7,0)) -> 0 | X10: =VLOOKUP($A10,'NOTEBOOK-1 (Entry)'!$1:$1048576,7,0) -> 0 | Y10: =VLOOKUP($A10,'ENRICH-1(Entry)'!$1:$1048576,7,0) -> 0 | Z10: =VLOOKUP($A10,'HALF YEARLY'!$1:$1048576,7,0) -> 0 | AA10: =SUM(W10:Z10) -> 0 | AB10: =VLOOKUP($A10,'HALF YEARLY'!$1:$1048576,8,0) -> 0 | AC10: =VLOOKUP($A10,'HALF YEARLY'!$1:$1048576,9,0) -> E | AD10: =VLOOKUP($A10,'HALF YEARLY'!$1:$1048576,10,0) -> E | AE10: =VLOOKUP($A10,'HALF YEARLY'!$1:$1048576,11,0) -> 0 | AF10: =VLOOKUP($A10,'HALF YEARLY'!$1:$1048576,12,0) -> 0 | AG10: =VLOOKUP($A10,'HALF YEARLY'!$1:$1048576,13,0) -> 0 | AH10: =VLOOKUP($A10,'HALF YEARLY'!$1:$1048576,14,0) -> 0 | AI10: =VLOOKUP($A10,'HALF YEARLY'!$1:$1048576,15,0) -> 0
A11: =DETAILS!A10 -> 1915 | B11: =DETAILS!B10 -> AKRITI SHUKLA | C11: =IFERROR(ROUND(VLOOKUP($A11,'UT-I '!$1:$1048576,3,0)/2,0),VLOOKUP($A11,'UT-I '!$1:$1048576,3,0)) -> 0 | D11: =VLOOKUP($A11,'NOTEBOOK-1 (Entry)'!$1:$1048576,3,0) -> 0 | E11: =VLOOKUP($A11,'ENRICH-1(Entry)'!$1:$1048576,3,0) -> 0 | F11: =VLOOKUP(A11,'HALF YEARLY'!$1:$1048576,3,0) -> 0 | G11: =SUM(C11:F11) -> 0 | H11: =IFERROR(ROUND(VLOOKUP($A11,'UT-I '!$1:$1048576,4,0)/2,0),VLOOKUP($A11,'UT-I '!$1:$1048576,4,0)) -> 0 | I11: =VLOOKUP($A11,'NOTEBOOK-1 (Entry)'!$1:$1048576,4,0) -> 0 | J11: =VLOOKUP($A11,'ENRICH-1(Entry)'!$1:$1048576,4,0) -> 0 | K11: =VLOOKUP($A11,'HALF YEARLY'!$1:$1048576,4,0) -> 0 | L11: =SUM(H11:K11) -> 0 | M11: =IFERROR(ROUND(VLOOKUP($A11,'UT-I '!$1:$1048576,5,0)/2,0),VLOOKUP($A11,'UT-I '!$1:$1048576,5,0)) -> 0 | N11: =VLOOKUP($A11,'NOTEBOOK-1 (Entry)'!$1:$1048576,5,0) -> 0 | O11: =VLOOKUP($A11,'ENRICH-1(Entry)'!$1:$1048576,5,0) -> 0 | P11: =VLOOKUP($A11,'HALF YEARLY'!$1:$1048576,5,0) -> 0 | Q11: =SUM(M11:P11) -> 0 | R11: =IFERROR(ROUND(VLOOKUP($A11,'UT-I '!$1:$1048576,6,0)/2,0),VLOOKUP($A11,'UT-I '!$1:$1048576,6,0)) -> 0 | S11: =VLOOKUP($A11,'NOTEBOOK-1 (Entry)'!$1:$1048576,6,0) -> 0 | T11: =VLOOKUP($A11,'ENRICH-1(Entry)'!$1:$1048576,6,0) -> 0 | U11: =VLOOKUP($A11,'HALF YEARLY'!$1:$1048576,6,0) -> 0 | V11: =SUM(R11:U11) -> 0 | W11: =IFERROR(ROUND(VLOOKUP($A11,'UT-I '!$1:$1048576,7,0)/2,0),VLOOKUP($A11,'UT-I '!$1:$1048576,7,0)) -> 0 | X11: =VLOOKUP($A11,'NOTEBOOK-1 (Entry)'!$1:$1048576,7,0) -> 0 | Y11: =VLOOKUP($A11,'ENRICH-1(Entry)'!$1:$1048576,7,0) -> 0 | Z11: =VLOOKUP($A11,'HALF YEARLY'!$1:$1048576,7,0) -> 0 | AA11: =SUM(W11:Z11) -> 0 | AB11: =VLOOKUP($A11,'HALF YEARLY'!$1:$1048576,8,0) -> 0 | AC11: =VLOOKUP($A11,'HALF YEARLY'!$1:$1048576,9,0) -> E | AD11: =VLOOKUP($A11,'HALF YEARLY'!$1:$1048576,10,0) -> E | AE11: =VLOOKUP($A11,'HALF YEARLY'!$1:$1048576,11,0) -> 0 | AF11: =VLOOKUP($A11,'HALF YEARLY'!$1:$1048576,12,0) -> 0 | AG11: =VLOOKUP($A11,'HALF YEARLY'!$1:$1048576,13,0) -> 0 | AH11: =VLOOKUP($A11,'HALF YEARLY'!$1:$1048576,14,0) -> 0 | AI11: =VLOOKUP($A11,'HALF YEARLY'!$1:$1048576,15,0) -> 0
