Workbook

Sheet DETAILS
A1: STUDENT'S DETAIL
A2: SR NO | B2: NAME | C2: MOTHER'S NAME | D2: FATHER'S NAME | E2: DOB | F2: CLASS & SEC
A3: 1887 | B3: ABHINAV YADAV | C3: NEELAM DEVI | D3: AMBRESH YADAV | E3: 20.08.2010 | F3: IX-B
A4: 1926 | B4: ADITYA KUMAR | C4: PUSHPA DEVI | D4: SANJAY KUMAR | E4: 20.02.2011 | F4: IX-B
A5: 1841 | B5: ANSHIKA THAKUR | C5: LALITA SINGH | D5: VISHWANATH PRATAP SINGH | E5: 23.11.2011 | F5: IX-B
A6: 1724 | B6: ANSHIKA YADAV | C6: SANJAY YADAV | D6: UMESH CHANDRA | E6: 16.06.2011 | F6: IX-B
A7: 1112 | B7: AQSA BANO | C7: RESHMA BANO | D7: MOHD. ATEEQ | E7: 28.07.2011 | F7: IX-B
A8: 1830 | B8: ATHARVA SHARMA | C8: NEETU SHARMA | D8: SANDEEP SHARMA | E8: 20.08.2011 | F8: IX-B
A9: 1516 | B9: AYUB KHAN | C9: SHABANA BEGUM | D9: GABBAR KHAN | E9: 20.03.2011 | F9: IX-B
A10: 1109 | B10: AYUSH MISHRA | C10: JULI MISHRA | D10: SURYAKANT MISHRA | E10: 08.12.2010 | F10: IX-B
A11: 1951 | B11: AYUSHI YADAV | C11: RANJU DEVI | D11: SANTOSH KUMAR YADAV | E11: 01.01.2011 | F11: IX-B
A12: 1863 | B12: BARIRA KHAN | C12: TANVEER | D12: MOHD. ILIYAS | E12: 14.04.2011 | F12: IX-B
A13: 899 | B13: DEEPANSHU MEENA | C13: MAMTA DEVI | D13: HARIRAM MEENA | E13: 04.07.2010 | F13: IX-B
A14: 1924 | B14: DEVANSH SINGH | C14: ANEETA SINGH | D14: RANVIJAY SINGH | E14: 18.11.2012 | F14: IX-B
... A31: 1778 | B31: YUSRA SHARIQ | C31: SHAYMA SHARIQ | D31: LATE SHARIQ RASHEED | E31: 01.01.2011 | F31: IX-B

Sheet UT-I(Entry)
A1: UNIT TEST-I (2025-26) CLASS - IX-B
A2: SR. NO. | B2: NAME | C2: ENGLISH | D2: HINDI | E2: MATHS | F2: SCIENCE | G2: SOCIAL SCIENCE | H2: ARTIFICIAL INTELLIGENCE | I2: Attendance
I3: Present | J3: Working Day
A4: =DETAILS!A3 -> 1887 | B4: =DETAILS!B3 -> ABHINAV YADAV
A5: =DETAILS!A4 -> 1926 | B5: =DETAILS!B4 -> ADITYA KUMAR
A6: =DETAILS!A5 -> 1841 | B6: =DETAILS!B5 -> ANSHIKA THAKUR
A7: =DETAILS!A6 -> 1724 | B7: =DETAILS!B6 -> ANSHIKA YADAV
A8: =DETAILS!A7 -> 1112 | B8: =DETAILS!B7 -> AQSA BANO
A9: =DETAILS!A8 -> 1830 | B9: =DETAILS!B8 -> ATHARVA SHARMA
A10: =DETAILS!A9 -> 1516 | B10: =DETAILS!B9 -> AYUB KHAN
A11: =DETAILS!A10 -> 1109 | B11: =DETAILS!B10 -> AYUSH MISHRA
A12: =DETAILS!A11 -> 1951 | B12: =DETAILS!B11 -> AYUSHI YADAV
A13: =DETAILS!A12 -> 1863 | B13: =DETAILS!B12 -> BARIRA KHAN
A14: =DETAILS!A13 -> 899 | B14: =DETAILS!B13 -> DEEPANSHU MEENA
A15: =DETAILS!A14 -> 1924 | B15: =DETAILS!B14 -> DEVANSH SINGH
... A32: =DETAILS!A31 -> 1778 | B32: =DETAILS!B31 -> YUSRA SHARIQ

Sheet UT-I 
A1: UNIT TEST-I (2025-26) CLASS - IX-B
A2: SR. NO. | B2: NAME | C2: ENGLISH | D2: HINDI | E2: MATHS | F2: SCIENCE | G2: SOCIAL SCIENCE | H2: ARTIFICIAL INTELLIGENCE | I2: TOTAL | J2: PERCENTAGE | K2: Attendance
K3: Present | L3: Working Day
A4: =DETAILS!A3 -> 1887 | B4: =DETAILS!B3 -> ABHINAV YADAV | C4: =IFERROR(ROUND((VLOOKUP(A4,'UT-I(Entry)'!$1:$1048576,3,0))/2,0),VLOOKUP(A4,'UT-I(Entry)'!$1:$1048576,3,0)) -> 0 | D4: =IFERROR(ROUND((VLOOKUP(A4,'UT-I(Entry)'!$1:$1048576,4,0))/2,0),VLOOKUP(A4,'UT-I(Entry)'!$1:$1048576,4,0)) -> 0 | E4: =IFERROR(ROUND((VLOOKUP(A4,'UT-I(Entry)'!$1:$1048576,5,0))/2,0),VLOOKUP(A4,'UT-I(Entry)'!$1:$1048576,5,0)) -> 0 | F4: =IFERROR(ROUND((VLOOKUP(A4,'UT-I(Entry)'!$1:$1048576,6,0))/2,0),VLOOKUP(A4,'UT-I(Entry)'!$1:$1048576,6,0)) -> 0 | G4: =IFERROR(ROUND((VLOOKUP($A4,'UT-I(Entry)'!$1:$1048576,7,0))/2,0),VLOOKUP($A4,'UT-I(Entry)'!$1:$1048576,7,0)) -> 0 | H4: =IFERROR(ROUND((VLOOKUP($A4,'UT-I(Entry)'!$1:$1048576,8,0))/2,0),VLOOKUP($A4,'UT-I(Entry)'!$1:$1048576,8,0)) -> 0 | I4: =SUM(C4:H4) -> 0 | J4: =ROUND(I4/1.2,2)&" %" -> 0 % | K4: =VLOOKUP(A4,'UT-I(Entry)'!$1:$1048576,10,0) -> 0 | L4: =VLOOKUP(A4,'UT-I(Entry)'!$1:$1048576,11,0) -> 0
A5: =DETAILS!A4 -> 1926 | B5: =DETAILS!B4 -> ADITYA KUMAR | C5: =IFERROR(ROUND((VLOOKUP(A5,'UT-I(Entry)'!$1:$1048576,3,0))/2,0),VLOOKUP(A5,'UT-I(Entry)'!$1:$1048576,3,0)) -> 0 | D5: =IFERROR(ROUND((VLOOKUP(A5,'UT-I(Entry)'!$1:$1048576,4,0))/2,0),VLOOKUP(A5,'UT-I(Entry)'!$1:$1048576,4,0)) -> 0 | E5: =IFERROR(ROUND((VLOOKUP(A5,'UT-I(Entry)'!$1:$1048576,5,0))/2,0),VLOOKUP(A5,'UT-I(Entry)'!$1:$1048576,5,0)) -> 0 | F5: =IFERROR(ROUND((VLOOKUP(A5,'UT-I(Entry)'!$1:$1048576,6,0))/2,0),VLOOKUP(A5,'UT-I(Entry)'!$1:$1048576,6,0)) -> 0 | G5: =IFERROR(ROUND((VLOOKUP(A5,'UT-I(Entry)'!$1:$1048576,7,0))/2,0),VLOOKUP(A5,'UT-I(Entry)'!$1:$1048576,7,0)) -> 0 | H5: =IFERROR(ROUND((VLOOKUP($A5,'UT-I(Entry)'!$1:$1048576,8,0))/2,0),VLOOKUP($A5,'UT-I(Entry)'!$1:$1048576,8,0)) -> 0 | I5: =SUM(C5:H5) -> 0 | J5: =ROUND(I5/1.2,2)&" %" -> 0 % | K5: =VLOOKUP(A5,'UT-I(Entry)'!$1:$1048576,10,0) -> 0 | L5: =VLOOKUP(A5,'UT-I(Entry)'!$1:$1048576,11,0) -> 0
A6: =DETAILS!A5 -> 1841 | B6: =DETAILS!B5 -> ANSHIKA THAKUR | C6: =IFERROR(ROUND((VLOOKUP(A6,'UT-I(Entry)'!$1:$1048576,3,0))/2,0),VLOOKUP(A6,'UT-I(Entry)'!$1:$1048576,3,0)) -> 0 | D6: =IFERROR(ROUND((VLOOKUP(A6,'UT-I(Entry)'!$1:$1048576,4,0))/2,0),VLOOKUP(A6,'UT-I(Entry)'!$1:$1048576,4,0)) -> 0 | E6: =IFERROR(ROUND((VLOOKUP(A6,'UT-I(Entry)'!$1:$1048576,5,0))/2,0),VLOOKUP(A6,'UT-I(Entry)'!$1:$1048576,5,0)) -> 0 | F6: =IFERROR(ROUND((VLOOKUP(A6,'UT-I(Entry)'!$1:$1048576,6,0))/2,0),VLOOKUP(A6,'UT-I(Entry)'!$1:$1048576,6,0)) -> 0 | G6: =IFERROR(ROUND((VLOOKUP(A6,'UT-I(Entry)'!$1:$1048576,7,0))/2,0),VLOOKUP(A6,'UT-I(Entry)'!$1:$1048576,7,0)) -> 0 | H6: =IFERROR(ROUND((VLOOKUP($A6,'UT-I(Entry)'!$1:$1048576,8,0))/2,0),VLOOKUP($A6,'UT-I(Entry)'!$1:$1048576,8,0)) -> 0 | I6: =SUM(C6:H6) -> 0 | J6: =ROUND(I6/1.2,2)&" %" -> 0 % | K6: =VLOOKUP(A6,'UT-I(Entry)'!$1:$1048576,10,0) -> 0 | L6: =VLOOKUP(A6,'UT-I(Entry)'!$1:$1048576,11,0) -> 0
A7: =DETAILS!A6 -> 1724 | B7: =DETAILS!B6 -> ANSHIKA YADAV | C7: =IFERROR(ROUND((VLOOKUP(A7,'UT-I(Entry)'!$1:$1048576,3,0))/2,0),VLOOKUP(A7,'UT-I(Entry)'!$1:$1048576,3,0)) -> 0 | D7: =IFERROR(ROUND((VLOOKUP(A7,'UT-I(Entry)'!$1:$1048576,4,0))/2,0),VLOOKUP(A7,'UT-I(Entry)'!$1:$1048576,4,0)) -> 0 | E7: =IFERROR(ROUND((VLOOKUP(A7,'UT-I(Entry)'!$1:$1048576,5,0))/2,0),VLOOKUP(A7,'UT-I(Entry)'!$1:$1048576,5,0)) -> 0 | F7: =IFERROR(ROUND((VLOOKUP(A7,'UT-I(Entry)'!$1:$1048576,6,0))/2,0),VLOOKUP(A7,'UT-I(Entry)'!$1:$1048576,6,0)) -> 0 | G7: =IFERROR(ROUND((VLOOKUP(A7,'UT-I(Entry)'!$1:$1048576,7,0))/2,0),VLOOKUP(A7,'UT-I(Entry)'!$1:$1048576,7,0)) -> 0 | H7: =IFERROR(ROUND((VLOOKUP($A7,'UT-I(Entry)'!$1:$1048576,8,0))/2,0),VLOOKUP($A7,'UT-I(Entry)'!$1:$1048576,8,0)) -> 0 | I7: =SUM(C7:H7) -> 0 | J7: =ROUND(I7/1.2,2)&" %" -> 0 % | K7: =VLOOKUP(A7,'UT-I(Entry)'!$1:$1048576,10,0) -> 0 | L7: =VLOOKUP(A7,'UT-I(Entry)'!$1:$1048576,11,0) -> 0
A8: =DETAILS!A7 -> 1112 | B8: =DETAILS!B7 -> AQSA BANO | C8: =IFERROR(ROUND((VLOOKUP(A8,'UT-I(Entry)'!$1:$1048576,3,0))/2,0),VLOOKUP(A8,'UT-I(Entry)'!$1:$1048576,3,0)) -> 0 | D8: =IFERROR(ROUND((VLOOKUP(A8,'UT-I(Entry)'!$1:$1048576,4,0))/2,0),VLOOKUP(A8,'UT-I(Entry)'!$1:$1048576,4,0)) -> 0 | E8: =IFERROR(ROUND((VLOOKUP(A8,'UT-I(Entry)'!$1:$1048576,5,0))/2,0),VLOOKUP(A8,'UT-I(Entry)'!$1:$1048576,5,0)) -> 0 | F8: =IFERROR(ROUND((VLOOKUP(A8,'UT-I(Entry)'!$1:$1048576,6,0))/2,0),VLOOKUP(A8,'UT-I(Entry)'!$1:$1048576,6,0)) -> 0 | G8: =IFERROR(ROUND((VLOOKUP(A8,'UT-I(Entry)'!$1:$1048576,7,0))/2,0),VLOOKUP(A8,'UT-I(Entry)'!$1:$1048576,7,0)) -> 0 | H8: =IFERROR(ROUND((VLOOKUP($A8,'UT-I(Entry)'!$1:$1048576,8,0))/2,0),VLOOKUP($A8,'UT-I(Entry)'!$1:$1048576,8,0)) -> 0 | I8: =SUM(C8:H8) -> 0 | J8: =ROUND(I8/1.2,2)&" %" -> 0 % | K8: =VLOOKUP(A8,'UT-I(Entry)'!$1:$1048576,10,0) -> 0 | L8: =VLOOKUP(A8,'UT-I(Entry)'!$1:$1048576,11,0) -> 0
A9: =DETAILS!A8 -> 1830 | B9: =DETAILS!B8 -> ATHARVA SHARMA | C9: =IFERROR(ROUND((VLOOKUP(A9,'UT-I(Entry)'!$1:$1048576,3,0))/2,0),VLOOKUP(A9,'UT-I(Entry)'!$1:$1048576,3,0)) -> 0 | D9: =IFERROR(ROUND((VLOOKUP(A9,'UT-I(Entry)'!$1:$1048576,4,0))/2,0),VLOOKUP(A9,'UT-I(Entry)'!$1:$1048576,4,0)) -> 0 | E9: =IFERROR(ROUND((VLOOKUP(A9,'UT-I(Entry)'!$1:$1048576,5,0))/2,0),VLOOKUP(A9,'UT-I(Entry)'!$1:$1048576,5,0)) -> 0 | F9: =IFERROR(ROUND((VLOOKUP(A9,'UT-I(Entry)'!$1:$1048576,6,0))/2,0),VLOOKUP(A9,'UT-I(Entry)'!$1:$1048576,6,0)) -> 0 | G9: =IFERROR(ROUND((VLOOKUP(A9,'UT-I(Entry)'!$1:$1048576,7,0))/2,0),VLOOKUP(A9,'UT-I(Entry)'!$1:$1048576,7,0)) -> 0 | H9: =IFERROR(ROUND((VLOOKUP($A9,'UT-I(Entry)'!$1:$1048576,8,0))/2,0),VLOOKUP($A9,'UT-I(Entry)'!$1:$1048576,8,0)) -> 0 | I9: =SUM(C9:H9) -> 0 | J9: =ROUND(I9/1.2,2)&" %" -> 0 % | K9: =VLOOKUP(A9,'UT-I(Entry)'!$1:$1048576,10,0) -> 0 | L9: =VLOOKUP(A9,'UT-I(Entry)'!$1:$1048576,11,0) -> 0
A10: =DETAILS!A9 -> 1516 | B10: =DETAILS!B9 -> AYUB KHAN | C10: =IFERROR(ROUND((VLOOKUP(A10,'UT-I(Entry)'!$1:$1048576,3,0))/2,0),VLOOKUP(A10,'UT-I(Entry)'!$1:$1048576,3,0)) -> 0 | D10: =IFERROR(ROUND((VLOOKUP(A10,'UT-I(Entry)'!$1:$1048576,4,0))/2,0),VLOOKUP(A10,'UT-I(Entry)'!$1:$1048576,4,0)) -> 0 | E10: =IFERROR(ROUND((VLOOKUP(A10,'UT-I(Entry)'!$1:$1048576,5,0))/2,0),VLOOKUP(A10,'UT-I(Entry)'!$1:$1048576,5,0)) -> 0 | F10: =IFERROR(ROUND((VLOOKUP(A10,'UT-I(Entry)'!$1:$1048576,6,0))/2,0),VLOOKUP(A10,'UT-I(Entry)'!$1:$1048576,6,0)) -> 0 | G10: =IFERROR(ROUND((VLOOKUP(A10,'UT-I(Entry)'!$1:$1048576,7,0))/2,0),VLOOKUP(A10,'UT-I(Entry)'!$1:$1048576,7,0)) -> 0 | H10: =IFERROR(ROUND((VLOOKUP($A10,'UT-I(Entry)'!$1:$1048576,8,0))/2,0),VLOOKUP($A10,'UT-I(Entry)'!$1:$1048576,8,0)) -> 0 | I10: =SUM(C10:H10) -> 0 | J10: =ROUND(I10/1.2,2)&" %" -> 0 % | K10: =VLOOKUP(A10,'UT-I(Entry)'!$1:$1048576,10,0) -> 0 | L10: =VLOOKUP(A10,'UT-I(Entry)'!$1:$1048576,11,0) -> 0
A11: =DETAILS!A10 -> 1109 | B11: =DETAILS!B10 -> AYUSH MISHRA | C11: =IFERROR(ROUND((VLOOKUP(A11,'UT-I(Entry)'!$1:$1048576,3,0))/2,0),VLOOKUP(A11,'UT-I(Entry)'!$1:$1048576,3,0)) -> 0 | D11: =IFERROR(ROUND((VLOOKUP(A11,'UT-I(Entry)'!$1:$1048576,4,0))/2,0),VLOOKUP(A11,'UT-I(Entry)'!$1:$1048576,4,0)) -> 0 | E11: =IFERROR(ROUND((VLOOKUP(A11,'UT-I(Entry)'!$1:$1048576,5,0))/2,0),VLOOKUP(A11,'UT-I(Entry)'!$1:$1048576,5,0)) -> 0 | F11: =IFERROR(ROUND((VLOOKUP(A11,'UT-I(Entry)'!$1:$1048576,6,0))/2,0),VLOOKUP(A11,'UT-I(Entry)'!$1:$1048576,6,0)) -> 0 | G11: =IFERROR(ROUND((VLOOKUP(A11,'UT-I(Entry)'!$1:$1048576,7,0))/2,0),VLOOKUP(A11,'UT-I(Entry)'!$1:$1048576,7,0)) -> 0 | H11: =IFERROR(ROUND((VLOOKUP($A11,'UT-I(Entry)'!$1:$1048576,8,0))/2,0),VLOOKUP($A11,'UT-I(Entry)'!$1:$1048576,8,0)) -> 0 | I11: =SUM(C11:H11) -> 0 | J11: =ROUND(I11/1.2,2)&" %" -> 0 % | K11: =VLOOKUP(A11,'UT-I(Entry)'!$1:$1048576,10,0) -> 0 | L11: =VLOOKUP(A11,'UT-I(Entry)'!$1:$1048576,11,0) -> 0
A12: =DETAILS!A11 -> 1951 | B12: =DETAILS!B11 -> AYUSHI YADAV | C12: =IFERROR(ROUND((VLOOKUP(A12,'UT-I(Entry)'!$1:$1048576,3,0))/2,0),VLOOKUP(A12,'UT-I(Entry)'!$1:$1048576,3,0)) -> 0 | D12: =IFERROR(ROUND((VLOOKUP(A12,'UT-I(Entry)'!$1:$1048576,4,0))/2,0),VLOOKUP(A12,'UT-I(Entry)'!$1:$1048576,4,0)) -> 0 | E12: =IFERROR(ROUND((VLOOKUP(A12,'UT-I(Entry)'!$1:$1048576,5,0))/2,0),VLOOKUP(A12,'UT-I(Entry)'!$1:$1048576,5,0)) -> 0 | F12: =IFERROR(ROUND((VLOOKUP(A12,'UT-I(Entry)'!$1:$1048576,6,0))/2,0),VLOOKUP(A12,'UT-I(Entry)'!$1:$1048576,6,0)) -> 0 | G12: =IFERROR(ROUND((VLOOKUP(A12,'UT-I(Entry)'!$1:$1048576,7,0))/2,0),VLOOKUP(A12,'UT-I(Entry)'!$1:$1048576,7,0)) -> 0 | H12: =IFERROR(ROUND((VLOOKUP($A12,'UT-I(Entry)'!$1:$1048576,8,0))/2,0),VLOOKUP($A12,'UT-I(Entry)'!$1:$1048576,8,0)) -> 0 | I12: =SUM(C12:H12) -> 0 | J12: =ROUND(I12/1.2,2)&" %" -> 0 % | K12: =VLOOKUP(A12,'UT-I(Entry)'!$1:$1048576,10,0) -> 0 | L12: =VLOOKUP(A12,'UT-I(Entry)'!$1:$1048576,11,0) -> 0
A13: =DETAILS!A12 -> 1863 | B13: =DETAILS!B12 -> BARIRA KHAN | C13: =IFERROR(ROUND((VLOOKUP(A13,'UT-I(Entry)'!$1:$1048576,3,0))/2,0),VLOOKUP(A13,'UT-I(Entry)'!$1:$1048576,3,0)) -> 0 | D13: =IFERROR(ROUND((VLOOKUP(A13,'UT-I(Entry)'!$1:$1048576,4,0))/2,0),VLOOKUP(A13,'UT-I(Entry)'!$1:$1048576,4,0)) -> 0 | E13: =IFERROR(ROUND((VLOOKUP(A13,'UT-I(Entry)'!$1:$1048576,5,0))/2,0),VLOOKUP(A13,'UT-I(Entry)'!$1:$1048576,5,0)) -> 0 | F13: =IFERROR(ROUND((VLOOKUP(A13,'UT-I(Entry)'!$1:$1048576,6,0))/2,0),VLOOKUP(A13,'UT-I(Entry)'!$1:$1048576,6,0)) -> 0 | G13: =IFERROR(ROUND((VLOOKUP(A13,'UT-I(Entry)'!$1:$1048576,7,0))/2,0),VLOOKUP(A13,'UT-I(Entry)'!$1:$1048576,7,0)) -> 0 | H13: =IFERROR(ROUND((VLOOKUP($A13,'UT-I(Entry)'!$1:$1048576,8,0))/2,0),VLOOKUP($A13,'UT-I(Entry)'!$1:$1048576,8,0)) -> 0 | I13: =SUM(C13:H13) -> 0 | J13: =ROUND(I13/1.2,2)&" %" -> 0 % | K13: =VLOOKUP(A13,'UT-I(Entry)'!$1:$1048576,10,0) -> 0 | L13: =VLOOKUP(A13,'UT-I(Entry)'!$1:$1048576,11,0) -> 0
A14: =DETAILS!A13 -> 899 | B14: =DETAILS!B13 -> DEEPANSHU MEENA | C14: =IFERROR(ROUND((VLOOKUP(A14,'UT-I(Entry)'!$1:$1048576,3,0))/2,0),VLOOKUP(A14,'UT-I(Entry)'!$1:$1048576,3,0)) -> 0 | D14: =IFERROR(ROUND((VLOOKUP(A14,'UT-I(Entry)'!$1:$1048576,4,0))/2,0),VLOOKUP(A14,'UT-I(Entry)'!$1:$1048576,4,0)) -> 0 | E14: =IFERROR(ROUND((VLOOKUP(A14,'UT-I(Entry)'!$1:$1048576,5,0))/2,0),VLOOKUP(A14,'UT-I(Entry)'!$1:$1048576,5,0)) -> 0 | F14: =IFERROR(ROUND((VLOOKUP(A14,'UT-I(Entry)'!$1:$1048576,6,0))/2,0),VLOOKUP(A14,'UT-I(Entry)'!$1:$1048576,6,0)) -> 0 | G14: =IFERROR(ROUND((VLOOKUP(A14,'UT-I(Entry)'!$1:$1048576,7,0))/2,0),VLOOKUP(A14,'UT-I(Entry)'!$1:$1048576,7,0)) -> 0 | H14: =IFERROR(ROUND((VLOOKUP($A14,'UT-I(Entry)'!$1:$1048576,8,0))/2,0),VLOOKUP($A14,'UT-I(Entry)'!$1:$1048576,8,0)) -> 0 | I14: =SUM(C14:H14) -> 0 | J14: =ROUND(I14/1.2,2)&" %" -> 0 % | K14: =VLOOKUP(A14,'UT-I(Entry)'!$1:$1048576,10,0) -> 0 | L14: =VLOOKUP(A14,'UT-I(Entry)'!$1:$1048576,11,0) -> 0
A15: =DETAILS!A14 -> 1924 | B15: =DETAILS!B14 -> DEVANSH SINGH | C15: =IFERROR(ROUND((VLOOKUP(A15,'UT-I(Entry)'!$1:$1048576,3,0))/2,0),VLOOKUP(A15,'UT-I(Entry)'!$1:$1048576,3,0)) -> 0 | D15: =IFERROR(ROUND((VLOOKUP(A15,'UT-I(Entry)'!$1:$1048576,4,0))/2,0),VLOOKUP(A15,'UT-I(Entry)'!$1:$1048576,4,0)) -> 0 | E15: =IFERROR(ROUND((VLOOKUP(A15,'UT-I(Entry)'!$1:$1048576,5,0))/2,0),VLOOKUP(A15,'UT-I(Entry)'!$1:$1048576,5,0)) -> 0 | F15: =IFERROR(ROUND((VLOOKUP(A15,'UT-I(Entry)'!$1:$1048576,6,0))/2,0),VLOOKUP(A15,'UT-I(Entry)'!$1:$1048576,6,0)) -> 0 | G15: =IFERROR(ROUND((VLOOKUP(A15,'UT-I(Entry)'!$1:$1048576,7,0))/2,0),VLOOKUP(A15,'UT-I(Entry)'!$1:$1048576,7,0)) -> 0 | H15: =IFERROR(ROUND((VLOOKUP($A15,'UT-I(Entry)'!$1:$1048576,8,0))/2,0),VLOOKUP($A15,'UT-I(Entry)'!$1:$1048576,8,0)) -> 0 | I15: =SUM(C15:H15) -> 0 | J15: =ROUND(I15/1.2,2)&" %" -> 0 % | K15: =VLOOKUP(A15,'UT-I(Entry)'!$1:$1048576,10,0) -> 0 | L15: =VLOOKUP(A15,'UT-I(Entry)'!$1:$1048576,11,0) -> 0
A16: =DETAILS!A15 -> 900 | B16: =DETAILS!B15 -> DIVYANSH MISHRA | C16: =IFERROR(ROUND((VLOOKUP(A16,'UT-I(Entry)'!$1:$1048576,3,0))/2,0),VLOOKUP(A16,'UT-I(Entry)'!$1:$1048576,3,0)) -> 0 | D16: =IFERROR(ROUND((VLOOKUP(A16,'UT-I(Entry)'!$1:$1048576,4,0))/2,0),VLOOKUP(A16,'UT-I(Entry)'!$1:$1048576,4,0)) -> 0 | E16: =IFERROR(ROUND((VLOOKUP(A16,'UT-I(Entry)'!$1:$1048576,5,0))/2,0),VLOOKUP(A16,'UT-I(Entry)'!$1:$1048576,5,0)) -> 0 | F16: =IFERROR(ROUND((VLOOKUP(A16,'UT-I(Entry)'!$1:$1048576,6,0))/2,0),VLOOKUP(A16,'UT-I(Entry)'!$1:$1048576,6,0)) -> 0 | G16: =IFERROR(ROUND((VLOOKUP(A16,'UT-I(Entry)'!$1:$1048576,7,0))/2,0),VLOOKUP(A16,'UT-I(Entry)'!$1:$1048576,7,0)) -> 0 | H16: =IFERROR(ROUND((VLOOKUP($A16,'UT-I(Entry)'!$1:$1048576,8,0))/2,0),VLOOKUP($A16,'UT-I(Entry)'!$1:$1048576,8,0)) -> 0 | I16: =SUM(C16:H16) -> 0 | J16: =ROUND(I16/1.2,2)&" %" -> 0 % | K16: =VLOOKUP(A16,'UT-I(Entry)'!$1:$1048576,10,0) -> 0 | L16: =VLOOKUP(A16,'UT-I(Entry)'!$1:$1048576,11,0) -> 0
... A32: =DETAILS!A31 -> 1778 | B32: =DETAILS!B31 -> YUSRA SHARIQ | C32: =IFERROR(ROUND((VLOOKUP(A32,'UT-I(Entry)'!$1:$1048576,3,0))/2,0),VLOOKUP(A32,'UT-I(Entry)'!$1:$1048576,3,0)) -> 0 | D32: =IFERROR(ROUND((VLOOKUP(A32,'UT-I(Entry)'!$1:$1048576,4,0))/2,0),VLOOKUP(A32,'UT-I(Entry)'!$1:$1048576,4,0)) -> 0 | E32: =IFERROR(ROUND((VLOOKUP(A32,'UT-I(Entry)'!$1:$1048576,5,0))/2,0),VLOOKUP(A32,'UT-I(Entry)'!$1:$1048576,5,0)) -> 0 | F32: =IFERROR(ROUND((VLOOKUP(A32,'UT-I(Entry)'!$1:$1048576,6,0))/2,0),VLOOKUP(A32,'UT-I(Entry)'!$1:$1048576,6,0)) -> 0 | G32: =IFERROR(ROUND((VLOOKUP(A32,'UT-I(Entry)'!$1:$1048576,7,0))/2,0),VLOOKUP(A32,'UT-I(Entry)'!$1:$1048576,7,0)) -> 0 | H32: =IFERROR(ROUND((VLOOKUP($A32,'UT-I(Entry)'!$1:$1048576,8,0))/2,0),VLOOKUP($A32,'UT-I(Entry)'!$1:$1048576,8,0)) -> 0 | I32: =SUM(C32:H32) -> 0 | J32: =ROUND(I32/1.2,2)&" %" -> 0 % | K32: =VLOOKUP(A32,'UT-I(Entry)'!$1:$1048576,10,0) -> 0 | L32: =VLOOKUP(A32,'UT-I(Entry)'!$1:$1048576,11,0) -> 0

Sheet Grade(40)
A2: 40 | B2: A
A3: 39 | B3: A
A4: 38 | B4: A
A5: 37 | B5: A
A6: 36 | B6: A
A7: 35 | B7: A
A8: 34 | B8: A
A9: 33 | B9: A
A10: 32 | B10: B
A11: 31 | B11: B
A12: 30 | B12: B
A13: 29 | B13: B
... A42: 0 | B42: E

Sheet HALF YEARLY(Entry)
A1: HALF YEARLY EXAMINATION (2025-26) CLASS - IX-A
A2: SR. NO. | B2: NAME | C2: ENGLISH | D2: HINDI | E2: MATHS | F2: SCIENCE | G2: SOCIAL SCIENCE | H2: ARTIFICIAL INTELLIGENCE | I2: WORK EDUCATION | J2: ART EDUCATION | K2: HEALTH & PHYSICAL EDUCATION | L2: DISCIPLINE | M2: Total Present | N2: Total Working | O2: Class Teacher's Remark | P2: TOTAL | Q2: Percentage
A3: =DETAILS!A3 -> 1887 | B3: =DETAILS!B3 -> ABHINAV YADAV | P3: =SUM(C3:H3) -> 0 | Q3: =ROUND(P3/6,2)&" %" -> 0 %
A4: =DETAILS!A4 -> 1926 | B4: =DETAILS!B4 -> ADITYA KUMAR | P4: =SUM(C4:H4) -> 0 | Q4: =ROUND(P4/6,2)&" %" -> 0 %
A5: =DETAILS!A5 -> 1841 | B5: =DETAILS!B5 -> ANSHIKA THAKUR | P5: =SUM(C5:H5) -> 0 | Q5: =ROUND(P5/6,2)&" %" -> 0 %
A6: =DETAILS!A6 -> 1724 | B6: =DETAILS!B6 -> ANSHIKA YADAV | P6: =SUM(C6:H6) -> 0 | Q6: =ROUND(P6/6,2)&" %" -> 0 %
A7: =DETAILS!A7 -> 1112 | B7: =DETAILS!B7 -> AQSA BANO | P7: =SUM(C7:H7) -> 0 | Q7: =ROUND(P7/6,2)&" %" -> 0 %
A8: =DETAILS!A8 -> 1830 | B8: =DETAILS!B8 -> ATHARVA SHARMA | P8: =SUM(C8:H8) -> 0 | Q8: =ROUND(P8/6,2)&" %" -> 0 %
A9: =DETAILS!A9 -> 1516 | B9: =DETAILS!B9 -> AYUB KHAN | P9: =SUM(C9:H9) -> 0 | Q9: =ROUND(P9/6,2)&" %" -> 0 %
A10: =DETAILS!A10 -> 1109 | B10: =DETAILS!B10 -> AYUSH MISHRA | P10: =SUM(C10:H10) -> 0 | Q10: =ROUND(P10/6,2)&" %" -> 0 %
A11: =DETAILS!A11 -> 1951 | B11: =DETAILS!B11 -> AYUSHI YADAV | P11: =SUM(C11:H11) -> 0 | Q11: =ROUND(P11/6,2)&" %" -> 0 %
A12: =DETAILS!A12 -> 1863 | B12: =DETAILS!B12 -> BARIRA KHAN | P12: =SUM(C12:H12) -> 0 | Q12: =ROUND(P12/6,2)&" %" -> 0 %
A13: =DETAILS!A13 -> 899 | B13: =DETAILS!B13 -> DEEPANSHU MEENA | P13: =SUM(C13:H13) -> 0 | Q13: =ROUND(P13/6,2)&" %" -> 0 %
A14: =DETAILS!A14 -> 1924 | B14: =DETAILS!B14 -> DEVANSH SINGH | P14: =SUM(C14:H14) -> 0 | Q14: =ROUND(P14/6,2)&" %" -> 0 %
... A31: =DETAILS!A31 -> 1778 | B31: =DETAILS!B31 -> YUSRA SHARIQ | P31: =SUM(C31:H31) -> 0 | Q31: =ROUND(P31/6,2)&" %" -> 0 %
A32: =DETAILS!#REF! -> #REF! | B32: =DETAILS!#REF! -> #REF! | P32: =SUM(C32:H32) -> 0 | Q32: =ROUND(P32/6,2)&" %" -> 0 %
A33: =DETAILS!#REF! -> #REF! | B33: =DETAILS!#REF! -> #REF! | P33: =SUM(C33:H33) -> 0 | Q33: =ROUND(P33/6,2)&" %" -> 0 %
A34: =DETAILS!#REF! -> #REF! | B34: =DETAILS!#REF! -> #REF! | P34: =SUM(C34:H34) -> 0 | Q34: =ROUND(P34/6,2)&" %" -> 0 %
A35: =DETAILS!#REF! -> #REF! | B35: =DETAILS!#REF! -> #REF! | P35: =SUM(C35:H35) -> 0 | Q35: =ROUND(P35/6,2)&" %" -> 0 %
A36: =DETAILS!#REF! -> #REF! | B36: =DETAILS!#REF! -> #REF! | P36: =SUM(C36:H36) -> 0 | Q36: =ROUND(P36/6,2)&" %" -> 0 %
A37: =DETAILS!#REF! -> #REF! | B37: =DETAILS!#REF! -> #REF! | P37: =SUM(C37:H37) -> 0 | Q37: =ROUND(P37/6,2)&" %" -> 0 %
A38: =DETAILS!#REF! -> #REF! | B38: =DETAILS!#REF! -> #REF! | P38: =SUM(C38:H38) -> 0 | Q38: =ROUND(P38/6,2)&" %" -> 0 %
A39: =DETAILS!#REF! -> #REF! | B39: =DETAILS!#REF! -> #REF! | P39: =SUM(C39:H39) -> 0 | Q39: =ROUND(P39/6,2)&" %" -> 0 %
A40: =DETAILS!#REF! -> #REF! | B40: =DETAILS!#REF! -> #REF! | P40: =SUM(C40:H40) -> 0 | Q40: =ROUND(P40/6,2)&" %" -> 0 %
A41: =DETAILS!#REF! -> #REF! | B41: =DETAILS!#REF! -> #REF! | P41: =SUM(C41:H41) -> 0 | Q41: =ROUND(P41/6,2)&" %" -> 0 %

Sheet HALF YEARLY
A1: HALF YEARLY EXAMINATION (2025-26) CLASS - IX-A
A2: SR. NO. | B2: NAME | C2: ENGLISH | D2: HINDI | E2: MATHS | F2: SCIENCE | G2: SOCIAL SCIENCE | H2: ARTIFICIAL INTELLIGENCE | I2: WORK EDUCATION | J2: ART EDUCATION | K2: HEALTH & PHYSICAL EDUCATION | L2: DISCIPLINE | M2: Total Present | N2: Total Working | O2: Class Teacher's Remark | P2: TOTAL | Q2: Percentage
A3: =DETAILS!A3 -> 1887 | B3: =DETAILS!B3 -> ABHINAV YADAV | C3: =VLOOKUP($A3,'HALF YEARLY(Entry)'!$1:$1048576,3,0) -> 0 | D3: =VLOOKUP($A3,'HALF YEARLY(Entry)'!$1:$1048576,4,0) -> 0 | E3: =VLOOKUP($A3,'HALF YEARLY(Entry)'!$1:$1048576,5,0) -> 0 | F3: =VLOOKUP($A3,'HALF YEARLY(Entry)'!$1:$1048576,6,0) -> 0 | G3: =VLOOKUP($A3,'HALF YEARLY(Entry)'!$1:$1048576,7,0) -> 0 | H3: =VLOOKUP($A3,'HALF YEARLY(Entry)'!$1:$1048576,8,0) -> 0 | I3: =VLOOKUP($A3,'HALF YEARLY(Entry)'!$1:$1048576,9,0) -> 0 | J3: =VLOOKUP($A3,'HALF YEARLY(Entry)'!$1:$1048576,10,0) -> 0 | K3: =VLOOKUP($A3,'HALF YEARLY(Entry)'!$1:$1048576,11,0) -> 0 | L3: =VLOOKUP($A3,'HALF YEARLY(Entry)'!$1:$1048576,12,0) -> 0 | M3: =VLOOKUP($A3,'HALF YEARLY(Entry)'!$1:$1048576,13,0) -> 0 | N3: =VLOOKUP($A3,'HALF YEARLY(Entry)'!$1:$1048576,14,0) -> 0 | O3: =VLOOKUP($A3,'HALF YEARLY(Entry)'!$1:$1048576,15,0) -> 0 | P3: =SUM(C3:H3) -> 0 | Q3: =ROUND(P3/6,2)&" %" -> 0 %
A4: =DETAILS!A4 -> 1926 | B4: =DETAILS!B4 -> ADITYA KUMAR | C4: =VLOOKUP($A4,'HALF YEARLY(Entry)'!$1:$1048576,3,0) -> 0 | D4: =VLOOKUP($A4,'HALF YEARLY(Entry)'!$1:$1048576,4,0) -> 0 | E4: =VLOOKUP($A4,'HALF YEARLY(Entry)'!$1:$1048576,5,0) -> 0 | F4: =VLOOKUP($A4,'HALF YEARLY(Entry)'!$1:$1048576,6,0) -> 0 | G4: =VLOOKUP($A4,'HALF YEARLY(Entry)'!$1:$1048576,7,0) -> 0 | H4: =VLOOKUP($A4,'HALF YEARLY(Entry)'!$1:$1048576,8,0) -> 0 | I4: =VLOOKUP($A4,'HALF YEARLY(Entry)'!$1:$1048576,9,0) -> 0 | J4: =VLOOKUP($A4,'HALF YEARLY(Entry)'!$1:$1048576,10,0) -> 0 | K4: =VLOOKUP($A4,'HALF YEARLY(Entry)'!$1:$1048576,11,0) -> 0 | L4: =VLOOKUP($A4,'HALF YEARLY(Entry)'!$1:$1048576,12,0) -> 0 | M4: =VLOOKUP($A4,'HALF YEARLY(Entry)'!$1:$1048576,13,0) -> 0 | N4: =VLOOKUP($A4,'HALF YEARLY(Entry)'!$1:$1048576,14,0) -> 0 | O4: =VLOOKUP($A4,'HALF YEARLY(Entry)'!$1:$1048576,15,0) -> 0 | P4: =SUM(C4:H4) -> 0 | Q4: =ROUND(P4/6,2)&" %" -> 0 %
A5: =DETAILS!A5 -> 1841 | B5: =DETAILS!B5 -> ANSHIKA THAKUR | C5: =VLOOKUP($A5,'HALF YEARLY(Entry)'!$1:$1048576,3,0) -> 0 | D5: =VLOOKUP($A5,'HALF YEARLY(Entry)'!$1:$1048576,4,0) -> 0 | E5: =VLOOKUP($A5,'HALF YEARLY(Entry)'!$1:$1048576,5,0) -> 0 | F5: =VLOOKUP($A5,'HALF YEARLY(Entry)'!$1:$1048576,6,0) -> 0 | G5: =VLOOKUP($A5,'HALF YEARLY(Entry)'!$1:$1048576,7,0) -> 0 | H5: =VLOOKUP($A5,'HALF YEARLY(Entry)'!$1:$1048576,8,0) -> 0 | I5: =VLOOKUP($A5,'HALF YEARLY(Entry)'!$1:$1048576,9,0) -> 0 | J5: =VLOOKUP($A5,'HALF YEARLY(Entry)'!$1:$1048576,10,0) -> 0 | K5: =VLOOKUP($A5,'HALF YEARLY(Entry)'!$1:$1048576,11,0) -> 0 | L5: =VLOOKUP($A5,'HALF YEARLY(Entry)'!$1:$1048576,12,0) -> 0 | M5: =VLOOKUP($A5,'HALF YEARLY(Entry)'!$1:$1048576,13,0) -> 0 | N5: =VLOOKUP($A5,'HALF YEARLY(Entry)'!$1:$1048576,14,0) -> 0 | O5: =VLOOKUP($A5,'HALF YEARLY(Entry)'!$1:$1048576,15,0) -> 0 | P5: =SUM(C5:H5) -> 0 | Q5: =ROUND(P5/6,2)&" %" -> 0 %
A6: =DETAILS!A6 -> 1724 | B6: =DETAILS!B6 -> ANSHIKA YADAV | C6: =VLOOKUP($A6,'HALF YEARLY(Entry)'!$1:$1048576,3,0) -> 0 | D6: =VLOOKUP($A6,'HALF YEARLY(Entry)'!$1:$1048576,4,0) -> 0 | E6: =VLOOKUP($A6,'HALF YEARLY(Entry)'!$1:$1048576,5,0) -> 0 | F6: =VLOOKUP($A6,'HALF YEARLY(Entry)'!$1:$1048576,6,0) -> 0 | G6: =VLOOKUP($A6,'HALF YEARLY(Entry)'!$1:$1048576,7,0) -> 0 | H6: =VLOOKUP($A6,'HALF YEARLY(Entry)'!$1:$1048576,8,0) -> 0 | I6: =VLOOKUP($A6,'HALF YEARLY(Entry)'!$1:$1048576,9,0) -> 0 | J6: =VLOOKUP($A6,'HALF YEARLY(Entry)'!$1:$1048576,10,0) -> 0 | K6: =VLOOKUP($A6,'HALF YEARLY(Entry)'!$1:$1048576,11,0) -> 0 | L6: =VLOOKUP($A6,'HALF YEARLY(Entry)'!$1:$1048576,12,0) -> 0 | M6: =VLOOKUP($A6,'HALF YEARLY(Entry)'!$1:$1048576,13,0) -> 0 | N6: =VLOOKUP($A6,'HALF YEARLY(Entry)'!$1:$1048576,14,0) -> 0 | O6: =VLOOKUP($A6,'HALF YEARLY(Entry)'!$1:$1048576,15,0) -> 0 | P6: =SUM(C6:H6) -> 0 | Q6: =ROUND(P6/6,2)&" %" -> 0 %
A7: =DETAILS!A7 -> 1112 | B7: =DETAILS!B7 -> AQSA BANO | C7: =VLOOKUP($A7,'HALF YEARLY(Entry)'!$1:$1048576,3,0) -> 0 | D7: =VLOOKUP($A7,'HALF YEARLY(Entry)'!$1:$1048576,4,0) -> 0 | E7: =VLOOKUP($A7,'HALF YEARLY(Entry)'!$1:$1048576,5,0) -> 0 | F7: =VLOOKUP($A7,'HALF YEARLY(Entry)'!$1:$1048576,6,0) -> 0 | G7: =VLOOKUP($A7,'HALF YEARLY(Entry)'!$1:$1048576,7,0) -> 0 | H7: =VLOOKUP($A7,'HALF YEARLY(Entry)'!$1:$1048576,8,0) -> 0 | I7: =VLOOKUP($A7,'HALF YEARLY(Entry)'!$1:$1048576,9,0) -> 0 | J7: =VLOOKUP($A7,'HALF YEARLY(Entry)'!$1:$1048576,10,0) -> 0 | K7: =VLOOKUP($A7,'HALF YEARLY(Entry)'!$1:$1048576,11,0) -> 0 | L7: =VLOOKUP($A7,'HALF YEARLY(Entry)'!$1:$1048576,12,0) -> 0 | M7: =VLOOKUP($A7,'HALF YEARLY(Entry)'!$1:$1048576,13,0) -> 0 | N7: =VLOOKUP($A7,'HALF YEARLY(Entry)'!$1:$1048576,14,0) -> 0 | O7: =VLOOKUP($A7,'HALF YEARLY(Entry)'!$1:$1048576,15,0) -> 0 | P7: =SUM(C7:H7) -> 0 | Q7: =ROUND(P7/6,2)&" %" -> 0 %
A8: =DETAILS!A8 -> 1830 | B8: =DETAILS!B8 -> ATHARVA SHARMA | C8: =VLOOKUP($A8,'HALF YEARLY(Entry)'!$1:$1048576,3,0) -> 0 | D8: =VLOOKUP($A8,'HALF YEARLY(Entry)'!$1:$1048576,4,0) -> 0 | E8: =VLOOKUP($A8,'HALF YEARLY(Entry)'!$1:$1048576,5,0) -> 0 | F8: =VLOOKUP($A8,'HALF YEARLY(Entry)'!$1:$1048576,6,0) -> 0 | G8: =VLOOKUP($A8,'HALF YEARLY(Entry)'!$1:$1048576,7,0) -> 0 | H8: =VLOOKUP($A8,'HALF YEARLY(Entry)'!$1:$1048576,8,0) -> 0 | I8: =VLOOKUP($A8,'HALF YEARLY(Entry)'!$1:$1048576,9,0) -> 0 | J8: =VLOOKUP($A8,'HALF YEARLY(Entry)'!$1:$1048576,10,0) -> 0 | K8: =VLOOKUP($A8,'HALF YEARLY(Entry)'!$1:$1048576,11,0) -> 0 | L8: =VLOOKUP($A8,'HALF YEARLY(Entry)'!$1:$1048576,12,0) -> 0 | M8: =VLOOKUP($A8,'HALF YEARLY(Entry)'!$1:$1048576,13,0) -> 0 | N8: =VLOOKUP($A8,'HALF YEARLY(Entry)'!$1:$1048576,14,0) -> 0 | O8: =VLOOKUP($A8,'HALF YEARLY(Entry)'!$1:$1048576,15,0) -> 0 | P8: =SUM(C8:H8) -> 0 | Q8: =ROUND(P8/6,2)&" %" -> 0 %
A9: =DETAILS!A9 -> 1516 | B9: =DETAILS!B9 -> AYUB KHAN | C9: =VLOOKUP($A9,'HALF YEARLY(Entry)'!$1:$1048576,3,0) -> 0 | D9: =VLOOKUP($A9,'HALF YEARLY(Entry)'!$1:$1048576,4,0) -> 0 | E9: =VLOOKUP($A9,'HALF YEARLY(Entry)'!$1:$1048576,5,0) -> 0 | F9: =VLOOKUP($A9,'HALF YEARLY(Entry)'!$1:$1048576,6,0) -> 0 | G9: =VLOOKUP($A9,'HALF YEARLY(Entry)'!$1:$1048576,7,0) -> 0 | H9: =VLOOKUP($A9,'HALF YEARLY(Entry)'!$1:$1048576,8,0) -> 0 | I9: =VLOOKUP($A9,'HALF YEARLY(Entry)'!$1:$1048576,9,0) -> 0 | J9: =VLOOKUP($A9,'HALF YEARLY(Entry)'!$1:$1048576,10,0) -> 0 | K9: =VLOOKUP($A9,'HALF YEARLY(Entry)'!$1:$1048576,11,0) -> 0 | L9: =VLOOKUP($A9,'HALF YEARLY(Entry)'!$1:$1048576,12,0) -> 0 | M9: =VLOOKUP($A9,'HALF YEARLY(Entry)'!$1:$1048576,13,0) -> 0 | N9: =VLOOKUP($A9,'HALF YEARLY(Entry)'!$1:$1048576,14,0) -> 0 | O9: =VLOOKUP($A9,'HALF YEARLY(Entry)'!$1:$1048576,15,0) -> 0 | P9: =SUM(C9:H9) -> 0 | Q9: =ROUND(P9/6,2)&" %" -> 0 %
A10: =DETAILS!A10 -> 1109 | B10: =DETAILS!B10 -> AYUSH MISHRA | C10: =VLOOKUP($A10,'HALF YEARLY(Entry)'!$1:$1048576,3,0) -> 0 | D10: =VLOOKUP($A10,'HALF YEARLY(Entry)'!$1:$1048576,4,0) -> 0 | E10: =VLOOKUP($A10,'HALF YEARLY(Entry)'!$1:$1048576,5,0) -> 0 | F10: =VLOOKUP($A10,'HALF YEARLY(Entry)'!$1:$1048576,6,0) -> 0 | G10: =VLOOKUP($A10,'HALF YEARLY(Entry)'!$1:$1048576,7,0) -> 0 | H10: =VLOOKUP($A10,'HALF YEARLY(Entry)'!$1:$1048576,8,0) -> 0 | I10: =VLOOKUP($A10,'HALF YEARLY(Entry)'!$1:$1048576,9,0) -> 0 | J10: =VLOOKUP($A10,'HALF YEARLY(Entry)'!$1:$1048576,10,0) -> 0 | K10: =VLOOKUP($A10,'HALF YEARLY(Entry)'!$1:$1048576,11,0) -> 0 | L10: =VLOOKUP($A10,'HALF YEARLY(Entry)'!$1:$1048576,12,0) -> 0 | M10: =VLOOKUP($A10,'HALF YEARLY(Entry)'!$1:$1048576,13,0) -> 0 | N10: =VLOOKUP($A10,'HALF YEARLY(Entry)'!$1:$1048576,14,0) -> 0 | O10: =VLOOKUP($A10,'HALF YEARLY(Entry)'!$1:$1048576,15,0) -> 0 | P10: =SUM(C10:H10) -> 0 | Q10: =ROUND(P10/6,2)&" %" -> 0 %
A11: =DETAILS!A11 -> 1951 | B11: =DETAILS!B11 -> AYUSHI YADAV | C11: =VLOOKUP($A11,'HALF YEARLY(Entry)'!$1:$1048576,3,0) -> 0 | D11: =VLOOKUP($A11,'HALF YEARLY(Entry)'!$1:$1048576,4,0) -> 0 | E11: =VLOOKUP($A11,'HALF YEARLY(Entry)'!$1:$1048576,5,0) -> 0 | F11: =VLOOKUP($A11,'HALF YEARLY(Entry)'!$1:$1048576,6,0) -> 0 | G11: =VLOOKUP($A11,'HALF YEARLY(Entry)'!$1:$1048576,7,0) -> 0 | H11: =VLOOKUP($A11,'HALF YEARLY(Entry)'!$1:$1048576,8,0) -> 0 | I11: =VLOOKUP($A11,'HALF YEARLY(Entry)'!$1:$1048576,9,0) -> 0 | J11: =VLOOKUP($A11,'HALF YEARLY(Entry)'!$1:$1048576,10,0) -> 0 | K11: =VLOOKUP($A11,'HALF YEARLY(Entry)'!$1:$1048576,11,0) -> 0 | L11: =VLOOKUP($A11,'HALF YEARLY(Entry)'!$1:$1048576,12,0) -> 0 | M11: =VLOOKUP($A11,'HALF YEARLY(Entry)'!$1:$1048576,13,0) -> 0 | N11: =VLOOKUP($A11,'HALF YEARLY(Entry)'!$1:$1048576,14,0) -> 0 | O11: =VLOOKUP($A11,'HALF YEARLY(Entry)'!$1:$1048576,15,0) -> 0 | P11: =SUM(C11:H11) -> 0 | Q11: =ROUND(P11/6,2)&" %" -> 0 %
A12: =DETAILS!A12 -> 1863 | B12: =DETAILS!B12 -> BARIRA KHAN | C12: =VLOOKUP($A12,'HALF YEARLY(Entry)'!$1:$1048576,3,0) -> 0 | D12: =VLOOKUP($A12,'HALF YEARLY(Entry)'!$1:$1048576,4,0) -> 0 | E12: =VLOOKUP($A12,'HALF YEARLY(Entry)'!$1:$1048576,5,0) -> 0 | F12: =VLOOKUP($A12,'HALF YEARLY(Entry)'!$1:$1048576,6,0) -> 0 | G12: =VLOOKUP($A12,'HALF YEARLY(Entry)'!$1:$1048576,7,0) -> 0 | H12: =VLOOKUP($A12,'HALF YEARLY(Entry)'!$1:$1048576,8,0) -> 0 | I12: =VLOOKUP($A12,'HALF YEARLY(Entry)'!$1:$1048576,9,0) -> 0 | J12: =VLOOKUP($A12,'HALF YEARLY(Entry)'!$1:$1048576,10,0) -> 0 | K12: =VLOOKUP($A12,'HALF YEARLY(Entry)'!$1:$1048576,11,0) -> 0 | L12: =VLOOKUP($A12,'HALF YEARLY(Entry)'!$1:$1048576,12,0) -> 0 | M12: =VLOOKUP($A12,'HALF YEARLY(Entry)'!$1:$1048576,13,0) -> 0 | N12: =VLOOKUP($A12,'HALF YEARLY(Entry)'!$1:$1048576,14,0) -> 0 | O12: =VLOOKUP($A12,'HALF YEARLY(Entry)'!$1:$1048576,15,0) -> 0 | P12: =SUM(C12:H12) -> 0 | Q12: =ROUND(P12/6,2)&" %" -> 0 %
A13: =DETAILS!A13 -> 899 | B13: =DETAILS!B13 -> DEEPANSHU MEENA | C13: =VLOOKUP($A13,'HALF YEARLY(Entry)'!$1:$1048576,3,0) -> 0 | D13: =VLOOKUP($A13,'HALF YEARLY(Entry)'!$1:$1048576,4,0) -> 0 | E13: =VLOOKUP($A13,'HALF YEARLY(Entry)'!$1:$1048576,5,0) -> 0 | F13: =VLOOKUP($A13,'HALF YEARLY(Entry)'!$1:$1048576,6,0) -> 0 | G13: =VLOOKUP($A13,'HALF YEARLY(Entry)'!$1:$1048576,7,0) -> 0 | H13: =VLOOKUP($A13,'HALF YEARLY(Entry)'!$1:$1048576,8,0) -> 0 | I13: =VLOOKUP($A13,'HALF YEARLY(Entry)'!$1:$1048576,9,0) -> 0 | J13: =VLOOKUP($A13,'HALF YEARLY(Entry)'!$1:$1048576,10,0) -> 0 | K13: =VLOOKUP($A13,'HALF YEARLY(Entry)'!$1:$1048576,11,0) -> 0 | L13: =VLOOKUP($A13,'HALF YEARLY(Entry)'!$1:$1048576,12,0) -> 0 | M13: =VLOOKUP($A13,'HALF YEARLY(Entry)'!$1:$1048576,13,0) -> 0 | N13: =VLOOKUP($A13,'HALF YEARLY(Entry)'!$1:$1048576,14,0) -> 0 | O13: =VLOOKUP($A13,'HALF YEARLY(Entry)'!$1:$1048576,15,0) -> 0 | P13: =SUM(C13:H13) -> 0 | Q13: =ROUND(P13/6,2)&" %" -> 0 %
A14: =DETAILS!A14 -> 1924 | B14: =DETAILS!B14 -> DEVANSH SINGH | C14: =VLOOKUP($A14,'HALF YEARLY(Entry)'!$1:$1048576,3,0) -> 0 | D14: =VLOOKUP($A14,'HALF YEARLY(Entry)'!$1:$1048576,4,0) -> 0 | E14: =VLOOKUP($A14,'HALF YEARLY(Entry)'!$1:$1048576,5,0) -> 0 | F14: =VLOOKUP($A14,'HALF YEARLY(Entry)'!$1:$1048576,6,0) -> 0 | G14: =VLOOKUP($A14,'HALF YEARLY(Entry)'!$1:$1048576,7,0) -> 0 | H14: =VLOOKUP($A14,'HALF YEARLY(Entry)'!$1:$1048576,8,0) -> 0 | I14: =VLOOKUP($A14,'HALF YEARLY(Entry)'!$1:$1048576,9,0) -> 0 | J14: =VLOOKUP($A14,'HALF YEARLY(Entry)'!$1:$1048576,10,0) -> 0 | K14: =VLOOKUP($A14,'HALF YEARLY(Entry)'!$1:$1048576,11,0) -> 0 | L14: =VLOOKUP($A14,'HALF YEARLY(Entry)'!$1:$1048576,12,0) -> 0 | M14: =VLOOKUP($A14,'HALF YEARLY(Entry)'!$1:$1048576,13,0) -> 0 | N14: =VLOOKUP($A14,'HALF YEARLY(Entry)'!$1:$1048576,14,0) -> 0 | O14: =VLOOKUP($A14,'HALF YEARLY(Entry)'!$1:$1048576,15,0) -> 0 | P14: =SUM(C14:H14) -> 0 | Q14: =ROUND(P14/6,2)&" %" -> 0 %
... A31: =DETAILS!A31 -> 1778 | B31: =DETAILS!B31 -> YUSRA SHARIQ | C31: =VLOOKUP($A31,'HALF YEARLY(Entry)'!$1:$1048576,3,0) -> 0 | D31: =VLOOKUP($A31,'HALF YEARLY(Entry)'!$1:$1048576,4,0) -> 0 | E31: =VLOOKUP($A31,'HALF YEARLY(Entry)'!$1:$1048576,5,0) -> 0 | F31: =VLOOKUP($A31,'HALF YEARLY(Entry)'!$1:$1048576,6,0) -> 0 | G31: =VLOOKUP($A31,'HALF YEARLY(Entry)'!$1:$1048576,7,0) -> 0 | H31: =VLOOKUP($A31,'HALF YEARLY(Entry)'!$1:$1048576,8,0) -> 0 | I31: =VLOOKUP($A31,'HALF YEARLY(Entry)'!$1:$1048576,9,0) -> 0 | J31: =VLOOKUP($A31,'HALF YEARLY(Entry)'!$1:$1048576,10,0) -> 0 | K31: =VLOOKUP($A31,'HALF YEARLY(Entry)'!$1:$1048576,11,0) -> 0 | L31: =VLOOKUP($A31,'HALF YEARLY(Entry)'!$1:$1048576,12,0) -> 0 | M31: =VLOOKUP($A31,'HALF YEARLY(Entry)'!$1:$1048576,13,0) -> 0 | N31: =VLOOKUP($A31,'HALF YEARLY(Entry)'!$1:$1048576,14,0) -> 0 | O31: =VLOOKUP($A31,'HALF YEARLY(Entry)'!$1:$1048576,15,0) -> 0 | P31: =SUM(C31:H31) -> 0 | Q31: =ROUND(P31/6,2)&" %" -> 0 %
A32: =DETAILS!#REF! -> #REF! | B32: =DETAILS!#REF! -> #REF! | C32: =VLOOKUP($A32,'HALF YEARLY(Entry)'!$1:$1048576,3,0) -> #REF! | D32: =VLOOKUP($A32,'HALF YEARLY(Entry)'!$1:$1048576,4,0) -> #REF! | E32: =VLOOKUP($A32,'HALF YEARLY(Entry)'!$1:$1048576,5,0) -> #REF! | F32: =VLOOKUP($A32,'HALF YEARLY(Entry)'!$1:$1048576,6,0) -> #REF! | G32: =VLOOKUP($A32,'HALF YEARLY(Entry)'!$1:$1048576,7,0) -> #REF! | H32: =VLOOKUP($A32,'HALF YEARLY(Entry)'!$1:$1048576,8,0) -> #REF! | I32: =VLOOKUP($A32,'HALF YEARLY(Entry)'!$1:$1048576,9,0) -> #REF! | J32: =VLOOKUP($A32,'HALF YEARLY(Entry)'!$1:$1048576,10,0) -> #REF! | K32: =VLOOKUP($A32,'HALF YEARLY(Entry)'!$1:$1048576,11,0) -> #REF! | L32: =VLOOKUP($A32,'HALF YEARLY(Entry)'!$1:$1048576,12,0) -> #REF! | M32: =VLOOKUP($A32,'HALF YEARLY(Entry)'!$1:$1048576,13,0) -> #REF! | N32: =VLOOKUP($A32,'HALF YEARLY(Entry)'!$1:$1048576,14,0) -> #REF! | O32: =VLOOKUP($A32,'HALF YEARLY(Entry)'!$1:$1048576,15,0) -> #REF! | P32: =SUM(C32:H32) -> #REF! | Q32: =ROUND(P32/6,2)&" %" -> #REF!
A33: =DETAILS!#REF! -> #REF! | B33: =DETAILS!#REF! -> #REF! | C33: =VLOOKUP($A33,'HALF YEARLY(Entry)'!$1:$1048576,3,0) -> #REF! | D33: =VLOOKUP($A33,'HALF YEARLY(Entry)'!$1:$1048576,4,0) -> #REF! | E33: =VLOOKUP($A33,'HALF YEARLY(Entry)'!$1:$1048576,5,0) -> #REF! | F33: =VLOOKUP($A33,'HALF YEARLY(Entry)'!$1:$1048576,6,0) -> #REF! | G33: =VLOOKUP($A33,'HALF YEARLY(Entry)'!$1:$1048576,7,0) -> #REF! | H33: =VLOOKUP($A33,'HALF YEARLY(Entry)'!$1:$1048576,8,0) -> #REF! | I33: =VLOOKUP($A33,'HALF YEARLY(Entry)'!$1:$1048576,9,0) -> #REF! | J33: =VLOOKUP($A33,'HALF YEARLY(Entry)'!$1:$1048576,10,0) -> #REF! | K33: =VLOOKUP($A33,'HALF YEARLY(Entry)'!$1:$1048576,11,0) -> #REF! | L33: =VLOOKUP($A33,'HALF YEARLY(Entry)'!$1:$1048576,12,0) -> #REF! | M33: =VLOOKUP($A33,'HALF YEARLY(Entry)'!$1:$1048576,13,0) -> #REF! | N33: =VLOOKUP($A33,'HALF YEARLY(Entry)'!$1:$1048576,14,0) -> #REF! | O33: =VLOOKUP($A33,'HALF YEARLY(Entry)'!$1:$1048576,15,0) -> #REF! | P33: =SUM(C33:H33) -> #REF! | Q33: =ROUND(P33/6,2)&" %" -> #REF!
A34: =DETAILS!#REF! -> #REF! | B34: =DETAILS!#REF! -> #REF! | C34: =VLOOKUP($A34,'HALF YEARLY(Entry)'!$1:$1048576,3,0) -> #REF! | D34: =VLOOKUP($A34,'HALF YEARLY(Entry)'!$1:$1048576,4,0) -> #REF! | E34: =VLOOKUP($A34,'HALF YEARLY(Entry)'!$1:$1048576,5,0) -> #REF! | F34: =VLOOKUP($A34,'HALF YEARLY(Entry)'!$1:$1048576,6,0) -> #REF! | G34: =VLOOKUP($A34,'HALF YEARLY(Entry)'!$1:$1048576,7,0) -> #REF! | H34: =VLOOKUP($A34,'HALF YEARLY(Entry)'!$1:$1048576,8,0) -> #REF! | I34: =VLOOKUP($A34,'HALF YEARLY(Entry)'!$1:$1048576,9,0) -> #REF! | J34: =VLOOKUP($A34,'HALF YEARLY(Entry)'!$1:$1048576,10,0) -> #REF! | K34: =VLOOKUP($A34,'HALF YEARLY(Entry)'!$1:$1048576,11,0) -> #REF! | L34: =VLOOKUP($A34,'HALF YEARLY(Entry)'!$1:$1048576,12,0) -> #REF! | M34: =VLOOKUP($A34,'HALF YEARLY(Entry)'!$1:$1048576,13,0) -> #REF! | N34: =VLOOKUP($A34,'HALF YEARLY(Entry)'!$1:$1048576,14,0) -> #REF! | O34: =VLOOKUP($A34,'HALF YEARLY(Entry)'!$1:$1048576,15,0) -> #REF! | P34: =SUM(C34:H34) -> #REF! | Q34: =ROUND(P34/6,2)&" %" -> #REF!
A35: =DETAILS!#REF! -> #REF! | B35: =DETAILS!#REF! -> #REF! | C35: =VLOOKUP($A35,'HALF YEARLY(Entry)'!$1:$1048576,3,0) -> #REF! | D35: =VLOOKUP($A35,'HALF YEARLY(Entry)'!$1:$1048576,4,0) -> #REF! | E35: =VLOOKUP($A35,'HALF YEARLY(Entry)'!$1:$1048576,5,0) -> #REF! | F35: =VLOOKUP($A35,'HALF YEARLY(Entry)'!$1:$1048576,6,0) -> #REF! | G35: =VLOOKUP($A35,'HALF YEARLY(Entry)'!$1:$1048576,7,0) -> #REF! | H35: =VLOOKUP($A35,'HALF YEARLY(Entry)'!$1:$1048576,8,0) -> #REF! | I35: =VLOOKUP($A35,'HALF YEARLY(Entry)'!$1:$1048576,9,0) -> #REF! | J35: =VLOOKUP($A35,'HALF YEARLY(Entry)'!$1:$1048576,10,0) -> #REF! | K35: =VLOOKUP($A35,'HALF YEARLY(Entry)'!$1:$1048576,11,0) -> #REF! | L35: =VLOOKUP($A35,'HALF YEARLY(Entry)'!$1:$1048576,12,0) -> #REF! | M35: =VLOOKUP($A35,'HALF YEARLY(Entry)'!$1:$1048576,13,0) -> #REF! | N35: =VLOOKUP($A35,'HALF YEARLY(Entry)'!$1:$1048576,14,0) -> #REF! | O35: =VLOOKUP($A35,'HALF YEARLY(Entry)'!$1:$1048576,15,0) -> #REF! | P35: =SUM(C35:H35) -> #REF! | Q35: =ROUND(P35/6,2)&" %" -> #REF!
A36: =DETAILS!#REF! -> #REF! | B36: =DETAILS!#REF! -> #REF! | C36: =VLOOKUP($A36,'HALF YEARLY(Entry)'!$1:$1048576,3,0) -> #REF! | D36: =VLOOKUP($A36,'HALF YEARLY(Entry)'!$1:$1048576,4,0) -> #REF! | E36: =VLOOKUP($A36,'HALF YEARLY(Entry)'!$1:$1048576,5,0) -> #REF! | F36: =VLOOKUP($A36,'HALF YEARLY(Entry)'!$1:$1048576,6,0) -> #REF! | G36: =VLOOKUP($A36,'HALF YEARLY(Entry)'!$1:$1048576,7,0) -> #REF! | H36: =VLOOKUP($A36,'HALF YEARLY(Entry)'!$1:$1048576,8,0) -> #REF! | I36: =VLOOKUP($A36,'HALF YEARLY(Entry)'!$1:$1048576,9,0) -> #REF! | J36: =VLOOKUP($A36,'HALF YEARLY(Entry)'!$1:$1048576,10,0) -> #REF! | K36: =VLOOKUP($A36,'HALF YEARLY(Entry)'!$1:$1048576,11,0) -> #REF! | L36: =VLOOKUP($A36,'HALF YEARLY(Entry)'!$1:$1048576,12,0) -> #REF! | M36: =VLOOKUP($A36,'HALF YEARLY(Entry)'!$1:$1048576,13,0) -> #REF! | N36: =VLOOKUP($A36,'HALF YEARLY(Entry)'!$1:$1048576,14,0) -> #REF! | O36: =VLOOKUP($A36,'HALF YEARLY(Entry)'!$1:$1048576,15,0) -> #REF! | P36: =SUM(C36:H36) -> #REF! | Q36: =ROUND(P36/6,2)&" %" -> #REF!
A37: =DETAILS!#REF! -> #REF! | B37: =DETAILS!#REF! -> #REF! | C37: =VLOOKUP($A37,'HALF YEARLY(Entry)'!$1:$1048576,3,0) -> #REF! | D37: =VLOOKUP($A37,'HALF YEARLY(Entry)'!$1:$1048576,4,0) -> #REF! | E37: =VLOOKUP($A37,'HALF YEARLY(Entry)'!$1:$1048576,5,0) -> #REF! | F37: =VLOOKUP($A37,'HALF YEARLY(Entry)'!$1:$1048576,6,0) -> #REF! | G37: =VLOOKUP($A37,'HALF YEARLY(Entry)'!$1:$1048576,7,0) -> #REF! | H37: =VLOOKUP($A37,'HALF YEARLY(Entry)'!$1:$1048576,8,0) -> #REF! | I37: =VLOOKUP($A37,'HALF YEARLY(Entry)'!$1:$1048576,9,0) -> #REF! | J37: =VLOOKUP($A37,'HALF YEARLY(Entry)'!$1:$1048576,10,0) -> #REF! | K37: =VLOOKUP($A37,'HALF YEARLY(Entry)'!$1:$1048576,11,0) -> #REF! | L37: =VLOOKUP($A37,'HALF YEARLY(Entry)'!$1:$1048576,12,0) -> #REF! | M37: =VLOOKUP($A37,'HALF YEARLY(Entry)'!$1:$1048576,13,0) -> #REF! | N37: =VLOOKUP($A37,'HALF YEARLY(Entry)'!$1:$1048576,14,0) -> #REF! | O37: =VLOOKUP($A37,'HALF YEARLY(Entry)'!$1:$1048576,15,0) -> #REF! | P37: =SUM(C37:H37) -> #REF! | Q37: =ROUND(P37/6,2)&" %" -> #REF!
A38: =DETAILS!#REF! -> #REF! | B38: =DETAILS!#REF! -> #REF! | C38: =VLOOKUP($A38,'HALF YEARLY(Entry)'!$1:$1048576,3,0) -> #REF! | D38: =VLOOKUP($A38,'HALF YEARLY(Entry)'!$1:$1048576,4,0) -> #REF! | E38: =VLOOKUP($A38,'HALF YEARLY(Entry)'!$1:$1048576,5,0) -> #REF! | F38: =VLOOKUP($A38,'HALF YEARLY(Entry)'!$1:$1048576,6,0) -> #REF! | G38: =VLOOKUP($A38,'HALF YEARLY(Entry)'!$1:$1048576,7,0) -> #REF! | H38: =VLOOKUP($A38,'HALF YEARLY(Entry)'!$1:$1048576,8,0) -> #REF! | I38: =VLOOKUP($A38,'HALF YEARLY(Entry)'!$1:$1048576,9,0) -> #REF! | J38: =VLOOKUP($A38,'HALF YEARLY(Entry)'!$1:$1048576,10,0) -> #REF! | K38: =VLOOKUP($A38,'HALF YEARLY(Entry)'!$1:$1048576,11,0) -> #REF! | L38: =VLOOKUP($A38,'HALF YEARLY(Entry)'!$1:$1048576,12,0) -> #REF! | M38: =VLOOKUP($A38,'HALF YEARLY(Entry)'!$1:$1048576,13,0) -> #REF! | N38: =VLOOKUP($A38,'HALF YEARLY(Entry)'!$1:$1048576,14,0) -> #REF! | O38: =VLOOKUP($A38,'HALF YEARLY(Entry)'!$1:$1048576,15,0) -> #REF! | P38: =SUM(C38:H38) -> #REF! | Q38: =ROUND(P38/6,2)&" %" -> #REF!
A39: =DETAILS!#REF! -> #REF! | B39: =DETAILS!#REF! -> #REF! | C39: =VLOOKUP($A39,'HALF YEARLY(Entry)'!$1:$1048576,3,0) -> #REF! | D39: =VLOOKUP($A39,'HALF YEARLY(Entry)'!$1:$1048576,4,0) -> #REF! | E39: =VLOOKUP($A39,'HALF YEARLY(Entry)'!$1:$1048576,5,0) -> #REF! | F39: =VLOOKUP($A39,'HALF YEARLY(Entry)'!$1:$1048576,6,0) -> #REF! | G39: =VLOOKUP($A39,'HALF YEARLY(Entry)'!$1:$1048576,7,0) -> #REF! | H39: =VLOOKUP($A39,'HALF YEARLY(Entry)'!$1:$1048576,8,0) -> #REF! | I39: =VLOOKUP($A39,'HALF YEARLY(Entry)'!$1:$1048576,9,0) -> #REF! | J39: =VLOOKUP($A39,'HALF YEARLY(Entry)'!$1:$1048576,10,0) -> #REF! | K39: =VLOOKUP($A39,'HALF YEARLY(Entry)'!$1:$1048576,11,0) -> #REF! | L39: =VLOOKUP($A39,'HALF YEARLY(Entry)'!$1:$1048576,12,0) -> #REF! | M39: =VLOOKUP($A39,'HALF YEARLY(Entry)'!$1:$1048576,13,0) -> #REF! | N39: =VLOOKUP($A39,'HALF YEARLY(Entry)'!$1:$1048576,14,0) -> #REF! | O39: =VLOOKUP($A39,'HALF YEARLY(Entry)'!$1:$1048576,15,0) -> #REF! | P39: =SUM(C39:H39) -> #REF! | Q39: =ROUND(P39/6,2)&" %" -> #REF!
A40: =DETAILS!#REF! -> #REF! | B40: =DETAILS!#REF! -> #REF! | C40: =VLOOKUP($A40,'HALF YEARLY(Entry)'!$1:$1048576,3,0) -> #REF! | D40: =VLOOKUP($A40,'HALF YEARLY(Entry)'!$1:$1048576,4,0) -> #REF! | E40: =VLOOKUP($A40,'HALF YEARLY(Entry)'!$1:$1048576,5,0) -> #REF! | F40: =VLOOKUP($A40,'HALF YEARLY(Entry)'!$1:$1048576,6,0) -> #REF! | G40: =VLOOKUP($A40,'HALF YEARLY(Entry)'!$1:$1048576,7,0) -> #REF! | H40: =VLOOKUP($A40,'HALF YEARLY(Entry)'!$1:$1048576,8,0) -> #REF! | I40: =VLOOKUP($A40,'HALF YEARLY(Entry)'!$1:$1048576,9,0) -> #REF! | J40: =VLOOKUP($A40,'HALF YEARLY(Entry)'!$1:$1048576,10,0) -> #REF! | K40: =VLOOKUP($A40,'HALF YEARLY(Entry)'!$1:$1048576,11,0) -> #REF! | L40: =VLOOKUP($A40,'HALF YEARLY(Entry)'!$1:$1048576,12,0) -> #REF! | M40: =VLOOKUP($A40,'HALF YEARLY(Entry)'!$1:$1048576,13,0) -> #REF! | N40: =VLOOKUP($A40,'HALF YEARLY(Entry)'!$1:$1048576,14,0) -> #REF! | O40: =VLOOKUP($A40,'HALF YEARLY(Entry)'!$1:$1048576,15,0) -> #REF! | P40: =SUM(C40:H40) -> #REF! | Q40: =ROUND(P40/6,2)&" %" -> #REF!
A41: =DETAILS!#REF! -> #REF! | B41: =DETAILS!#REF! -> #REF! | C41: =VLOOKUP($A41,'HALF YEARLY(Entry)'!$1:$1048576,3,0) -> #REF! | D41: =VLOOKUP($A41,'HALF YEARLY(Entry)'!$1:$1048576,4,0) -> #REF! | E41: =VLOOKUP($A41,'HALF YEARLY(Entry)'!$1:$1048576,5,0) -> #REF! | F41: =VLOOKUP($A41,'HALF YEARLY(Entry)'!$1:$1048576,6,0) -> #REF! | G41: =VLOOKUP($A41,'HALF YEARLY(Entry)'!$1:$1048576,7,0) -> #REF! | H41: =VLOOKUP($A41,'HALF YEARLY(Entry)'!$1:$1048576,8,0) -> #REF! | I41: =VLOOKUP($A41,'HALF YEARLY(Entry)'!$1:$1048576,9,0) -> #REF! | J41: =VLOOKUP($A41,'HALF YEARLY(Entry)'!$1:$1048576,10,0) -> #REF! | K41: =VLOOKUP($A41,'HALF YEARLY(Entry)'!$1:$1048576,11,0) -> #REF! | L41: =VLOOKUP($A41,'HALF YEARLY(Entry)'!$1:$1048576,12,0) -> #REF! | M41: =VLOOKUP($A41,'HALF YEARLY(Entry)'!$1:$1048576,13,0) -> #REF! | N41: =VLOOKUP($A41,'HALF YEARLY(Entry)'!$1:$1048576,14,0) -> #REF! | O41: =VLOOKUP($A41,'HALF YEARLY(Entry)'!$1:$1048576,15,0) -> #REF! | P41: =SUM(C41:H41) -> #REF! | Q41: =ROUND(P41/6,2)&" %" -> #REF!

Sheet Grade 50
A2: 50 | B2: A
A3: 49 | B3: A
A4: 48 | B4: A
A5: 47 | B5: A
A6: 46 | B6: A
A7: 45 | B7: A
A8: 44 | B8: A
A9: 43 | B9: A
A10: 42 | B10: A
A11: 41 | B11: A
A12: 40 | B12: B
A13: 39 | B13: B
... A52: 0 | B52: E

Sheet HY Compile
A1: Half Yearly Compile Report (2025-26) Class - IX-A
A2: S.R. No. | B2: Student's Name | C2: ENGLISH | F2: HINDI | I2: MATHEMATICS | L2: SCIENCE | O2: SOCIAL SCIENCE | R2: ARTIFICIAL INTELLIGENCE | U2: WORK EDUCATION | V2: ART EDUCATION | W2: HEALTH & PHYSICAL EDUCATION | X2: DISCIPLINE | Y2: TOTAL PRESENT | Z2: TORAL WORKING DAY | AA2: CLASS TEACHER'S REAMRK
C3: UT-I | D3: HY | E3: Total | F3: UT-I | G3: HY | H3: Total | I3: UT-I | J3: HY | K3: Total | L3: UT-I | M3: HY | N3: Total | O3: UT-I | P3: HY | Q3: Total | R3: UT-I | S3: HY | T3: Total
A4: =DETAILS!A3 -> 1887 | B4: =DETAILS!B3 -> ABHINAV YADAV | C4: =VLOOKUP($A4,'UT-I '!$1:$1048576,3,0) -> 0 | D4: =IFERROR(ROUND(VLOOKUP($A4,'HALF YEARLY'!$1:$1048576,3,0)*0.8,0),VLOOKUP($A4,'HALF YEARLY'!$1:$1048576,3,0)) -> 0 | E4: =SUM(C4:D4) -> 0 | F4: =VLOOKUP($A4,'UT-I '!$1:$1048576,4,0) -> 0 | G4: =IFERROR(ROUND(VLOOKUP($A4,'HALF YEARLY'!$1:$1048576,4,0)*0.8,0),VLOOKUP($A4,'HALF YEARLY'!$1:$1048576,4,0)) -> 0 | H4: =SUM(F4:G4) -> 0 | I4: =VLOOKUP($A4,'UT-I '!$1:$1048576,5,0) -> 0 | J4: =IFERROR(ROUND(VLOOKUP($A4,'HALF YEARLY'!$1:$1048576,5,0)*0.8,0),VLOOKUP($A4,'HALF YEARLY'!$1:$1048576,5,0)) -> 0 | K4: =SUM(I4:J4) -> 0 | L4: =VLOOKUP($A4,'UT-I '!$1:$1048576,6,0) -> 0 | M4: =IFERROR(ROUND(VLOOKUP($A4,'HALF YEARLY'!$1:$1048576,6,0)*0.8,0),VLOOKUP($A4,'HALF YEARLY'!$1:$1048576,6,0)) -> 0 | N4: =SUM(L4:M4) -> 0 | O4: =VLOOKUP($A4,'UT-I '!$1:$1048576,7,0) -> 0 | P4: =IFERROR(ROUND(VLOOKUP($A4,'HALF YEARLY'!$1:$1048576,7,0)*0.8,0),VLOOKUP($A4,'HALF YEARLY'!$1:$1048576,7,0)) -> 0 | Q4: =SUM(O4:P4) -> 0 | R4: =VLOOKUP($A4,'UT-I '!$1:$1048576,8,0) -> 0 | S4: =IFERROR(ROUND(VLOOKUP($A4,'HALF YEARLY'!$1:$1048576,8,0)*0.8,0),VLOOKUP($A4,'HALF YEARLY'!$1:$1048576,8,0)) -> 0 | T4: =SUM(R4:S4) -> 0 | U4: =VLOOKUP($A4,'HALF YEARLY'!$1:$1048576,9,0) -> 0 | V4: =VLOOKUP($A4,'HALF YEARLY'!$1:$1048576,10,0) -> 0 | W4: =VLOOKUP($A4,'HALF YEARLY'!$1:$1048576,11,0) -> 0 | X4: =VLOOKUP($A4,'HALF YEARLY'!$1:$1048576,12,0) -> 0 | Y4: =VLOOKUP($A4,'HALF YEARLY'!$1:$1048576,13,0) -> 0 | Z4: =VLOOKUP($A4,'HALF YEARLY'!$1:$1048576,14,0) -> 0 | AA4: =VLOOKUP($A4,'HALF YEARLY'!$1:$1048576,15,0) -> 0
A5: =DETAILS!A4 -> 1926 | B5: =DETAILS!B4 -> ADITYA KUMAR | C5: =VLOOKUP($A5,'UT-I '!$1:$1048576,3,0) -> 0 | D5: =IFERROR(ROUND(VLOOKUP($A5,'HALF YEARLY'!$1:$1048576,3,0)*0.8,0),VLOOKUP($A5,'HALF YEARLY'!$1:$1048576,3,0)) -> 0 | E5: =SUM(C5:D5) -> 0 | F5: =VLOOKUP($A5,'UT-I '!$1:$1048576,4,0) -> 0 | G5: =IFERROR(ROUND(VLOOKUP($A5,'HALF YEARLY'!$1:$1048576,4,0)*0.8,0),VLOOKUP($A5,'HALF YEARLY'!$1:$1048576,4,0)) -> 0 | H5: =SUM(F5:G5) -> 0 | I5: =VLOOKUP($A5,'UT-I '!$1:$1048576,5,0) -> 0 | J5: =IFERROR(ROUND(VLOOKUP($A5,'HALF YEARLY'!$1:$1048576,5,0)*0.8,0),VLOOKUP($A5,'HALF YEARLY'!$1:$1048576,5,0)) -> 0 | K5: =SUM(I5:J5) -> 0 | L5: =VLOOKUP($A5,'UT-I '!$1:$1048576,6,0) -> 0 | M5: =IFERROR(ROUND(VLOOKUP($A5,'HALF YEARLY'!$1:$1048576,6,0)*0.8,0),VLOOKUP($A5,'HALF YEARLY'!$1:$1048576,6,0)) -> 0 | N5: =SUM(L5:M5) -> 0 | O5: =VLOOKUP($A5,'UT-I '!$1:$1048576,7,0) -> 0 | P5: =IFERROR(ROUND(VLOOKUP($A5,'HALF YEARLY'!$1:$1048576,7,0)*0.8,0),VLOOKUP($A5,'HALF YEARLY'!$1:$1048576,7,0)) -> 0 | Q5: =SUM(O5:P5) -> 0 | R5: =VLOOKUP($A5,'UT-I '!$1:$1048576,8,0) -> 0 | S5: =IFERROR(ROUND(VLOOKUP($A5,'HALF YEARLY'!$1:$1048576,8,0)*0.8,0),VLOOKUP($A5,'HALF YEARLY'!$1:$1048576,8,0)) -> 0 | T5: =SUM(R5:S5) -> 0 | U5: =VLOOKUP($A5,'HALF YEARLY'!$1:$1048576,9,0) -> 0 | V5: =VLOOKUP($A5,'HALF YEARLY'!$1:$1048576,10,0) -> 0 | W5: =VLOOKUP($A5,'HALF YEARLY'!$1:$1048576,11,0) -> 0 | X5: =VLOOKUP($A5,'HALF YEARLY'!$1:$1048576,12,0) -> 0 | Y5: =VLOOKUP($A5,'HALF YEARLY'!$1:$1048576,13,0) -> 0 | Z5: =VLOOKUP($A5,'HALF YEARLY'!$1:$1048576,14,0) -> 0 | AA5: =VLOOKUP($A5,'HALF YEARLY'!$1:$1048576,15,0) -> 0
A6: =DETAILS!A5 -> 1841 | B6: =DETAILS!B5 -> ANSHIKA THAKUR | C6: =VLOOKUP($A6,'UT-I '!$1:$1048576,3,0) -> 0 | D6: =IFERROR(ROUND(VLOOKUP($A6,'HALF YEARLY'!$1:$1048576,3,0)*0.8,0),VLOOKUP($A6,'HALF YEARLY'!$1:$1048576,3,0)) -> 0 | E6: =SUM(C6:D6) -> 0 | F6: =VLOOKUP($A6,'UT-I '!$1:$1048576,4,0) -> 0 | G6: =IFERROR(ROUND(VLOOKUP($A6,'HALF YEARLY'!$1:$1048576,4,0)*0.8,0),VLOOKUP($A6,'HALF YEARLY'!$1:$1048576,4,0)) -> 0 | H6: =SUM(F6:G6) -> 0 | I6: =VLOOKUP($A6,'UT-I '!$1:$1048576,5,0) -> 0 | J6: =IFERROR(ROUND(VLOOKUP($A6,'HALF YEARLY'!$1:$1048576,5,0)*0.8,0),VLOOKUP($A6,'HALF YEARLY'!$1:$1048576,5,0)) -> 0 | K6: =SUM(I6:J6) -> 0 | L6: =VLOOKUP($A6,'UT-I '!$1:$1048576,6,0) -> 0 | M6: =IFERROR(ROUND(VLOOKUP($A6,'HALF YEARLY'!$1:$1048576,6,0)*0.8,0),VLOOKUP($A6,'HALF YEARLY'!$1:$1048576,6,0)) -> 0 | N6: =SUM(L6:M6) -> 0 | O6: =VLOOKUP($A6,'UT-I '!$1:$1048576,7,0) -> 0 | P6: =IFERROR(ROUND(VLOOKUP($A6,'HALF YEARLY'!$1:$1048576,7,0)*0.8,0),VLOOKUP($A6,'HALF YEARLY'!$1:$1048576,7,0)) -> 0 | Q6: =SUM(O6:P6) -> 0 | R6: =VLOOKUP($A6,'UT-I '!$1:$1048576,8,0) -> 0 | S6: =IFERROR(ROUND(VLOOKUP($A6,'HALF YEARLY'!$1:$1048576,8,0)*0.8,0),VLOOKUP($A6,'HALF YEARLY'!$1:$1048576,8,0)) -> 0 | T6: =SUM(R6:S6) -> 0 | U6: =VLOOKUP($A6,'HALF YEARLY'!$1:$1048576,9,0) -> 0 | V6: =VLOOKUP($A6,'HALF YEARLY'!$1:$1048576,10,0) -> 0 | W6: =VLOOKUP($A6,'HALF YEARLY'!$1:$1048576,11,0) -> 0 | X6: =VLOOKUP($A6,'HALF YEARLY'!$1:$1048576,12,0) -> 0 | Y6: =VLOOKUP($A6,'HALF YEARLY'!$1:$1048576,13,0) -> 0 | Z6: =VLOOKUP($A6,'HALF YEARLY'!$1:$1048576,14,0) -> 0 | AA6: =VLOOKUP($A6,'HALF YEARLY'!$1:$1048576,15,0) -> 0
A7: =DETAILS!A6 -> 1724 | B7: =DETAILS!B6 -> ANSHIKA YADAV | C7: =VLOOKUP($A7,'UT-I '!$1:$1048576,3,0) -> 0 | D7: =IFERROR(ROUND(VLOOKUP($A7,'HALF YEARLY'!$1:$1048576,3,0)*0.8,0),VLOOKUP($A7,'HALF YEARLY'!$1:$1048576,3,0)) -> 0 | E7: =SUM(C7:D7) -> 0 | F7: =VLOOKUP($A7,'UT-I '!$1:$1048576,4,0) -> 0 | G7: =IFERROR(ROUND(VLOOKUP($A7,'HALF YEARLY'!$1:$1048576,4,0)*0.8,0),VLOOKUP($A7,'HALF YEARLY'!$1:$1048576,4,0)) -> 0 | H7: =SUM(F7:G7) -> 0 | I7: =VLOOKUP($A7,'UT-I '!$1:$1048576,5,0) -> 0 | J7: =IFERROR(ROUND(VLOOKUP($A7,'HALF YEARLY'!$1:$1048576,5,0)*0.8,0),VLOOKUP($A7,'HALF YEARLY'!$1:$1048576,5,0)) -> 0 | K7: =SUM(I7:J7) -> 0 | L7: =VLOOKUP($A7,'UT-I '!$1:$1048576,6,0) -> 0 | M7: =IFERROR(ROUND(VLOOKUP($A7,'HALF YEARLY'!$1:$1048576,6,0)*0.8,0),VLOOKUP($A7,'HALF YEARLY'!$1:$1048576,6,0)) -> 0 | N7: =SUM(L7:M7) -> 0 | O7: =VLOOKUP($A7,'UT-I '!$1:$1048576,7,0) -> 0 | P7: =IFERROR(ROUND(VLOOKUP($A7,'HALF YEARLY'!$1:$1048576,7,0)*0.8,0),VLOOKUP($A7,'HALF YEARLY'!$1:$1048576,7,0)) -> 0 | Q7: =SUM(O7:P7) -> 0 | R7: =VLOOKUP($A7,'UT-I '!$1:$1048576,8,0) -> 0 | S7: =IFERROR(ROUND(VLOOKUP($A7,'HALF YEARLY'!$1:$1048576,8,0)*0.8,0),VLOOKUP($A7,'HALF YEARLY'!$1:$1048576,8,0)) -> 0 | T7: =SUM(R7:S7) -> 0 | U7: =VLOOKUP($A7,'HALF YEARLY'!$1:$1048576,9,0) -> 0 | V7: =VLOOKUP($A7,'HALF YEARLY'!$1:$1048576,10,0) -> 0 | W7: =VLOOKUP($A7,'HALF YEARLY'!$1:$1048576,11,0) -> 0 | X7: =VLOOKUP($A7,'HALF YEARLY'!$1:$1048576,12,0) -> 0 | Y7: =VLOOKUP($A7,'HALF YEARLY'!$1:$1048576,13,0) -> 0 | Z7: =VLOOKUP($A7,'HALF YEARLY'!$1:$1048576,14,0) -> 0 | AA7: =VLOOKUP($A7,'HALF YEARLY'!$1:$1048576,15,0) -> 0
A8: =DETAILS!A7 -> 1112 | B8: =DETAILS!B7 -> AQSA BANO | C8: =VLOOKUP($A8,'UT-I '!$1:$1048576,3,0) -> 0 | D8: =IFERROR(ROUND(VLOOKUP($A8,'HALF YEARLY'!$1:$1048576,3,0)*0.8,0),VLOOKUP($A8,'HALF YEARLY'!$1:$1048576,3,0)) -> 0 | E8: =SUM(C8:D8) -> 0 | F8: =VLOOKUP($A8,'UT-I '!$1:$1048576,4,0) -> 0 | G8: =IFERROR(ROUND(VLOOKUP($A8,'HALF YEARLY'!$1:$1048576,4,0)*0.8,0),VLOOKUP($A8,'HALF YEARLY'!$1:$1048576,4,0)) -> 0 | H8: =SUM(F8:G8) -> 0 | I8: =VLOOKUP($A8,'UT-I '!$1:$1048576,5,0) -> 0 | J8: =IFERROR(ROUND(VLOOKUP($A8,'HALF YEARLY'!$1:$1048576,5,0)*0.8,0),VLOOKUP($A8,'HALF YEARLY'!$1:$1048576,5,0)) -> 0 | K8: =SUM(I8:J8) -> 0 | L8: =VLOOKUP($A8,'UT-I '!$1:$1048576,6,0) -> 0 | M8: =IFERROR(ROUND(VLOOKUP($A8,'HALF YEARLY'!$1:$1048576,6,0)*0.8,0),VLOOKUP($A8,'HALF YEARLY'!$1:$1048576,6,0)) -> 0 | N8: =SUM(L8:M8) -> 0 | O8: =VLOOKUP($A8,'UT-I '!$1:$1048576,7,0) -> 0 | P8: =IFERROR(ROUND(VLOOKUP($A8,'HALF YEARLY'!$1:$1048576,7,0)*0.8,0),VLOOKUP($A8,'HALF YEARLY'!$1:$1048576,7,0)) -> 0 | Q8: =SUM(O8:P8) -> 0 | R8: =VLOOKUP($A8,'UT-I '!$1:$1048576,8,0) -> 0 | S8: =IFERROR(ROUND(VLOOKUP($A8,'HALF YEARLY'!$1:$1048576,8,0)*0.8,0),VLOOKUP($A8,'HALF YEARLY'!$1:$1048576,8,0)) -> 0 | T8: =SUM(R8:S8) -> 0 | U8: =VLOOKUP($A8,'HALF YEARLY'!$1:$1048576,9,0) -> 0 | V8: =VLOOKUP($A8,'HALF YEARLY'!$1:$1048576,10,0) -> 0 | W8: =VLOOKUP($A8,'HALF YEARLY'!$1:$1048576,11,0) -> 0 | X8: =VLOOKUP($A8,'HALF YEARLY'!$1:$1048576,12,0) -> 0 | Y8: =VLOOKUP($A8,'HALF YEARLY'!$1:$1048576,13,0) -> 0 | Z8: =VLOOKUP($A8,'HALF YEARLY'!$1:$1048576,14,0) -> 0 | AA8: =VLOOKUP($A8,'HALF YEARLY'!$1:$1048576,15,0) -> 0
A9: =DETAILS!A8 -> 1830 | B9: =DETAILS!B8 -> ATHARVA SHARMA | C9: =VLOOKUP($A9,'UT-I '!$1:$1048576,3,0) -> 0 | D9: =IFERROR(ROUND(VLOOKUP($A9,'HALF YEARLY'!$1:$1048576,3,0)*0.8,0),VLOOKUP($A9,'HALF YEARLY'!$1:$1048576,3,0)) -> 0 | E9: =SUM(C9:D9) -> 0 | F9: =VLOOKUP($A9,'UT-I '!$1:$1048576,4,0) -> 0 | G9: =IFERROR(ROUND(VLOOKUP($A9,'HALF YEARLY'!$1:$1048576,4,0)*0.8,0),VLOOKUP($A9,'HALF YEARLY'!$1:$1048576,4,0)) -> 0 | H9: =SUM(F9:G9) -> 0 | I9: =VLOOKUP($A9,'UT-I '!$1:$1048576,5,0) -> 0 | J9: =IFERROR(ROUND(VLOOKUP($A9,'HALF YEARLY'!$1:$1048576,5,0)*0.8,0),VLOOKUP($A9,'HALF YEARLY'!$1:$1048576,5,0)) -> 0 | K9: =SUM(I9:J9) -> 0 | L9: =VLOOKUP($A9,'UT-I '!$1:$1048576,6,0) -> 0 | M9: =IFERROR(ROUND(VLOOKUP($A9,'HALF YEARLY'!$1:$1048576,6,0)*0.8,0),VLOOKUP($A9,'HALF YEARLY'!$1:$1048576,6,0)) -> 0 | N9: =SUM(L9:M9) -> 0 | O9: =VLOOKUP($A9,'UT-I '!$1:$1048576,7,0) -> 0 | P9: =IFERROR(ROUND(VLOOKUP($A9,'HALF YEARLY'!$1:$1048576,7,0)*0.8,0),VLOOKUP($A9,'HALF YEARLY'!$1:$1048576,7,0)) -> 0 | Q9: =SUM(O9:P9) -> 0 | R9: =VLOOKUP($A9,'UT-I '!$1:$1048576,8,0) -> 0 | S9: =IFERROR(ROUND(VLOOKUP($A9,'HALF YEARLY'!$1:$1048576,8,0)*0.8,0),VLOOKUP($A9,'HALF YEARLY'!$1:$1048576,8,0)) -> 0 | T9: =SUM(R9:S9) -> 0 | U9: =VLOOKUP($A9,'HALF YEARLY'!$1:$1048576,9,0) -> 0 | V9: =VLOOKUP($A9,'HALF YEARLY'!$1:$1048576,10,0) -> 0 | W9: =VLOOKUP($A9,'HALF YEARLY'!$1:$1048576,11,0) -> 0 | X9: =VLOOKUP($A9,'HALF YEARLY'!$1:$1048576,12,0) -> 0 | Y9: =VLOOKUP($A9,'HALF YEARLY'!$1:$1048576,13,0) -> 0 | Z9: =VLOOKUP($A9,'HALF YEARLY'!$1:$1048576,14,0) -> 0 | AA9: =VLOOKUP($A9,'HALF YEARLY'!$1:$1048576,15,0) -> 0
A10: =DETAILS!A9 -> 1516 | B10: =DETAILS!B9 -> AYUB KHAN | C10: =VLOOKUP($A10,'UT-I '!$1:$1048576,3,0) -> 0 | D10: =IFERROR(ROUND(VLOOKUP($A10,'HALF YEARLY'!$1:$1048576,3,0)*0.8,0),VLOOKUP($A10,'HALF YEARLY'!$1:$1048576,3,0)) -> 0 | E10: =SUM(C10:D10) -> 0 | F10: =VLOOKUP($A10,'UT-I '!$1:$1048576,4,0) -> 0 | G10: =IFERROR(ROUND(VLOOKUP($A10,'HALF YEARLY'!$1:$1048576,4,0)*0.8,0),VLOOKUP($A10,'HALF YEARLY'!$1:$1048576,4,0)) -> 0 | H10: =SUM(F10:G10) -> 0 | I10: =VLOOKUP($A10,'UT-I '!$1:$1048576,5,0) -> 0 | J10: =IFERROR(ROUND(VLOOKUP($A10,'HALF YEARLY'!$1:$1048576,5,0)*0.8,0),VLOOKUP($A10,'HALF YEARLY'!$1:$1048576,5,0)) -> 0 | K10: =SUM(I10:J10) -> 0 | L10: =VLOOKUP($A10,'UT-I '!$1:$1048576,6,0) -> 0 | M10: =IFERROR(ROUND(VLOOKUP($A10,'HALF YEARLY'!$1:$1048576,6,0)*0.8,0),VLOOKUP($A10,'HALF YEARLY'!$1:$1048576,6,0)) -> 0 | N10: =SUM(L10:M10) -> 0 | O10: =VLOOKUP($A10,'UT-I '!$1:$1048576,7,0) -> 0 | P10: =IFERROR(ROUND(VLOOKUP($A10,'HALF YEARLY'!$1:$1048576,7,0)*0.8,0),VLOOKUP($A10,'HALF YEARLY'!$1:$1048576,7,0)) -> 0 | Q10: =SUM(O10:P10) -> 0 | R10: =VLOOKUP($A10,'UT-I '!$1:$1048576,8,0) -> 0 | S10: =IFERROR(ROUND(VLOOKUP($A10,'HALF YEARLY'!$1:$1048576,8,0)*0.8,0),VLOOKUP($A10,'HALF YEARLY'!$1:$1048576,8,0)) -> 0 | T10: =SUM(R10:S10) -> 0 | U10: =VLOOKUP($A10,'HALF YEARLY'!$1:$1048576,9,0) -> 0 | V10: =VLOOKUP($A10,'HALF YEARLY'!$1:$1048576,10,0) -> 0 | W10: =VLOOKUP($A10,'HALF YEARLY'!$1:$1048576,11,0) -> 0 | X10: =VLOOKUP($A10,'HALF YEARLY'!$1:$1048576,12,0) -> 0 | Y10: =VLOOKUP($A10,'HALF YEARLY'!$1:$1048576,13,0) -> 0 | Z10: =VLOOKUP($A10,'HALF YEARLY'!$1:$1048576,14,0) -> 0 | AA10: =VLOOKUP($A10,'HALF YEARLY'!$1:$1048576,15,0) -> 0
A11: =DETAILS!A10 -> 1109 | B11: =DETAILS!B10 -> AYUSH MISHRA | C11: =VLOOKUP($A11,'UT-I '!$1:$1048576,3,0) -> 0 | D11: =IFERROR(ROUND(VLOOKUP($A11,'HALF YEARLY'!$1:$1048576,3,0)*0.8,0),VLOOKUP($A11,'HALF YEARLY'!$1:$1048576,3,0)) -> 0 | E11: =SUM(C11:D11) -> 0 | F11: =VLOOKUP($A11,'UT-I '!$1:$1048576,4,0) -> 0 | G11: =IFERROR(ROUND(VLOOKUP($A11,'HALF YEARLY'!$1:$1048576,4,0)*0.8,0),VLOOKUP($A11,'HALF YEARLY'!$1:$1048576,4,0)) -> 0 | H11: =SUM(F11:G11) -> 0 | I11: =VLOOKUP($A11,'UT-I '!$1:$1048576,5,0) -> 0 | J11: =IFERROR(ROUND(VLOOKUP($A11,'HALF YEARLY'!$1:$1048576,5,0)*0.8,0),VLOOKUP($A11,'HALF YEARLY'!$1:$1048576,5,0)) -> 0 | K11: =SUM(I11:J11) -> 0 | L11: =VLOOKUP($A11,'UT-I '!$1:$1048576,6,0) -> 0 | M11: =IFERROR(ROUND(VLOOKUP($A11,'HALF YEARLY'!$1:$1048576,6,0)*0.8,0),VLOOKUP($A11,'HALF YEARLY'!$1:$1048576,6,0)) -> 0 | N11: =SUM(L11:M11) -> 0 | O11: =VLOOKUP($A11,'UT-I '!$1:$1048576,7,0) -> 0 | P11: =IFERROR(ROUND(VLOOKUP($A11,'HALF YEARLY'!$1:$1048576,7,0)*0.8,0),VLOOKUP($A11,'HALF YEARLY'!$1:$1048576,7,0)) -> 0 | Q11: =SUM(O11:P11) -> 0 | R11: =VLOOKUP($A11,'UT-I '!$1:$1048576,8,0) -> 0 | S11: =IFERROR(ROUND(VLOOKUP($A11,'HALF YEARLY'!$1:$1048576,8,0)*0.8,0),VLOOKUP($A11,'HALF YEARLY'!$1:$1048576,8,0)) -> 0 | T11: =SUM(R11:S11) -> 0 | U11: =VLOOKUP($A11,'HALF YEARLY'!$1:$1048576,9,0) -> 0 | V11: =VLOOKUP($A11,'HALF YEARLY'!$1:$1048576,10,0) -> 0 | W11: =VLOOKUP($A11,'HALF YEARLY'!$1:$1048576,11,0) -> 0 | X11: =VLOOKUP($A11,'HALF YEARLY'!$1:$1048576,12,0) -> 0 | Y11: =VLOOKUP($A11,'HALF YEARLY'!$1:$1048576,13,0) -> 0 | Z11: =VLOOKUP($A11,'HALF YEARLY'!$1:$1048576,14,0) -> 0 | AA11: =VLOOKUP($A11,'HALF YEARLY'!$1:$1048576,15,0) -> 0
A12: =DETAILS!A11 -> 1951 | B12: =DETAILS!B11 -> AYUSHI YADAV | C12: =VLOOKUP($A12,'UT-I '!$1:$1048576,3,0) -> 0 | D12: =IFERROR(ROUND(VLOOKUP($A12,'HALF YEARLY'!$1:$1048576,3,0)*0.8,0),VLOOKUP($A12,'HALF YEARLY'!$1:$1048576,3,0)) -> 0 | E12: =SUM(C12:D12) -> 0 | F12: =VLOOKUP($A12,'UT-I '!$1:$1048576,4,0) -> 0 | G12: =IFERROR(ROUND(VLOOKUP($A12,'HALF YEARLY'!$1:$1048576,4,0)*0.8,0),VLOOKUP($A12,'HALF YEARLY'!$1:$1048576,4,0)) -> 0 | H12: =SUM(F12:G12) -> 0 | I12: =VLOOKUP($A12,'UT-I '!$1:$1048576,5,0) -> 0 | J12: =IFERROR(ROUND(VLOOKUP($A12,'HALF YEARLY'!$1:$1048576,5,0)*0.8,0),VLOOKUP($A12,'HALF YEARLY'!$1:$1048576,5,0)) -> 0 | K12: =SUM(I12:J12) -> 0 | L12: =VLOOKUP($A12,'UT-I '!$1:$1048576,6,0) -> 0 | M12: =IFERROR(ROUND(VLOOKUP($A12,'HALF YEARLY'!$1:$1048576,6,0)*0.8,0),VLOOKUP($A12,'HALF YEARLY'!$1:$1048576,6,0)) -> 0 | N12: =SUM(L12:M12) -> 0 | O12: =VLOOKUP($A12,'UT-I '!$1:$1048576,7,0) -> 0 | P12: =IFERROR(ROUND(VLOOKUP($A12,'HALF YEARLY'!$1:$1048576,7,0)*0.8,0),VLOOKUP($A12,'HALF YEARLY'!$1:$1048576,7,0)) -> 0 | Q12: =SUM(O12:P12) -> 0 | R12: =VLOOKUP($A12,'UT-I '!$1:$1048576,8,0) -> 0 | S12: =IFERROR(ROUND(VLOOKUP($A12,'HALF YEARLY'!$1:$1048576,8,0)*0.8,0),VLOOKUP($A12,'HALF YEARLY'!$1:$1048576,8,0)) -> 0 | T12: =SUM(R12:S12) -> 0 | U12: =VLOOKUP($A12,'HALF YEARLY'!$1:$1048576,9,0) -> 0 | V12: =VLOOKUP($A12,'HALF YEARLY'!$1:$1048576,10,0) -> 0 | W12: =VLOOKUP($A12,'HALF YEARLY'!$1:$1048576,11,0) -> 0 | X12: =VLOOKUP($A12,'HALF YEARLY'!$1:$1048576,12,0) -> 0 | Y12: =VLOOKUP($A12,'HALF YEARLY'!$1:$1048576,13,0) -> 0 | Z12: =VLOOKUP($A12,'HALF YEARLY'!$1:$1048576,14,0) -> 0 | AA12: =VLOOKUP($A12,'HALF YEARLY'!$1:$1048576,15,0) -> 0
A13: =DETAILS!A12 -> 1863 | B13: =DETAILS!B12 -> BARIRA KHAN | C13: =VLOOKUP($A13,'UT-I '!$1:$1048576,3,0) -> 0 | D13: =IFERROR(ROUND(VLOOKUP($A13,'HALF YEARLY'!$1:$1048576,3,0)*0.8,0),VLOOKUP($A13,'HALF YEARLY'!$1:$1048576,3,0)) -> 0 | E13: =SUM(C13:D13) -> 0 | F13: =VLOOKUP($A13,'UT-I '!$1:$1048576,4,0) -> 0 | G13: =IFERROR(ROUND(VLOOKUP($A13,'HALF YEARLY'!$1:$1048576,4,0)*0.8,0),VLOOKUP($A13,'HALF YEARLY'!$1:$1048576,4,0)) -> 0 | H13: =SUM(F13:G13) -> 0 | I13: =VLOOKUP($A13,'UT-I '!$1:$1048576,5,0) -> 0 | J13: =IFERROR(ROUND(VLOOKUP($A13,'HALF YEARLY'!$1:$1048576,5,0)*0.8,0),VLOOKUP($A13,'HALF YEARLY'!$1:$1048576,5,0)) -> 0 | K13: =SUM(I13:J13) -> 0 | L13: =VLOOKUP($A13,'UT-I '!$1:$1048576,6,0) -> 0 | M13: =IFERROR(ROUND(VLOOKUP($A13,'HALF YEARLY'!$1:$1048576,6,0)*0.8,0),VLOOKUP($A13,'HALF YEARLY'!$1:$1048576,6,0)) -> 0 | N13: =SUM(L13:M13) -> 0 | O13: =VLOOKUP($A13,'UT-I '!$1:$1048576,7,0) -> 0 | P13: =IFERROR(ROUND(VLOOKUP($A13,'HALF YEARLY'!$1:$1048576,7,0)*0.8,0),VLOOKUP($A13,'HALF YEARLY'!$1:$1048576,7,0)) -> 0 | Q13: =SUM(O13:P13) -> 0 | R13: =VLOOKUP($A13,'UT-I '!$1:$1048576,8,0) -> 0 | S13: =IFERROR(ROUND(VLOOKUP($A13,'HALF YEARLY'!$1:$1048576,8,0)*0.8,0),VLOOKUP($A13,'HALF YEARLY'!$1:$1048576,8,0)) -> 0 | T13: =SUM(R13:S13) -> 0 | U13: =VLOOKUP($A13,'HALF YEARLY'!$1:$1048576,9,0) -> 0 | V13: =VLOOKUP($A13,'HALF YEARLY'!$1:$1048576,10,0) -> 0 | W13: =VLOOKUP($A13,'HALF YEARLY'!$1:$1048576,11,0) -> 0 | X13: =VLOOKUP($A13,'HALF YEARLY'!$1:$1048576,12,0) -> 0 | Y13: =VLOOKUP($A13,'HALF YEARLY'!$1:$1048576,13,0) -> 0 | Z13: =VLOOKUP($A13,'HALF YEARLY'!$1:$1048576,14,0) -> 0 | AA13: =VLOOKUP($A13,'HALF YEARLY'!$1:$1048576,15,0) -> 0
