Workbook

Sheet DETAILS
A1: STUDENT'S DETAIL
A2: SR NO | B2: NAME | C2: MOTHER'S NAME | D2: FATHER'S NAME | E2: DOB | F2: CLASS & SEC
A3: 1633 | B3: AADVIK SRIVASTAVA | C3: RAJANI SRIVASTAVA | D3: SANJEEV KUMAR SRIVASTAVA | E3: 14.08.2013 | F3: VII-A
A4: 1119 | B4: AARYASH SONI | C4: PINKI SONI | D4: NATHURAM VERMA | E4: 01.05.2013 | F4: VII-A
A5: 1407 | B5: AKSHAY DUBEY | C5: BEBI DUBEY | D5: SANTOSH KUMAR AWADHESH DUBEY | E5: 02.02.2015 | F5: VII-A
A6: 1077 | B6: ALISHA | C6: AISHA KHATOON | D6: SYED MUNNWWAR ALI | E6: 27.04.2012 | F6: VII-A
A7: 1210 | B7: ANJALI JHA | C7: SAROJ JHA | D7: SHAYMANAND JHA | E7: 19.11.2013 | F7: VII-A
A8: 1286 | B8: AROHI JAISWAL | C8: MEENA JAISWAL | D8: OMJI JAISWAL | E8: 31.12.2012 | F8: VII-A
A9: 1862 | B9: ASHUTOSH MISHRA | C9: SEEMA MISHRA | D9: AMIT KUMAR MISHRA | E9: 04.07.2014 | F9: VII-A
A10: 1684 | B10: AYUSH GUPTA | C10: POONAM GUPTA | D10: NARAYAN PRASAD GUPTA | E10: 21.06.2013 | F10: VII-A
A11: 1662 | B11: AYUSH KUMAR YOGI | C11: REKHA ANAND | D11: GIRJA SHANKAR | E11: 06.05.2013 | F11: VII-A
A12: 1602 | B12: AYUSHI MISHRA | C12: LAXMI MISHRA | D12: AMIT MISHRA | E12: 01.02.2014 | F12: VII-A
A13: 1842 | B13: DEEPANSH YADAV | C13: SARVESH KUMARI | D13: MUKESH KUMAR | E13: 09.08.2016 | F13: VII-A
A14: 1127 | B14: DIKSHA MISHRA | C14: BRIJESHWARI MISHRA | D14: SUDHAKAR MISHRA | E14: 23.02.2013 | F14: VII-A
... A43: 1773 | B43: YASHRAJ | C43: ANAMIKA DEVI | D43: SATENDRA KUSHWAHA | E43: 16.04.2013 | F43: VII-A

Sheet UT-I(Entry)
A1: UNIT TEST-I (2025-26) CLASS - VII
A2: SR. NO. | B2: NAME | C2: ENGLISH | D2: HINDI | E2: MATHS | F2: SCIENCE | G2: SOCIAL STUDIES | H2: SANSKRIT | I2: COMPUTER | J2: G.K. | K2: ART | L2: Attendance
L3: Present | M3: Working Day
A4: =DETAILS!A3 -> 1633 | B4: =DETAILS!B3 -> AADVIK SRIVASTAVA
A5: =DETAILS!A4 -> 1119 | B5: =DETAILS!B4 -> AARYASH SONI
A6: =DETAILS!A5 -> 1407 | B6: =DETAILS!B5 -> AKSHAY DUBEY
A7: =DETAILS!A6 -> 1077 | B7: =DETAILS!B6 -> ALISHA
A8: =DETAILS!A7 -> 1210 | B8: =DETAILS!B7 -> ANJALI JHA
A9: =DETAILS!A8 -> 1286 | B9: =DETAILS!B8 -> AROHI JAISWAL
A10: =DETAILS!A9 -> 1862 | B10: =DETAILS!B9 -> ASHUTOSH MISHRA
A11: =DETAILS!A10 -> 1684 | B11: =DETAILS!B10 -> AYUSH GUPTA
A12: =DETAILS!A11 -> 1662 | B12: =DETAILS!B11 -> AYUSH KUMAR YOGI
A13: =DETAILS!A12 -> 1602 | B13: =DETAILS!B12 -> AYUSHI MISHRA
A14: =DETAILS!A13 -> 1842 | B14: =DETAILS!B13 -> DEEPANSH YADAV
A15: =DETAILS!A14 -> 1127 | B15: =DETAILS!B14 -> DIKSHA MISHRA
... A44: =DETAILS!A43 -> 1773 | B44: =DETAILS!B43 -> YASHRAJ

Sheet UT-I 
A1: UNIT TEST-I (2025-26) CLASS - VII
A2: SR. NO. | B2: NAME | C2: ENGLISH | D2: HINDI | E2: MATHS | F2: SCIENCE | G2: SOCIAL STUDIES | H2: SANSKRIT | I2: COMPUTER | J2: G.K. | K2: ART | L2: TOTAL | M2: PERCENTAGE | N2: Attendance
N3: Present | O3: Working Day
A4: =DETAILS!A3 -> 1633 | B4: =DETAILS!B3 -> AADVIK SRIVASTAVA | C4: =IFERROR(ROUND((VLOOKUP(A4,'UT-I(Entry)'!$1:$1048576,3,0))/2,0),VLOOKUP(A4,'UT-I(Entry)'!$1:$1048576,3,0)) -> 0 | D4: =IFERROR(ROUND((VLOOKUP(A4,'UT-I(Entry)'!$1:$1048576,4,0))/2,0),VLOOKUP(A4,'UT-I(Entry)'!$1:$1048576,4,0)) -> 0 | E4: =IFERROR(ROUND((VLOOKUP(A4,'UT-I(Entry)'!$1:$1048576,5,0))/2,0),VLOOKUP(A4,'UT-I(Entry)'!$1:$1048576,5,0)) -> 0 | F4: =IFERROR(ROUND((VLOOKUP(A4,'UT-I(Entry)'!$1:$1048576,6,0))/2,0),VLOOKUP(A4,'UT-I(Entry)'!$1:$1048576,6,0)) -> 0 | G4: =IFERROR(ROUND((VLOOKUP($A4,'UT-I(Entry)'!$1:$1048576,7,0))/2,0),VLOOKUP($A4,'UT-I(Entry)'!$1:$1048576,7,0)) -> 0 | H4: =IFERROR(ROUND((VLOOKUP($A4,'UT-I(Entry)'!$1:$1048576,8,0))/2,0),VLOOKUP($A4,'UT-I(Entry)'!$1:$1048576,8,0)) -> 0 | I4: =IFERROR(ROUND((VLOOKUP(A4,'UT-I(Entry)'!$1:$1048576,9,0))/2,0),VLOOKUP(A4,'UT-I(Entry)'!$1:$1048576,9,0)) -> 0 | J4: =IFERROR(VLOOKUP(VLOOKUP(A4,'UT-I(Entry)'!$1:$1048576,10,0),'Grade(40)'!$1:$1048576,2,0),VLOOKUP(A4,'UT-I(Entry)'!$1:$1048576,10,0)) -> E | K4: =IFERROR(VLOOKUP(VLOOKUP(A4,'UT-I(Entry)'!$1:$1048576,11,0),'Grade(40)'!$1:$1048576,2,0),VLOOKUP(A4,'UT-I(Entry)'!$1:$1048576,11,0)) -> E | L4: =SUM(C4:I4) -> 0 | M4: =ROUND(L4/1.4,2)&" %" -> 0 % | N4: =VLOOKUP(A4,'UT-I(Entry)'!$1:$1048576,12,0) -> 0 | O4: =VLOOKUP(A4,'UT-I(Entry)'!$1:$1048576,13,0) -> 0
A5: =DETAILS!A4 -> 1119 | B5: =DETAILS!B4 -> AARYASH SONI | C5: =IFERROR(ROUND((VLOOKUP(A5,'UT-I(Entry)'!$1:$1048576,3,0))/2,0),VLOOKUP(A5,'UT-I(Entry)'!$1:$1048576,3,0)) -> 0 | D5: =IFERROR(ROUND((VLOOKUP(A5,'UT-I(Entry)'!$1:$1048576,4,0))/2,0),VLOOKUP(A5,'UT-I(Entry)'!$1:$1048576,4,0)) -> 0 | E5: =IFERROR(ROUND((VLOOKUP(A5,'UT-I(Entry)'!$1:$1048576,5,0))/2,0),VLOOKUP(A5,'UT-I(Entry)'!$1:$1048576,5,0)) -> 0 | F5: =IFERROR(ROUND((VLOOKUP(A5,'UT-I(Entry)'!$1:$1048576,6,0))/2,0),VLOOKUP(A5,'UT-I(Entry)'!$1:$1048576,6,0)) -> 0 | G5: =IFERROR(ROUND((VLOOKUP($A5,'UT-I(Entry)'!$1:$1048576,7,0))/2,0),VLOOKUP(A5,'UT-I(Entry)'!$1:$1048576,7,0)) -> 0 | H5: =IFERROR(ROUND((VLOOKUP($A5,'UT-I(Entry)'!$1:$1048576,8,0))/2,0),VLOOKUP($A5,'UT-I(Entry)'!$1:$1048576,8,0)) -> 0 | I5: =IFERROR(ROUND((VLOOKUP(A5,'UT-I(Entry)'!$1:$1048576,9,0))/2,0),VLOOKUP(A5,'UT-I(Entry)'!$1:$1048576,9,0)) -> 0 | J5: =IFERROR(VLOOKUP(VLOOKUP(A5,'UT-I(Entry)'!$1:$1048576,10,0),'Grade(40)'!$1:$1048576,2,0),VLOOKUP(A5,'UT-I(Entry)'!$1:$1048576,10,0)) -> E | K5: =IFERROR(VLOOKUP(VLOOKUP(A5,'UT-I(Entry)'!$1:$1048576,11,0),'Grade(40)'!$1:$1048576,2,0),VLOOKUP(A5,'UT-I(Entry)'!$1:$1048576,11,0)) -> E | L5: =SUM(C5:I5) -> 0 | M5: =ROUND(L5/1.4,2)&" %" -> 0 % | N5: =VLOOKUP(A5,'UT-I(Entry)'!$1:$1048576,12,0) -> 0 | O5: =VLOOKUP(A5,'UT-I(Entry)'!$1:$1048576,13,0) -> 0
A6: =DETAILS!A5 -> 1407 | B6: =DETAILS!B5 -> AKSHAY DUBEY | C6: =IFERROR(ROUND((VLOOKUP(A6,'UT-I(Entry)'!$1:$1048576,3,0))/2,0),VLOOKUP(A6,'UT-I(Entry)'!$1:$1048576,3,0)) -> 0 | D6: =IFERROR(ROUND((VLOOKUP(A6,'UT-I(Entry)'!$1:$1048576,4,0))/2,0),VLOOKUP(A6,'UT-I(Entry)'!$1:$1048576,4,0)) -> 0 | E6: =IFERROR(ROUND((VLOOKUP(A6,'UT-I(Entry)'!$1:$1048576,5,0))/2,0),VLOOKUP(A6,'UT-I(Entry)'!$1:$1048576,5,0)) -> 0 | F6: =IFERROR(ROUND((VLOOKUP(A6,'UT-I(Entry)'!$1:$1048576,6,0))/2,0),VLOOKUP(A6,'UT-I(Entry)'!$1:$1048576,6,0)) -> 0 | G6: =IFERROR(ROUND((VLOOKUP($A6,'UT-I(Entry)'!$1:$1048576,7,0))/2,0),VLOOKUP(A6,'UT-I(Entry)'!$1:$1048576,7,0)) -> 0 | H6: =IFERROR(ROUND((VLOOKUP($A6,'UT-I(Entry)'!$1:$1048576,8,0))/2,0),VLOOKUP($A6,'UT-I(Entry)'!$1:$1048576,8,0)) -> 0 | I6: =IFERROR(ROUND((VLOOKUP(A6,'UT-I(Entry)'!$1:$1048576,9,0))/2,0),VLOOKUP(A6,'UT-I(Entry)'!$1:$1048576,9,0)) -> 0 | J6: =IFERROR(VLOOKUP(VLOOKUP(A6,'UT-I(Entry)'!$1:$1048576,10,0),'Grade(40)'!$1:$1048576,2,0),VLOOKUP(A6,'UT-I(Entry)'!$1:$1048576,10,0)) -> E | K6: =IFERROR(VLOOKUP(VLOOKUP(A6,'UT-I(Entry)'!$1:$1048576,11,0),'Grade(40)'!$1:$1048576,2,0),VLOOKUP(A6,'UT-I(Entry)'!$1:$1048576,11,0)) -> E | L6: =SUM(C6:I6) -> 0 | M6: =ROUND(L6/1.4,2)&" %" -> 0 % | N6: =VLOOKUP(A6,'UT-I(Entry)'!$1:$1048576,12,0) -> 0 | O6: =VLOOKUP(A6,'UT-I(Entry)'!$1:$1048576,13,0) -> 0
A7: =DETAILS!A6 -> 1077 | B7: =DETAILS!B6 -> ALISHA | C7: =IFERROR(ROUND((VLOOKUP(A7,'UT-I(Entry)'!$1:$1048576,3,0))/2,0),VLOOKUP(A7,'UT-I(Entry)'!$1:$1048576,3,0)) -> 0 | D7: =IFERROR(ROUND((VLOOKUP(A7,'UT-I(Entry)'!$1:$1048576,4,0))/2,0),VLOOKUP(A7,'UT-I(Entry)'!$1:$1048576,4,0)) -> 0 | E7: =IFERROR(ROUND((VLOOKUP(A7,'UT-I(Entry)'!$1:$1048576,5,0))/2,0),VLOOKUP(A7,'UT-I(Entry)'!$1:$1048576,5,0)) -> 0 | F7: =IFERROR(ROUND((VLOOKUP(A7,'UT-I(Entry)'!$1:$1048576,6,0))/2,0),VLOOKUP(A7,'UT-I(Entry)'!$1:$1048576,6,0)) -> 0 | G7: =IFERROR(ROUND((VLOOKUP($A7,'UT-I(Entry)'!$1:$1048576,7,0))/2,0),VLOOKUP(A7,'UT-I(Entry)'!$1:$1048576,7,0)) -> 0 | H7: =IFERROR(ROUND((VLOOKUP($A7,'UT-I(Entry)'!$1:$1048576,8,0))/2,0),VLOOKUP($A7,'UT-I(Entry)'!$1:$1048576,8,0)) -> 0 | I7: =IFERROR(ROUND((VLOOKUP(A7,'UT-I(Entry)'!$1:$1048576,9,0))/2,0),VLOOKUP(A7,'UT-I(Entry)'!$1:$1048576,9,0)) -> 0 | J7: =IFERROR(VLOOKUP(VLOOKUP(A7,'UT-I(Entry)'!$1:$1048576,10,0),'Grade(40)'!$1:$1048576,2,0),VLOOKUP(A7,'UT-I(Entry)'!$1:$1048576,10,0)) -> E | K7: =IFERROR(VLOOKUP(VLOOKUP(A7,'UT-I(Entry)'!$1:$1048576,11,0),'Grade(40)'!$1:$1048576,2,0),VLOOKUP(A7,'UT-I(Entry)'!$1:$1048576,11,0)) -> E | L7: =SUM(C7:I7) -> 0 | M7: =ROUND(L7/1.4,2)&" %" -> 0 % | N7: =VLOOKUP(A7,'UT-I(Entry)'!$1:$1048576,12,0) -> 0 | O7: =VLOOKUP(A7,'UT-I(Entry)'!$1:$1048576,13,0) -> 0
A8: =DETAILS!A7 -> 1210 | B8: =DETAILS!B7 -> ANJALI JHA | C8: =IFERROR(ROUND((VLOOKUP(A8,'UT-I(Entry)'!$1:$1048576,3,0))/2,0),VLOOKUP(A8,'UT-I(Entry)'!$1:$1048576,3,0)) -> 0 | D8: =IFERROR(ROUND((VLOOKUP(A8,'UT-I(Entry)'!$1:$1048576,4,0))/2,0),VLOOKUP(A8,'UT-I(Entry)'!$1:$1048576,4,0)) -> 0 | E8: =IFERROR(ROUND((VLOOKUP(A8,'UT-I(Entry)'!$1:$1048576,5,0))/2,0),VLOOKUP(A8,'UT-I(Entry)'!$1:$1048576,5,0)) -> 0 | F8: =IFERROR(ROUND((VLOOKUP(A8,'UT-I(Entry)'!$1:$1048576,6,0))/2,0),VLOOKUP(A8,'UT-I(Entry)'!$1:$1048576,6,0)) -> 0 | G8: =IFERROR(ROUND((VLOOKUP($A8,'UT-I(Entry)'!$1:$1048576,7,0))/2,0),VLOOKUP(A8,'UT-I(Entry)'!$1:$1048576,7,0)) -> 0 | H8: =IFERROR(ROUND((VLOOKUP($A8,'UT-I(Entry)'!$1:$1048576,8,0))/2,0),VLOOKUP($A8,'UT-I(Entry)'!$1:$1048576,8,0)) -> 0 | I8: =IFERROR(ROUND((VLOOKUP(A8,'UT-I(Entry)'!$1:$1048576,9,0))/2,0),VLOOKUP(A8,'UT-I(Entry)'!$1:$1048576,9,0)) -> 0 | J8: =IFERROR(VLOOKUP(VLOOKUP(A8,'UT-I(Entry)'!$1:$1048576,10,0),'Grade(40)'!$1:$1048576,2,0),VLOOKUP(A8,'UT-I(Entry)'!$1:$1048576,10,0)) -> E | K8: =IFERROR(VLOOKUP(VLOOKUP(A8,'UT-I(Entry)'!$1:$1048576,11,0),'Grade(40)'!$1:$1048576,2,0),VLOOKUP(A8,'UT-I(Entry)'!$1:$1048576,11,0)) -> E | L8: =SUM(C8:I8) -> 0 | M8: =ROUND(L8/1.4,2)&" %" -> 0 % | N8: =VLOOKUP(A8,'UT-I(Entry)'!$1:$1048576,12,0) -> 0 | O8: =VLOOKUP(A8,'UT-I(Entry)'!$1:$1048576,13,0) -> 0
A9: =DETAILS!A8 -> 1286 | B9: =DETAILS!B8 -> AROHI JAISWAL | C9: =IFERROR(ROUND((VLOOKUP(A9,'UT-I(Entry)'!$1:$1048576,3,0))/2,0),VLOOKUP(A9,'UT-I(Entry)'!$1:$1048576,3,0)) -> 0 | D9: =IFERROR(ROUND((VLOOKUP(A9,'UT-I(Entry)'!$1:$1048576,4,0))/2,0),VLOOKUP(A9,'UT-I(Entry)'!$1:$1048576,4,0)) -> 0 | E9: =IFERROR(ROUND((VLOOKUP(A9,'UT-I(Entry)'!$1:$1048576,5,0))/2,0),VLOOKUP(A9,'UT-I(Entry)'!$1:$1048576,5,0)) -> 0 | F9: =IFERROR(ROUND((VLOOKUP(A9,'UT-I(Entry)'!$1:$1048576,6,0))/2,0),VLOOKUP(A9,'UT-I(Entry)'!$1:$1048576,6,0)) -> 0 | G9: =IFERROR(ROUND((VLOOKUP($A9,'UT-I(Entry)'!$1:$1048576,7,0))/2,0),VLOOKUP(A9,'UT-I(Entry)'!$1:$1048576,7,0)) -> 0 | H9: =IFERROR(ROUND((VLOOKUP($A9,'UT-I(Entry)'!$1:$1048576,8,0))/2,0),VLOOKUP($A9,'UT-I(Entry)'!$1:$1048576,8,0)) -> 0 | I9: =IFERROR(ROUND((VLOOKUP(A9,'UT-I(Entry)'!$1:$1048576,9,0))/2,0),VLOOKUP(A9,'UT-I(Entry)'!$1:$1048576,9,0)) -> 0 | J9: =IFERROR(VLOOKUP(VLOOKUP(A9,'UT-I(Entry)'!$1:$1048576,10,0),'Grade(40)'!$1:$1048576,2,0),VLOOKUP(A9,'UT-I(Entry)'!$1:$1048576,10,0)) -> E | K9: =IFERROR(VLOOKUP(VLOOKUP(A9,'UT-I(Entry)'!$1:$1048576,11,0),'Grade(40)'!$1:$1048576,2,0),VLOOKUP(A9,'UT-I(Entry)'!$1:$1048576,11,0)) -> E | L9: =SUM(C9:I9) -> 0 | M9: =ROUND(L9/1.4,2)&" %" -> 0 % | N9: =VLOOKUP(A9,'UT-I(Entry)'!$1:$1048576,12,0) -> 0 | O9: =VLOOKUP(A9,'UT-I(Entry)'!$1:$1048576,13,0) -> 0
A10: =DETAILS!A9 -> 1862 | B10: =DETAILS!B9 -> ASHUTOSH MISHRA | C10: =IFERROR(ROUND((VLOOKUP(A10,'UT-I(Entry)'!$1:$1048576,3,0))/2,0),VLOOKUP(A10,'UT-I(Entry)'!$1:$1048576,3,0)) -> 0 | D10: =IFERROR(ROUND((VLOOKUP(A10,'UT-I(Entry)'!$1:$1048576,4,0))/2,0),VLOOKUP(A10,'UT-I(Entry)'!$1:$1048576,4,0)) -> 0 | E10: =IFERROR(ROUND((VLOOKUP(A10,'UT-I(Entry)'!$1:$1048576,5,0))/2,0),VLOOKUP(A10,'UT-I(Entry)'!$1:$1048576,5,0)) -> 0 | F10: =IFERROR(ROUND((VLOOKUP(A10,'UT-I(Entry)'!$1:$1048576,6,0))/2,0),VLOOKUP(A10,'UT-I(Entry)'!$1:$1048576,6,0)) -> 0 | G10: =IFERROR(ROUND((VLOOKUP($A10,'UT-I(Entry)'!$1:$1048576,7,0))/2,0),VLOOKUP(A10,'UT-I(Entry)'!$1:$1048576,7,0)) -> 0 | H10: =IFERROR(ROUND((VLOOKUP($A10,'UT-I(Entry)'!$1:$1048576,8,0))/2,0),VLOOKUP($A10,'UT-I(Entry)'!$1:$1048576,8,0)) -> 0 | I10: =IFERROR(ROUND((VLOOKUP(A10,'UT-I(Entry)'!$1:$1048576,9,0))/2,0),VLOOKUP(A10,'UT-I(Entry)'!$1:$1048576,9,0)) -> 0 | J10: =IFERROR(VLOOKUP(VLOOKUP(A10,'UT-I(Entry)'!$1:$1048576,10,0),'Grade(40)'!$1:$1048576,2,0),VLOOKUP(A10,'UT-I(Entry)'!$1:$1048576,10,0)) -> E | K10: =IFERROR(VLOOKUP(VLOOKUP(A10,'UT-I(Entry)'!$1:$1048576,11,0),'Grade(40)'!$1:$1048576,2,0),VLOOKUP(A10,'UT-I(Entry)'!$1:$1048576,11,0)) -> E | L10: =SUM(C10:I10) -> 0 | M10: =ROUND(L10/1.4,2)&" %" -> 0 % | N10: =VLOOKUP(A10,'UT-I(Entry)'!$1:$1048576,12,0) -> 0 | O10: =VLOOKUP(A10,'UT-I(Entry)'!$1:$1048576,13,0) -> 0
A11: =DETAILS!A10 -> 1684 | B11: =DETAILS!B10 -> AYUSH GUPTA | C11: =IFERROR(ROUND((VLOOKUP(A11,'UT-I(Entry)'!$1:$1048576,3,0))/2,0),VLOOKUP(A11,'UT-I(Entry)'!$1:$1048576,3,0)) -> 0 | D11: =IFERROR(ROUND((VLOOKUP(A11,'UT-I(Entry)'!$1:$1048576,4,0))/2,0),VLOOKUP(A11,'UT-I(Entry)'!$1:$1048576,4,0)) -> 0 | E11: =IFERROR(ROUND((VLOOKUP(A11,'UT-I(Entry)'!$1:$1048576,5,0))/2,0),VLOOKUP(A11,'UT-I(Entry)'!$1:$1048576,5,0)) -> 0 | F11: =IFERROR(ROUND((VLOOKUP(A11,'UT-I(Entry)'!$1:$1048576,6,0))/2,0),VLOOKUP(A11,'UT-I(Entry)'!$1:$1048576,6,0)) -> 0 | G11: =IFERROR(ROUND((VLOOKUP($A11,'UT-I(Entry)'!$1:$1048576,7,0))/2,0),VLOOKUP(A11,'UT-I(Entry)'!$1:$1048576,7,0)) -> 0 | H11: =IFERROR(ROUND((VLOOKUP($A11,'UT-I(Entry)'!$1:$1048576,8,0))/2,0),VLOOKUP($A11,'UT-I(Entry)'!$1:$1048576,8,0)) -> 0 | I11: =IFERROR(ROUND((VLOOKUP(A11,'UT-I(Entry)'!$1:$1048576,9,0))/2,0),VLOOKUP(A11,'UT-I(Entry)'!$1:$1048576,9,0)) -> 0 | J11: =IFERROR(VLOOKUP(VLOOKUP(A11,'UT-I(Entry)'!$1:$1048576,10,0),'Grade(40)'!$1:$1048576,2,0),VLOOKUP(A11,'UT-I(Entry)'!$1:$1048576,10,0)) -> E | K11: =IFERROR(VLOOKUP(VLOOKUP(A11,'UT-I(Entry)'!$1:$1048576,11,0),'Grade(40)'!$1:$1048576,2,0),VLOOKUP(A11,'UT-I(Entry)'!$1:$1048576,11,0)) -> E | L11: =SUM(C11:I11) -> 0 | M11: =ROUND(L11/1.4,2)&" %" -> 0 % | N11: =VLOOKUP(A11,'UT-I(Entry)'!$1:$1048576,12,0) -> 0 | O11: =VLOOKUP(A11,'UT-I(Entry)'!$1:$1048576,13,0) -> 0
A12: =DETAILS!A11 -> 1662 | B12: =DETAILS!B11 -> AYUSH KUMAR YOGI | C12: =IFERROR(ROUND((VLOOKUP(A12,'UT-I(Entry)'!$1:$1048576,3,0))/2,0),VLOOKUP(A12,'UT-I(Entry)'!$1:$1048576,3,0)) -> 0 | D12: =IFERROR(ROUND((VLOOKUP(A12,'UT-I(Entry)'!$1:$1048576,4,0))/2,0),VLOOKUP(A12,'UT-I(Entry)'!$1:$1048576,4,0)) -> 0 | E12: =IFERROR(ROUND((VLOOKUP(A12,'UT-I(Entry)'!$1:$1048576,5,0))/2,0),VLOOKUP(A12,'UT-I(Entry)'!$1:$1048576,5,0)) -> 0 | F12: =IFERROR(ROUND((VLOOKUP(A12,'UT-I(Entry)'!$1:$1048576,6,0))/2,0),VLOOKUP(A12,'UT-I(Entry)'!$1:$1048576,6,0)) -> 0 | G12: =IFERROR(ROUND((VLOOKUP($A12,'UT-I(Entry)'!$1:$1048576,7,0))/2,0),VLOOKUP(A12,'UT-I(Entry)'!$1:$1048576,7,0)) -> 0 | H12: =IFERROR(ROUND((VLOOKUP($A12,'UT-I(Entry)'!$1:$1048576,8,0))/2,0),VLOOKUP($A12,'UT-I(Entry)'!$1:$1048576,8,0)) -> 0 | I12: =IFERROR(ROUND((VLOOKUP(A12,'UT-I(Entry)'!$1:$1048576,9,0))/2,0),VLOOKUP(A12,'UT-I(Entry)'!$1:$1048576,9,0)) -> 0 | J12: =IFERROR(VLOOKUP(VLOOKUP(A12,'UT-I(Entry)'!$1:$1048576,10,0),'Grade(40)'!$1:$1048576,2,0),VLOOKUP(A12,'UT-I(Entry)'!$1:$1048576,10,0)) -> E | K12: =IFERROR(VLOOKUP(VLOOKUP(A12,'UT-I(Entry)'!$1:$1048576,11,0),'Grade(40)'!$1:$1048576,2,0),VLOOKUP(A12,'UT-I(Entry)'!$1:$1048576,11,0)) -> E | L12: =SUM(C12:I12) -> 0 | M12: =ROUND(L12/1.4,2)&" %" -> 0 % | N12: =VLOOKUP(A12,'UT-I(Entry)'!$1:$1048576,12,0) -> 0 | O12: =VLOOKUP(A12,'UT-I(Entry)'!$1:$1048576,13,0) -> 0
A13: =DETAILS!A12 -> 1602 | B13: =DETAILS!B12 -> AYUSHI MISHRA | C13: =IFERROR(ROUND((VLOOKUP(A13,'UT-I(Entry)'!$1:$1048576,3,0))/2,0),VLOOKUP(A13,'UT-I(Entry)'!$1:$1048576,3,0)) -> 0 | D13: =IFERROR(ROUND((VLOOKUP(A13,'UT-I(Entry)'!$1:$1048576,4,0))/2,0),VLOOKUP(A13,'UT-I(Entry)'!$1:$1048576,4,0)) -> 0 | E13: =IFERROR(ROUND((VLOOKUP(A13,'UT-I(Entry)'!$1:$1048576,5,0))/2,0),VLOOKUP(A13,'UT-I(Entry)'!$1:$1048576,5,0)) -> 0 | F13: =IFERROR(ROUND((VLOOKUP(A13,'UT-I(Entry)'!$1:$1048576,6,0))/2,0),VLOOKUP(A13,'UT-I(Entry)'!$1:$1048576,6,0)) -> 0 | G13: =IFERROR(ROUND((VLOOKUP($A13,'UT-I(Entry)'!$1:$1048576,7,0))/2,0),VLOOKUP(A13,'UT-I(Entry)'!$1:$1048576,7,0)) -> 0 | H13: =IFERROR(ROUND((VLOOKUP($A13,'UT-I(Entry)'!$1:$1048576,8,0))/2,0),VLOOKUP($A13,'UT-I(Entry)'!$1:$1048576,8,0)) -> 0 | I13: =IFERROR(ROUND((VLOOKUP(A13,'UT-I(Entry)'!$1:$1048576,9,0))/2,0),VLOOKUP(A13,'UT-I(Entry)'!$1:$1048576,9,0)) -> 0 | J13: =IFERROR(VLOOKUP(VLOOKUP(A13,'UT-I(Entry)'!$1:$1048576,10,0),'Grade(40)'!$1:$1048576,2,0),VLOOKUP(A13,'UT-I(Entry)'!$1:$1048576,10,0)) -> E | K13: =IFERROR(VLOOKUP(VLOOKUP(A13,'UT-I(Entry)'!$1:$1048576,11,0),'Grade(40)'!$1:$1048576,2,0),VLOOKUP(A13,'UT-I(Entry)'!$1:$1048576,11,0)) -> E | L13: =SUM(C13:I13) -> 0 | M13: =ROUND(L13/1.4,2)&" %" -> 0 % | N13: =VLOOKUP(A13,'UT-I(Entry)'!$1:$1048576,12,0) -> 0 | O13: =VLOOKUP(A13,'UT-I(Entry)'!$1:$1048576,13,0) -> 0
A14: =DETAILS!A13 -> 1842 | B14: =DETAILS!B13 -> DEEPANSH YADAV | C14: =IFERROR(ROUND((VLOOKUP(A14,'UT-I(Entry)'!$1:$1048576,3,0))/2,0),VLOOKUP(A14,'UT-I(Entry)'!$1:$1048576,3,0)) -> 0 | D14: =IFERROR(ROUND((VLOOKUP(A14,'UT-I(Entry)'!$1:$1048576,4,0))/2,0),VLOOKUP(A14,'UT-I(Entry)'!$1:$1048576,4,0)) -> 0 | E14: =IFERROR(ROUND((VLOOKUP(A14,'UT-I(Entry)'!$1:$1048576,5,0))/2,0),VLOOKUP(A14,'UT-I(Entry)'!$1:$1048576,5,0)) -> 0 | F14: =IFERROR(ROUND((VLOOKUP(A14,'UT-I(Entry)'!$1:$1048576,6,0))/2,0),VLOOKUP(A14,'UT-I(Entry)'!$1:$1048576,6,0)) -> 0 | G14: =IFERROR(ROUND((VLOOKUP($A14,'UT-I(Entry)'!$1:$1048576,7,0))/2,0),VLOOKUP(A14,'UT-I(Entry)'!$1:$1048576,7,0)) -> 0 | H14: =IFERROR(ROUND((VLOOKUP($A14,'UT-I(Entry)'!$1:$1048576,8,0))/2,0),VLOOKUP($A14,'UT-I(Entry)'!$1:$1048576,8,0)) -> 0 | I14: =IFERROR(ROUND((VLOOKUP(A14,'UT-I(Entry)'!$1:$1048576,9,0))/2,0),VLOOKUP(A14,'UT-I(Entry)'!$1:$1048576,9,0)) -> 0 | J14: =IFERROR(VLOOKUP(VLOOKUP(A14,'UT-I(Entry)'!$1:$1048576,10,0),'Grade(40)'!$1:$1048576,2,0),VLOOKUP(A14,'UT-I(Entry)'!$1:$1048576,10,0)) -> E | K14: =IFERROR(VLOOKUP(VLOOKUP(A14,'UT-I(Entry)'!$1:$1048576,11,0),'Grade(40)'!$1:$1048576,2,0),VLOOKUP(A14,'UT-I(Entry)'!$1:$1048576,11,0)) -> E | L14: =SUM(C14:I14) -> 0 | M14: =ROUND(L14/1.4,2)&" %" -> 0 % | N14: =VLOOKUP(A14,'UT-I(Entry)'!$1:$1048576,12,0) -> 0 | O14: =VLOOKUP(A14,'UT-I(Entry)'!$1:$1048576,13,0) -> 0
A15: =DETAILS!A14 -> 1127 | B15: =DETAILS!B14 -> DIKSHA MISHRA | C15: =IFERROR(ROUND((VLOOKUP(A15,'UT-I(Entry)'!$1:$1048576,3,0))/2,0),VLOOKUP(A15,'UT-I(Entry)'!$1:$1048576,3,0)) -> 0 | D15: =IFERROR(ROUND((VLOOKUP(A15,'UT-I(Entry)'!$1:$1048576,4,0))/2,0),VLOOKUP(A15,'UT-I(Entry)'!$1:$1048576,4,0)) -> 0 | E15: =IFERROR(ROUND((VLOOKUP(A15,'UT-I(Entry)'!$1:$1048576,5,0))/2,0),VLOOKUP(A15,'UT-I(Entry)'!$1:$1048576,5,0)) -> 0 | F15: =IFERROR(ROUND((VLOOKUP(A15,'UT-I(Entry)'!$1:$1048576,6,0))/2,0),VLOOKUP(A15,'UT-I(Entry)'!$1:$1048576,6,0)) -> 0 | G15: =IFERROR(ROUND((VLOOKUP($A15,'UT-I(Entry)'!$1:$1048576,7,0))/2,0),VLOOKUP(A15,'UT-I(Entry)'!$1:$1048576,7,0)) -> 0 | H15: =IFERROR(ROUND((VLOOKUP($A15,'UT-I(Entry)'!$1:$1048576,8,0))/2,0),VLOOKUP($A15,'UT-I(Entry)'!$1:$1048576,8,0)) -> 0 | I15: =IFERROR(ROUND((VLOOKUP(A15,'UT-I(Entry)'!$1:$1048576,9,0))/2,0),VLOOKUP(A15,'UT-I(Entry)'!$1:$1048576,9,0)) -> 0 | J15: =IFERROR(VLOOKUP(VLOOKUP(A15,'UT-I(Entry)'!$1:$1048576,10,0),'Grade(40)'!$1:$1048576,2,0),VLOOKUP(A15,'UT-I(Entry)'!$1:$1048576,10,0)) -> E | K15: =IFERROR(VLOOKUP(VLOOKUP(A15,'UT-I(Entry)'!$1:$1048576,11,0),'Grade(40)'!$1:$1048576,2,0),VLOOKUP(A15,'UT-I(Entry)'!$1:$1048576,11,0)) -> E | L15: =SUM(C15:I15) -> 0 | M15: =ROUND(L15/1.4,2)&" %" -> 0 % | N15: =VLOOKUP(A15,'UT-I(Entry)'!$1:$1048576,12,0) -> 0 | O15: =VLOOKUP(A15,'UT-I(Entry)'!$1:$1048576,13,0) -> 0
A16: =DETAILS!A15 -> 1128 | B16: =DETAILS!B15 -> DIVYANSHI KANAUJIA | C16: =IFERROR(ROUND((VLOOKUP(A16,'UT-I(Entry)'!$1:$1048576,3,0))/2,0),VLOOKUP(A16,'UT-I(Entry)'!$1:$1048576,3,0)) -> 0 | D16: =IFERROR(ROUND((VLOOKUP(A16,'UT-I(Entry)'!$1:$1048576,4,0))/2,0),VLOOKUP(A16,'UT-I(Entry)'!$1:$1048576,4,0)) -> 0 | E16: =IFERROR(ROUND((VLOOKUP(A16,'UT-I(Entry)'!$1:$1048576,5,0))/2,0),VLOOKUP(A16,'UT-I(Entry)'!$1:$1048576,5,0)) -> 0 | F16: =IFERROR(ROUND((VLOOKUP(A16,'UT-I(Entry)'!$1:$1048576,6,0))/2,0),VLOOKUP(A16,'UT-I(Entry)'!$1:$1048576,6,0)) -> 0 | G16: =IFERROR(ROUND((VLOOKUP($A16,'UT-I(Entry)'!$1:$1048576,7,0))/2,0),VLOOKUP(A16,'UT-I(Entry)'!$1:$1048576,7,0)) -> 0 | H16: =IFERROR(ROUND((VLOOKUP($A16,'UT-I(Entry)'!$1:$1048576,8,0))/2,0),VLOOKUP($A16,'UT-I(Entry)'!$1:$1048576,8,0)) -> 0 | I16: =IFERROR(ROUND((VLOOKUP(A16,'UT-I(Entry)'!$1:$1048576,9,0))/2,0),VLOOKUP(A16,'UT-I(Entry)'!$1:$1048576,9,0)) -> 0 | J16: =IFERROR(VLOOKUP(VLOOKUP(A16,'UT-I(Entry)'!$1:$1048576,10,0),'Grade(40)'!$1:$1048576,2,0),VLOOKUP(A16,'UT-I(Entry)'!$1:$1048576,10,0)) -> E | K16: =IFERROR(VLOOKUP(VLOOKUP(A16,'UT-I(Entry)'!$1:$1048576,11,0),'Grade(40)'!$1:$1048576,2,0),VLOOKUP(A16,'UT-I(Entry)'!$1:$1048576,11,0)) -> E | L16: =SUM(C16:I16) -> 0 | M16: =ROUND(L16/1.4,2)&" %" -> 0 % | N16: =VLOOKUP(A16,'UT-I(Entry)'!$1:$1048576,12,0) -> 0 | O16: =VLOOKUP(A16,'UT-I(Entry)'!$1:$1048576,13,0) -> 0
... A44: =DETAILS!A43 -> 1773 | B44: =DETAILS!B43 -> YASHRAJ | C44: =IFERROR(ROUND((VLOOKUP(A44,'UT-I(Entry)'!$1:$1048576,3,0))/2,0),VLOOKUP(A44,'UT-I(Entry)'!$1:$1048576,3,0)) -> 0 | D44: =IFERROR(ROUND((VLOOKUP(A44,'UT-I(Entry)'!$1:$1048576,4,0))/2,0),VLOOKUP(A44,'UT-I(Entry)'!$1:$1048576,4,0)) -> 0 | E44: =IFERROR(ROUND((VLOOKUP(A44,'UT-I(Entry)'!$1:$1048576,5,0))/2,0),VLOOKUP(A44,'UT-I(Entry)'!$1:$1048576,5,0)) -> 0 | F44: =IFERROR(ROUND((VLOOKUP(A44,'UT-I(Entry)'!$1:$1048576,6,0))/2,0),VLOOKUP(A44,'UT-I(Entry)'!$1:$1048576,6,0)) -> 0 | G44: =IFERROR(ROUND((VLOOKUP($A44,'UT-I(Entry)'!$1:$1048576,7,0))/2,0),VLOOKUP(A44,'UT-I(Entry)'!$1:$1048576,7,0)) -> 0 | H44: =IFERROR(ROUND((VLOOKUP($A44,'UT-I(Entry)'!$1:$1048576,8,0))/2,0),VLOOKUP($A44,'UT-I(Entry)'!$1:$1048576,8,0)) -> 0 | I44: =IFERROR(ROUND((VLOOKUP(A44,'UT-I(Entry)'!$1:$1048576,9,0))/2,0),VLOOKUP(A44,'UT-I(Entry)'!$1:$1048576,9,0)) -> 0 | J44: =IFERROR(VLOOKUP(VLOOKUP(A44,'UT-I(Entry)'!$1:$1048576,10,0),'Grade(40)'!$1:$1048576,2,0),VLOOKUP(A44,'UT-I(Entry)'!$1:$1048576,10,0)) -> E | K44: =IFERROR(VLOOKUP(VLOOKUP(A44,'UT-I(Entry)'!$1:$1048576,11,0),'Grade(40)'!$1:$1048576,2,0),VLOOKUP(A44,'UT-I(Entry)'!$1:$1048576,11,0)) -> E | L44: =SUM(C44:I44) -> 0 | M44: =ROUND(L44/1.4,2)&" %" -> 0 % | N44: =VLOOKUP(A44,'UT-I(Entry)'!$1:$1048576,12,0) -> 0 | O44: =VLOOKUP(A44,'UT-I(Entry)'!$1:$1048576,13,0) -> 0

Sheet Grade(40)
A2: 40 | B2: A
A3: 39 | B3: A
A4: 38 | B4: A
A5: 37 | B5: A
A6: 36 | B6: A
A7: 35 | B7: A
A8: 34 | B8: A
A9: 33 | B9: A
A10: 32 | B10: B
A11: 31 | B11: B
A12: 30 | B12: B
A13: 29 | B13: B
... A42: 0 | B42: E

Sheet NOTEBOOK-1 (Entry)
A1: NOTEBOOK-1 (2025-26) CLASS -III
A2: SR. NO. | B2: NAME | C2: ENGLISH | D2: HINDI | E2: MATHS | F2: SCIENCE | G2: SOCIAL STUDIES | H2: SANSKRIT | I2: COMPUTER
A3: =DETAILS!A3 -> 1633 | B3: =DETAILS!B3 -> AADVIK SRIVASTAVA
A4: =DETAILS!A4 -> 1119 | B4: =DETAILS!B4 -> AARYASH SONI
A5: =DETAILS!A5 -> 1407 | B5: =DETAILS!B5 -> AKSHAY DUBEY
A6: =DETAILS!A6 -> 1077 | B6: =DETAILS!B6 -> ALISHA
A7: =DETAILS!A7 -> 1210 | B7: =DETAILS!B7 -> ANJALI JHA
A8: =DETAILS!A8 -> 1286 | B8: =DETAILS!B8 -> AROHI JAISWAL
A9: =DETAILS!A9 -> 1862 | B9: =DETAILS!B9 -> ASHUTOSH MISHRA
A10: =DETAILS!A10 -> 1684 | B10: =DETAILS!B10 -> AYUSH GUPTA
A11: =DETAILS!A11 -> 1662 | B11: =DETAILS!B11 -> AYUSH KUMAR YOGI
A12: =DETAILS!A12 -> 1602 | B12: =DETAILS!B12 -> AYUSHI MISHRA
A13: =DETAILS!A13 -> 1842 | B13: =DETAILS!B13 -> DEEPANSH YADAV
A14: =DETAILS!A14 -> 1127 | B14: =DETAILS!B14 -> DIKSHA MISHRA
... A27: =DETAILS!A27 -> 1482 | B27: =DETAILS!B27 -> PRAVLEEN KAUR
A28: =DETAILS!A28 -> 1230 | B28: =DETAILS!B28 -> PRITHVE RAJ | I28: =SUM(C28:F28) -> 0
A29: =DETAILS!A29 -> 1395 | B29: =DETAILS!B29 -> RASHI PANDEY | I29: =SUM(C29:F29) -> 0
A30: =DETAILS!A30 -> 1897 | B30: =DETAILS!B30 -> RIYA SATISH KARPE | I30: =SUM(C30:F30) -> 0
A31: =DETAILS!A31 -> 1295 | B31: =DETAILS!B31 -> RIYA SINGH | I31: =SUM(C31:F31) -> 0
A32: =DETAILS!A32 -> 1728 | B32: =DETAILS!B32 -> SAMAR SINGH | I32: =SUM(C32:F32) -> 0
A33: =DETAILS!A33 -> 1660 | B33: =DETAILS!B33 -> SAMARTH SRIVASTAVA | I33: =SUM(C33:F33) -> 0
A34: =DETAILS!A34 -> 1942 | B34: =DETAILS!B34 -> SHAGUN SHUKLA | I34: =SUM(C34:F34) -> 0
A35: =DETAILS!A35 -> 1666 | B35: =DETAILS!B35 -> SHAURYA RAWAT | I35: =SUM(C35:F35) -> 0
A36: =DETAILS!A36 -> 1823 | B36: =DETAILS!B36 -> SHIVIKA SRIVASTAVA | I36: =SUM(C36:F36) -> 0
A37: =DETAILS!A37 -> 1848 | B37: =DETAILS!B37 -> SHRUTI KUMARI | I37: =SUM(C37:F37) -> 0
A38: =DETAILS!A38 -> 1137 | B38: =DETAILS!B38 -> SONALI YADAV | I38: =SUM(C38:F38) -> 0
A39: =DETAILS!A39 -> 1795 | B39: =DETAILS!B39 -> TEJASVA TRIPATHI | I39: =SUM(C39:F39) -> 0
... A41: =DETAILS!A41 -> 1860 | B41: =DETAILS!B41 -> VIKAS VERMA | I41: =SUM(C41:F41) -> 0

Sheet ENRICH-1(Entry)
A1: SUBJECT ENRICHMENT -1 (2025-26) CLASS -III
A2: SR. NO. | B2: NAME | C2: ENGLISH | D2: HINDI | E2: MATHS | F2: SCIENCE | G2: SOCIAL STUDIES | H2: SANSKRIT | I2: COMPUTER
A3: =DETAILS!A3 -> 1633 | B3: =DETAILS!B3 -> AADVIK SRIVASTAVA
A4: =DETAILS!A4 -> 1119 | B4: =DETAILS!B4 -> AARYASH SONI
A5: =DETAILS!A5 -> 1407 | B5: =DETAILS!B5 -> AKSHAY DUBEY
A6: =DETAILS!A6 -> 1077 | B6: =DETAILS!B6 -> ALISHA
A7: =DETAILS!A7 -> 1210 | B7: =DETAILS!B7 -> ANJALI JHA
A8: =DETAILS!A8 -> 1286 | B8: =DETAILS!B8 -> AROHI JAISWAL
A9: =DETAILS!A9 -> 1862 | B9: =DETAILS!B9 -> ASHUTOSH MISHRA
A10: =DETAILS!A10 -> 1684 | B10: =DETAILS!B10 -> AYUSH GUPTA
A11: =DETAILS!A11 -> 1662 | B11: =DETAILS!B11 -> AYUSH KUMAR YOGI
A12: =DETAILS!A12 -> 1602 | B12: =DETAILS!B12 -> AYUSHI MISHRA
A13: =DETAILS!A13 -> 1842 | B13: =DETAILS!B13 -> DEEPANSH YADAV
A14: =DETAILS!A14 -> 1127 | B14: =DETAILS!B14 -> DIKSHA MISHRA
... A27: =DETAILS!A27 -> 1482 | B27: =DETAILS!B27 -> PRAVLEEN KAUR
A28: =DETAILS!A28 -> 1230 | B28: =DETAILS!B28 -> PRITHVE RAJ | I28: =SUM(C28:F28) -> 0
A29: =DETAILS!A29 -> 1395 | B29: =DETAILS!B29 -> RASHI PANDEY | I29: =SUM(C29:F29) -> 0
A30: =DETAILS!A30 -> 1897 | B30: =DETAILS!B30 -> RIYA SATISH KARPE | I30: =SUM(C30:F30) -> 0
A31: =DETAILS!A31 -> 1295 | B31: =DETAILS!B31 -> RIYA SINGH | I31: =SUM(C31:F31) -> 0
A32: =DETAILS!A32 -> 1728 | B32: =DETAILS!B32 -> SAMAR SINGH | I32: =SUM(C32:F32) -> 0
A33: =DETAILS!A33 -> 1660 | B33: =DETAILS!B33 -> SAMARTH SRIVASTAVA | I33: =SUM(C33:F33) -> 0
A34: =DETAILS!A34 -> 1942 | B34: =DETAILS!B34 -> SHAGUN SHUKLA | I34: =SUM(C34:F34) -> 0
A35: =DETAILS!A35 -> 1666 | B35: =DETAILS!B35 -> SHAURYA RAWAT | I35: =SUM(C35:F35) -> 0
A36: =DETAILS!A36 -> 1823 | B36: =DETAILS!B36 -> SHIVIKA SRIVASTAVA | I36: =SUM(C36:F36) -> 0
A37: =DETAILS!A37 -> 1848 | B37: =DETAILS!B37 -> SHRUTI KUMARI | I37: =SUM(C37:F37) -> 0
A38: =DETAILS!A38 -> 1137 | B38: =DETAILS!B38 -> SONALI YADAV | I38: =SUM(C38:F38) -> 0
A39: =DETAILS!A39 -> 1795 | B39: =DETAILS!B39 -> TEJASVA TRIPATHI | I39: =SUM(C39:F39) -> 0
... A41: =DETAILS!A41 -> 1860 | B41: =DETAILS!B41 -> VIKAS VERMA | I41: =SUM(C41:F41) -> 0

Sheet HALF YEARLY(Entry)
A1: HALF YEARLY EXAMINATION (2025-26) CLASS - III
A2: SR. NO. | B2: NAME | C2: ENGLISH | D2: HINDI | E2: MATHS | F2: SCIENCE | G2: SOCIAL STUDIES | H2: SANSKRIT | I2: COMPUTER | J2: WORK EDUCATION | K2: ART EDUCATION | L2: GENERAL KNOWLEDGE | M2: HEALTH & PHYSICAL EDUCATION | N2: DISCIPLINE | O2: Total Present | P2: Total Working | Q2: Class Teacher's Remark | R2: TOTAL | S2: Percentage
A3: =DETAILS!A3 -> 1633 | B3: =DETAILS!B3 -> AADVIK SRIVASTAVA | R3: =SUM(C3:I3) -> 0 | S3: =ROUND(R3/4.8,2)&" %" -> 0 %
A4: =DETAILS!A4 -> 1119 | B4: =DETAILS!B4 -> AARYASH SONI | R4: =SUM(C4:I4) -> 0 | S4: =ROUND(R4/4.8,2)&" %" -> 0 %
A5: =DETAILS!A5 -> 1407 | B5: =DETAILS!B5 -> AKSHAY DUBEY | R5: =SUM(C5:I5) -> 0 | S5: =ROUND(R5/4.8,2)&" %" -> 0 %
A6: =DETAILS!A6 -> 1077 | B6: =DETAILS!B6 -> ALISHA | R6: =SUM(C6:I6) -> 0 | S6: =ROUND(R6/4.8,2)&" %" -> 0 %
A7: =DETAILS!A7 -> 1210 | B7: =DETAILS!B7 -> ANJALI JHA | R7: =SUM(C7:I7) -> 0 | S7: =ROUND(R7/4.8,2)&" %" -> 0 %
A8: =DETAILS!A8 -> 1286 | B8: =DETAILS!B8 -> AROHI JAISWAL | R8: =SUM(C8:I8) -> 0 | S8: =ROUND(R8/4.8,2)&" %" -> 0 %
A9: =DETAILS!A9 -> 1862 | B9: =DETAILS!B9 -> ASHUTOSH MISHRA | R9: =SUM(C9:I9) -> 0 | S9: =ROUND(R9/4.8,2)&" %" -> 0 %
A10: =DETAILS!A10 -> 1684 | B10: =DETAILS!B10 -> AYUSH GUPTA | R10: =SUM(C10:I10) -> 0 | S10: =ROUND(R10/4.8,2)&" %" -> 0 %
A11: =DETAILS!A11 -> 1662 | B11: =DETAILS!B11 -> AYUSH KUMAR YOGI | R11: =SUM(C11:I11) -> 0 | S11: =ROUND(R11/4.8,2)&" %" -> 0 %
A12: =DETAILS!A12 -> 1602 | B12: =DETAILS!B12 -> AYUSHI MISHRA | R12: =SUM(C12:I12) -> 0 | S12: =ROUND(R12/4.8,2)&" %" -> 0 %
A13: =DETAILS!A13 -> 1842 | B13: =DETAILS!B13 -> DEEPANSH YADAV | R13: =SUM(C13:I13) -> 0 | S13: =ROUND(R13/4.8,2)&" %" -> 0 %
A14: =DETAILS!A14 -> 1127 | B14: =DETAILS!B14 -> DIKSHA MISHRA | R14: =SUM(C14:I14) -> 0 | S14: =ROUND(R14/4.8,2)&" %" -> 0 %
... A41: =DETAILS!A41 -> 1860 | B41: =DETAILS!B41 -> VIKAS VERMA | R41: =SUM(C41:I41) -> 0 | S41: =ROUND(R41/4.8,2)&" %" -> 0 %

Sheet HALF YEARLY
A1: HALF YEARLY EXAMINATION (2025-26) CLASS - III
A2: SR. NO. | B2: NAME | C2: ENGLISH | D2: HINDI | E2: MATHS | F2: SCIENCE | G2: SOCIAL STUDIES | H2: SANSKRIT | I2: COMPUTER | J2: WORK EDUCATION | K2: ART EDUCATION | L2: GENERAL KNOWLEDGE | M2: HEALTH & PHYSICAL EDUCATION | N2: DISCIPLINE | O2: Total Present | P2: Total Working | Q2: Class Teacher's Remark | R2: TOTAL | S2: Percentage
A3: =DETAILS!A3 -> 1633 | B3: =DETAILS!B3 -> AADVIK SRIVASTAVA | C3: =VLOOKUP($A3,'HALF YEARLY(Entry)'!$1:$1048576,3,0) -> 0 | D3: =VLOOKUP($A3,'HALF YEARLY(Entry)'!$1:$1048576,4,0) -> 0 | E3: =VLOOKUP($A3,'HALF YEARLY(Entry)'!$1:$1048576,5,0) -> 0 | F3: =VLOOKUP($A3,'HALF YEARLY(Entry)'!$1:$1048576,6,0) -> 0 | G3: =VLOOKUP($A3,'HALF YEARLY(Entry)'!$1:$1048576,7,0) -> 0 | H3: =VLOOKUP($A3,'HALF YEARLY(Entry)'!$1:$1048576,8,0) -> 0 | I3: =VLOOKUP($A3,'HALF YEARLY(Entry)'!$1:$1048576,9,0) -> 0 | J3: =VLOOKUP($A3,'HALF YEARLY(Entry)'!$1:$1048576,10,0) -> 0 | K3: =IFERROR(VLOOKUP(VLOOKUP($A3,'HALF YEARLY(Entry)'!$1:$1048576,11,0),'Grade 50'!$1:$1048576,2,0),VLOOKUP($A3,'HALF YEARLY(Entry)'!$1:$1048576,11,0)) -> E | L3: =IFERROR(VLOOKUP(VLOOKUP($A3,'HALF YEARLY(Entry)'!$1:$1048576,12,0),'Grade 50'!$1:$1048576,2,0),VLOOKUP($A3,'HALF YEARLY(Entry)'!$1:$1048576,12,0)) -> E | M3: =VLOOKUP($A3,'HALF YEARLY(Entry)'!$1:$1048576,13,0) -> 0 | N3: =VLOOKUP($A3,'HALF YEARLY(Entry)'!$1:$1048576,14,0) -> 0 | O3: =VLOOKUP($A3,'HALF YEARLY(Entry)'!$1:$1048576,15,0) -> 0 | P3: =VLOOKUP($A3,'HALF YEARLY(Entry)'!$1:$1048576,16,0) -> 0 | Q3: =VLOOKUP($A3,'HALF YEARLY(Entry)'!$1:$1048576,17,0) -> 0 | R3: =SUM(C3:I3) -> 0 | S3: =ROUND(R3/5.6,2)&" %" -> 0 %
A4: =DETAILS!A4 -> 1119 | B4: =DETAILS!B4 -> AARYASH SONI | C4: =VLOOKUP($A4,'HALF YEARLY(Entry)'!$1:$1048576,3,0) -> 0 | D4: =VLOOKUP($A4,'HALF YEARLY(Entry)'!$1:$1048576,4,0) -> 0 | E4: =VLOOKUP($A4,'HALF YEARLY(Entry)'!$1:$1048576,5,0) -> 0 | F4: =VLOOKUP($A4,'HALF YEARLY(Entry)'!$1:$1048576,6,0) -> 0 | G4: =VLOOKUP($A4,'HALF YEARLY(Entry)'!$1:$1048576,7,0) -> 0 | H4: =VLOOKUP($A4,'HALF YEARLY(Entry)'!$1:$1048576,8,0) -> 0 | I4: =VLOOKUP($A4,'HALF YEARLY(Entry)'!$1:$1048576,9,0) -> 0 | J4: =VLOOKUP($A4,'HALF YEARLY(Entry)'!$1:$1048576,10,0) -> 0 | K4: =IFERROR(VLOOKUP(VLOOKUP($A4,'HALF YEARLY(Entry)'!$1:$1048576,11,0),'Grade 50'!$1:$1048576,2,0),VLOOKUP($A4,'HALF YEARLY(Entry)'!$1:$1048576,11,0)) -> E | L4: =IFERROR(VLOOKUP(VLOOKUP($A4,'HALF YEARLY(Entry)'!$1:$1048576,12,0),'Grade 50'!$1:$1048576,2,0),VLOOKUP($A4,'HALF YEARLY(Entry)'!$1:$1048576,12,0)) -> E | M4: =VLOOKUP($A4,'HALF YEARLY(Entry)'!$1:$1048576,13,0) -> 0 | N4: =VLOOKUP($A4,'HALF YEARLY(Entry)'!$1:$1048576,14,0) -> 0 | O4: =VLOOKUP($A4,'HALF YEARLY(Entry)'!$1:$1048576,15,0) -> 0 | P4: =VLOOKUP($A4,'HALF YEARLY(Entry)'!$1:$1048576,16,0) -> 0 | Q4: =VLOOKUP($A4,'HALF YEARLY(Entry)'!$1:$1048576,17,0) -> 0 | R4: =SUM(C4:I4) -> 0 | S4: =ROUND(R4/5.6,2)&" %" -> 0 %
A5: =DETAILS!A5 -> 1407 | B5: =DETAILS!B5 -> AKSHAY DUBEY | C5: =VLOOKUP($A5,'HALF YEARLY(Entry)'!$1:$1048576,3,0) -> 0 | D5: =VLOOKUP($A5,'HALF YEARLY(Entry)'!$1:$1048576,4,0) -> 0 | E5: =VLOOKUP($A5,'HALF YEARLY(Entry)'!$1:$1048576,5,0) -> 0 | F5: =VLOOKUP($A5,'HALF YEARLY(Entry)'!$1:$1048576,6,0) -> 0 | G5: =VLOOKUP($A5,'HALF YEARLY(Entry)'!$1:$1048576,7,0) -> 0 | H5: =VLOOKUP($A5,'HALF YEARLY(Entry)'!$1:$1048576,8,0) -> 0 | I5: =VLOOKUP($A5,'HALF YEARLY(Entry)'!$1:$1048576,9,0) -> 0 | J5: =VLOOKUP($A5,'HALF YEARLY(Entry)'!$1:$1048576,10,0) -> 0 | K5: =IFERROR(VLOOKUP(VLOOKUP($A5,'HALF YEARLY(Entry)'!$1:$1048576,11,0),'Grade 50'!$1:$1048576,2,0),VLOOKUP($A5,'HALF YEARLY(Entry)'!$1:$1048576,11,0)) -> E | L5: =IFERROR(VLOOKUP(VLOOKUP($A5,'HALF YEARLY(Entry)'!$1:$1048576,12,0),'Grade 50'!$1:$1048576,2,0),VLOOKUP($A5,'HALF YEARLY(Entry)'!$1:$1048576,12,0)) -> E | M5: =VLOOKUP($A5,'HALF YEARLY(Entry)'!$1:$1048576,13,0) -> 0 | N5: =VLOOKUP($A5,'HALF YEARLY(Entry)'!$1:$1048576,14,0) -> 0 | O5: =VLOOKUP($A5,'HALF YEARLY(Entry)'!$1:$1048576,15,0) -> 0 | P5: =VLOOKUP($A5,'HALF YEARLY(Entry)'!$1:$1048576,16,0) -> 0 | Q5: =VLOOKUP($A5,'HALF YEARLY(Entry)'!$1:$1048576,17,0) -> 0 | R5: =SUM(C5:I5) -> 0 | S5: =ROUND(R5/5.6,2)&" %" -> 0 %
A6: =DETAILS!A6 -> 1077 | B6: =DETAILS!B6 -> ALISHA | C6: =VLOOKUP($A6,'HALF YEARLY(Entry)'!$1:$1048576,3,0) -> 0 | D6: =VLOOKUP($A6,'HALF YEARLY(Entry)'!$1:$1048576,4,0) -> 0 | E6: =VLOOKUP($A6,'HALF YEARLY(Entry)'!$1:$1048576,5,0) -> 0 | F6: =VLOOKUP($A6,'HALF YEARLY(Entry)'!$1:$1048576,6,0) -> 0 | G6: =VLOOKUP($A6,'HALF YEARLY(Entry)'!$1:$1048576,7,0) -> 0 | H6: =VLOOKUP($A6,'HALF YEARLY(Entry)'!$1:$1048576,8,0) -> 0 | I6: =VLOOKUP($A6,'HALF YEARLY(Entry)'!$1:$1048576,9,0) -> 0 | J6: =VLOOKUP($A6,'HALF YEARLY(Entry)'!$1:$1048576,10,0) -> 0 | K6: =IFERROR(VLOOKUP(VLOOKUP($A6,'HALF YEARLY(Entry)'!$1:$1048576,11,0),'Grade 50'!$1:$1048576,2,0),VLOOKUP($A6,'HALF YEARLY(Entry)'!$1:$1048576,11,0)) -> E | L6: =IFERROR(VLOOKUP(VLOOKUP($A6,'HALF YEARLY(Entry)'!$1:$1048576,12,0),'Grade 50'!$1:$1048576,2,0),VLOOKUP($A6,'HALF YEARLY(Entry)'!$1:$1048576,12,0)) -> E | M6: =VLOOKUP($A6,'HALF YEARLY(Entry)'!$1:$1048576,13,0) -> 0 | N6: =VLOOKUP($A6,'HALF YEARLY(Entry)'!$1:$1048576,14,0) -> 0 | O6: =VLOOKUP($A6,'HALF YEARLY(Entry)'!$1:$1048576,15,0) -> 0 | P6: =VLOOKUP($A6,'HALF YEARLY(Entry)'!$1:$1048576,16,0) -> 0 | Q6: =VLOOKUP($A6,'HALF YEARLY(Entry)'!$1:$1048576,17,0) -> 0 | R6: =SUM(C6:I6) -> 0 | S6: =ROUND(R6/5.6,2)&" %" -> 0 %
A7: =DETAILS!A7 -> 1210 | B7: =DETAILS!B7 -> ANJALI JHA | C7: =VLOOKUP($A7,'HALF YEARLY(Entry)'!$1:$1048576,3,0) -> 0 | D7: =VLOOKUP($A7,'HALF YEARLY(Entry)'!$1:$1048576,4,0) -> 0 | E7: =VLOOKUP($A7,'HALF YEARLY(Entry)'!$1:$1048576,5,0) -> 0 | F7: =VLOOKUP($A7,'HALF YEARLY(Entry)'!$1:$1048576,6,0) -> 0 | G7: =VLOOKUP($A7,'HALF YEARLY(Entry)'!$1:$1048576,7,0) -> 0 | H7: =VLOOKUP($A7,'HALF YEARLY(Entry)'!$1:$1048576,8,0) -> 0 | I7: =VLOOKUP($A7,'HALF YEARLY(Entry)'!$1:$1048576,9,0) -> 0 | J7: =VLOOKUP($A7,'HALF YEARLY(Entry)'!$1:$1048576,10,0) -> 0 | K7: =IFERROR(VLOOKUP(VLOOKUP($A7,'HALF YEARLY(Entry)'!$1:$1048576,11,0),'Grade 50'!$1:$1048576,2,0),VLOOKUP($A7,'HALF YEARLY(Entry)'!$1:$1048576,11,0)) -> E | L7: =IFERROR(VLOOKUP(VLOOKUP($A7,'HALF YEARLY(Entry)'!$1:$1048576,12,0),'Grade 50'!$1:$1048576,2,0),VLOOKUP($A7,'HALF YEARLY(Entry)'!$1:$1048576,12,0)) -> E | M7: =VLOOKUP($A7,'HALF YEARLY(Entry)'!$1:$1048576,13,0) -> 0 | N7: =VLOOKUP($A7,'HALF YEARLY(Entry)'!$1:$1048576,14,0) -> 0 | O7: =VLOOKUP($A7,'HALF YEARLY(Entry)'!$1:$1048576,15,0) -> 0 | P7: =VLOOKUP($A7,'HALF YEARLY(Entry)'!$1:$1048576,16,0) -> 0 | Q7: =VLOOKUP($A7,'HALF YEARLY(Entry)'!$1:$1048576,17,0) -> 0 | R7: =SUM(C7:I7) -> 0 | S7: =ROUND(R7/5.6,2)&" %" -> 0 %
A8: =DETAILS!A8 -> 1286 | B8: =DETAILS!B8 -> AROHI JAISWAL | C8: =VLOOKUP($A8,'HALF YEARLY(Entry)'!$1:$1048576,3,0) -> 0 | D8: =VLOOKUP($A8,'HALF YEARLY(Entry)'!$1:$1048576,4,0) -> 0 | E8: =VLOOKUP($A8,'HALF YEARLY(Entry)'!$1:$1048576,5,0) -> 0 | F8: =VLOOKUP($A8,'HALF YEARLY(Entry)'!$1:$1048576,6,0) -> 0 | G8: =VLOOKUP($A8,'HALF YEARLY(Entry)'!$1:$1048576,7,0) -> 0 | H8: =VLOOKUP($A8,'HALF YEARLY(Entry)'!$1:$1048576,8,0) -> 0 | I8: =VLOOKUP($A8,'HALF YEARLY(Entry)'!$1:$1048576,9,0) -> 0 | J8: =VLOOKUP($A8,'HALF YEARLY(Entry)'!$1:$1048576,10,0) -> 0 | K8: =IFERROR(VLOOKUP(VLOOKUP($A8,'HALF YEARLY(Entry)'!$1:$1048576,11,0),'Grade 50'!$1:$1048576,2,0),VLOOKUP($A8,'HALF YEARLY(Entry)'!$1:$1048576,11,0)) -> E | L8: =IFERROR(VLOOKUP(VLOOKUP($A8,'HALF YEARLY(Entry)'!$1:$1048576,12,0),'Grade 50'!$1:$1048576,2,0),VLOOKUP($A8,'HALF YEARLY(Entry)'!$1:$1048576,12,0)) -> E | M8: =VLOOKUP($A8,'HALF YEARLY(Entry)'!$1:$1048576,13,0) -> 0 | N8: =VLOOKUP($A8,'HALF YEARLY(Entry)'!$1:$1048576,14,0) -> 0 | O8: =VLOOKUP($A8,'HALF YEARLY(Entry)'!$1:$1048576,15,0) -> 0 | P8: =VLOOKUP($A8,'HALF YEARLY(Entry)'!$1:$1048576,16,0) -> 0 | Q8: =VLOOKUP($A8,'HALF YEARLY(Entry)'!$1:$1048576,17,0) -> 0 | R8: =SUM(C8:I8) -> 0 | S8: =ROUND(R8/5.6,2)&" %" -> 0 %
A9: =DETAILS!A9 -> 1862 | B9: =DETAILS!B9 -> ASHUTOSH MISHRA | C9: =VLOOKUP($A9,'HALF YEARLY(Entry)'!$1:$1048576,3,0) -> 0 | D9: =VLOOKUP($A9,'HALF YEARLY(Entry)'!$1:$1048576,4,0) -> 0 | E9: =VLOOKUP($A9,'HALF YEARLY(Entry)'!$1:$1048576,5,0) -> 0 | F9: =VLOOKUP($A9,'HALF YEARLY(Entry)'!$1:$1048576,6,0) -> 0 | G9: =VLOOKUP($A9,'HALF YEARLY(Entry)'!$1:$1048576,7,0) -> 0 | H9: =VLOOKUP($A9,'HALF YEARLY(Entry)'!$1:$1048576,8,0) -> 0 | I9: =VLOOKUP($A9,'HALF YEARLY(Entry)'!$1:$1048576,9,0) -> 0 | J9: =VLOOKUP($A9,'HALF YEARLY(Entry)'!$1:$1048576,10,0) -> 0 | K9: =IFERROR(VLOOKUP(VLOOKUP($A9,'HALF YEARLY(Entry)'!$1:$1048576,11,0),'Grade 50'!$1:$1048576,2,0),VLOOKUP($A9,'HALF YEARLY(Entry)'!$1:$1048576,11,0)) -> E | L9: =IFERROR(VLOOKUP(VLOOKUP($A9,'HALF YEARLY(Entry)'!$1:$1048576,12,0),'Grade 50'!$1:$1048576,2,0),VLOOKUP($A9,'HALF YEARLY(Entry)'!$1:$1048576,12,0)) -> E | M9: =VLOOKUP($A9,'HALF YEARLY(Entry)'!$1:$1048576,13,0) -> 0 | N9: =VLOOKUP($A9,'HALF YEARLY(Entry)'!$1:$1048576,14,0) -> 0 | O9: =VLOOKUP($A9,'HALF YEARLY(Entry)'!$1:$1048576,15,0) -> 0 | P9: =VLOOKUP($A9,'HALF YEARLY(Entry)'!$1:$1048576,16,0) -> 0 | Q9: =VLOOKUP($A9,'HALF YEARLY(Entry)'!$1:$1048576,17,0) -> 0 | R9: =SUM(C9:I9) -> 0 | S9: =ROUND(R9/5.6,2)&" %" -> 0 %
A10: =DETAILS!A10 -> 1684 | B10: =DETAILS!B10 -> AYUSH GUPTA | C10: =VLOOKUP($A10,'HALF YEARLY(Entry)'!$1:$1048576,3,0) -> 0 | D10: =VLOOKUP($A10,'HALF YEARLY(Entry)'!$1:$1048576,4,0) -> 0 | E10: =VLOOKUP($A10,'HALF YEARLY(Entry)'!$1:$1048576,5,0) -> 0 | F10: =VLOOKUP($A10,'HALF YEARLY(Entry)'!$1:$1048576,6,0) -> 0 | G10: =VLOOKUP($A10,'HALF YEARLY(Entry)'!$1:$1048576,7,0) -> 0 | H10: =VLOOKUP($A10,'HALF YEARLY(Entry)'!$1:$1048576,8,0) -> 0 | I10: =VLOOKUP($A10,'HALF YEARLY(Entry)'!$1:$1048576,9,0) -> 0 | J10: =VLOOKUP($A10,'HALF YEARLY(Entry)'!$1:$1048576,10,0) -> 0 | K10: =IFERROR(VLOOKUP(VLOOKUP($A10,'HALF YEARLY(Entry)'!$1:$1048576,11,0),'Grade 50'!$1:$1048576,2,0),VLOOKUP($A10,'HALF YEARLY(Entry)'!$1:$1048576,11,0)) -> E | L10: =IFERROR(VLOOKUP(VLOOKUP($A10,'HALF YEARLY(Entry)'!$1:$1048576,12,0),'Grade 50'!$1:$1048576,2,0),VLOOKUP($A10,'HALF YEARLY(Entry)'!$1:$1048576,12,0)) -> E | M10: =VLOOKUP($A10,'HALF YEARLY(Entry)'!$1:$1048576,13,0) -> 0 | N10: =VLOOKUP($A10,'HALF YEARLY(Entry)'!$1:$1048576,14,0) -> 0 | O10: =VLOOKUP($A10,'HALF YEARLY(Entry)'!$1:$1048576,15,0) -> 0 | P10: =VLOOKUP($A10,'HALF YEARLY(Entry)'!$1:$1048576,16,0) -> 0 | Q10: =VLOOKUP($A10,'HALF YEARLY(Entry)'!$1:$1048576,17,0) -> 0 | R10: =SUM(C10:I10) -> 0 | S10: =ROUND(R10/5.6,2)&" %" -> 0 %
A11: =DETAILS!A11 -> 1662 | B11: =DETAILS!B11 -> AYUSH KUMAR YOGI | C11: =VLOOKUP($A11,'HALF YEARLY(Entry)'!$1:$1048576,3,0) -> 0 | D11: =VLOOKUP($A11,'HALF YEARLY(Entry)'!$1:$1048576,4,0) -> 0 | E11: =VLOOKUP($A11,'HALF YEARLY(Entry)'!$1:$1048576,5,0) -> 0 | F11: =VLOOKUP($A11,'HALF YEARLY(Entry)'!$1:$1048576,6,0) -> 0 | G11: =VLOOKUP($A11,'HALF YEARLY(Entry)'!$1:$1048576,7,0) -> 0 | H11: =VLOOKUP($A11,'HALF YEARLY(Entry)'!$1:$1048576,8,0) -> 0 | I11: =VLOOKUP($A11,'HALF YEARLY(Entry)'!$1:$1048576,9,0) -> 0 | J11: =VLOOKUP($A11,'HALF YEARLY(Entry)'!$1:$1048576,10,0) -> 0 | K11: =IFERROR(VLOOKUP(VLOOKUP($A11,'HALF YEARLY(Entry)'!$1:$1048576,11,0),'Grade 50'!$1:$1048576,2,0),VLOOKUP($A11,'HALF YEARLY(Entry)'!$1:$1048576,11,0)) -> E | L11: =IFERROR(VLOOKUP(VLOOKUP($A11,'HALF YEARLY(Entry)'!$1:$1048576,12,0),'Grade 50'!$1:$1048576,2,0),VLOOKUP($A11,'HALF YEARLY(Entry)'!$1:$1048576,12,0)) -> E | M11: =VLOOKUP($A11,'HALF YEARLY(Entry)'!$1:$1048576,13,0) -> 0 | N11: =VLOOKUP($A11,'HALF YEARLY(Entry)'!$1:$1048576,14,0) -> 0 | O11: =VLOOKUP($A11,'HALF YEARLY(Entry)'!$1:$1048576,15,0) -> 0 | P11: =VLOOKUP($A11,'HALF YEARLY(Entry)'!$1:$1048576,16,0) -> 0 | Q11: =VLOOKUP($A11,'HALF YEARLY(Entry)'!$1:$1048576,17,0) -> 0 | R11: =SUM(C11:I11) -> 0 | S11: =ROUND(R11/5.6,2)&" %" -> 0 %
A12: =DETAILS!A12 -> 1602 | B12: =DETAILS!B12 -> AYUSHI MISHRA | C12: =VLOOKUP($A12,'HALF YEARLY(Entry)'!$1:$1048576,3,0) -> 0 | D12: =VLOOKUP($A12,'HALF YEARLY(Entry)'!$1:$1048576,4,0) -> 0 | E12: =VLOOKUP($A12,'HALF YEARLY(Entry)'!$1:$1048576,5,0) -> 0 | F12: =VLOOKUP($A12,'HALF YEARLY(Entry)'!$1:$1048576,6,0) -> 0 | G12: =VLOOKUP($A12,'HALF YEARLY(Entry)'!$1:$1048576,7,0) -> 0 | H12: =VLOOKUP($A12,'HALF YEARLY(Entry)'!$1:$1048576,8,0) -> 0 | I12: =VLOOKUP($A12,'HALF YEARLY(Entry)'!$1:$1048576,9,0) -> 0 | J12: =VLOOKUP($A12,'HALF YEARLY(Entry)'!$1:$1048576,10,0) -> 0 | K12: =IFERROR(VLOOKUP(VLOOKUP($A12,'HALF YEARLY(Entry)'!$1:$1048576,11,0),'Grade 50'!$1:$1048576,2,0),VLOOKUP($A12,'HALF YEARLY(Entry)'!$1:$1048576,11,0)) -> E | L12: =IFERROR(VLOOKUP(VLOOKUP($A12,'HALF YEARLY(Entry)'!$1:$1048576,12,0),'Grade 50'!$1:$1048576,2,0),VLOOKUP($A12,'HALF YEARLY(Entry)'!$1:$1048576,12,0)) -> E | M12: =VLOOKUP($A12,'HALF YEARLY(Entry)'!$1:$1048576,13,0) -> 0 | N12: =VLOOKUP($A12,'HALF YEARLY(Entry)'!$1:$1048576,14,0) -> 0 | O12: =VLOOKUP($A12,'HALF YEARLY(Entry)'!$1:$1048576,15,0) -> 0 | P12: =VLOOKUP($A12,'HALF YEARLY(Entry)'!$1:$1048576,16,0) -> 0 | Q12: =VLOOKUP($A12,'HALF YEARLY(Entry)'!$1:$1048576,17,0) -> 0 | R12: =SUM(C12:I12) -> 0 | S12: =ROUND(R12/5.6,2)&" %" -> 0 %
A13: =DETAILS!A13 -> 1842 | B13: =DETAILS!B13 -> DEEPANSH YADAV | C13: =VLOOKUP($A13,'HALF YEARLY(Entry)'!$1:$1048576,3,0) -> 0 | D13: =VLOOKUP($A13,'HALF YEARLY(Entry)'!$1:$1048576,4,0) -> 0 | E13: =VLOOKUP($A13,'HALF YEARLY(Entry)'!$1:$1048576,5,0) -> 0 | F13: =VLOOKUP($A13,'HALF YEARLY(Entry)'!$1:$1048576,6,0) -> 0 | G13: =VLOOKUP($A13,'HALF YEARLY(Entry)'!$1:$1048576,7,0) -> 0 | H13: =VLOOKUP($A13,'HALF YEARLY(Entry)'!$1:$1048576,8,0) -> 0 | I13: =VLOOKUP($A13,'HALF YEARLY(Entry)'!$1:$1048576,9,0) -> 0 | J13: =VLOOKUP($A13,'HALF YEARLY(Entry)'!$1:$1048576,10,0) -> 0 | K13: =IFERROR(VLOOKUP(VLOOKUP($A13,'HALF YEARLY(Entry)'!$1:$1048576,11,0),'Grade 50'!$1:$1048576,2,0),VLOOKUP($A13,'HALF YEARLY(Entry)'!$1:$1048576,11,0)) -> E | L13: =IFERROR(VLOOKUP(VLOOKUP($A13,'HALF YEARLY(Entry)'!$1:$1048576,12,0),'Grade 50'!$1:$1048576,2,0),VLOOKUP($A13,'HALF YEARLY(Entry)'!$1:$1048576,12,0)) -> E | M13: =VLOOKUP($A13,'HALF YEARLY(Entry)'!$1:$1048576,13,0) -> 0 | N13: =VLOOKUP($A13,'HALF YEARLY(Entry)'!$1:$1048576,14,0) -> 0 | O13: =VLOOKUP($A13,'HALF YEARLY(Entry)'!$1:$1048576,15,0) -> 0 | P13: =VLOOKUP($A13,'HALF YEARLY(Entry)'!$1:$1048576,16,0) -> 0 | Q13: =VLOOKUP($A13,'HALF YEARLY(Entry)'!$1:$1048576,17,0) -> 0 | R13: =SUM(C13:I13) -> 0 | S13: =ROUND(R13/5.6,2)&" %" -> 0 %
A14: =DETAILS!A14 -> 1127 | B14: =DETAILS!B14 -> DIKSHA MISHRA | C14: =VLOOKUP($A14,'HALF YEARLY(Entry)'!$1:$1048576,3,0) -> 0 | D14: =VLOOKUP($A14,'HALF YEARLY(Entry)'!$1:$1048576,4,0) -> 0 | E14: =VLOOKUP($A14,'HALF YEARLY(Entry)'!$1:$1048576,5,0) -> 0 | F14: =VLOOKUP($A14,'HALF YEARLY(Entry)'!$1:$1048576,6,0) -> 0 | G14: =VLOOKUP($A14,'HALF YEARLY(Entry)'!$1:$1048576,7,0) -> 0 | H14: =VLOOKUP($A14,'HALF YEARLY(Entry)'!$1:$1048576,8,0) -> 0 | I14: =VLOOKUP($A14,'HALF YEARLY(Entry)'!$1:$1048576,9,0) -> 0 | J14: =VLOOKUP($A14,'HALF YEARLY(Entry)'!$1:$1048576,10,0) -> 0 | K14: =IFERROR(VLOOKUP(VLOOKUP($A14,'HALF YEARLY(Entry)'!$1:$1048576,11,0),'Grade 50'!$1:$1048576,2,0),VLOOKUP($A14,'HALF YEARLY(Entry)'!$1:$1048576,11,0)) -> E | L14: =IFERROR(VLOOKUP(VLOOKUP($A14,'HALF YEARLY(Entry)'!$1:$1048576,12,0),'Grade 50'!$1:$1048576,2,0),VLOOKUP($A14,'HALF YEARLY(Entry)'!$1:$1048576,12,0)) -> E | M14: =VLOOKUP($A14,'HALF YEARLY(Entry)'!$1:$1048576,13,0) -> 0 | N14: =VLOOKUP($A14,'HALF YEARLY(Entry)'!$1:$1048576,14,0) -> 0 | O14: =VLOOKUP($A14,'HALF YEARLY(Entry)'!$1:$1048576,15,0) -> 0 | P14: =VLOOKUP($A14,'HALF YEARLY(Entry)'!$1:$1048576,16,0) -> 0 | Q14: =VLOOKUP($A14,'HALF YEARLY(Entry)'!$1:$1048576,17,0) -> 0 | R14: =SUM(C14:I14) -> 0 | S14: =ROUND(R14/5.6,2)&" %" -> 0 %
... A41: =DETAILS!A41 -> 1860 | B41: =DETAILS!B41 -> VIKAS VERMA | C41: =VLOOKUP($A41,'HALF YEARLY(Entry)'!$1:$1048576,3,0) -> 0 | D41: =VLOOKUP($A41,'HALF YEARLY(Entry)'!$1:$1048576,4,0) -> 0 | E41: =VLOOKUP($A41,'HALF YEARLY(Entry)'!$1:$1048576,5,0) -> 0 | F41: =VLOOKUP($A41,'HALF YEARLY(Entry)'!$1:$1048576,6,0) -> 0 | G41: =VLOOKUP($A41,'HALF YEARLY(Entry)'!$1:$1048576,7,0) -> 0 | H41: =VLOOKUP($A41,'HALF YEARLY(Entry)'!$1:$1048576,8,0) -> 0 | I41: =VLOOKUP($A41,'HALF YEARLY(Entry)'!$1:$1048576,9,0) -> 0 | J41: =VLOOKUP($A41,'HALF YEARLY(Entry)'!$1:$1048576,10,0) -> 0 | K41: =IFERROR(VLOOKUP(VLOOKUP($A41,'HALF YEARLY(Entry)'!$1:$1048576,11,0),'Grade 50'!$1:$1048576,2,0),VLOOKUP($A41,'HALF YEARLY(Entry)'!$1:$1048576,11,0)) -> E | L41: =IFERROR(VLOOKUP(VLOOKUP($A41,'HALF YEARLY(Entry)'!$1:$1048576,12,0),'Grade 50'!$1:$1048576,2,0),VLOOKUP($A41,'HALF YEARLY(Entry)'!$1:$1048576,12,0)) -> E | M41: =VLOOKUP($A41,'HALF YEARLY(Entry)'!$1:$1048576,13,0) -> 0 | N41: =VLOOKUP($A41,'HALF YEARLY(Entry)'!$1:$1048576,14,0) -> 0 | O41: =VLOOKUP($A41,'HALF YEARLY(Entry)'!$1:$1048576,15,0) -> 0 | P41: =VLOOKUP($A41,'HALF YEARLY(Entry)'!$1:$1048576,16,0) -> 0 | Q41: =VLOOKUP($A41,'HALF YEARLY(Entry)'!$1:$1048576,17,0) -> 0 | R41: =SUM(C41:I41) -> 0 | S41: =ROUND(R41/5.6,2)&" %" -> 0 %

Sheet Grade 50
A2: 50 | B2: A
A3: 49 | B3: A
A4: 48 | B4: A
A5: 47 | B5: A
A6: 46 | B6: A
A7: 45 | B7: A
A8: 44 | B8: A
A9: 43 | B9: A
A10: 42 | B10: A
A11: 41 | B11: A
A12: 40 | B12: B
A13: 39 | B13: B
... A52: 0 | B52: E

Sheet HY Compile
A1: Half Yearly Compile Report (2025-26) Class - III
A2: S.R. No. | B2: Student's Name | C2: ENGLISH | H2: HINDI | M2: MATHEMATICS | R2: SCIENCE | W2: SOCIAL STUDIES | AB2: SANSKRIT | AG2: COMPUTER | AL2: WORK EDUCATION | AM2: ART EDUCATION | AN2: GENERAL KNOWLEDGE | AO2: HEALTH & PHYSICAL EDUCATION | AP2: DISCIPLINE | AQ2: TOTAL PRESENT | AR2: TORAL WORKING DAY | AS2: CLASS TEACHER'S REAMRK
C3: UT-I | D3: NB-I | E3: SE-I | F3: HY | G3: Total | H3: UT-I | I3: NB-I | J3: SE-I | K3: HY | L3: Total | M3: UT-I | N3: NB-I | O3: SE-I | P3: HY | Q3: Total | R3: UT-I | S3: NB-I | T3: SE-I | U3: HY | V3: Total | W3: UT-I | X3: NB-I | Y3: SE-I | Z3: HY | AA3: Total | AB3: UT-I | AC3: NB-I | AD3: SE-I | AE3: HY | AF3: Total | AG3: UT-I | AH3: NB-I | AI3: SE-I | AJ3: HY | AK3: Total
A4: =DETAILS!A3 -> 1633 | B4: =DETAILS!B3 -> AADVIK SRIVASTAVA | C4: =IFERROR(ROUND(VLOOKUP($A4,'UT-I '!$1:$1048576,3,0)/2,0),VLOOKUP($A4,'UT-I '!$1:$1048576,3,0)) -> 0 | D4: =VLOOKUP($A4,'NOTEBOOK-1 (Entry)'!$1:$1048576,3,0) -> 0 | E4: =VLOOKUP($A4,'ENRICH-1(Entry)'!$1:$1048576,3,0) -> 0 | F4: =VLOOKUP(A4,'HALF YEARLY'!$1:$1048576,3,0) -> 0 | G4: =SUM(C4:F4) -> 0 | H4: =IFERROR(ROUND(VLOOKUP($A4,'UT-I '!$1:$1048576,4,0)/2,0),VLOOKUP($A4,'UT-I '!$1:$1048576,4,0)) -> 0 | I4: =VLOOKUP($A4,'NOTEBOOK-1 (Entry)'!$1:$1048576,4,0) -> 0 | J4: =VLOOKUP($A4,'ENRICH-1(Entry)'!$1:$1048576,4,0) -> 0 | K4: =VLOOKUP($A4,'HALF YEARLY'!$1:$1048576,4,0) -> 0 | L4: =SUM(H4:K4) -> 0 | M4: =IFERROR(ROUND(VLOOKUP($A4,'UT-I '!$1:$1048576,5,0)/2,0),VLOOKUP($A4,'UT-I '!$1:$1048576,5,0)) -> 0 | N4: =VLOOKUP($A4,'NOTEBOOK-1 (Entry)'!$1:$1048576,5,0) -> 0 | O4: =VLOOKUP($A4,'ENRICH-1(Entry)'!$1:$1048576,5,0) -> 0 | P4: =VLOOKUP($A4,'HALF YEARLY'!$1:$1048576,5,0) -> 0 | Q4: =SUM(M4:P4) -> 0 | R4: =IFERROR(ROUND(VLOOKUP($A4,'UT-I '!$1:$1048576,6,0)/2,0),VLOOKUP($A4,'UT-I '!$1:$1048576,6,0)) -> 0 | S4: =VLOOKUP($A4,'NOTEBOOK-1 (Entry)'!$1:$1048576,6,0) -> 0 | T4: =VLOOKUP($A4,'ENRICH-1(Entry)'!$1:$1048576,6,0) -> 0 | U4: =VLOOKUP($A4,'HALF YEARLY'!$1:$1048576,6,0) -> 0 | V4: =SUM(R4:U4) -> 0 | W4: =IFERROR(ROUND(VLOOKUP($A4,'UT-I '!$1:$1048576,7,0)/2,0),VLOOKUP($A4,'UT-I '!$1:$1048576,7,0)) -> 0 | X4: =VLOOKUP($A4,'NOTEBOOK-1 (Entry)'!$1:$1048576,7,0) -> 0 | Y4: =VLOOKUP($A4,'ENRICH-1(Entry)'!$1:$1048576,7,0) -> 0 | Z4: =VLOOKUP($A4,'HALF YEARLY'!$1:$1048576,7,0) -> 0 | AA4: =SUM(W4:Z4) -> 0 | AB4: =IFERROR(ROUND(VLOOKUP($A4,'UT-I '!$1:$1048576,8,0)/2,0),VLOOKUP($A4,'UT-I '!$1:$1048576,8,0)) -> 0 | AC4: =VLOOKUP($A4,'NOTEBOOK-1 (Entry)'!$1:$1048576,8,0) -> 0 | AD4: =VLOOKUP($A4,'ENRICH-1(Entry)'!$1:$1048576,8,0) -> 0 | AE4: =VLOOKUP($A4,'HALF YEARLY'!$1:$1048576,8,0) -> 0 | AF4: =SUM(AB4:AE4) -> 0 | AG4: =IFERROR(ROUND(VLOOKUP($A4,'UT-I '!$1:$1048576,9,0)/2,0),VLOOKUP($A4,'UT-I '!$1:$1048576,9,0)) -> 0 | AH4: =VLOOKUP($A4,'NOTEBOOK-1 (Entry)'!$1:$1048576,9,0) -> 0 | AI4: =VLOOKUP($A4,'ENRICH-1(Entry)'!$1:$1048576,9,0) -> 0 | AJ4: =VLOOKUP($A4,'HALF YEARLY'!$1:$1048576,9,0) -> 0 | AK4: =SUM(AG4:AJ4) -> 0 | AL4: =VLOOKUP($A4,'HALF YEARLY'!$1:$1048576,10,0) -> 0 | AM4: =VLOOKUP($A4,'HALF YEARLY'!$1:$1048576,11,0) -> E | AN4: =VLOOKUP($A4,'HALF YEARLY'!$1:$1048576,12,0) -> E | AO4: =VLOOKUP($A4,'HALF YEARLY'!$1:$1048576,13,0) -> 0 | AP4: =VLOOKUP($A4,'HALF YEARLY'!$1:$1048576,14,0) -> 0 | AQ4: =VLOOKUP($A4,'HALF YEARLY'!$1:$1048576,15,0) -> 0 | AR4: =VLOOKUP($A4,'HALF YEARLY'!$1:$1048576,16,0) -> 0 | AS4: =VLOOKUP($A4,'HALF YEARLY'!$1:$1048576,17,0) -> 0
A5: =DETAILS!A4 -> 1119 | B5: =DETAILS!B4 -> AARYASH SONI | C5: =IFERROR(ROUND(VLOOKUP($A5,'UT-I '!$1:$1048576,3,0)/2,0),VLOOKUP($A5,'UT-I '!$1:$1048576,3,0)) -> 0 | D5: =VLOOKUP($A5,'NOTEBOOK-1 (Entry)'!$1:$1048576,3,0) -> 0 | E5: =VLOOKUP($A5,'ENRICH-1(Entry)'!$1:$1048576,3,0) -> 0 | F5: =VLOOKUP(A5,'HALF YEARLY'!$1:$1048576,3,0) -> 0 | G5: =SUM(C5:F5) -> 0 | H5: =IFERROR(ROUND(VLOOKUP($A5,'UT-I '!$1:$1048576,4,0)/2,0),VLOOKUP($A5,'UT-I '!$1:$1048576,4,0)) -> 0 | I5: =VLOOKUP($A5,'NOTEBOOK-1 (Entry)'!$1:$1048576,4,0) -> 0 | J5: =VLOOKUP($A5,'ENRICH-1(Entry)'!$1:$1048576,4,0) -> 0 | K5: =VLOOKUP($A5,'HALF YEARLY'!$1:$1048576,4,0) -> 0 | L5: =SUM(H5:K5) -> 0 | M5: =IFERROR(ROUND(VLOOKUP($A5,'UT-I '!$1:$1048576,5,0)/2,0),VLOOKUP($A5,'UT-I '!$1:$1048576,5,0)) -> 0 | N5: =VLOOKUP($A5,'NOTEBOOK-1 (Entry)'!$1:$1048576,5,0) -> 0 | O5: =VLOOKUP($A5,'ENRICH-1(Entry)'!$1:$1048576,5,0) -> 0 | P5: =VLOOKUP($A5,'HALF YEARLY'!$1:$1048576,5,0) -> 0 | Q5: =SUM(M5:P5) -> 0 | R5: =IFERROR(ROUND(VLOOKUP($A5,'UT-I '!$1:$1048576,6,0)/2,0),VLOOKUP($A5,'UT-I '!$1:$1048576,6,0)) -> 0 | S5: =VLOOKUP($A5,'NOTEBOOK-1 (Entry)'!$1:$1048576,6,0) -> 0 | T5: =VLOOKUP($A5,'ENRICH-1(Entry)'!$1:$1048576,6,0) -> 0 | U5: =VLOOKUP($A5,'HALF YEARLY'!$1:$1048576,6,0) -> 0 | V5: =SUM(R5:U5) -> 0 | W5: =IFERROR(ROUND(VLOOKUP($A5,'UT-I '!$1:$1048576,7,0)/2,0),VLOOKUP($A5,'UT-I '!$1:$1048576,7,0)) -> 0 | X5: =VLOOKUP($A5,'NOTEBOOK-1 (Entry)'!$1:$1048576,7,0) -> 0 | Y5: =VLOOKUP($A5,'ENRICH-1(Entry)'!$1:$1048576,7,0) -> 0 | Z5: =VLOOKUP($A5,'HALF YEARLY'!$1:$1048576,7,0) -> 0 | AA5: =SUM(W5:Z5) -> 0 | AB5: =IFERROR(ROUND(VLOOKUP($A5,'UT-I '!$1:$1048576,8,0)/2,0),VLOOKUP($A5,'UT-I '!$1:$1048576,8,0)) -> 0 | AC5: =VLOOKUP($A5,'NOTEBOOK-1 (Entry)'!$1:$1048576,8,0) -> 0 | AD5: =VLOOKUP($A5,'ENRICH-1(Entry)'!$1:$1048576,8,0) -> 0 | AE5: =VLOOKUP($A5,'HALF YEARLY'!$1:$1048576,8,0) -> 0 | AF5: =SUM(AB5:AE5) -> 0 | AG5: =IFERROR(ROUND(VLOOKUP($A5,'UT-I '!$1:$1048576,9,0)/2,0),VLOOKUP($A5,'UT-I '!$1:$1048576,9,0)) -> 0 | AH5: =VLOOKUP($A5,'NOTEBOOK-1 (Entry)'!$1:$1048576,9,0) -> 0 | AI5: =VLOOKUP($A5,'ENRICH-1(Entry)'!$1:$1048576,9,0) -> 0 | AJ5: =VLOOKUP($A5,'HALF YEARLY'!$1:$1048576,9,0) -> 0 | AK5: =SUM(AG5:AJ5) -> 0 | AL5: =VLOOKUP($A5,'HALF YEARLY'!$1:$1048576,10,0) -> 0 | AM5: =VLOOKUP($A5,'HALF YEARLY'!$1:$1048576,11,0) -> E | AN5: =VLOOKUP($A5,'HALF YEARLY'!$1:$1048576,12,0) -> E | AO5: =VLOOKUP($A5,'HALF YEARLY'!$1:$1048576,13,0) -> 0 | AP5: =VLOOKUP($A5,'HALF YEARLY'!$1:$1048576,14,0) -> 0 | AQ5: =VLOOKUP($A5,'HALF YEARLY'!$1:$1048576,15,0) -> 0 | AR5: =VLOOKUP($A5,'HALF YEARLY'!$1:$1048576,16,0) -> 0 | AS5: =VLOOKUP($A5,'HALF YEARLY'!$1:$1048576,17,0) -> 0
A6: =DETAILS!A5 -> 1407 | B6: =DETAILS!B5 -> AKSHAY DUBEY | C6: =IFERROR(ROUND(VLOOKUP($A6,'UT-I '!$1:$1048576,3,0)/2,0),VLOOKUP($A6,'UT-I '!$1:$1048576,3,0)) -> 0 | D6: =VLOOKUP($A6,'NOTEBOOK-1 (Entry)'!$1:$1048576,3,0) -> 0 | E6: =VLOOKUP($A6,'ENRICH-1(Entry)'!$1:$1048576,3,0) -> 0 | F6: =VLOOKUP(A6,'HALF YEARLY'!$1:$1048576,3,0) -> 0 | G6: =SUM(C6:F6) -> 0 | H6: =IFERROR(ROUND(VLOOKUP($A6,'UT-I '!$1:$1048576,4,0)/2,0),VLOOKUP($A6,'UT-I '!$1:$1048576,4,0)) -> 0 | I6: =VLOOKUP($A6,'NOTEBOOK-1 (Entry)'!$1:$1048576,4,0) -> 0 | J6: =VLOOKUP($A6,'ENRICH-1(Entry)'!$1:$1048576,4,0) -> 0 | K6: =VLOOKUP($A6,'HALF YEARLY'!$1:$1048576,4,0) -> 0 | L6: =SUM(H6:K6) -> 0 | M6: =IFERROR(ROUND(VLOOKUP($A6,'UT-I '!$1:$1048576,5,0)/2,0),VLOOKUP($A6,'UT-I '!$1:$1048576,5,0)) -> 0 | N6: =VLOOKUP($A6,'NOTEBOOK-1 (Entry)'!$1:$1048576,5,0) -> 0 | O6: =VLOOKUP($A6,'ENRICH-1(Entry)'!$1:$1048576,5,0) -> 0 | P6: =VLOOKUP($A6,'HALF YEARLY'!$1:$1048576,5,0) -> 0 | Q6: =SUM(M6:P6) -> 0 | R6: =IFERROR(ROUND(VLOOKUP($A6,'UT-I '!$1:$1048576,6,0)/2,0),VLOOKUP($A6,'UT-I '!$1:$1048576,6,0)) -> 0 | S6: =VLOOKUP($A6,'NOTEBOOK-1 (Entry)'!$1:$1048576,6,0) -> 0 | T6: =VLOOKUP($A6,'ENRICH-1(Entry)'!$1:$1048576,6,0) -> 0 | U6: =VLOOKUP($A6,'HALF YEARLY'!$1:$1048576,6,0) -> 0 | V6: =SUM(R6:U6) -> 0 | W6: =IFERROR(ROUND(VLOOKUP($A6,'UT-I '!$1:$1048576,7,0)/2,0),VLOOKUP($A6,'UT-I '!$1:$1048576,7,0)) -> 0 | X6: =VLOOKUP($A6,'NOTEBOOK-1 (Entry)'!$1:$1048576,7,0) -> 0 | Y6: =VLOOKUP($A6,'ENRICH-1(Entry)'!$1:$1048576,7,0) -> 0 | Z6: =VLOOKUP($A6,'HALF YEARLY'!$1:$1048576,7,0) -> 0 | AA6: =SUM(W6:Z6) -> 0 | AB6: =IFERROR(ROUND(VLOOKUP($A6,'UT-I '!$1:$1048576,8,0)/2,0),VLOOKUP($A6,'UT-I '!$1:$1048576,8,0)) -> 0 | AC6: =VLOOKUP($A6,'NOTEBOOK-1 (Entry)'!$1:$1048576,8,0) -> 0 | AD6: =VLOOKUP($A6,'ENRICH-1(Entry)'!$1:$1048576,8,0) -> 0 | AE6: =VLOOKUP($A6,'HALF YEARLY'!$1:$1048576,8,0) -> 0 | AF6: =SUM(AB6:AE6) -> 0 | AG6: =IFERROR(ROUND(VLOOKUP($A6,'UT-I '!$1:$1048576,9,0)/2,0),VLOOKUP($A6,'UT-I '!$1:$1048576,9,0)) -> 0 | AH6: =VLOOKUP($A6,'NOTEBOOK-1 (Entry)'!$1:$1048576,9,0) -> 0 | AI6: =VLOOKUP($A6,'ENRICH-1(Entry)'!$1:$1048576,9,0) -> 0 | AJ6: =VLOOKUP($A6,'HALF YEARLY'!$1:$1048576,9,0) -> 0 | AK6: =SUM(AG6:AJ6) -> 0 | AL6: =VLOOKUP($A6,'HALF YEARLY'!$1:$1048576,10,0) -> 0 | AM6: =VLOOKUP($A6,'HALF YEARLY'!$1:$1048576,11,0) -> E | AN6: =VLOOKUP($A6,'HALF YEARLY'!$1:$1048576,12,0) -> E | AO6: =VLOOKUP($A6,'HALF YEARLY'!$1:$1048576,13,0) -> 0 | AP6: =VLOOKUP($A6,'HALF YEARLY'!$1:$1048576,14,0) -> 0 | AQ6: =VLOOKUP($A6,'HALF YEARLY'!$1:$1048576,15,0) -> 0 | AR6: =VLOOKUP($A6,'HALF YEARLY'!$1:$1048576,16,0) -> 0 | AS6: =VLOOKUP($A6,'HALF YEARLY'!$1:$1048576,17,0) -> 0
A7: =DETAILS!A6 -> 1077 | B7: =DETAILS!B6 -> ALISHA | C7: =IFERROR(ROUND(VLOOKUP($A7,'UT-I '!$1:$1048576,3,0)/2,0),VLOOKUP($A7,'UT-I '!$1:$1048576,3,0)) -> 0 | D7: =VLOOKUP($A7,'NOTEBOOK-1 (Entry)'!$1:$1048576,3,0) -> 0 | E7: =VLOOKUP($A7,'ENRICH-1(Entry)'!$1:$1048576,3,0) -> 0 | F7: =VLOOKUP(A7,'HALF YEARLY'!$1:$1048576,3,0) -> 0 | G7: =SUM(C7:F7) -> 0 | H7: =IFERROR(ROUND(VLOOKUP($A7,'UT-I '!$1:$1048576,4,0)/2,0),VLOOKUP($A7,'UT-I '!$1:$1048576,4,0)) -> 0 | I7: =VLOOKUP($A7,'NOTEBOOK-1 (Entry)'!$1:$1048576,4,0) -> 0 | J7: =VLOOKUP($A7,'ENRICH-1(Entry)'!$1:$1048576,4,0) -> 0 | K7: =VLOOKUP($A7,'HALF YEARLY'!$1:$1048576,4,0) -> 0 | L7: =SUM(H7:K7) -> 0 | M7: =IFERROR(ROUND(VLOOKUP($A7,'UT-I '!$1:$1048576,5,0)/2,0),VLOOKUP($A7,'UT-I '!$1:$1048576,5,0)) -> 0 | N7: =VLOOKUP($A7,'NOTEBOOK-1 (Entry)'!$1:$1048576,5,0) -> 0 | O7: =VLOOKUP($A7,'ENRICH-1(Entry)'!$1:$1048576,5,0) -> 0 | P7: =VLOOKUP($A7,'HALF YEARLY'!$1:$1048576,5,0) -> 0 | Q7: =SUM(M7:P7) -> 0 | R7: =IFERROR(ROUND(VLOOKUP($A7,'UT-I '!$1:$1048576,6,0)/2,0),VLOOKUP($A7,'UT-I '!$1:$1048576,6,0)) -> 0 | S7: =VLOOKUP($A7,'NOTEBOOK-1 (Entry)'!$1:$1048576,6,0) -> 0 | T7: =VLOOKUP($A7,'ENRICH-1(Entry)'!$1:$1048576,6,0) -> 0 | U7: =VLOOKUP($A7,'HALF YEARLY'!$1:$1048576,6,0) -> 0 | V7: =SUM(R7:U7) -> 0 | W7: =IFERROR(ROUND(VLOOKUP($A7,'UT-I '!$1:$1048576,7,0)/2,0),VLOOKUP($A7,'UT-I '!$1:$1048576,7,0)) -> 0 | X7: =VLOOKUP($A7,'NOTEBOOK-1 (Entry)'!$1:$1048576,7,0) -> 0 | Y7: =VLOOKUP($A7,'ENRICH-1(Entry)'!$1:$1048576,7,0) -> 0 | Z7: =VLOOKUP($A7,'HALF YEARLY'!$1:$1048576,7,0) -> 0 | AA7: =SUM(W7:Z7) -> 0 | AB7: =IFERROR(ROUND(VLOOKUP($A7,'UT-I '!$1:$1048576,8,0)/2,0),VLOOKUP($A7,'UT-I '!$1:$1048576,8,0)) -> 0 | AC7: =VLOOKUP($A7,'NOTEBOOK-1 (Entry)'!$1:$1048576,8,0) -> 0 | AD7: =VLOOKUP($A7,'ENRICH-1(Entry)'!$1:$1048576,8,0) -> 0 | AE7: =VLOOKUP($A7,'HALF YEARLY'!$1:$1048576,8,0) -> 0 | AF7: =SUM(AB7:AE7) -> 0 | AG7: =IFERROR(ROUND(VLOOKUP($A7,'UT-I '!$1:$1048576,9,0)/2,0),VLOOKUP($A7,'UT-I '!$1:$1048576,9,0)) -> 0 | AH7: =VLOOKUP($A7,'NOTEBOOK-1 (Entry)'!$1:$1048576,9,0) -> 0 | AI7: =VLOOKUP($A7,'ENRICH-1(Entry)'!$1:$1048576,9,0) -> 0 | AJ7: =VLOOKUP($A7,'HALF YEARLY'!$1:$1048576,9,0) -> 0 | AK7: =SUM(AG7:AJ7) -> 0 | AL7: =VLOOKUP($A7,'HALF YEARLY'!$1:$1048576,10,0) -> 0 | AM7: =VLOOKUP($A7,'HALF YEARLY'!$1:$1048576,11,0) -> E | AN7: =VLOOKUP($A7,'HALF YEARLY'!$1:$1048576,12,0) -> E | AO7: =VLOOKUP($A7,'HALF YEARLY'!$1:$1048576,13,0) -> 0 | AP7: =VLOOKUP($A7,'HALF YEARLY'!$1:$1048576,14,0) -> 0 | AQ7: =VLOOKUP($A7,'HALF YEARLY'!$1:$1048576,15,0) -> 0 | AR7: =VLOOKUP($A7,'HALF YEARLY'!$1:$1048576,16,0) -> 0 | AS7: =VLOOKUP($A7,'HALF YEARLY'!$1:$1048576,17,0) -> 0
A8: =DETAILS!A7 -> 1210 | B8: =DETAILS!B7 -> ANJALI JHA | C8: =IFERROR(ROUND(VLOOKUP($A8,'UT-I '!$1:$1048576,3,0)/2,0),VLOOKUP($A8,'UT-I '!$1:$1048576,3,0)) -> 0 | D8: =VLOOKUP($A8,'NOTEBOOK-1 (Entry)'!$1:$1048576,3,0) -> 0 | E8: =VLOOKUP($A8,'ENRICH-1(Entry)'!$1:$1048576,3,0) -> 0 | F8: =VLOOKUP(A8,'HALF YEARLY'!$1:$1048576,3,0) -> 0 | G8: =SUM(C8:F8) -> 0 | H8: =IFERROR(ROUND(VLOOKUP($A8,'UT-I '!$1:$1048576,4,0)/2,0),VLOOKUP($A8,'UT-I '!$1:$1048576,4,0)) -> 0 | I8: =VLOOKUP($A8,'NOTEBOOK-1 (Entry)'!$1:$1048576,4,0) -> 0 | J8: =VLOOKUP($A8,'ENRICH-1(Entry)'!$1:$1048576,4,0) -> 0 | K8: =VLOOKUP($A8,'HALF YEARLY'!$1:$1048576,4,0) -> 0 | L8: =SUM(H8:K8) -> 0 | M8: =IFERROR(ROUND(VLOOKUP($A8,'UT-I '!$1:$1048576,5,0)/2,0),VLOOKUP($A8,'UT-I '!$1:$1048576,5,0)) -> 0 | N8: =VLOOKUP($A8,'NOTEBOOK-1 (Entry)'!$1:$1048576,5,0) -> 0 | O8: =VLOOKUP($A8,'ENRICH-1(Entry)'!$1:$1048576,5,0) -> 0 | P8: =VLOOKUP($A8,'HALF YEARLY'!$1:$1048576,5,0) -> 0 | Q8: =SUM(M8:P8) -> 0 | R8: =IFERROR(ROUND(VLOOKUP($A8,'UT-I '!$1:$1048576,6,0)/2,0),VLOOKUP($A8,'UT-I '!$1:$1048576,6,0)) -> 0 | S8: =VLOOKUP($A8,'NOTEBOOK-1 (Entry)'!$1:$1048576,6,0) -> 0 | T8: =VLOOKUP($A8,'ENRICH-1(Entry)'!$1:$1048576,6,0) -> 0 | U8: =VLOOKUP($A8,'HALF YEARLY'!$1:$1048576,6,0) -> 0 | V8: =SUM(R8:U8) -> 0 | W8: =IFERROR(ROUND(VLOOKUP($A8,'UT-I '!$1:$1048576,7,0)/2,0),VLOOKUP($A8,'UT-I '!$1:$1048576,7,0)) -> 0 | X8: =VLOOKUP($A8,'NOTEBOOK-1 (Entry)'!$1:$1048576,7,0) -> 0 | Y8: =VLOOKUP($A8,'ENRICH-1(Entry)'!$1:$1048576,7,0) -> 0 | Z8: =VLOOKUP($A8,'HALF YEARLY'!$1:$1048576,7,0) -> 0 | AA8: =SUM(W8:Z8) -> 0 | AB8: =IFERROR(ROUND(VLOOKUP($A8,'UT-I '!$1:$1048576,8,0)/2,0),VLOOKUP($A8,'UT-I '!$1:$1048576,8,0)) -> 0 | AC8: =VLOOKUP($A8,'NOTEBOOK-1 (Entry)'!$1:$1048576,8,0) -> 0 | AD8: =VLOOKUP($A8,'ENRICH-1(Entry)'!$1:$1048576,8,0) -> 0 | AE8: =VLOOKUP($A8,'HALF YEARLY'!$1:$1048576,8,0) -> 0 | AF8: =SUM(AB8:AE8) -> 0 | AG8: =IFERROR(ROUND(VLOOKUP($A8,'UT-I '!$1:$1048576,9,0)/2,0),VLOOKUP($A8,'UT-I '!$1:$1048576,9,0)) -> 0 | AH8: =VLOOKUP($A8,'NOTEBOOK-1 (Entry)'!$1:$1048576,9,0) -> 0 | AI8: =VLOOKUP($A8,'ENRICH-1(Entry)'!$1:$1048576,9,0) -> 0 | AJ8: =VLOOKUP($A8,'HALF YEARLY'!$1:$1048576,9,0) -> 0 | AK8: =SUM(AG8:AJ8) -> 0 | AL8: =VLOOKUP($A8,'HALF YEARLY'!$1:$1048576,10,0) -> 0 | AM8: =VLOOKUP($A8,'HALF YEARLY'!$1:$1048576,11,0) -> E | AN8: =VLOOKUP($A8,'HALF YEARLY'!$1:$1048576,12,0) -> E | AO8: =VLOOKUP($A8,'HALF YEARLY'!$1:$1048576,13,0) -> 0 | AP8: =VLOOKUP($A8,'HALF YEARLY'!$1:$1048576,14,0) -> 0 | AQ8: =VLOOKUP($A8,'HALF YEARLY'!$1:$1048576,15,0) -> 0 | AR8: =VLOOKUP($A8,'HALF YEARLY'!$1:$1048576,16,0) -> 0 | AS8: =VLOOKUP($A8,'HALF YEARLY'!$1:$1048576,17,0) -> 0
