Workbook

Sheet DETAILS
A1: STUDENT'S DETAIL
A2: SR NO | B2: NAME | C2: MOTHER'S NAME | D2: FATHER'S NAME | E2: DOB | F2: CLASS & SEC
A3: 1454 | B3: AARUSH SONI | C3: PINKI SONI | D3: NATHU RAM VERMA | E3: 25.05.2011 | F3: X-A
A4: 1680 | B4: AARVI JAISWAL | C4: RITU JAISWAL | D4: RAHUL JAISWAL | E4: 19.12.2012 | F4: X-A
A5: 758 | B5: ABDUL AHAD | C5: AQEELA NISAR | D5: IZHAR AHMAD | E5: 20.04.2010 | F5: X-A
A6: 1616 | B6: ANAV SINGH | C6: SHEELA SINGH | D6: SAMAR SINGH | E6: 10.04.2011 | F6: X-A
A7: 1443 | B7: ANKIT KUMAR | C7: NEELAM DEVI | D7: SHRAVAN KUMAR | E7: 24.02.2010 | F7: X-A
A8: 2100 | B8: ANSH SHUKLA | F8: X-A
A9: 1767 | B9: ANSHIKA MISHRA | C9: SEEMA MISHRA | D9: AMIT KUMAR MISHRA | E9: 04.12.2010 | F9: X-A
A10: 1486 | B10: ANUBHAV CHOUDHARY | C10: SHALINI | D10: ARVIND KUMAR | E10: 25.03.2010 | F10: X-A
A11: 1615 | B11: ARADHYA TIWARI | C11: SANJU | D11: AJAY TIWARI | E11: 12.04.2012 | F11: X-A
A12: 993 | B12: ARYAN MAURYA | C12: AKANKSHA | D12: SUBHASH CHANDRA | E12: 28.08.2010 | F12: X-A
A13: 1296 | B13: ARYAN SINGH | C13: RINKU DEVI | D13: LATE ASHOK SINGH | E13: 09.02.2011 | F13: X-A
A14: 1392 | B14: ASTITVA SHYAM TIWARI | C14: MAMTA TIWARI | D14: SHYAM JI TIWARI | E14: 06.01.2010 | F14: X-A
A15: 759 | B15: DEVENDRA PATHAK | C15: VINDHYAVASINI PATHAK | D15: VARUN PATHAK | E15: 10.07.2010 | F15: X-A
A16: 1598 | B16: DIVYANSHI SINGH | C16: AMRATA SINGH | D16: PRABHAT SINGH | E16: 20.01.2011 | F16: X-A
A17: 1650 | B17: DIVYANSHU YADAV | C17: VIMLA DEVI | D17: PAVAN KUMAR | E17: 16.09.2010 | F17: X-A
A18: 1661 | B18: GARIMA YADAV | C18: USHA DEVI | D18: SIYARAM YADAV | E18: 27.09.2011 | F18: X-A
A19: 1704 | B19: HARSH SINGH | C19: VINDA SINGH | D19: ASHOK SINGH | E19: 30.01.2010 | F19: X-A
A20: 1437 | B20: KANISHKA YADAV | C20: KIRAN YADAV | D20: AKHILESH YADAV | E20: 25.06.2009 | F20: X-A
... A48: 1104 | B48: VARTIKA RANA | C48: SANGEETA KUMARI | D48: MANOJ KUMAR | E48: 10.10.2010 | F48: X-A

Sheet UT-I(Entry)
A1: UNIT TEST-I (2025-26) CLASS - X
A2: SR. NO. | B2: NAME | C2: ENGLISH | D2: HINDI | E2: MATHS | F2: SCIENCE | G2: SOCIAL SCIENCE | H2: ARTIFICIAL INTELLIGENCE | I2: Attendance
I3: Present | J3: Working Day
A4: =DETAILS!A3 -> 1454 | B4: =DETAILS!B3 -> AARUSH SONI
A5: =DETAILS!A4 -> 1680 | B5: =DETAILS!B4 -> AARVI JAISWAL
A6: =DETAILS!A5 -> 758 | B6: =DETAILS!B5 -> ABDUL AHAD
A7: =DETAILS!A6 -> 1616 | B7: =DETAILS!B6 -> ANAV SINGH
A8: =DETAILS!A7 -> 1443 | B8: =DETAILS!B7 -> ANKIT KUMAR
A9: =DETAILS!A8 -> 2100 | B9: =DETAILS!B8 -> ANSH SHUKLA
A10: =DETAILS!A9 -> 1767 | B10: =DETAILS!B9 -> ANSHIKA MISHRA
A11: =DETAILS!A10 -> 1486 | B11: =DETAILS!B10 -> ANUBHAV CHOUDHARY
A12: =DETAILS!A11 -> 1615 | B12: =DETAILS!B11 -> ARADHYA TIWARI
A13: =DETAILS!A12 -> 993 | B13: =DETAILS!B12 -> ARYAN MAURYA
A14: =DETAILS!A13 -> 1296 | B14: =DETAILS!B13 -> ARYAN SINGH
A15: =DETAILS!A14 -> 1392 | B15: =DETAILS!B14 -> ASTITVA SHYAM TIWARI
... A49: =DETAILS!A48 -> 1104 | B49: =DETAILS!B48 -> VARTIKA RANA

Sheet UT-I 
A1: UNIT TEST-I (2025-26) CLASS - X
A2: SR. NO. | B2: NAME | C2: ENGLISH | D2: HINDI | E2: MATHS | F2: SCIENCE | G2: SOCIAL SCIENCE | H2: ARTIFICIAL INTELLIGENCE | I2: TOTAL | J2: PERCENTAGE | K2: Attendance
K3: Present | L3: Working Day
A4: =DETAILS!A3 -> 1454 | B4: =DETAILS!B3 -> AARUSH SONI | C4: =IFERROR(ROUND((VLOOKUP(A4,'UT-I(Entry)'!$1:$1048576,3,0))/2,0),VLOOKUP(A4,'UT-I(Entry)'!$1:$1048576,3,0)) -> 0 | D4: =IFERROR(ROUND((VLOOKUP(A4,'UT-I(Entry)'!$1:$1048576,4,0))/2,0),VLOOKUP(A4,'UT-I(Entry)'!$1:$1048576,4,0)) -> 0 | E4: =IFERROR(ROUND((VLOOKUP(A4,'UT-I(Entry)'!$1:$1048576,5,0))/2,0),VLOOKUP(A4,'UT-I(Entry)'!$1:$1048576,5,0)) -> 0 | F4: =IFERROR(ROUND((VLOOKUP(A4,'UT-I(Entry)'!$1:$1048576,6,0))/2,0),VLOOKUP(A4,'UT-I(Entry)'!$1:$1048576,6,0)) -> 0 | G4: =IFERROR(ROUND((VLOOKUP($A4,'UT-I(Entry)'!$1:$1048576,7,0))/2,0),VLOOKUP($A4,'UT-I(Entry)'!$1:$1048576,7,0)) -> 0 | H4: =IFERROR(ROUND((VLOOKUP($A4,'UT-I(Entry)'!$1:$1048576,8,0))/2,0),VLOOKUP($A4,'UT-I(Entry)'!$1:$1048576,8,0)) -> 0 | I4: =SUM(C4:H4) -> 0 | J4: =ROUND(I4/1.2,2)&" %" -> 0 % | K4: =VLOOKUP(A4,'UT-I(Entry)'!$1:$1048576,9,0) -> 0 | L4: =VLOOKUP(A4,'UT-I(Entry)'!$1:$1048576,10,0) -> 0
A5: =DETAILS!A4 -> 1680 | B5: =DETAILS!B4 -> AARVI JAISWAL | C5: =IFERROR(ROUND((VLOOKUP(A5,'UT-I(Entry)'!$1:$1048576,3,0))/2,0),VLOOKUP(A5,'UT-I(Entry)'!$1:$1048576,3,0)) -> 0 | D5: =IFERROR(ROUND((VLOOKUP(A5,'UT-I(Entry)'!$1:$1048576,4,0))/2,0),VLOOKUP(A5,'UT-I(Entry)'!$1:$1048576,4,0)) -> 0 | E5: =IFERROR(ROUND((VLOOKUP(A5,'UT-I(Entry)'!$1:$1048576,5,0))/2,0),VLOOKUP(A5,'UT-I(Entry)'!$1:$1048576,5,0)) -> 0 | F5: =IFERROR(ROUND((VLOOKUP(A5,'UT-I(Entry)'!$1:$1048576,6,0))/2,0),VLOOKUP(A5,'UT-I(Entry)'!$1:$1048576,6,0)) -> 0 | G5: =IFERROR(ROUND((VLOOKUP(A5,'UT-I(Entry)'!$1:$1048576,7,0))/2,0),VLOOKUP(A5,'UT-I(Entry)'!$1:$1048576,7,0)) -> 0 | H5: =IFERROR(ROUND((VLOOKUP($A5,'UT-I(Entry)'!$1:$1048576,8,0))/2,0),VLOOKUP($A5,'UT-I(Entry)'!$1:$1048576,8,0)) -> 0 | I5: =SUM(C5:H5) -> 0 | J5: =ROUND(I5/1.2,2)&" %" -> 0 % | K5: =VLOOKUP(A5,'UT-I(Entry)'!$1:$1048576,9,0) -> 0 | L5: =VLOOKUP(A5,'UT-I(Entry)'!$1:$1048576,10,0) -> 0
A6: =DETAILS!A5 -> 758 | B6: =DETAILS!B5 -> ABDUL AHAD | C6: =IFERROR(ROUND((VLOOKUP(A6,'UT-I(Entry)'!$1:$1048576,3,0))/2,0),VLOOKUP(A6,'UT-I(Entry)'!$1:$1048576,3,0)) -> 0 | D6: =IFERROR(ROUND((VLOOKUP(A6,'UT-I(Entry)'!$1:$1048576,4,0))/2,0),VLOOKUP(A6,'UT-I(Entry)'!$1:$1048576,4,0)) -> 0 | E6: =IFERROR(ROUND((VLOOKUP(A6,'UT-I(Entry)'!$1:$1048576,5,0))/2,0),VLOOKUP(A6,'UT-I(Entry)'!$1:$1048576,5,0)) -> 0 | F6: =IFERROR(ROUND((VLOOKUP(A6,'UT-I(Entry)'!$1:$1048576,6,0))/2,0),VLOOKUP(A6,'UT-I(Entry)'!$1:$1048576,6,0)) -> 0 | G6: =IFERROR(ROUND((VLOOKUP(A6,'UT-I(Entry)'!$1:$1048576,7,0))/2,0),VLOOKUP(A6,'UT-I(Entry)'!$1:$1048576,7,0)) -> 0 | H6: =IFERROR(ROUND((VLOOKUP($A6,'UT-I(Entry)'!$1:$1048576,8,0))/2,0),VLOOKUP($A6,'UT-I(Entry)'!$1:$1048576,8,0)) -> 0 | I6: =SUM(C6:H6) -> 0 | J6: =ROUND(I6/1.2,2)&" %" -> 0 % | K6: =VLOOKUP(A6,'UT-I(Entry)'!$1:$1048576,9,0) -> 0 | L6: =VLOOKUP(A6,'UT-I(Entry)'!$1:$1048576,10,0) -> 0
A7: =DETAILS!A6 -> 1616 | B7: =DETAILS!B6 -> ANAV SINGH | C7: =IFERROR(ROUND((VLOOKUP(A7,'UT-I(Entry)'!$1:$1048576,3,0))/2,0),VLOOKUP(A7,'UT-I(Entry)'!$1:$1048576,3,0)) -> 0 | D7: =IFERROR(ROUND((VLOOKUP(A7,'UT-I(Entry)'!$1:$1048576,4,0))/2,0),VLOOKUP(A7,'UT-I(Entry)'!$1:$1048576,4,0)) -> 0 | E7: =IFERROR(ROUND((VLOOKUP(A7,'UT-I(Entry)'!$1:$1048576,5,0))/2,0),VLOOKUP(A7,'UT-I(Entry)'!$1:$1048576,5,0)) -> 0 | F7: =IFERROR(ROUND((VLOOKUP(A7,'UT-I(Entry)'!$1:$1048576,6,0))/2,0),VLOOKUP(A7,'UT-I(Entry)'!$1:$1048576,6,0)) -> 0 | G7: =IFERROR(ROUND((VLOOKUP(A7,'UT-I(Entry)'!$1:$1048576,7,0))/2,0),VLOOKUP(A7,'UT-I(Entry)'!$1:$1048576,7,0)) -> 0 | H7: =IFERROR(ROUND((VLOOKUP($A7,'UT-I(Entry)'!$1:$1048576,8,0))/2,0),VLOOKUP($A7,'UT-I(Entry)'!$1:$1048576,8,0)) -> 0 | I7: =SUM(C7:H7) -> 0 | J7: =ROUND(I7/1.2,2)&" %" -> 0 % | K7: =VLOOKUP(A7,'UT-I(Entry)'!$1:$1048576,9,0) -> 0 | L7: =VLOOKUP(A7,'UT-I(Entry)'!$1:$1048576,10,0) -> 0
A8: =DETAILS!A7 -> 1443 | B8: =DETAILS!B7 -> ANKIT KUMAR | C8: =IFERROR(ROUND((VLOOKUP(A8,'UT-I(Entry)'!$1:$1048576,3,0))/2,0),VLOOKUP(A8,'UT-I(Entry)'!$1:$1048576,3,0)) -> 0 | D8: =IFERROR(ROUND((VLOOKUP(A8,'UT-I(Entry)'!$1:$1048576,4,0))/2,0),VLOOKUP(A8,'UT-I(Entry)'!$1:$1048576,4,0)) -> 0 | E8: =IFERROR(ROUND((VLOOKUP(A8,'UT-I(Entry)'!$1:$1048576,5,0))/2,0),VLOOKUP(A8,'UT-I(Entry)'!$1:$1048576,5,0)) -> 0 | F8: =IFERROR(ROUND((VLOOKUP(A8,'UT-I(Entry)'!$1:$1048576,6,0))/2,0),VLOOKUP(A8,'UT-I(Entry)'!$1:$1048576,6,0)) -> 0 | G8: =IFERROR(ROUND((VLOOKUP(A8,'UT-I(Entry)'!$1:$1048576,7,0))/2,0),VLOOKUP(A8,'UT-I(Entry)'!$1:$1048576,7,0)) -> 0 | H8: =IFERROR(ROUND((VLOOKUP($A8,'UT-I(Entry)'!$1:$1048576,8,0))/2,0),VLOOKUP($A8,'UT-I(Entry)'!$1:$1048576,8,0)) -> 0 | I8: =SUM(C8:H8) -> 0 | J8: =ROUND(I8/1.2,2)&" %" -> 0 % | K8: =VLOOKUP(A8,'UT-I(Entry)'!$1:$1048576,9,0) -> 0 | L8: =VLOOKUP(A8,'UT-I(Entry)'!$1:$1048576,10,0) -> 0
A9: =DETAILS!A8 -> 2100 | B9: =DETAILS!B8 -> ANSH SHUKLA | C9: =IFERROR(ROUND((VLOOKUP(A9,'UT-I(Entry)'!$1:$1048576,3,0))/2,0),VLOOKUP(A9,'UT-I(Entry)'!$1:$1048576,3,0)) -> 0 | D9: =IFERROR(ROUND((VLOOKUP(A9,'UT-I(Entry)'!$1:$1048576,4,0))/2,0),VLOOKUP(A9,'UT-I(Entry)'!$1:$1048576,4,0)) -> 0 | E9: =IFERROR(ROUND((VLOOKUP(A9,'UT-I(Entry)'!$1:$1048576,5,0))/2,0),VLOOKUP(A9,'UT-I(Entry)'!$1:$1048576,5,0)) -> 0 | F9: =IFERROR(ROUND((VLOOKUP(A9,'UT-I(Entry)'!$1:$1048576,6,0))/2,0),VLOOKUP(A9,'UT-I(Entry)'!$1:$1048576,6,0)) -> 0 | G9: =IFERROR(ROUND((VLOOKUP(A9,'UT-I(Entry)'!$1:$1048576,7,0))/2,0),VLOOKUP(A9,'UT-I(Entry)'!$1:$1048576,7,0)) -> 0 | H9: =IFERROR(ROUND((VLOOKUP($A9,'UT-I(Entry)'!$1:$1048576,8,0))/2,0),VLOOKUP($A9,'UT-I(Entry)'!$1:$1048576,8,0)) -> 0 | I9: =SUM(C9:H9) -> 0 | J9: =ROUND(I9/1.2,2)&" %" -> 0 % | K9: =VLOOKUP(A9,'UT-I(Entry)'!$1:$1048576,9,0) -> 0 | L9: =VLOOKUP(A9,'UT-I(Entry)'!$1:$1048576,10,0) -> 0
A10: =DETAILS!A9 -> 1767 | B10: =DETAILS!B9 -> ANSHIKA MISHRA | C10: =IFERROR(ROUND((VLOOKUP(A10,'UT-I(Entry)'!$1:$1048576,3,0))/2,0),VLOOKUP(A10,'UT-I(Entry)'!$1:$1048576,3,0)) -> 0 | D10: =IFERROR(ROUND((VLOOKUP(A10,'UT-I(Entry)'!$1:$1048576,4,0))/2,0),VLOOKUP(A10,'UT-I(Entry)'!$1:$1048576,4,0)) -> 0 | E10: =IFERROR(ROUND((VLOOKUP(A10,'UT-I(Entry)'!$1:$1048576,5,0))/2,0),VLOOKUP(A10,'UT-I(Entry)'!$1:$1048576,5,0)) -> 0 | F10: =IFERROR(ROUND((VLOOKUP(A10,'UT-I(Entry)'!$1:$1048576,6,0))/2,0),VLOOKUP(A10,'UT-I(Entry)'!$1:$1048576,6,0)) -> 0 | G10: =IFERROR(ROUND((VLOOKUP(A10,'UT-I(Entry)'!$1:$1048576,7,0))/2,0),VLOOKUP(A10,'UT-I(Entry)'!$1:$1048576,7,0)) -> 0 | H10: =IFERROR(ROUND((VLOOKUP($A10,'UT-I(Entry)'!$1:$1048576,8,0))/2,0),VLOOKUP($A10,'UT-I(Entry)'!$1:$1048576,8,0)) -> 0 | I10: =SUM(C10:H10) -> 0 | J10: =ROUND(I10/1.2,2)&" %" -> 0 % | K10: =VLOOKUP(A10,'UT-I(Entry)'!$1:$1048576,9,0) -> 0 | L10: =VLOOKUP(A10,'UT-I(Entry)'!$1:$1048576,10,0) -> 0
A11: =DETAILS!A10 -> 1486 | B11: =DETAILS!B10 -> ANUBHAV CHOUDHARY | C11: =IFERROR(ROUND((VLOOKUP(A11,'UT-I(Entry)'!$1:$1048576,3,0))/2,0),VLOOKUP(A11,'UT-I(Entry)'!$1:$1048576,3,0)) -> 0 | D11: =IFERROR(ROUND((VLOOKUP(A11,'UT-I(Entry)'!$1:$1048576,4,0))/2,0),VLOOKUP(A11,'UT-I(Entry)'!$1:$1048576,4,0)) -> 0 | E11: =IFERROR(ROUND((VLOOKUP(A11,'UT-I(Entry)'!$1:$1048576,5,0))/2,0),VLOOKUP(A11,'UT-I(Entry)'!$1:$1048576,5,0)) -> 0 | F11: =IFERROR(ROUND((VLOOKUP(A11,'UT-I(Entry)'!$1:$1048576,6,0))/2,0),VLOOKUP(A11,'UT-I(Entry)'!$1:$1048576,6,0)) -> 0 | G11: =IFERROR(ROUND((VLOOKUP(A11,'UT-I(Entry)'!$1:$1048576,7,0))/2,0),VLOOKUP(A11,'UT-I(Entry)'!$1:$1048576,7,0)) -> 0 | H11: =IFERROR(ROUND((VLOOKUP($A11,'UT-I(Entry)'!$1:$1048576,8,0))/2,0),VLOOKUP($A11,'UT-I(Entry)'!$1:$1048576,8,0)) -> 0 | I11: =SUM(C11:H11) -> 0 | J11: =ROUND(I11/1.2,2)&" %" -> 0 % | K11: =VLOOKUP(A11,'UT-I(Entry)'!$1:$1048576,9,0) -> 0 | L11: =VLOOKUP(A11,'UT-I(Entry)'!$1:$1048576,10,0) -> 0
A12: =DETAILS!A11 -> 1615 | B12: =DETAILS!B11 -> ARADHYA TIWARI | C12: =IFERROR(ROUND((VLOOKUP(A12,'UT-I(Entry)'!$1:$1048576,3,0))/2,0),VLOOKUP(A12,'UT-I(Entry)'!$1:$1048576,3,0)) -> 0 | D12: =IFERROR(ROUND((VLOOKUP(A12,'UT-I(Entry)'!$1:$1048576,4,0))/2,0),VLOOKUP(A12,'UT-I(Entry)'!$1:$1048576,4,0)) -> 0 | E12: =IFERROR(ROUND((VLOOKUP(A12,'UT-I(Entry)'!$1:$1048576,5,0))/2,0),VLOOKUP(A12,'UT-I(Entry)'!$1:$1048576,5,0)) -> 0 | F12: =IFERROR(ROUND((VLOOKUP(A12,'UT-I(Entry)'!$1:$1048576,6,0))/2,0),VLOOKUP(A12,'UT-I(Entry)'!$1:$1048576,6,0)) -> 0 | G12: =IFERROR(ROUND((VLOOKUP(A12,'UT-I(Entry)'!$1:$1048576,7,0))/2,0),VLOOKUP(A12,'UT-I(Entry)'!$1:$1048576,7,0)) -> 0 | H12: =IFERROR(ROUND((VLOOKUP($A12,'UT-I(Entry)'!$1:$1048576,8,0))/2,0),VLOOKUP($A12,'UT-I(Entry)'!$1:$1048576,8,0)) -> 0 | I12: =SUM(C12:H12) -> 0 | J12: =ROUND(I12/1.2,2)&" %" -> 0 % | K12: =VLOOKUP(A12,'UT-I(Entry)'!$1:$1048576,9,0) -> 0 | L12: =VLOOKUP(A12,'UT-I(Entry)'!$1:$1048576,10,0) -> 0
A13: =DETAILS!A12 -> 993 | B13: =DETAILS!B12 -> ARYAN MAURYA | C13: =IFERROR(ROUND((VLOOKUP(A13,'UT-I(Entry)'!$1:$1048576,3,0))/2,0),VLOOKUP(A13,'UT-I(Entry)'!$1:$1048576,3,0)) -> 0 | D13: =IFERROR(ROUND((VLOOKUP(A13,'UT-I(Entry)'!$1:$1048576,4,0))/2,0),VLOOKUP(A13,'UT-I(Entry)'!$1:$1048576,4,0)) -> 0 | E13: =IFERROR(ROUND((VLOOKUP(A13,'UT-I(Entry)'!$1:$1048576,5,0))/2,0),VLOOKUP(A13,'UT-I(Entry)'!$1:$1048576,5,0)) -> 0 | F13: =IFERROR(ROUND((VLOOKUP(A13,'UT-I(Entry)'!$1:$1048576,6,0))/2,0),VLOOKUP(A13,'UT-I(Entry)'!$1:$1048576,6,0)) -> 0 | G13: =IFERROR(ROUND((VLOOKUP(A13,'UT-I(Entry)'!$1:$1048576,7,0))/2,0),VLOOKUP(A13,'UT-I(Entry)'!$1:$1048576,7,0)) -> 0 | H13: =IFERROR(ROUND((VLOOKUP($A13,'UT-I(Entry)'!$1:$1048576,8,0))/2,0),VLOOKUP($A13,'UT-I(Entry)'!$1:$1048576,8,0)) -> 0 | I13: =SUM(C13:H13) -> 0 | J13: =ROUND(I13/1.2,2)&" %" -> 0 % | K13: =VLOOKUP(A13,'UT-I(Entry)'!$1:$1048576,9,0) -> 0 | L13: =VLOOKUP(A13,'UT-I(Entry)'!$1:$1048576,10,0) -> 0
A14: =DETAILS!A13 -> 1296 | B14: =DETAILS!B13 -> ARYAN SINGH | C14: =IFERROR(ROUND((VLOOKUP(A14,'UT-I(Entry)'!$1:$1048576,3,0))/2,0),VLOOKUP(A14,'UT-I(Entry)'!$1:$1048576,3,0)) -> 0 | D14: =IFERROR(ROUND((VLOOKUP(A14,'UT-I(Entry)'!$1:$1048576,4,0))/2,0),VLOOKUP(A14,'UT-I(Entry)'!$1:$1048576,4,0)) -> 0 | E14: =IFERROR(ROUND((VLOOKUP(A14,'UT-I(Entry)'!$1:$1048576,5,0))/2,0),VLOOKUP(A14,'UT-I(Entry)'!$1:$1048576,5,0)) -> 0 | F14: =IFERROR(ROUND((VLOOKUP(A14,'UT-I(Entry)'!$1:$1048576,6,0))/2,0),VLOOKUP(A14,'UT-I(Entry)'!$1:$1048576,6,0)) -> 0 | G14: =IFERROR(ROUND((VLOOKUP(A14,'UT-I(Entry)'!$1:$1048576,7,0))/2,0),VLOOKUP(A14,'UT-I(Entry)'!$1:$1048576,7,0)) -> 0 | H14: =IFERROR(ROUND((VLOOKUP($A14,'UT-I(Entry)'!$1:$1048576,8,0))/2,0),VLOOKUP($A14,'UT-I(Entry)'!$1:$1048576,8,0)) -> 0 | I14: =SUM(C14:H14) -> 0 | J14: =ROUND(I14/1.2,2)&" %" -> 0 % | K14: =VLOOKUP(A14,'UT-I(Entry)'!$1:$1048576,9,0) -> 0 | L14: =VLOOKUP(A14,'UT-I(Entry)'!$1:$1048576,10,0) -> 0
A15: =DETAILS!A14 -> 1392 | B15: =DETAILS!B14 -> ASTITVA SHYAM TIWARI | C15: =IFERROR(ROUND((VLOOKUP(A15,'UT-I(Entry)'!$1:$1048576,3,0))/2,0),VLOOKUP(A15,'UT-I(Entry)'!$1:$1048576,3,0)) -> 0 | D15: =IFERROR(ROUND((VLOOKUP(A15,'UT-I(Entry)'!$1:$1048576,4,0))/2,0),VLOOKUP(A15,'UT-I(Entry)'!$1:$1048576,4,0)) -> 0 | E15: =IFERROR(ROUND((VLOOKUP(A15,'UT-I(Entry)'!$1:$1048576,5,0))/2,0),VLOOKUP(A15,'UT-I(Entry)'!$1:$1048576,5,0)) -> 0 | F15: =IFERROR(ROUND((VLOOKUP(A15,'UT-I(Entry)'!$1:$1048576,6,0))/2,0),VLOOKUP(A15,'UT-I(Entry)'!$1:$1048576,6,0)) -> 0 | G15: =IFERROR(ROUND((VLOOKUP(A15,'UT-I(Entry)'!$1:$1048576,7,0))/2,0),VLOOKUP(A15,'UT-I(Entry)'!$1:$1048576,7,0)) -> 0 | H15: =IFERROR(ROUND((VLOOKUP($A15,'UT-I(Entry)'!$1:$1048576,8,0))/2,0),VLOOKUP($A15,'UT-I(Entry)'!$1:$1048576,8,0)) -> 0 | I15: =SUM(C15:H15) -> 0 | J15: =ROUND(I15/1.2,2)&" %" -> 0 % | K15: =VLOOKUP(A15,'UT-I(Entry)'!$1:$1048576,9,0) -> 0 | L15: =VLOOKUP(A15,'UT-I(Entry)'!$1:$1048576,10,0) -> 0
A16: =DETAILS!A15 -> 759 | B16: =DETAILS!B15 -> DEVENDRA PATHAK | C16: =IFERROR(ROUND((VLOOKUP(A16,'UT-I(Entry)'!$1:$1048576,3,0))/2,0),VLOOKUP(A16,'UT-I(Entry)'!$1:$1048576,3,0)) -> 0 | D16: =IFERROR(ROUND((VLOOKUP(A16,'UT-I(Entry)'!$1:$1048576,4,0))/2,0),VLOOKUP(A16,'UT-I(Entry)'!$1:$1048576,4,0)) -> 0 | E16: =IFERROR(ROUND((VLOOKUP(A16,'UT-I(Entry)'!$1:$1048576,5,0))/2,0),VLOOKUP(A16,'UT-I(Entry)'!$1:$1048576,5,0)) -> 0 | F16: =IFERROR(ROUND((VLOOKUP(A16,'UT-I(Entry)'!$1:$1048576,6,0))/2,0),VLOOKUP(A16,'UT-I(Entry)'!$1:$1048576,6,0)) -> 0 | G16: =IFERROR(ROUND((VLOOKUP(A16,'UT-I(Entry)'!$1:$1048576,7,0))/2,0),VLOOKUP(A16,'UT-I(Entry)'!$1:$1048576,7,0)) -> 0 | H16: =IFERROR(ROUND((VLOOKUP($A16,'UT-I(Entry)'!$1:$1048576,8,0))/2,0),VLOOKUP($A16,'UT-I(Entry)'!$1:$1048576,8,0)) -> 0 | I16: =SUM(C16:H16) -> 0 | J16: =ROUND(I16/1.2,2)&" %" -> 0 % | K16: =VLOOKUP(A16,'UT-I(Entry)'!$1:$1048576,9,0) -> 0 | L16: =VLOOKUP(A16,'UT-I(Entry)'!$1:$1048576,10,0) -> 0
... A49: =DETAILS!A48 -> 1104 | B49: =DETAILS!B48 -> VARTIKA RANA | C49: =IFERROR(ROUND((VLOOKUP(A49,'UT-I(Entry)'!$1:$1048576,3,0))/2,0),VLOOKUP(A49,'UT-I(Entry)'!$1:$1048576,3,0)) -> 0 | D49: =IFERROR(ROUND((VLOOKUP(A49,'UT-I(Entry)'!$1:$1048576,4,0))/2,0),VLOOKUP(A49,'UT-I(Entry)'!$1:$1048576,4,0)) -> 0 | E49: =IFERROR(ROUND((VLOOKUP(A49,'UT-I(Entry)'!$1:$1048576,5,0))/2,0),VLOOKUP(A49,'UT-I(Entry)'!$1:$1048576,5,0)) -> 0 | F49: =IFERROR(ROUND((VLOOKUP(A49,'UT-I(Entry)'!$1:$1048576,6,0))/2,0),VLOOKUP(A49,'UT-I(Entry)'!$1:$1048576,6,0)) -> 0 | G49: =IFERROR(ROUND((VLOOKUP(A49,'UT-I(Entry)'!$1:$1048576,7,0))/2,0),VLOOKUP(A49,'UT-I(Entry)'!$1:$1048576,7,0)) -> 0 | H49: =IFERROR(ROUND((VLOOKUP($A49,'UT-I(Entry)'!$1:$1048576,8,0))/2,0),VLOOKUP($A49,'UT-I(Entry)'!$1:$1048576,8,0)) -> 0 | I49: =SUM(C49:H49) -> 0 | J49: =ROUND(I49/1.2,2)&" %" -> 0 % | K49: =VLOOKUP(A49,'UT-I(Entry)'!$1:$1048576,9,0) -> 0 | L49: =VLOOKUP(A49,'UT-I(Entry)'!$1:$1048576,10,0) -> 0

Sheet Grade(40)
A2: 40 | B2: A
A3: 39 | B3: A
A4: 38 | B4: A
A5: 37 | B5: A
A6: 36 | B6: A
A7: 35 | B7: A
A8: 34 | B8: A
A9: 33 | B9: A
A10: 32 | B10: B
A11: 31 | B11: B
A12: 30 | B12: B
A13: 29 | B13: B
... A42: 0 | B42: E

Sheet HALF YEARLY(Entry)
A1: HALF YEARLY EXAMINATION (2025-26) CLASS - IX-A
A2: SR. NO. | B2: NAME | C2: ENGLISH | D2: HINDI | E2: MATHS | F2: SCIENCE | G2: SOCIAL SCIENCE | H2: ARTIFICIAL INTELLIGENCE | I2: WORK EDUCATION | J2: ART EDUCATION | K2: HEALTH & PHYSICAL EDUCATION | L2: DISCIPLINE | M2: Total Present | N2: Total Working | O2: Class Teacher's Remark | P2: TOTAL | Q2: Percentage
A3: =DETAILS!A3 -> 1454 | B3: =DETAILS!B3 -> AARUSH SONI | P3: =SUM(C3:H3) -> 0 | Q3: =ROUND(P3/6,2)&" %" -> 0 %
A4: =DETAILS!A4 -> 1680 | B4: =DETAILS!B4 -> AARVI JAISWAL | P4: =SUM(C4:H4) -> 0 | Q4: =ROUND(P4/6,2)&" %" -> 0 %
A5: =DETAILS!A5 -> 758 | B5: =DETAILS!B5 -> ABDUL AHAD | P5: =SUM(C5:H5) -> 0 | Q5: =ROUND(P5/6,2)&" %" -> 0 %
A6: =DETAILS!A6 -> 1616 | B6: =DETAILS!B6 -> ANAV SINGH | P6: =SUM(C6:H6) -> 0 | Q6: =ROUND(P6/6,2)&" %" -> 0 %
A7: =DETAILS!A7 -> 1443 | B7: =DETAILS!B7 -> ANKIT KUMAR | P7: =SUM(C7:H7) -> 0 | Q7: =ROUND(P7/6,2)&" %" -> 0 %
A8: =DETAILS!A8 -> 2100 | B8: =DETAILS!B8 -> ANSH SHUKLA | P8: =SUM(C8:H8) -> 0 | Q8: =ROUND(P8/6,2)&" %" -> 0 %
A9: =DETAILS!A9 -> 1767 | B9: =DETAILS!B9 -> ANSHIKA MISHRA | P9: =SUM(C9:H9) -> 0 | Q9: =ROUND(P9/6,2)&" %" -> 0 %
A10: =DETAILS!A10 -> 1486 | B10: =DETAILS!B10 -> ANUBHAV CHOUDHARY | P10: =SUM(C10:H10) -> 0 | Q10: =ROUND(P10/6,2)&" %" -> 0 %
A11: =DETAILS!A11 -> 1615 | B11: =DETAILS!B11 -> ARADHYA TIWARI | P11: =SUM(C11:H11) -> 0 | Q11: =ROUND(P11/6,2)&" %" -> 0 %
A12: =DETAILS!A12 -> 993 | B12: =DETAILS!B12 -> ARYAN MAURYA | P12: =SUM(C12:H12) -> 0 | Q12: =ROUND(P12/6,2)&" %" -> 0 %
A13: =DETAILS!A13 -> 1296 | B13: =DETAILS!B13 -> ARYAN SINGH | P13: =SUM(C13:H13) -> 0 | Q13: =ROUND(P13/6,2)&" %" -> 0 %
A14: =DETAILS!A14 -> 1392 | B14: =DETAILS!B14 -> ASTITVA SHYAM TIWARI | P14: =SUM(C14:H14) -> 0 | Q14: =ROUND(P14/6,2)&" %" -> 0 %
... A41: =DETAILS!A41 -> 989 | B41: =DETAILS!B41 -> SHUBHAM KUMAR VERMA | P41: =SUM(C41:H41) -> 0 | Q41: =ROUND(P41/6,2)&" %" -> 0 %

Sheet HALF YEARLY
A1: HALF YEARLY EXAMINATION (2025-26) CLASS - IX-A
A2: SR. NO. | B2: NAME | C2: ENGLISH | D2: HINDI | E2: MATHS | F2: SCIENCE | G2: SOCIAL SCIENCE | H2: ARTIFICIAL INTELLIGENCE | I2: WORK EDUCATION | J2: ART EDUCATION | K2: HEALTH & PHYSICAL EDUCATION | L2: DISCIPLINE | M2: Total Present | N2: Total Working | O2: Class Teacher's Remark | P2: TOTAL | Q2: Percentage
A3: =DETAILS!A3 -> 1454 | B3: =DETAILS!B3 -> AARUSH SONI | C3: =VLOOKUP($A3,'HALF YEARLY(Entry)'!$1:$1048576,3,0) -> 0 | D3: =VLOOKUP($A3,'HALF YEARLY(Entry)'!$1:$1048576,4,0) -> 0 | E3: =VLOOKUP($A3,'HALF YEARLY(Entry)'!$1:$1048576,5,0) -> 0 | F3: =VLOOKUP($A3,'HALF YEARLY(Entry)'!$1:$1048576,6,0) -> 0 | G3: =VLOOKUP($A3,'HALF YEARLY(Entry)'!$1:$1048576,7,0) -> 0 | H3: =VLOOKUP($A3,'HALF YEARLY(Entry)'!$1:$1048576,8,0) -> 0 | I3: =VLOOKUP($A3,'HALF YEARLY(Entry)'!$1:$1048576,9,0) -> 0 | J3: =VLOOKUP($A3,'HALF YEARLY(Entry)'!$1:$1048576,10,0) -> 0 | K3: =VLOOKUP($A3,'HALF YEARLY(Entry)'!$1:$1048576,11,0) -> 0 | L3: =VLOOKUP($A3,'HALF YEARLY(Entry)'!$1:$1048576,12,0) -> 0 | M3: =VLOOKUP($A3,'HALF YEARLY(Entry)'!$1:$1048576,13,0) -> 0 | N3: =VLOOKUP($A3,'HALF YEARLY(Entry)'!$1:$1048576,14,0) -> 0 | O3: =VLOOKUP($A3,'HALF YEARLY(Entry)'!$1:$1048576,15,0) -> 0 | P3: =SUM(C3:H3) -> 0 | Q3: =ROUND(P3/6,2)&" %" -> 0 %
A4: =DETAILS!A4 -> 1680 | B4: =DETAILS!B4 -> AARVI JAISWAL | C4: =VLOOKUP($A4,'HALF YEARLY(Entry)'!$1:$1048576,3,0) -> 0 | D4: =VLOOKUP($A4,'HALF YEARLY(Entry)'!$1:$1048576,4,0) -> 0 | E4: =VLOOKUP($A4,'HALF YEARLY(Entry)'!$1:$1048576,5,0) -> 0 | F4: =VLOOKUP($A4,'HALF YEARLY(Entry)'!$1:$1048576,6,0) -> 0 | G4: =VLOOKUP($A4,'HALF YEARLY(Entry)'!$1:$1048576,7,0) -> 0 | H4: =VLOOKUP($A4,'HALF YEARLY(Entry)'!$1:$1048576,8,0) -> 0 | I4: =VLOOKUP($A4,'HALF YEARLY(Entry)'!$1:$1048576,9,0) -> 0 | J4: =VLOOKUP($A4,'HALF YEARLY(Entry)'!$1:$1048576,10,0) -> 0 | K4: =VLOOKUP($A4,'HALF YEARLY(Entry)'!$1:$1048576,11,0) -> 0 | L4: =VLOOKUP($A4,'HALF YEARLY(Entry)'!$1:$1048576,12,0) -> 0 | M4: =VLOOKUP($A4,'HALF YEARLY(Entry)'!$1:$1048576,13,0) -> 0 | N4: =VLOOKUP($A4,'HALF YEARLY(Entry)'!$1:$1048576,14,0) -> 0 | O4: =VLOOKUP($A4,'HALF YEARLY(Entry)'!$1:$1048576,15,0) -> 0 | P4: =SUM(C4:H4) -> 0 | Q4: =ROUND(P4/6,2)&" %" -> 0 %
A5: =DETAILS!A5 -> 758 | B5: =DETAILS!B5 -> ABDUL AHAD | C5: =VLOOKUP($A5,'HALF YEARLY(Entry)'!$1:$1048576,3,0) -> 0 | D5: =VLOOKUP($A5,'HALF YEARLY(Entry)'!$1:$1048576,4,0) -> 0 | E5: =VLOOKUP($A5,'HALF YEARLY(Entry)'!$1:$1048576,5,0) -> 0 | F5: =VLOOKUP($A5,'HALF YEARLY(Entry)'!$1:$1048576,6,0) -> 0 | G5: =VLOOKUP($A5,'HALF YEARLY(Entry)'!$1:$1048576,7,0) -> 0 | H5: =VLOOKUP($A5,'HALF YEARLY(Entry)'!$1:$1048576,8,0) -> 0 | I5: =VLOOKUP($A5,'HALF YEARLY(Entry)'!$1:$1048576,9,0) -> 0 | J5: =VLOOKUP($A5,'HALF YEARLY(Entry)'!$1:$1048576,10,0) -> 0 | K5: =VLOOKUP($A5,'HALF YEARLY(Entry)'!$1:$1048576,11,0) -> 0 | L5: =VLOOKUP($A5,'HALF YEARLY(Entry)'!$1:$1048576,12,0) -> 0 | M5: =VLOOKUP($A5,'HALF YEARLY(Entry)'!$1:$1048576,13,0) -> 0 | N5: =VLOOKUP($A5,'HALF YEARLY(Entry)'!$1:$1048576,14,0) -> 0 | O5: =VLOOKUP($A5,'HALF YEARLY(Entry)'!$1:$1048576,15,0) -> 0 | P5: =SUM(C5:H5) -> 0 | Q5: =ROUND(P5/6,2)&" %" -> 0 %
A6: =DETAILS!A6 -> 1616 | B6: =DETAILS!B6 -> ANAV SINGH | C6: =VLOOKUP($A6,'HALF YEARLY(Entry)'!$1:$1048576,3,0) -> 0 | D6: =VLOOKUP($A6,'HALF YEARLY(Entry)'!$1:$1048576,4,0) -> 0 | E6: =VLOOKUP($A6,'HALF YEARLY(Entry)'!$1:$1048576,5,0) -> 0 | F6: =VLOOKUP($A6,'HALF YEARLY(Entry)'!$1:$1048576,6,0) -> 0 | G6: =VLOOKUP($A6,'HALF YEARLY(Entry)'!$1:$1048576,7,0) -> 0 | H6: =VLOOKUP($A6,'HALF YEARLY(Entry)'!$1:$1048576,8,0) -> 0 | I6: =VLOOKUP($A6,'HALF YEARLY(Entry)'!$1:$1048576,9,0) -> 0 | J6: =VLOOKUP($A6,'HALF YEARLY(Entry)'!$1:$1048576,10,0) -> 0 | K6: =VLOOKUP($A6,'HALF YEARLY(Entry)'!$1:$1048576,11,0) -> 0 | L6: =VLOOKUP($A6,'HALF YEARLY(Entry)'!$1:$1048576,12,0) -> 0 | M6: =VLOOKUP($A6,'HALF YEARLY(Entry)'!$1:$1048576,13,0) -> 0 | N6: =VLOOKUP($A6,'HALF YEARLY(Entry)'!$1:$1048576,14,0) -> 0 | O6: =VLOOKUP($A6,'HALF YEARLY(Entry)'!$1:$1048576,15,0) -> 0 | P6: =SUM(C6:H6) -> 0 | Q6: =ROUND(P6/6,2)&" %" -> 0 %
A7: =DETAILS!A7 -> 1443 | B7: =DETAILS!B7 -> ANKIT KUMAR | C7: =VLOOKUP($A7,'HALF YEARLY(Entry)'!$1:$1048576,3,0) -> 0 | D7: =VLOOKUP($A7,'HALF YEARLY(Entry)'!$1:$1048576,4,0) -> 0 | E7: =VLOOKUP($A7,'HALF YEARLY(Entry)'!$1:$1048576,5,0) -> 0 | F7: =VLOOKUP($A7,'HALF YEARLY(Entry)'!$1:$1048576,6,0) -> 0 | G7: =VLOOKUP($A7,'HALF YEARLY(Entry)'!$1:$1048576,7,0) -> 0 | H7: =VLOOKUP($A7,'HALF YEARLY(Entry)'!$1:$1048576,8,0) -> 0 | I7: =VLOOKUP($A7,'HALF YEARLY(Entry)'!$1:$1048576,9,0) -> 0 | J7: =VLOOKUP($A7,'HALF YEARLY(Entry)'!$1:$1048576,10,0) -> 0 | K7: =VLOOKUP($A7,'HALF YEARLY(Entry)'!$1:$1048576,11,0) -> 0 | L7: =VLOOKUP($A7,'HALF YEARLY(Entry)'!$1:$1048576,12,0) -> 0 | M7: =VLOOKUP($A7,'HALF YEARLY(Entry)'!$1:$1048576,13,0) -> 0 | N7: =VLOOKUP($A7,'HALF YEARLY(Entry)'!$1:$1048576,14,0) -> 0 | O7: =VLOOKUP($A7,'HALF YEARLY(Entry)'!$1:$1048576,15,0) -> 0 | P7: =SUM(C7:H7) -> 0 | Q7: =ROUND(P7/6,2)&" %" -> 0 %
A8: =DETAILS!A8 -> 2100 | B8: =DETAILS!B8 -> ANSH SHUKLA | C8: =VLOOKUP($A8,'HALF YEARLY(Entry)'!$1:$1048576,3,0) -> 0 | D8: =VLOOKUP($A8,'HALF YEARLY(Entry)'!$1:$1048576,4,0) -> 0 | E8: =VLOOKUP($A8,'HALF YEARLY(Entry)'!$1:$1048576,5,0) -> 0 | F8: =VLOOKUP($A8,'HALF YEARLY(Entry)'!$1:$1048576,6,0) -> 0 | G8: =VLOOKUP($A8,'HALF YEARLY(Entry)'!$1:$1048576,7,0) -> 0 | H8: =VLOOKUP($A8,'HALF YEARLY(Entry)'!$1:$1048576,8,0) -> 0 | I8: =VLOOKUP($A8,'HALF YEARLY(Entry)'!$1:$1048576,9,0) -> 0 | J8: =VLOOKUP($A8,'HALF YEARLY(Entry)'!$1:$1048576,10,0) -> 0 | K8: =VLOOKUP($A8,'HALF YEARLY(Entry)'!$1:$1048576,11,0) -> 0 | L8: =VLOOKUP($A8,'HALF YEARLY(Entry)'!$1:$1048576,12,0) -> 0 | M8: =VLOOKUP($A8,'HALF YEARLY(Entry)'!$1:$1048576,13,0) -> 0 | N8: =VLOOKUP($A8,'HALF YEARLY(Entry)'!$1:$1048576,14,0) -> 0 | O8: =VLOOKUP($A8,'HALF YEARLY(Entry)'!$1:$1048576,15,0) -> 0 | P8: =SUM(C8:H8) -> 0 | Q8: =ROUND(P8/6,2)&" %" -> 0 %
A9: =DETAILS!A9 -> 1767 | B9: =DETAILS!B9 -> ANSHIKA MISHRA | C9: =VLOOKUP($A9,'HALF YEARLY(Entry)'!$1:$1048576,3,0) -> 0 | D9: =VLOOKUP($A9,'HALF YEARLY(Entry)'!$1:$1048576,4,0) -> 0 | E9: =VLOOKUP($A9,'HALF YEARLY(Entry)'!$1:$1048576,5,0) -> 0 | F9: =VLOOKUP($A9,'HALF YEARLY(Entry)'!$1:$1048576,6,0) -> 0 | G9: =VLOOKUP($A9,'HALF YEARLY(Entry)'!$1:$1048576,7,0) -> 0 | H9: =VLOOKUP($A9,'HALF YEARLY(Entry)'!$1:$1048576,8,0) -> 0 | I9: =VLOOKUP($A9,'HALF YEARLY(Entry)'!$1:$1048576,9,0) -> 0 | J9: =VLOOKUP($A9,'HALF YEARLY(Entry)'!$1:$1048576,10,0) -> 0 | K9: =VLOOKUP($A9,'HALF YEARLY(Entry)'!$1:$1048576,11,0) -> 0 | L9: =VLOOKUP($A9,'HALF YEARLY(Entry)'!$1:$1048576,12,0) -> 0 | M9: =VLOOKUP($A9,'HALF YEARLY(Entry)'!$1:$1048576,13,0) -> 0 | N9: =VLOOKUP($A9,'HALF YEARLY(Entry)'!$1:$1048576,14,0) -> 0 | O9: =VLOOKUP($A9,'HALF YEARLY(Entry)'!$1:$1048576,15,0) -> 0 | P9: =SUM(C9:H9) -> 0 | Q9: =ROUND(P9/6,2)&" %" -> 0 %
A10: =DETAILS!A10 -> 1486 | B10: =DETAILS!B10 -> ANUBHAV CHOUDHARY | C10: =VLOOKUP($A10,'HALF YEARLY(Entry)'!$1:$1048576,3,0) -> 0 | D10: =VLOOKUP($A10,'HALF YEARLY(Entry)'!$1:$1048576,4,0) -> 0 | E10: =VLOOKUP($A10,'HALF YEARLY(Entry)'!$1:$1048576,5,0) -> 0 | F10: =VLOOKUP($A10,'HALF YEARLY(Entry)'!$1:$1048576,6,0) -> 0 | G10: =VLOOKUP($A10,'HALF YEARLY(Entry)'!$1:$1048576,7,0) -> 0 | H10: =VLOOKUP($A10,'HALF YEARLY(Entry)'!$1:$1048576,8,0) -> 0 | I10: =VLOOKUP($A10,'HALF YEARLY(Entry)'!$1:$1048576,9,0) -> 0 | J10: =VLOOKUP($A10,'HALF YEARLY(Entry)'!$1:$1048576,10,0) -> 0 | K10: =VLOOKUP($A10,'HALF YEARLY(Entry)'!$1:$1048576,11,0) -> 0 | L10: =VLOOKUP($A10,'HALF YEARLY(Entry)'!$1:$1048576,12,0) -> 0 | M10: =VLOOKUP($A10,'HALF YEARLY(Entry)'!$1:$1048576,13,0) -> 0 | N10: =VLOOKUP($A10,'HALF YEARLY(Entry)'!$1:$1048576,14,0) -> 0 | O10: =VLOOKUP($A10,'HALF YEARLY(Entry)'!$1:$1048576,15,0) -> 0 | P10: =SUM(C10:H10) -> 0 | Q10: =ROUND(P10/6,2)&" %" -> 0 %
A11: =DETAILS!A11 -> 1615 | B11: =DETAILS!B11 -> ARADHYA TIWARI | C11: =VLOOKUP($A11,'HALF YEARLY(Entry)'!$1:$1048576,3,0) -> 0 | D11: =VLOOKUP($A11,'HALF YEARLY(Entry)'!$1:$1048576,4,0) -> 0 | E11: =VLOOKUP($A11,'HALF YEARLY(Entry)'!$1:$1048576,5,0) -> 0 | F11: =VLOOKUP($A11,'HALF YEARLY(Entry)'!$1:$1048576,6,0) -> 0 | G11: =VLOOKUP($A11,'HALF YEARLY(Entry)'!$1:$1048576,7,0) -> 0 | H11: =VLOOKUP($A11,'HALF YEARLY(Entry)'!$1:$1048576,8,0) -> 0 | I11: =VLOOKUP($A11,'HALF YEARLY(Entry)'!$1:$1048576,9,0) -> 0 | J11: =VLOOKUP($A11,'HALF YEARLY(Entry)'!$1:$1048576,10,0) -> 0 | K11: =VLOOKUP($A11,'HALF YEARLY(Entry)'!$1:$1048576,11,0) -> 0 | L11: =VLOOKUP($A11,'HALF YEARLY(Entry)'!$1:$1048576,12,0) -> 0 | M11: =VLOOKUP($A11,'HALF YEARLY(Entry)'!$1:$1048576,13,0) -> 0 | N11: =VLOOKUP($A11,'HALF YEARLY(Entry)'!$1:$1048576,14,0) -> 0 | O11: =VLOOKUP($A11,'HALF YEARLY(Entry)'!$1:$1048576,15,0) -> 0 | P11: =SUM(C11:H11) -> 0 | Q11: =ROUND(P11/6,2)&" %" -> 0 %
A12: =DETAILS!A12 -> 993 | B12: =DETAILS!B12 -> ARYAN MAURYA | C12: =VLOOKUP($A12,'HALF YEARLY(Entry)'!$1:$1048576,3,0) -> 0 | D12: =VLOOKUP($A12,'HALF YEARLY(Entry)'!$1:$1048576,4,0) -> 0 | E12: =VLOOKUP($A12,'HALF YEARLY(Entry)'!$1:$1048576,5,0) -> 0 | F12: =VLOOKUP($A12,'HALF YEARLY(Entry)'!$1:$1048576,6,0) -> 0 | G12: =VLOOKUP($A12,'HALF YEARLY(Entry)'!$1:$1048576,7,0) -> 0 | H12: =VLOOKUP($A12,'HALF YEARLY(Entry)'!$1:$1048576,8,0) -> 0 | I12: =VLOOKUP($A12,'HALF YEARLY(Entry)'!$1:$1048576,9,0) -> 0 | J12: =VLOOKUP($A12,'HALF YEARLY(Entry)'!$1:$1048576,10,0) -> 0 | K12: =VLOOKUP($A12,'HALF YEARLY(Entry)'!$1:$1048576,11,0) -> 0 | L12: =VLOOKUP($A12,'HALF YEARLY(Entry)'!$1:$1048576,12,0) -> 0 | M12: =VLOOKUP($A12,'HALF YEARLY(Entry)'!$1:$1048576,13,0) -> 0 | N12: =VLOOKUP($A12,'HALF YEARLY(Entry)'!$1:$1048576,14,0) -> 0 | O12: =VLOOKUP($A12,'HALF YEARLY(Entry)'!$1:$1048576,15,0) -> 0 | P12: =SUM(C12:H12) -> 0 | Q12: =ROUND(P12/6,2)&" %" -> 0 %
A13: =DETAILS!A13 -> 1296 | B13: =DETAILS!B13 -> ARYAN SINGH | C13: =VLOOKUP($A13,'HALF YEARLY(Entry)'!$1:$1048576,3,0) -> 0 | D13: =VLOOKUP($A13,'HALF YEARLY(Entry)'!$1:$1048576,4,0) -> 0 | E13: =VLOOKUP($A13,'HALF YEARLY(Entry)'!$1:$1048576,5,0) -> 0 | F13: =VLOOKUP($A13,'HALF YEARLY(Entry)'!$1:$1048576,6,0) -> 0 | G13: =VLOOKUP($A13,'HALF YEARLY(Entry)'!$1:$1048576,7,0) -> 0 | H13: =VLOOKUP($A13,'HALF YEARLY(Entry)'!$1:$1048576,8,0) -> 0 | I13: =VLOOKUP($A13,'HALF YEARLY(Entry)'!$1:$1048576,9,0) -> 0 | J13: =VLOOKUP($A13,'HALF YEARLY(Entry)'!$1:$1048576,10,0) -> 0 | K13: =VLOOKUP($A13,'HALF YEARLY(Entry)'!$1:$1048576,11,0) -> 0 | L13: =VLOOKUP($A13,'HALF YEARLY(Entry)'!$1:$1048576,12,0) -> 0 | M13: =VLOOKUP($A13,'HALF YEARLY(Entry)'!$1:$1048576,13,0) -> 0 | N13: =VLOOKUP($A13,'HALF YEARLY(Entry)'!$1:$1048576,14,0) -> 0 | O13: =VLOOKUP($A13,'HALF YEARLY(Entry)'!$1:$1048576,15,0) -> 0 | P13: =SUM(C13:H13) -> 0 | Q13: =ROUND(P13/6,2)&" %" -> 0 %
A14: =DETAILS!A14 -> 1392 | B14: =DETAILS!B14 -> ASTITVA SHYAM TIWARI | C14: =VLOOKUP($A14,'HALF YEARLY(Entry)'!$1:$1048576,3,0) -> 0 | D14: =VLOOKUP($A14,'HALF YEARLY(Entry)'!$1:$1048576,4,0) -> 0 | E14: =VLOOKUP($A14,'HALF YEARLY(Entry)'!$1:$1048576,5,0) -> 0 | F14: =VLOOKUP($A14,'HALF YEARLY(Entry)'!$1:$1048576,6,0) -> 0 | G14: =VLOOKUP($A14,'HALF YEARLY(Entry)'!$1:$1048576,7,0) -> 0 | H14: =VLOOKUP($A14,'HALF YEARLY(Entry)'!$1:$1048576,8,0) -> 0 | I14: =VLOOKUP($A14,'HALF YEARLY(Entry)'!$1:$1048576,9,0) -> 0 | J14: =VLOOKUP($A14,'HALF YEARLY(Entry)'!$1:$1048576,10,0) -> 0 | K14: =VLOOKUP($A14,'HALF YEARLY(Entry)'!$1:$1048576,11,0) -> 0 | L14: =VLOOKUP($A14,'HALF YEARLY(Entry)'!$1:$1048576,12,0) -> 0 | M14: =VLOOKUP($A14,'HALF YEARLY(Entry)'!$1:$1048576,13,0) -> 0 | N14: =VLOOKUP($A14,'HALF YEARLY(Entry)'!$1:$1048576,14,0) -> 0 | O14: =VLOOKUP($A14,'HALF YEARLY(Entry)'!$1:$1048576,15,0) -> 0 | P14: =SUM(C14:H14) -> 0 | Q14: =ROUND(P14/6,2)&" %" -> 0 %
... A41: =DETAILS!A41 -> 989 | B41: =DETAILS!B41 -> SHUBHAM KUMAR VERMA | C41: =VLOOKUP($A41,'HALF YEARLY(Entry)'!$1:$1048576,3,0) -> 0 | D41: =VLOOKUP($A41,'HALF YEARLY(Entry)'!$1:$1048576,4,0) -> 0 | E41: =VLOOKUP($A41,'HALF YEARLY(Entry)'!$1:$1048576,5,0) -> 0 | F41: =VLOOKUP($A41,'HALF YEARLY(Entry)'!$1:$1048576,6,0) -> 0 | G41: =VLOOKUP($A41,'HALF YEARLY(Entry)'!$1:$1048576,7,0) -> 0 | H41: =VLOOKUP($A41,'HALF YEARLY(Entry)'!$1:$1048576,8,0) -> 0 | I41: =VLOOKUP($A41,'HALF YEARLY(Entry)'!$1:$1048576,9,0) -> 0 | J41: =VLOOKUP($A41,'HALF YEARLY(Entry)'!$1:$1048576,10,0) -> 0 | K41: =VLOOKUP($A41,'HALF YEARLY(Entry)'!$1:$1048576,11,0) -> 0 | L41: =VLOOKUP($A41,'HALF YEARLY(Entry)'!$1:$1048576,12,0) -> 0 | M41: =VLOOKUP($A41,'HALF YEARLY(Entry)'!$1:$1048576,13,0) -> 0 | N41: =VLOOKUP($A41,'HALF YEARLY(Entry)'!$1:$1048576,14,0) -> 0 | O41: =VLOOKUP($A41,'HALF YEARLY(Entry)'!$1:$1048576,15,0) -> 0 | P41: =SUM(C41:H41) -> 0 | Q41: =ROUND(P41/6,2)&" %" -> 0 %

Sheet Grade 50
A2: 50 | B2: A
A3: 49 | B3: A
A4: 48 | B4: A
A5: 47 | B5: A
A6: 46 | B6: A
A7: 45 | B7: A
A8: 44 | B8: A
A9: 43 | B9: A
A10: 42 | B10: A
A11: 41 | B11: A
A12: 40 | B12: B
A13: 39 | B13: B
... A52: 0 | B52: E

Sheet HY Compile
A1: Half Yearly Compile Report (2025-26) Class - IX-A
A2: S.R. No. | B2: Student's Name | C2: ENGLISH | F2: HINDI | I2: MATHEMATICS | L2: SCIENCE | O2: SOCIAL SCIENCE | R2: ARTIFICIAL INTELLIGENCE | U2: WORK EDUCATION | V2: ART EDUCATION | W2: HEALTH & PHYSICAL EDUCATION | X2: DISCIPLINE | Y2: TOTAL PRESENT | Z2: TORAL WORKING DAY | AA2: CLASS TEACHER'S REAMRK
C3: UT-I | D3: HY | E3: Total | F3: UT-I | G3: HY | H3: Total | I3: UT-I | J3: HY | K3: Total | L3: UT-I | M3: HY | N3: Total | O3: UT-I | P3: HY | Q3: Total | R3: UT-I | S3: HY | T3: Total
A4: =DETAILS!A3 -> 1454 | B4: =DETAILS!B3 -> AARUSH SONI | C4: =VLOOKUP($A4,'UT-I '!$1:$1048576,3,0) -> 0 | D4: =IFERROR(ROUND(VLOOKUP($A4,'HALF YEARLY'!$1:$1048576,3,0)*0.8,0),VLOOKUP($A4,'HALF YEARLY'!$1:$1048576,3,0)) -> 0 | E4: =SUM(C4:D4) -> 0 | F4: =VLOOKUP($A4,'UT-I '!$1:$1048576,4,0) -> 0 | G4: =IFERROR(ROUND(VLOOKUP($A4,'HALF YEARLY'!$1:$1048576,4,0)*0.8,0),VLOOKUP($A4,'HALF YEARLY'!$1:$1048576,4,0)) -> 0 | H4: =SUM(F4:G4) -> 0 | I4: =VLOOKUP($A4,'UT-I '!$1:$1048576,5,0) -> 0 | J4: =IFERROR(ROUND(VLOOKUP($A4,'HALF YEARLY'!$1:$1048576,5,0)*0.8,0),VLOOKUP($A4,'HALF YEARLY'!$1:$1048576,5,0)) -> 0 | K4: =SUM(I4:J4) -> 0 | L4: =VLOOKUP($A4,'UT-I '!$1:$1048576,6,0) -> 0 | M4: =IFERROR(ROUND(VLOOKUP($A4,'HALF YEARLY'!$1:$1048576,6,0)*0.8,0),VLOOKUP($A4,'HALF YEARLY'!$1:$1048576,6,0)) -> 0 | N4: =SUM(L4:M4) -> 0 | O4: =VLOOKUP($A4,'UT-I '!$1:$1048576,7,0) -> 0 | P4: =IFERROR(ROUND(VLOOKUP($A4,'HALF YEARLY'!$1:$1048576,7,0)*0.8,0),VLOOKUP($A4,'HALF YEARLY'!$1:$1048576,7,0)) -> 0 | Q4: =SUM(O4:P4) -> 0 | R4: =VLOOKUP($A4,'UT-I '!$1:$1048576,8,0) -> 0 | S4: =IFERROR(ROUND(VLOOKUP($A4,'HALF YEARLY'!$1:$1048576,8,0)*0.8,0),VLOOKUP($A4,'HALF YEARLY'!$1:$1048576,8,0)) -> 0 | T4: =SUM(R4:S4) -> 0 | U4: =VLOOKUP($A4,'HALF YEARLY'!$1:$1048576,9,0) -> 0 | V4: =VLOOKUP($A4,'HALF YEARLY'!$1:$1048576,10,0) -> 0 | W4: =VLOOKUP($A4,'HALF YEARLY'!$1:$1048576,11,0) -> 0 | X4: =VLOOKUP($A4,'HALF YEARLY'!$1:$1048576,12,0) -> 0 | Y4: =VLOOKUP($A4,'HALF YEARLY'!$1:$1048576,13,0) -> 0 | Z4: =VLOOKUP($A4,'HALF YEARLY'!$1:$1048576,14,0) -> 0 | AA4: =VLOOKUP($A4,'HALF YEARLY'!$1:$1048576,15,0) -> 0
A5: =DETAILS!A4 -> 1680 | B5: =DETAILS!B4 -> AARVI JAISWAL | C5: =VLOOKUP($A5,'UT-I '!$1:$1048576,3,0) -> 0 | D5: =IFERROR(ROUND(VLOOKUP($A5,'HALF YEARLY'!$1:$1048576,3,0)*0.8,0),VLOOKUP($A5,'HALF YEARLY'!$1:$1048576,3,0)) -> 0 | E5: =SUM(C5:D5) -> 0 | F5: =VLOOKUP($A5,'UT-I '!$1:$1048576,4,0) -> 0 | G5: =IFERROR(ROUND(VLOOKUP($A5,'HALF YEARLY'!$1:$1048576,4,0)*0.8,0),VLOOKUP($A5,'HALF YEARLY'!$1:$1048576,4,0)) -> 0 | H5: =SUM(F5:G5) -> 0 | I5: =VLOOKUP($A5,'UT-I '!$1:$1048576,5,0) -> 0 | J5: =IFERROR(ROUND(VLOOKUP($A5,'HALF YEARLY'!$1:$1048576,5,0)*0.8,0),VLOOKUP($A5,'HALF YEARLY'!$1:$1048576,5,0)) -> 0 | K5: =SUM(I5:J5) -> 0 | L5: =VLOOKUP($A5,'UT-I '!$1:$1048576,6,0) -> 0 | M5: =IFERROR(ROUND(VLOOKUP($A5,'HALF YEARLY'!$1:$1048576,6,0)*0.8,0),VLOOKUP($A5,'HALF YEARLY'!$1:$1048576,6,0)) -> 0 | N5: =SUM(L5:M5) -> 0 | O5: =VLOOKUP($A5,'UT-I '!$1:$1048576,7,0) -> 0 | P5: =IFERROR(ROUND(VLOOKUP($A5,'HALF YEARLY'!$1:$1048576,7,0)*0.8,0),VLOOKUP($A5,'HALF YEARLY'!$1:$1048576,7,0)) -> 0 | Q5: =SUM(O5:P5) -> 0 | R5: =VLOOKUP($A5,'UT-I '!$1:$1048576,8,0) -> 0 | S5: =IFERROR(ROUND(VLOOKUP($A5,'HALF YEARLY'!$1:$1048576,8,0)*0.8,0),VLOOKUP($A5,'HALF YEARLY'!$1:$1048576,8,0)) -> 0 | T5: =SUM(R5:S5) -> 0 | U5: =VLOOKUP($A5,'HALF YEARLY'!$1:$1048576,9,0) -> 0 | V5: =VLOOKUP($A5,'HALF YEARLY'!$1:$1048576,10,0) -> 0 | W5: =VLOOKUP($A5,'HALF YEARLY'!$1:$1048576,11,0) -> 0 | X5: =VLOOKUP($A5,'HALF YEARLY'!$1:$1048576,12,0) -> 0 | Y5: =VLOOKUP($A5,'HALF YEARLY'!$1:$1048576,13,0) -> 0 | Z5: =VLOOKUP($A5,'HALF YEARLY'!$1:$1048576,14,0) -> 0 | AA5: =VLOOKUP($A5,'HALF YEARLY'!$1:$1048576,15,0) -> 0
A6: =DETAILS!A5 -> 758 | B6: =DETAILS!B5 -> ABDUL AHAD | C6: =VLOOKUP($A6,'UT-I '!$1:$1048576,3,0) -> 0 | D6: =IFERROR(ROUND(VLOOKUP($A6,'HALF YEARLY'!$1:$1048576,3,0)*0.8,0),VLOOKUP($A6,'HALF YEARLY'!$1:$1048576,3,0)) -> 0 | E6: =SUM(C6:D6) -> 0 | F6: =VLOOKUP($A6,'UT-I '!$1:$1048576,4,0) -> 0 | G6: =IFERROR(ROUND(VLOOKUP($A6,'HALF YEARLY'!$1:$1048576,4,0)*0.8,0),VLOOKUP($A6,'HALF YEARLY'!$1:$1048576,4,0)) -> 0 | H6: =SUM(F6:G6) -> 0 | I6: =VLOOKUP($A6,'UT-I '!$1:$1048576,5,0) -> 0 | J6: =IFERROR(ROUND(VLOOKUP($A6,'HALF YEARLY'!$1:$1048576,5,0)*0.8,0),VLOOKUP($A6,'HALF YEARLY'!$1:$1048576,5,0)) -> 0 | K6: =SUM(I6:J6) -> 0 | L6: =VLOOKUP($A6,'UT-I '!$1:$1048576,6,0) -> 0 | M6: =IFERROR(ROUND(VLOOKUP($A6,'HALF YEARLY'!$1:$1048576,6,0)*0.8,0),VLOOKUP($A6,'HALF YEARLY'!$1:$1048576,6,0)) -> 0 | N6: =SUM(L6:M6) -> 0 | O6: =VLOOKUP($A6,'UT-I '!$1:$1048576,7,0) -> 0 | P6: =IFERROR(ROUND(VLOOKUP($A6,'HALF YEARLY'!$1:$1048576,7,0)*0.8,0),VLOOKUP($A6,'HALF YEARLY'!$1:$1048576,7,0)) -> 0 | Q6: =SUM(O6:P6) -> 0 | R6: =VLOOKUP($A6,'UT-I '!$1:$1048576,8,0) -> 0 | S6: =IFERROR(ROUND(VLOOKUP($A6,'HALF YEARLY'!$1:$1048576,8,0)*0.8,0),VLOOKUP($A6,'HALF YEARLY'!$1:$1048576,8,0)) -> 0 | T6: =SUM(R6:S6) -> 0 | U6: =VLOOKUP($A6,'HALF YEARLY'!$1:$1048576,9,0) -> 0 | V6: =VLOOKUP($A6,'HALF YEARLY'!$1:$1048576,10,0) -> 0 | W6: =VLOOKUP($A6,'HALF YEARLY'!$1:$1048576,11,0) -> 0 | X6: =VLOOKUP($A6,'HALF YEARLY'!$1:$1048576,12,0) -> 0 | Y6: =VLOOKUP($A6,'HALF YEARLY'!$1:$1048576,13,0) -> 0 | Z6: =VLOOKUP($A6,'HALF YEARLY'!$1:$1048576,14,0) -> 0 | AA6: =VLOOKUP($A6,'HALF YEARLY'!$1:$1048576,15,0) -> 0
A7: =DETAILS!A6 -> 1616 | B7: =DETAILS!B6 -> ANAV SINGH | C7: =VLOOKUP($A7,'UT-I '!$1:$1048576,3,0) -> 0 | D7: =IFERROR(ROUND(VLOOKUP($A7,'HALF YEARLY'!$1:$1048576,3,0)*0.8,0),VLOOKUP($A7,'HALF YEARLY'!$1:$1048576,3,0)) -> 0 | E7: =SUM(C7:D7) -> 0 | F7: =VLOOKUP($A7,'UT-I '!$1:$1048576,4,0) -> 0 | G7: =IFERROR(ROUND(VLOOKUP($A7,'HALF YEARLY'!$1:$1048576,4,0)*0.8,0),VLOOKUP($A7,'HALF YEARLY'!$1:$1048576,4,0)) -> 0 | H7: =SUM(F7:G7) -> 0 | I7: =VLOOKUP($A7,'UT-I '!$1:$1048576,5,0) -> 0 | J7: =IFERROR(ROUND(VLOOKUP($A7,'HALF YEARLY'!$1:$1048576,5,0)*0.8,0),VLOOKUP($A7,'HALF YEARLY'!$1:$1048576,5,0)) -> 0 | K7: =SUM(I7:J7) -> 0 | L7: =VLOOKUP($A7,'UT-I '!$1:$1048576,6,0) -> 0 | M7: =IFERROR(ROUND(VLOOKUP($A7,'HALF YEARLY'!$1:$1048576,6,0)*0.8,0),VLOOKUP($A7,'HALF YEARLY'!$1:$1048576,6,0)) -> 0 | N7: =SUM(L7:M7) -> 0 | O7: =VLOOKUP($A7,'UT-I '!$1:$1048576,7,0) -> 0 | P7: =IFERROR(ROUND(VLOOKUP($A7,'HALF YEARLY'!$1:$1048576,7,0)*0.8,0),VLOOKUP($A7,'HALF YEARLY'!$1:$1048576,7,0)) -> 0 | Q7: =SUM(O7:P7) -> 0 | R7: =VLOOKUP($A7,'UT-I '!$1:$1048576,8,0) -> 0 | S7: =IFERROR(ROUND(VLOOKUP($A7,'HALF YEARLY'!$1:$1048576,8,0)*0.8,0),VLOOKUP($A7,'HALF YEARLY'!$1:$1048576,8,0)) -> 0 | T7: =SUM(R7:S7) -> 0 | U7: =VLOOKUP($A7,'HALF YEARLY'!$1:$1048576,9,0) -> 0 | V7: =VLOOKUP($A7,'HALF YEARLY'!$1:$1048576,10,0) -> 0 | W7: =VLOOKUP($A7,'HALF YEARLY'!$1:$1048576,11,0) -> 0 | X7: =VLOOKUP($A7,'HALF YEARLY'!$1:$1048576,12,0) -> 0 | Y7: =VLOOKUP($A7,'HALF YEARLY'!$1:$1048576,13,0) -> 0 | Z7: =VLOOKUP($A7,'HALF YEARLY'!$1:$1048576,14,0) -> 0 | AA7: =VLOOKUP($A7,'HALF YEARLY'!$1:$1048576,15,0) -> 0
A8: =DETAILS!A7 -> 1443 | B8: =DETAILS!B7 -> ANKIT KUMAR | C8: =VLOOKUP($A8,'UT-I '!$1:$1048576,3,0) -> 0 | D8: =IFERROR(ROUND(VLOOKUP($A8,'HALF YEARLY'!$1:$1048576,3,0)*0.8,0),VLOOKUP($A8,'HALF YEARLY'!$1:$1048576,3,0)) -> 0 | E8: =SUM(C8:D8) -> 0 | F8: =VLOOKUP($A8,'UT-I '!$1:$1048576,4,0) -> 0 | G8: =IFERROR(ROUND(VLOOKUP($A8,'HALF YEARLY'!$1:$1048576,4,0)*0.8,0),VLOOKUP($A8,'HALF YEARLY'!$1:$1048576,4,0)) -> 0 | H8: =SUM(F8:G8) -> 0 | I8: =VLOOKUP($A8,'UT-I '!$1:$1048576,5,0) -> 0 | J8: =IFERROR(ROUND(VLOOKUP($A8,'HALF YEARLY'!$1:$1048576,5,0)*0.8,0),VLOOKUP($A8,'HALF YEARLY'!$1:$1048576,5,0)) -> 0 | K8: =SUM(I8:J8) -> 0 | L8: =VLOOKUP($A8,'UT-I '!$1:$1048576,6,0) -> 0 | M8: =IFERROR(ROUND(VLOOKUP($A8,'HALF YEARLY'!$1:$1048576,6,0)*0.8,0),VLOOKUP($A8,'HALF YEARLY'!$1:$1048576,6,0)) -> 0 | N8: =SUM(L8:M8) -> 0 | O8: =VLOOKUP($A8,'UT-I '!$1:$1048576,7,0) -> 0 | P8: =IFERROR(ROUND(VLOOKUP($A8,'HALF YEARLY'!$1:$1048576,7,0)*0.8,0),VLOOKUP($A8,'HALF YEARLY'!$1:$1048576,7,0)) -> 0 | Q8: =SUM(O8:P8) -> 0 | R8: =VLOOKUP($A8,'UT-I '!$1:$1048576,8,0) -> 0 | S8: =IFERROR(ROUND(VLOOKUP($A8,'HALF YEARLY'!$1:$1048576,8,0)*0.8,0),VLOOKUP($A8,'HALF YEARLY'!$1:$1048576,8,0)) -> 0 | T8: =SUM(R8:S8) -> 0 | U8: =VLOOKUP($A8,'HALF YEARLY'!$1:$1048576,9,0) -> 0 | V8: =VLOOKUP($A8,'HALF YEARLY'!$1:$1048576,10,0) -> 0 | W8: =VLOOKUP($A8,'HALF YEARLY'!$1:$1048576,11,0) -> 0 | X8: =VLOOKUP($A8,'HALF YEARLY'!$1:$1048576,12,0) -> 0 | Y8: =VLOOKUP($A8,'HALF YEARLY'!$1:$1048576,13,0) -> 0 | Z8: =VLOOKUP($A8,'HALF YEARLY'!$1:$1048576,14,0) -> 0 | AA8: =VLOOKUP($A8,'HALF YEARLY'!$1:$1048576,15,0) -> 0
A9: =DETAILS!A8 -> 2100 | B9: =DETAILS!B8 -> ANSH SHUKLA | C9: =VLOOKUP($A9,'UT-I '!$1:$1048576,3,0) -> 0 | D9: =IFERROR(ROUND(VLOOKUP($A9,'HALF YEARLY'!$1:$1048576,3,0)*0.8,0),VLOOKUP($A9,'HALF YEARLY'!$1:$1048576,3,0)) -> 0 | E9: =SUM(C9:D9) -> 0 | F9: =VLOOKUP($A9,'UT-I '!$1:$1048576,4,0) -> 0 | G9: =IFERROR(ROUND(VLOOKUP($A9,'HALF YEARLY'!$1:$1048576,4,0)*0.8,0),VLOOKUP($A9,'HALF YEARLY'!$1:$1048576,4,0)) -> 0 | H9: =SUM(F9:G9) -> 0 | I9: =VLOOKUP($A9,'UT-I '!$1:$1048576,5,0) -> 0 | J9: =IFERROR(ROUND(VLOOKUP($A9,'HALF YEARLY'!$1:$1048576,5,0)*0.8,0),VLOOKUP($A9,'HALF YEARLY'!$1:$1048576,5,0)) -> 0 | K9: =SUM(I9:J9) -> 0 | L9: =VLOOKUP($A9,'UT-I '!$1:$1048576,6,0) -> 0 | M9: =IFERROR(ROUND(VLOOKUP($A9,'HALF YEARLY'!$1:$1048576,6,0)*0.8,0),VLOOKUP($A9,'HALF YEARLY'!$1:$1048576,6,0)) -> 0 | N9: =SUM(L9:M9) -> 0 | O9: =VLOOKUP($A9,'UT-I '!$1:$1048576,7,0) -> 0 | P9: =IFERROR(ROUND(VLOOKUP($A9,'HALF YEARLY'!$1:$1048576,7,0)*0.8,0),VLOOKUP($A9,'HALF YEARLY'!$1:$1048576,7,0)) -> 0 | Q9: =SUM(O9:P9) -> 0 | R9: =VLOOKUP($A9,'UT-I '!$1:$1048576,8,0) -> 0 | S9: =IFERROR(ROUND(VLOOKUP($A9,'HALF YEARLY'!$1:$1048576,8,0)*0.8,0),VLOOKUP($A9,'HALF YEARLY'!$1:$1048576,8,0)) -> 0 | T9: =SUM(R9:S9) -> 0 | U9: =VLOOKUP($A9,'HALF YEARLY'!$1:$1048576,9,0) -> 0 | V9: =VLOOKUP($A9,'HALF YEARLY'!$1:$1048576,10,0) -> 0 | W9: =VLOOKUP($A9,'HALF YEARLY'!$1:$1048576,11,0) -> 0 | X9: =VLOOKUP($A9,'HALF YEARLY'!$1:$1048576,12,0) -> 0 | Y9: =VLOOKUP($A9,'HALF YEARLY'!$1:$1048576,13,0) -> 0 | Z9: =VLOOKUP($A9,'HALF YEARLY'!$1:$1048576,14,0) -> 0 | AA9: =VLOOKUP($A9,'HALF YEARLY'!$1:$1048576,15,0) -> 0
A10: =DETAILS!A9 -> 1767 | B10: =DETAILS!B9 -> ANSHIKA MISHRA | C10: =VLOOKUP($A10,'UT-I '!$1:$1048576,3,0) -> 0 | D10: =IFERROR(ROUND(VLOOKUP($A10,'HALF YEARLY'!$1:$1048576,3,0)*0.8,0),VLOOKUP($A10,'HALF YEARLY'!$1:$1048576,3,0)) -> 0 | E10: =SUM(C10:D10) -> 0 | F10: =VLOOKUP($A10,'UT-I '!$1:$1048576,4,0) -> 0 | G10: =IFERROR(ROUND(VLOOKUP($A10,'HALF YEARLY'!$1:$1048576,4,0)*0.8,0),VLOOKUP($A10,'HALF YEARLY'!$1:$1048576,4,0)) -> 0 | H10: =SUM(F10:G10) -> 0 | I10: =VLOOKUP($A10,'UT-I '!$1:$1048576,5,0) -> 0 | J10: =IFERROR(ROUND(VLOOKUP($A10,'HALF YEARLY'!$1:$1048576,5,0)*0.8,0),VLOOKUP($A10,'HALF YEARLY'!$1:$1048576,5,0)) -> 0 | K10: =SUM(I10:J10) -> 0 | L10: =VLOOKUP($A10,'UT-I '!$1:$1048576,6,0) -> 0 | M10: =IFERROR(ROUND(VLOOKUP($A10,'HALF YEARLY'!$1:$1048576,6,0)*0.8,0),VLOOKUP($A10,'HALF YEARLY'!$1:$1048576,6,0)) -> 0 | N10: =SUM(L10:M10) -> 0 | O10: =VLOOKUP($A10,'UT-I '!$1:$1048576,7,0) -> 0 | P10: =IFERROR(ROUND(VLOOKUP($A10,'HALF YEARLY'!$1:$1048576,7,0)*0.8,0),VLOOKUP($A10,'HALF YEARLY'!$1:$1048576,7,0)) -> 0 | Q10: =SUM(O10:P10) -> 0 | R10: =VLOOKUP($A10,'UT-I '!$1:$1048576,8,0) -> 0 | S10: =IFERROR(ROUND(VLOOKUP($A10,'HALF YEARLY'!$1:$1048576,8,0)*0.8,0),VLOOKUP($A10,'HALF YEARLY'!$1:$1048576,8,0)) -> 0 | T10: =SUM(R10:S10) -> 0 | U10: =VLOOKUP($A10,'HALF YEARLY'!$1:$1048576,9,0) -> 0 | V10: =VLOOKUP($A10,'HALF YEARLY'!$1:$1048576,10,0) -> 0 | W10: =VLOOKUP($A10,'HALF YEARLY'!$1:$1048576,11,0) -> 0 | X10: =VLOOKUP($A10,'HALF YEARLY'!$1:$1048576,12,0) -> 0 | Y10: =VLOOKUP($A10,'HALF YEARLY'!$1:$1048576,13,0) -> 0 | Z10: =VLOOKUP($A10,'HALF YEARLY'!$1:$1048576,14,0) -> 0 | AA10: =VLOOKUP($A10,'HALF YEARLY'!$1:$1048576,15,0) -> 0
A11: =DETAILS!A10 -> 1486 | B11: =DETAILS!B10 -> ANUBHAV CHOUDHARY | C11: =VLOOKUP($A11,'UT-I '!$1:$1048576,3,0) -> 0 | D11: =IFERROR(ROUND(VLOOKUP($A11,'HALF YEARLY'!$1:$1048576,3,0)*0.8,0),VLOOKUP($A11,'HALF YEARLY'!$1:$1048576,3,0)) -> 0 | E11: =SUM(C11:D11) -> 0 | F11: =VLOOKUP($A11,'UT-I '!$1:$1048576,4,0) -> 0 | G11: =IFERROR(ROUND(VLOOKUP($A11,'HALF YEARLY'!$1:$1048576,4,0)*0.8,0),VLOOKUP($A11,'HALF YEARLY'!$1:$1048576,4,0)) -> 0 | H11: =SUM(F11:G11) -> 0 | I11: =VLOOKUP($A11,'UT-I '!$1:$1048576,5,0) -> 0 | J11: =IFERROR(ROUND(VLOOKUP($A11,'HALF YEARLY'!$1:$1048576,5,0)*0.8,0),VLOOKUP($A11,'HALF YEARLY'!$1:$1048576,5,0)) -> 0 | K11: =SUM(I11:J11) -> 0 | L11: =VLOOKUP($A11,'UT-I '!$1:$1048576,6,0) -> 0 | M11: =IFERROR(ROUND(VLOOKUP($A11,'HALF YEARLY'!$1:$1048576,6,0)*0.8,0),VLOOKUP($A11,'HALF YEARLY'!$1:$1048576,6,0)) -> 0 | N11: =SUM(L11:M11) -> 0 | O11: =VLOOKUP($A11,'UT-I '!$1:$1048576,7,0) -> 0 | P11: =IFERROR(ROUND(VLOOKUP($A11,'HALF YEARLY'!$1:$1048576,7,0)*0.8,0),VLOOKUP($A11,'HALF YEARLY'!$1:$1048576,7,0)) -> 0 | Q11: =SUM(O11:P11) -> 0 | R11: =VLOOKUP($A11,'UT-I '!$1:$1048576,8,0) -> 0 | S11: =IFERROR(ROUND(VLOOKUP($A11,'HALF YEARLY'!$1:$1048576,8,0)*0.8,0),VLOOKUP($A11,'HALF YEARLY'!$1:$1048576,8,0)) -> 0 | T11: =SUM(R11:S11) -> 0 | U11: =VLOOKUP($A11,'HALF YEARLY'!$1:$1048576,9,0) -> 0 | V11: =VLOOKUP($A11,'HALF YEARLY'!$1:$1048576,10,0) -> 0 | W11: =VLOOKUP($A11,'HALF YEARLY'!$1:$1048576,11,0) -> 0 | X11: =VLOOKUP($A11,'HALF YEARLY'!$1:$1048576,12,0) -> 0 | Y11: =VLOOKUP($A11,'HALF YEARLY'!$1:$1048576,13,0) -> 0 | Z11: =VLOOKUP($A11,'HALF YEARLY'!$1:$1048576,14,0) -> 0 | AA11: =VLOOKUP($A11,'HALF YEARLY'!$1:$1048576,15,0) -> 0
A12: =DETAILS!A11 -> 1615 | B12: =DETAILS!B11 -> ARADHYA TIWARI | C12: =VLOOKUP($A12,'UT-I '!$1:$1048576,3,0) -> 0 | D12: =IFERROR(ROUND(VLOOKUP($A12,'HALF YEARLY'!$1:$1048576,3,0)*0.8,0),VLOOKUP($A12,'HALF YEARLY'!$1:$1048576,3,0)) -> 0 | E12: =SUM(C12:D12) -> 0 | F12: =VLOOKUP($A12,'UT-I '!$1:$1048576,4,0) -> 0 | G12: =IFERROR(ROUND(VLOOKUP($A12,'HALF YEARLY'!$1:$1048576,4,0)*0.8,0),VLOOKUP($A12,'HALF YEARLY'!$1:$1048576,4,0)) -> 0 | H12: =SUM(F12:G12) -> 0 | I12: =VLOOKUP($A12,'UT-I '!$1:$1048576,5,0) -> 0 | J12: =IFERROR(ROUND(VLOOKUP($A12,'HALF YEARLY'!$1:$1048576,5,0)*0.8,0),VLOOKUP($A12,'HALF YEARLY'!$1:$1048576,5,0)) -> 0 | K12: =SUM(I12:J12) -> 0 | L12: =VLOOKUP($A12,'UT-I '!$1:$1048576,6,0) -> 0 | M12: =IFERROR(ROUND(VLOOKUP($A12,'HALF YEARLY'!$1:$1048576,6,0)*0.8,0),VLOOKUP($A12,'HALF YEARLY'!$1:$1048576,6,0)) -> 0 | N12: =SUM(L12:M12) -> 0 | O12: =VLOOKUP($A12,'UT-I '!$1:$1048576,7,0) -> 0 | P12: =IFERROR(ROUND(VLOOKUP($A12,'HALF YEARLY'!$1:$1048576,7,0)*0.8,0),VLOOKUP($A12,'HALF YEARLY'!$1:$1048576,7,0)) -> 0 | Q12: =SUM(O12:P12) -> 0 | R12: =VLOOKUP($A12,'UT-I '!$1:$1048576,8,0) -> 0 | S12: =IFERROR(ROUND(VLOOKUP($A12,'HALF YEARLY'!$1:$1048576,8,0)*0.8,0),VLOOKUP($A12,'HALF YEARLY'!$1:$1048576,8,0)) -> 0 | T12: =SUM(R12:S12) -> 0 | U12: =VLOOKUP($A12,'HALF YEARLY'!$1:$1048576,9,0) -> 0 | V12: =VLOOKUP($A12,'HALF YEARLY'!$1:$1048576,10,0) -> 0 | W12: =VLOOKUP($A12,'HALF YEARLY'!$1:$1048576,11,0) -> 0 | X12: =VLOOKUP($A12,'HALF YEARLY'!$1:$1048576,12,0) -> 0 | Y12: =VLOOKUP($A12,'HALF YEARLY'!$1:$1048576,13,0) -> 0 | Z12: =VLOOKUP($A12,'HALF YEARLY'!$1:$1048576,14,0) -> 0 | AA12: =VLOOKUP($A12,'HALF YEARLY'!$1:$1048576,15,0) -> 0
A13: =DETAILS!A12 -> 993 | B13: =DETAILS!B12 -> ARYAN MAURYA | C13: =VLOOKUP($A13,'UT-I '!$1:$1048576,3,0) -> 0 | D13: =IFERROR(ROUND(VLOOKUP($A13,'HALF YEARLY'!$1:$1048576,3,0)*0.8,0),VLOOKUP($A13,'HALF YEARLY'!$1:$1048576,3,0)) -> 0 | E13: =SUM(C13:D13) -> 0 | F13: =VLOOKUP($A13,'UT-I '!$1:$1048576,4,0) -> 0 | G13: =IFERROR(ROUND(VLOOKUP($A13,'HALF YEARLY'!$1:$1048576,4,0)*0.8,0),VLOOKUP($A13,'HALF YEARLY'!$1:$1048576,4,0)) -> 0 | H13: =SUM(F13:G13) -> 0 | I13: =VLOOKUP($A13,'UT-I '!$1:$1048576,5,0) -> 0 | J13: =IFERROR(ROUND(VLOOKUP($A13,'HALF YEARLY'!$1:$1048576,5,0)*0.8,0),VLOOKUP($A13,'HALF YEARLY'!$1:$1048576,5,0)) -> 0 | K13: =SUM(I13:J13) -> 0 | L13: =VLOOKUP($A13,'UT-I '!$1:$1048576,6,0) -> 0 | M13: =IFERROR(ROUND(VLOOKUP($A13,'HALF YEARLY'!$1:$1048576,6,0)*0.8,0),VLOOKUP($A13,'HALF YEARLY'!$1:$1048576,6,0)) -> 0 | N13: =SUM(L13:M13) -> 0 | O13: =VLOOKUP($A13,'UT-I '!$1:$1048576,7,0) -> 0 | P13: =IFERROR(ROUND(VLOOKUP($A13,'HALF YEARLY'!$1:$1048576,7,0)*0.8,0),VLOOKUP($A13,'HALF YEARLY'!$1:$1048576,7,0)) -> 0 | Q13: =SUM(O13:P13) -> 0 | R13: =VLOOKUP($A13,'UT-I '!$1:$1048576,8,0) -> 0 | S13: =IFERROR(ROUND(VLOOKUP($A13,'HALF YEARLY'!$1:$1048576,8,0)*0.8,0),VLOOKUP($A13,'HALF YEARLY'!$1:$1048576,8,0)) -> 0 | T13: =SUM(R13:S13) -> 0 | U13: =VLOOKUP($A13,'HALF YEARLY'!$1:$1048576,9,0) -> 0 | V13: =VLOOKUP($A13,'HALF YEARLY'!$1:$1048576,10,0) -> 0 | W13: =VLOOKUP($A13,'HALF YEARLY'!$1:$1048576,11,0) -> 0 | X13: =VLOOKUP($A13,'HALF YEARLY'!$1:$1048576,12,0) -> 0 | Y13: =VLOOKUP($A13,'HALF YEARLY'!$1:$1048576,13,0) -> 0 | Z13: =VLOOKUP($A13,'HALF YEARLY'!$1:$1048576,14,0) -> 0 | AA13: =VLOOKUP($A13,'HALF YEARLY'!$1:$1048576,15,0) -> 0
A14: =DETAILS!A13 -> 1296 | B14: =DETAILS!B13 -> ARYAN SINGH | C14: =VLOOKUP($A14,'UT-I '!$1:$1048576,3,0) -> 0 | D14: =IFERROR(ROUND(VLOOKUP($A14,'HALF YEARLY'!$1:$1048576,3,0)*0.8,0),VLOOKUP($A14,'HALF YEARLY'!$1:$1048576,3,0)) -> 0 | E14: =SUM(C14:D14) -> 0 | F14: =VLOOKUP($A14,'UT-I '!$1:$1048576,4,0) -> 0 | G14: =IFERROR(ROUND(VLOOKUP($A14,'HALF YEARLY'!$1:$1048576,4,0)*0.8,0),VLOOKUP($A14,'HALF YEARLY'!$1:$1048576,4,0)) -> 0 | H14: =SUM(F14:G14) -> 0 | I14: =VLOOKUP($A14,'UT-I '!$1:$1048576,5,0) -> 0 | J14: =IFERROR(ROUND(VLOOKUP($A14,'HALF YEARLY'!$1:$1048576,5,0)*0.8,0),VLOOKUP($A14,'HALF YEARLY'!$1:$1048576,5,0)) -> 0 | K14: =SUM(I14:J14) -> 0 | L14: =VLOOKUP($A14,'UT-I '!$1:$1048576,6,0) -> 0 | M14: =IFERROR(ROUND(VLOOKUP($A14,'HALF YEARLY'!$1:$1048576,6,0)*0.8,0),VLOOKUP($A14,'HALF YEARLY'!$1:$1048576,6,0)) -> 0 | N14: =SUM(L14:M14) -> 0 | O14: =VLOOKUP($A14,'UT-I '!$1:$1048576,7,0) -> 0 | P14: =IFERROR(ROUND(VLOOKUP($A14,'HALF YEARLY'!$1:$1048576,7,0)*0.8,0),VLOOKUP($A14,'HALF YEARLY'!$1:$1048576,7,0)) -> 0 | Q14: =SUM(O14:P14) -> 0 | R14: =VLOOKUP($A14,'UT-I '!$1:$1048576,8,0) -> 0 | S14: =IFERROR(ROUND(VLOOKUP($A14,'HALF YEARLY'!$1:$1048576,8,0)*0.8,0),VLOOKUP($A14,'HALF YEARLY'!$1:$1048576,8,0)) -> 0 | T14: =SUM(R14:S14) -> 0 | U14: =VLOOKUP($A14,'HALF YEARLY'!$1:$1048576,9,0) -> 0 | V14: =VLOOKUP($A14,'HALF YEARLY'!$1:$1048576,10,0) -> 0 | W14: =VLOOKUP($A14,'HALF YEARLY'!$1:$1048576,11,0) -> 0 | X14: =VLOOKUP($A14,'HALF YEARLY'!$1:$1048576,12,0) -> 0 | Y14: =VLOOKUP($A14,'HALF YEARLY'!$1:$1048576,13,0) -> 0 | Z14: =VLOOKUP($A14,'HALF YEARLY'!$1:$1048576,14,0) -> 0 | AA14: =VLOOKUP($A14,'HALF YEARLY'!$1:$1048576,15,0) -> 0
A15: =DETAILS!A14 -> 1392 | B15: =DETAILS!B14 -> ASTITVA SHYAM TIWARI | C15: =VLOOKUP($A15,'UT-I '!$1:$1048576,3,0) -> 0 | D15: =IFERROR(ROUND(VLOOKUP($A15,'HALF YEARLY'!$1:$1048576,3,0)*0.8,0),VLOOKUP($A15,'HALF YEARLY'!$1:$1048576,3,0)) -> 0 | E15: =SUM(C15:D15) -> 0 | F15: =VLOOKUP($A15,'UT-I '!$1:$1048576,4,0) -> 0 | G15: =IFERROR(ROUND(VLOOKUP($A15,'HALF YEARLY'!$1:$1048576,4,0)*0.8,0),VLOOKUP($A15,'HALF YEARLY'!$1:$1048576,4,0)) -> 0 | H15: =SUM(F15:G15) -> 0 | I15: =VLOOKUP($A15,'UT-I '!$1:$1048576,5,0) -> 0 | J15: =IFERROR(ROUND(VLOOKUP($A15,'HALF YEARLY'!$1:$1048576,5,0)*0.8,0),VLOOKUP($A15,'HALF YEARLY'!$1:$1048576,5,0)) -> 0 | K15: =SUM(I15:J15) -> 0 | L15: =VLOOKUP($A15,'UT-I '!$1:$1048576,6,0) -> 0 | M15: =IFERROR(ROUND(VLOOKUP($A15,'HALF YEARLY'!$1:$1048576,6,0)*0.8,0),VLOOKUP($A15,'HALF YEARLY'!$1:$1048576,6,0)) -> 0 | N15: =SUM(L15:M15) -> 0 | O15: =VLOOKUP($A15,'UT-I '!$1:$1048576,7,0) -> 0 | P15: =IFERROR(ROUND(VLOOKUP($A15,'HALF YEARLY'!$1:$1048576,7,0)*0.8,0),VLOOKUP($A15,'HALF YEARLY'!$1:$1048576,7,0)) -> 0 | Q15: =SUM(O15:P15) -> 0 | R15: =VLOOKUP($A15,'UT-I '!$1:$1048576,8,0) -> 0 | S15: =IFERROR(ROUND(VLOOKUP($A15,'HALF YEARLY'!$1:$1048576,8,0)*0.8,0),VLOOKUP($A15,'HALF YEARLY'!$1:$1048576,8,0)) -> 0 | T15: =SUM(R15:S15) -> 0 | U15: =VLOOKUP($A15,'HALF YEARLY'!$1:$1048576,9,0) -> 0 | V15: =VLOOKUP($A15,'HALF YEARLY'!$1:$1048576,10,0) -> 0 | W15: =VLOOKUP($A15,'HALF YEARLY'!$1:$1048576,11,0) -> 0 | X15: =VLOOKUP($A15,'HALF YEARLY'!$1:$1048576,12,0) -> 0 | Y15: =VLOOKUP($A15,'HALF YEARLY'!$1:$1048576,13,0) -> 0 | Z15: =VLOOKUP($A15,'HALF YEARLY'!$1:$1048576,14,0) -> 0 | AA15: =VLOOKUP($A15,'HALF YEARLY'!$1:$1048576,15,0) -> 0
... A41: =DETAILS!A40 -> 1614 | B41: =DETAILS!B40 -> SHRISTI PATEL | C41: =VLOOKUP($A41,'UT-I '!$1:$1048576,3,0) -> 0 | D41: =IFERROR(ROUND(VLOOKUP($A41,'HALF YEARLY'!$1:$1048576,3,0)*0.8,0),VLOOKUP($A41,'HALF YEARLY'!$1:$1048576,3,0)) -> 0 | E41: =SUM(C41:D41) -> 0 | F41: =VLOOKUP($A41,'UT-I '!$1:$1048576,4,0) -> 0 | G41: =IFERROR(ROUND(VLOOKUP($A41,'HALF YEARLY'!$1:$1048576,4,0)*0.8,0),VLOOKUP($A41,'HALF YEARLY'!$1:$1048576,4,0)) -> 0 | H41: =SUM(F41:G41) -> 0 | I41: =VLOOKUP($A41,'UT-I '!$1:$1048576,5,0) -> 0 | J41: =IFERROR(ROUND(VLOOKUP($A41,'HALF YEARLY'!$1:$1048576,5,0)*0.8,0),VLOOKUP($A41,'HALF YEARLY'!$1:$1048576,5,0)) -> 0 | K41: =SUM(I41:J41) -> 0 | L41: =VLOOKUP($A41,'UT-I '!$1:$1048576,6,0) -> 0 | M41: =IFERROR(ROUND(VLOOKUP($A41,'HALF YEARLY'!$1:$1048576,6,0)*0.8,0),VLOOKUP($A41,'HALF YEARLY'!$1:$1048576,6,0)) -> 0 | N41: =SUM(L41:M41) -> 0 | O41: =VLOOKUP($A41,'UT-I '!$1:$1048576,7,0) -> 0 | P41: =IFERROR(ROUND(VLOOKUP($A41,'HALF YEARLY'!$1:$1048576,7,0)*0.8,0),VLOOKUP($A41,'HALF YEARLY'!$1:$1048576,7,0)) -> 0 | Q41: =SUM(O41:P41) -> 0 | R41: =VLOOKUP($A41,'UT-I '!$1:$1048576,8,0) -> 0 | S41: =IFERROR(ROUND(VLOOKUP($A41,'HALF YEARLY'!$1:$1048576,8,0)*0.8,0),VLOOKUP($A41,'HALF YEARLY'!$1:$1048576,8,0)) -> 0 | T41: =SUM(R41:S41) -> 0 | U41: =VLOOKUP($A41,'HALF YEARLY'!$1:$1048576,9,0) -> 0 | V41: =VLOOKUP($A41,'HALF YEARLY'!$1:$1048576,10,0) -> 0 | W41: =VLOOKUP($A41,'HALF YEARLY'!$1:$1048576,11,0) -> 0 | X41: =VLOOKUP($A41,'HALF YEARLY'!$1:$1048576,12,0) -> 0 | Y41: =VLOOKUP($A41,'HALF YEARLY'!$1:$1048576,13,0) -> 0 | Z41: =VLOOKUP($A41,'HALF YEARLY'!$1:$1048576,14,0) -> 0 | AA41: =VLOOKUP($A41,'HALF YEARLY'!$1:$1048576,15,0) -> 0

Sheet HY Report
B2: SAINIK PUBLIC SCHOOL
B3: (Affiliated to C.B.S.E. New Delhi- Reg. No. : 2131299)
B4: Building No. VB1893, Vikas Bhawan Ward,
B5: Nagar Palika Parishad, Nawabganj, Barabanki
B6: HALF YEARLY REPORT CARD
B7: SESSION 2025-26
B8: STUDENT PROFILE
B9: Student's Name | C9: =": "&VLOOKUP($K$9,DETAILS!$1:$1048576,2,0) -> #N/A | I9: Admission No. : | K9: 1
B10: Mother's Name | C10: =": "&VLOOKUP($K$9,DETAILS!$1:$1048576,3,0) -> #N/A | I10: Class & Sec. : | K10: =VLOOKUP($K$9,DETAILS!$1:$1048576,6,0) -> #N/A
B11: Father's Name | C11: =": "&VLOOKUP($K$9,DETAILS!$1:$1048576,4,0) -> #N/A | I11: Date of Birth : | K11: =VLOOKUP($K$9,DETAILS!$1:$1048576,5,0) -> #N/A
B13: PART-1 : ACADEMIC PERFORMANCE-SCHOLASTIC AREAS
B14: SUBJECT | D14: UNIT TEST - I (20) | G14: HALF YEARLY (80) | K14: TOTAL (100)
B15: ENGLISH | D15: =VLOOKUP($K$9,'HY Compile'!$1:$1048576,3,0) -> #N/A | G15: =VLOOKUP($K$9,'HY Compile'!$1:$1048576,4,0) -> #N/A | K15: =SUM(D15:J15) -> #N/A
B16: HINDI | D16: =VLOOKUP($K$9,'HY Compile'!$1:$1048576,6,0) -> #N/A | G16: =VLOOKUP($K$9,'HY Compile'!$1:$1048576,7,0) -> #N/A | K16: =SUM(D16:J16) -> #N/A
B17: MATHEMATICS | D17: =VLOOKUP($K$9,'HY Compile'!$1:$1048576,9,0) -> #N/A | G17: =VLOOKUP($K$9,'HY Compile'!$1:$1048576,10,0) -> #N/A | K17: =SUM(D17:J17) -> #N/A
B18: SCIENCE | D18: =VLOOKUP($K$9,'HY Compile'!$1:$1048576,12,0) -> #N/A | G18: =VLOOKUP($K$9,'HY Compile'!$1:$1048576,13,0) -> #N/A | K18: =SUM(D18:J18) -> #N/A
B19: SOCIAL STUDIES | D19: =VLOOKUP($K$9,'HY Compile'!$1:$1048576,15,0) -> #N/A | G19: =VLOOKUP($K$9,'HY Compile'!$1:$1048576,16,0) -> #N/A | K19: =SUM(D19:J19) -> #N/A
B20: ARTIFICIAL INTELLIGENCE | D20: =VLOOKUP($K$9,'HY Compile'!$1:$1048576,18,0) -> #N/A | G20: =VLOOKUP($K$9,'HY Compile'!$1:$1048576,19,0) -> #N/A | K20: =SUM(D20:J20) -> #N/A
B22: Attendance | C22: =VLOOKUP($K$9,'HY Compile'!$1:$1048576,25,0) -> #N/A | D22: =VLOOKUP($K$9,'HY Compile'!$1:$1048576,26,0) -> #N/A | J22: Percentage : | L22: =ROUND(SUM(K15:M20)/6,2)&" %" -> #N/A
C23: =VLOOKUP($K$9,'HY Compile'!$1:$1048576,38,0) -> #N/A | D23: =VLOOKUP($K$9,'HY Compile'!$1:$1048576,38,0) -> #N/A | J23: Grand Total : | L23: =SUM(K15:M20)& "/600" -> #N/A
B26: PART-2:CO-SCHOLASTIC AREAS | K26: GRADE
B27: Work Education | K27: =VLOOKUP($K$9,'HY Compile'!$1:$1048576,21,0) -> #N/A
B28: Art Education | K28: =VLOOKUP($K$9,'HY Compile'!$1:$1048576,22,0) -> #N/A
B29: Health & Physical Education | K29: =VLOOKUP($K$9,'HY Compile'!$1:$1048576,23,0) -> #N/A
B30: Discipline | K30: =VLOOKUP($K$9,'HY Compile'!$1:$1048576,24,0) -> #N/A
B32: Mark Range | D32: 100-81 | F32: 80-61 | H32: 60-41 | J32: 40-33 | L32: 32-0
B33: Grade | D33: A | F33: B | H33: C | J33: D | L33: E
B36: ="Class Teacher's Remark: "&VLOOKUP($K$9,'HY Compile'!$1:$1048576,27,0) -> #N/A
B38: Issue Date: 10.10.2025
B41: Class Teacher's Signature | J41: Principal's Signature

Sheet Pre-Board-I(Entry)
A1: PRE-BOARD-I EXAMIANTION (2025-26) - X
A2: S.R. No. | B2: Name | C2: ENGLISH | E2: HINDI | G2: MATHEMATICS | I2: SCIENCE | K2: SOCIAL SCIENCE | M2: ARTIFICIAL INTELLIGENCE | O2: Total | P2: Work Educatino | Q2: Art Education | R2: Health & Physical Edcuation | S2: Discipline | T2: Attendance | V2: Class Teacher's Remark
C3: Theory | D3: Prac. | E3: Theory | F3: Prac. | G3: Theory | H3: Prac. | I3: Theory | J3: Prac. | K3: Theory | L3: Prac. | M3: Theory | N3: Prac. | T3: Total Working Days | U3: Present
A4: =DETAILS!A3 -> 1454 | B4: =DETAILS!B3 -> AARUSH SONI | O4: =SUM(C4:N4) -> 0
A5: =DETAILS!A4 -> 1680 | B5: =DETAILS!B4 -> AARVI JAISWAL | O5: =SUM(C5:N5) -> 0
A6: =DETAILS!A5 -> 758 | B6: =DETAILS!B5 -> ABDUL AHAD | O6: =SUM(C6:N6) -> 0
A7: =DETAILS!A6 -> 1616 | B7: =DETAILS!B6 -> ANAV SINGH | O7: =SUM(C7:N7) -> 0
A8: =DETAILS!A7 -> 1443 | B8: =DETAILS!B7 -> ANKIT KUMAR | O8: =SUM(C8:N8) -> 0
A9: =DETAILS!A8 -> 2100 | B9: =DETAILS!B8 -> ANSH SHUKLA | O9: =SUM(C9:N9) -> 0
A10: =DETAILS!A9 -> 1767 | B10: =DETAILS!B9 -> ANSHIKA MISHRA | O10: =SUM(C10:N10) -> 0
A11: =DETAILS!A10 -> 1486 | B11: =DETAILS!B10 -> ANUBHAV CHOUDHARY | O11: =SUM(C11:N11) -> 0
A12: =DETAILS!A11 -> 1615 | B12: =DETAILS!B11 -> ARADHYA TIWARI | O12: =SUM(C12:N12) -> 0
A13: =DETAILS!A12 -> 993 | B13: =DETAILS!B12 -> ARYAN MAURYA | O13: =SUM(C13:N13) -> 0
A14: =DETAILS!A13 -> 1296 | B14: =DETAILS!B13 -> ARYAN SINGH | O14: =SUM(C14:N14) -> 0
A15: =DETAILS!A14 -> 1392 | B15: =DETAILS!B14 -> ASTITVA SHYAM TIWARI | O15: =SUM(C15:N15) -> 0
... A46: =DETAILS!A45 -> 1617 | B46: =DETAILS!B45 -> TRAPTI | O46: =SUM(C46:N46) -> 0

Sheet Pre-Board-I
A1: PRE-BOARD-I EXAMIANTION (2025-26) - X
A2: S.R. No. | B2: Name | C2: ENGLISH | E2: HINDI | G2: MATHEMATICS | I2: SCIENCE | K2: SOCIAL SCIENCE | M2: ARTIFICIAL INTELLIGENCE | O2: Total | P2: Work Educatino | Q2: Art Education | R2: Health & Physical Edcuation | S2: Discipline | T2: Attendance | V2: Class Teacher's Remark
C3: Theory | D3: Prac. | E3: Theory | F3: Prac. | G3: Theory | H3: Prac. | I3: Theory | J3: Prac. | K3: Theory | L3: Prac. | M3: Theory | N3: Prac. | T3: Total Working Days | U3: Present
A4: =DETAILS!A3 -> 1454 | B4: =DETAILS!B3 -> AARUSH SONI | C4: ='Pre-Board-I(Entry)'!C4 -> 0 | D4: ='Pre-Board-I(Entry)'!D4 -> 0 | E4: ='Pre-Board-I(Entry)'!E4 -> 0 | F4: ='Pre-Board-I(Entry)'!F4 -> 0 | G4: ='Pre-Board-I(Entry)'!G4 -> 0 | H4: ='Pre-Board-I(Entry)'!H4 -> 0 | I4: ='Pre-Board-I(Entry)'!I4 -> 0 | J4: ='Pre-Board-I(Entry)'!J4 -> 0 | ... N4: ='Pre-Board-I(Entry)'!N4 -> 0 | O4: =SUM(C4:N4) -> 0 | P4: ='Pre-Board-I(Entry)'!P4 -> 0 | Q4: ='Pre-Board-I(Entry)'!Q4 -> 0 | R4: ='Pre-Board-I(Entry)'!R4 -> 0 | S4: ='Pre-Board-I(Entry)'!S4 -> 0 | T4: ='Pre-Board-I(Entry)'!T4 -> 0 | U4: ='Pre-Board-I(Entry)'!U4 -> 0 | V4: ='Pre-Board-I(Entry)'!V4 -> 0
A5: =DETAILS!A4 -> 1680 | B5: =DETAILS!B4 -> AARVI JAISWAL | C5: ='Pre-Board-I(Entry)'!C5 -> 0 | D5: ='Pre-Board-I(Entry)'!D5 -> 0 | E5: ='Pre-Board-I(Entry)'!E5 -> 0 | F5: ='Pre-Board-I(Entry)'!F5 -> 0 | G5: ='Pre-Board-I(Entry)'!G5 -> 0 | H5: ='Pre-Board-I(Entry)'!H5 -> 0 | I5: ='Pre-Board-I(Entry)'!I5 -> 0 | J5: ='Pre-Board-I(Entry)'!J5 -> 0 | ... N5: ='Pre-Board-I(Entry)'!N5 -> 0 | O5: =SUM(C5:N5) -> 0 | P5: ='Pre-Board-I(Entry)'!P5 -> 0 | Q5: ='Pre-Board-I(Entry)'!Q5 -> 0 | R5: ='Pre-Board-I(Entry)'!R5 -> 0 | S5: ='Pre-Board-I(Entry)'!S5 -> 0 | T5: ='Pre-Board-I(Entry)'!T5 -> 0 | U5: ='Pre-Board-I(Entry)'!U5 -> 0 | V5: ='Pre-Board-I(Entry)'!V5 -> 0
