Workbook

Sheet DETAILS
A1: STUDENT'S DETAIL
A2: SR NO | B2: NAME | C2: MOTHER'S NAME | D2: FATHER'S NAME | E2: DOB | F2: CLASS & SEC | G2: Elective1 | H2: Elective1 Code
A3: 1925 | B3: ARYAN GUPTA | C3: ANJALI GUPTA | D3: PREMCHANDRA GUPTA | E3: 07.07.2008 | F3: XI-HUM. | G3: HINDI CORE | H3: 302 | K3: 302
A4: 1918 | B4: SANJANA PATEL | C4: REKHA VERMA | D4: LATE MITHLESH KUMAR | E4: 15.04.2009 | F4: XI-HUM.

Sheet UT-I(Entry)
A1: UNIT TEST-I (2025-26) CLASS - XI-Human
A2: SR. NO. | B2: NAME | C2: ENGLISH | D2: HINDI/CS | E2: HISTORY | F2: POLITICAL SCIENCE | G2: GEOGRAPHY | H2: PHYSICAL EDUCATION | I2: Attendance
I3: Present | J3: Working Day
A4: =DETAILS!A3 -> 1925 | B4: =DETAILS!B3 -> ARYAN GUPTA
A5: =DETAILS!A4 -> 1918 | B5: =DETAILS!B4 -> SANJANA PATEL

Sheet UT-I 
A1: UNIT TEST-I (2025-26) CLASS - XI-Human
A2: SR. NO. | B2: NAME | C2: ENGLISH | D2: HINDI/CS | E2: HISTORY | F2: POLITICAL SCIENCE | G2: GEOGRAPHY | H2: PHYSICAL EDUCATION | I2: TOTAL | J2: PERCENTAGE | K2: Attendance
K3: Present | L3: Working Day
A4: =DETAILS!A3 -> 1925 | B4: =DETAILS!B3 -> ARYAN GUPTA | C4: =IFERROR(ROUND((VLOOKUP(A4,'UT-I(Entry)'!$1:$1048576,3,0))/2.5,0),VLOOKUP(A4,'UT-I(Entry)'!$1:$1048576,3,0)) -> 0 | D4: =IF(VLOOKUP($A4,DETAILS!$1:$1048576,8,0)=DETAILS!$K$3,IFERROR(ROUND((VLOOKUP($A4,'UT-I(Entry)'!$1:$1048576,4,0))/2,0),VLOOKUP($A4,'UT-I(Entry)'!$1:$1048576,4,0)),IFERROR(ROUND((VLOOKUP($A4,'UT-I(Entry)'!$1:$1048576,4,0))/1.75,0),VLOOKUP($A4,'UT-I(Entry)'!$1:$1048576,4,0))) -> 0 | E4: =IFERROR(ROUND((VLOOKUP(A4,'UT-I(Entry)'!$1:$1048576,5,0))/2.5,0),VLOOKUP(A4,'UT-I(Entry)'!$1:$1048576,5,0)) -> 0 | F4: =IFERROR(ROUND((VLOOKUP(A4,'UT-I(Entry)'!$1:$1048576,6,0))/2.5,0),VLOOKUP(A4,'UT-I(Entry)'!$1:$1048576,6,0)) -> 0 | G4: =IFERROR(ROUND((VLOOKUP($A4,'UT-I(Entry)'!$1:$1048576,7,0))/2.5,0),VLOOKUP($A4,'UT-I(Entry)'!$1:$1048576,7,0)) -> 0 | H4: =IFERROR(ROUND((VLOOKUP($A4,'UT-I(Entry)'!$1:$1048576,8,0))/2.5,0),VLOOKUP($A4,'UT-I(Entry)'!$1:$1048576,8,0)) -> 0 | I4: =SUM(C4:H4) -> 0 | J4: =ROUND(I4/1.2,2)&" %" -> 0 % | K4: =VLOOKUP(A4,'UT-I(Entry)'!$1:$1048576,10,0) -> 0 | L4: =VLOOKUP(A4,'UT-I(Entry)'!$1:$1048576,11,0) -> 0
A5: =DETAILS!A4 -> 1918 | B5: =DETAILS!B4 -> SANJANA PATEL | C5: =IFERROR(ROUND((VLOOKUP(A5,'UT-I(Entry)'!$1:$1048576,3,0))/2.5,0),VLOOKUP(A5,'UT-I(Entry)'!$1:$1048576,3,0)) -> 0 | D5: =IF(VLOOKUP($A5,DETAILS!$1:$1048576,8,0)=DETAILS!$K$3,IFERROR(ROUND((VLOOKUP($A5,'UT-I(Entry)'!$1:$1048576,4,0))/2,0),VLOOKUP($A5,'UT-I(Entry)'!$1:$1048576,4,0)),IFERROR(ROUND((VLOOKUP($A5,'UT-I(Entry)'!$1:$1048576,4,0))/1.75,0),VLOOKUP($A5,'UT-I(Entry)'!$1:$1048576,4,0))) -> 0 | E5: =IFERROR(ROUND((VLOOKUP(A5,'UT-I(Entry)'!$1:$1048576,5,0))/2.5,0),VLOOKUP(A5,'UT-I(Entry)'!$1:$1048576,5,0)) -> 0 | F5: =IFERROR(ROUND((VLOOKUP(A5,'UT-I(Entry)'!$1:$1048576,6,0))/2.5,0),VLOOKUP(A5,'UT-I(Entry)'!$1:$1048576,6,0)) -> 0 | G5: =IFERROR(ROUND((VLOOKUP($A5,'UT-I(Entry)'!$1:$1048576,7,0))/2.5,0),VLOOKUP($A5,'UT-I(Entry)'!$1:$1048576,7,0)) -> 0 | H5: =IFERROR(ROUND((VLOOKUP($A5,'UT-I(Entry)'!$1:$1048576,8,0))/2.5,0),VLOOKUP($A5,'UT-I(Entry)'!$1:$1048576,8,0)) -> 0 | I5: =SUM(C5:H5) -> 0 | J5: =ROUND(I5/1.2,2)&" %" -> 0 % | K5: =VLOOKUP(A5,'UT-I(Entry)'!$1:$1048576,10,0) -> 0 | L5: =VLOOKUP(A5,'UT-I(Entry)'!$1:$1048576,11,0) -> 0

Sheet Grade(40)
A2: 40 | B2: A
A3: 39 | B3: A
A4: 38 | B4: A
A5: 37 | B5: A
A6: 36 | B6: A
A7: 35 | B7: A
A8: 34 | B8: A
A9: 33 | B9: A
A10: 32 | B10: B
A11: 31 | B11: B
A12: 30 | B12: B
A13: 29 | B13: B
... A42: 0 | B42: E

Sheet HALF YEARLY(Entry)
A1: HALF YEARLY EXAMINATION (2025-26) CLASS - XI-Human
A2: SR. NO. | B2: NAME | C2: ENGLISH | D2: HINDI/CS | E2: HISTORY | F2: POLITICAL SCIENCE | G2: GEOGRAPHY | H2: PHYSICAL EDUCATION | I2: WORK EDUCATION | J2: ART EDUCATION | K2: HEALTH & PHYSICAL EDUCATION | L2: DISCIPLINE | M2: Total Present | N2: Total Working | O2: Class Teacher's Remark | P2: TOTAL | Q2: Percentage
A3: =DETAILS!A3 -> 1925 | B3: =DETAILS!B3 -> ARYAN GUPTA | P3: =SUM(C3:H3) -> 0 | Q3: =ROUND(P3/6,2)&" %" -> 0 %
A4: =DETAILS!A4 -> 1918 | B4: =DETAILS!B4 -> SANJANA PATEL | P4: =SUM(C4:H4) -> 0 | Q4: =ROUND(P4/6,2)&" %" -> 0 %
A5: =DETAILS!#REF! -> #REF! | B5: =DETAILS!#REF! -> #REF! | P5: =SUM(C5:H5) -> 0 | Q5: =ROUND(P5/6,2)&" %" -> 0 %
A6: =DETAILS!#REF! -> #REF! | B6: =DETAILS!#REF! -> #REF! | P6: =SUM(C6:H6) -> 0 | Q6: =ROUND(P6/6,2)&" %" -> 0 %
A7: =DETAILS!#REF! -> #REF! | B7: =DETAILS!#REF! -> #REF! | P7: =SUM(C7:H7) -> 0 | Q7: =ROUND(P7/6,2)&" %" -> 0 %
A8: =DETAILS!#REF! -> #REF! | B8: =DETAILS!#REF! -> #REF! | P8: =SUM(C8:H8) -> 0 | Q8: =ROUND(P8/6,2)&" %" -> 0 %
A9: =DETAILS!#REF! -> #REF! | B9: =DETAILS!#REF! -> #REF! | P9: =SUM(C9:H9) -> 0 | Q9: =ROUND(P9/6,2)&" %" -> 0 %
A10: =DETAILS!#REF! -> #REF! | B10: =DETAILS!#REF! -> #REF! | P10: =SUM(C10:H10) -> 0 | Q10: =ROUND(P10/6,2)&" %" -> 0 %
A11: =DETAILS!#REF! -> #REF! | B11: =DETAILS!#REF! -> #REF! | P11: =SUM(C11:H11) -> 0 | Q11: =ROUND(P11/6,2)&" %" -> 0 %
A12: =DETAILS!#REF! -> #REF! | B12: =DETAILS!#REF! -> #REF! | P12: =SUM(C12:H12) -> 0 | Q12: =ROUND(P12/6,2)&" %" -> 0 %
A13: =DETAILS!#REF! -> #REF! | B13: =DETAILS!#REF! -> #REF! | P13: =SUM(C13:H13) -> 0 | Q13: =ROUND(P13/6,2)&" %" -> 0 %
A14: =DETAILS!#REF! -> #REF! | B14: =DETAILS!#REF! -> #REF! | P14: =SUM(C14:H14) -> 0 | Q14: =ROUND(P14/6,2)&" %" -> 0 %
A15: =DETAILS!#REF! -> #REF! | B15: =DETAILS!#REF! -> #REF! | P15: =SUM(C15:H15) -> 0 | Q15: =ROUND(P15/6,2)&" %" -> 0 %
A16: =DETAILS!#REF! -> #REF! | B16: =DETAILS!#REF! -> #REF! | P16: =SUM(C16:H16) -> 0 | Q16: =ROUND(P16/6,2)&" %" -> 0 %
... A41: =DETAILS!#REF! -> #REF! | B41: =DETAILS!#REF! -> #REF! | P41: =SUM(C41:H41) -> 0 | Q41: =ROUND(P41/6,2)&" %" -> 0 %

Sheet HALF YEARLY
A1: HALF YEARLY EXAMINATION (2025-26) CLASS - XI-Human
A2: SR. NO. | B2: NAME | C2: ENGLISH | D2: HINDI/CS | E2: HISTORY | F2: POLITICAL SCIENCE | G2: GEOGRAPHY | H2: PHYSICAL EDUCATION | I2: WORK EDUCATION | J2: ART EDUCATION | K2: HEALTH & PHYSICAL EDUCATION | L2: DISCIPLINE | M2: Total Present | N2: Total Working | O2: Class Teacher's Remark | P2: TOTAL | Q2: Percentage
A3: =DETAILS!A3 -> 1925 | B3: =DETAILS!B3 -> ARYAN GUPTA | C3: =VLOOKUP($A3,'HALF YEARLY(Entry)'!$1:$1048576,3,0) -> 0 | D3: =VLOOKUP($A3,'HALF YEARLY(Entry)'!$1:$1048576,4,0) -> 0 | E3: =VLOOKUP($A3,'HALF YEARLY(Entry)'!$1:$1048576,5,0) -> 0 | F3: =VLOOKUP($A3,'HALF YEARLY(Entry)'!$1:$1048576,6,0) -> 0 | G3: =VLOOKUP($A3,'HALF YEARLY(Entry)'!$1:$1048576,7,0) -> 0 | H3: =VLOOKUP($A3,'HALF YEARLY(Entry)'!$1:$1048576,8,0) -> 0 | I3: =VLOOKUP($A3,'HALF YEARLY(Entry)'!$1:$1048576,9,0) -> 0 | J3: =VLOOKUP($A3,'HALF YEARLY(Entry)'!$1:$1048576,10,0) -> 0 | K3: =VLOOKUP($A3,'HALF YEARLY(Entry)'!$1:$1048576,11,0) -> 0 | L3: =VLOOKUP($A3,'HALF YEARLY(Entry)'!$1:$1048576,12,0) -> 0 | M3: =VLOOKUP($A3,'HALF YEARLY(Entry)'!$1:$1048576,13,0) -> 0 | N3: =VLOOKUP($A3,'HALF YEARLY(Entry)'!$1:$1048576,14,0) -> 0 | O3: =VLOOKUP($A3,'HALF YEARLY(Entry)'!$1:$1048576,15,0) -> 0 | P3: =SUM(C3:H3) -> 0 | Q3: =ROUND(P3/6,2)&" %" -> 0 %
A4: =DETAILS!A4 -> 1918 | B4: =DETAILS!B4 -> SANJANA PATEL | C4: =VLOOKUP($A4,'HALF YEARLY(Entry)'!$1:$1048576,3,0) -> 0 | D4: =VLOOKUP($A4,'HALF YEARLY(Entry)'!$1:$1048576,4,0) -> 0 | E4: =VLOOKUP($A4,'HALF YEARLY(Entry)'!$1:$1048576,5,0) -> 0 | F4: =VLOOKUP($A4,'HALF YEARLY(Entry)'!$1:$1048576,6,0) -> 0 | G4: =VLOOKUP($A4,'HALF YEARLY(Entry)'!$1:$1048576,7,0) -> 0 | H4: =VLOOKUP($A4,'HALF YEARLY(Entry)'!$1:$1048576,8,0) -> 0 | I4: =VLOOKUP($A4,'HALF YEARLY(Entry)'!$1:$1048576,9,0) -> 0 | J4: =VLOOKUP($A4,'HALF YEARLY(Entry)'!$1:$1048576,10,0) -> 0 | K4: =VLOOKUP($A4,'HALF YEARLY(Entry)'!$1:$1048576,11,0) -> 0 | L4: =VLOOKUP($A4,'HALF YEARLY(Entry)'!$1:$1048576,12,0) -> 0 | M4: =VLOOKUP($A4,'HALF YEARLY(Entry)'!$1:$1048576,13,0) -> 0 | N4: =VLOOKUP($A4,'HALF YEARLY(Entry)'!$1:$1048576,14,0) -> 0 | O4: =VLOOKUP($A4,'HALF YEARLY(Entry)'!$1:$1048576,15,0) -> 0 | P4: =SUM(C4:H4) -> 0 | Q4: =ROUND(P4/6,2)&" %" -> 0 %
A5: =DETAILS!#REF! -> #REF! | B5: =DETAILS!#REF! -> #REF! | C5: =VLOOKUP($A5,'HALF YEARLY(Entry)'!$1:$1048576,3,0) -> #REF! | D5: =VLOOKUP($A5,'HALF YEARLY(Entry)'!$1:$1048576,4,0) -> #REF! | E5: =VLOOKUP($A5,'HALF YEARLY(Entry)'!$1:$1048576,5,0) -> #REF! | F5: =VLOOKUP($A5,'HALF YEARLY(Entry)'!$1:$1048576,6,0) -> #REF! | G5: =VLOOKUP($A5,'HALF YEARLY(Entry)'!$1:$1048576,7,0) -> #REF! | H5: =VLOOKUP($A5,'HALF YEARLY(Entry)'!$1:$1048576,8,0) -> #REF! | I5: =VLOOKUP($A5,'HALF YEARLY(Entry)'!$1:$1048576,9,0) -> #REF! | J5: =VLOOKUP($A5,'HALF YEARLY(Entry)'!$1:$1048576,10,0) -> #REF! | K5: =VLOOKUP($A5,'HALF YEARLY(Entry)'!$1:$1048576,11,0) -> #REF! | L5: =VLOOKUP($A5,'HALF YEARLY(Entry)'!$1:$1048576,12,0) -> #REF! | M5: =VLOOKUP($A5,'HALF YEARLY(Entry)'!$1:$1048576,13,0) -> #REF! | N5: =VLOOKUP($A5,'HALF YEARLY(Entry)'!$1:$1048576,14,0) -> #REF! | O5: =VLOOKUP($A5,'HALF YEARLY(Entry)'!$1:$1048576,15,0) -> #REF! | P5: =SUM(C5:H5) -> #REF! | Q5: =ROUND(P5/6,2)&" %" -> #REF!
A6: =DETAILS!#REF! -> #REF! | B6: =DETAILS!#REF! -> #REF! | C6: =VLOOKUP($A6,'HALF YEARLY(Entry)'!$1:$1048576,3,0) -> #REF! | D6: =VLOOKUP($A6,'HALF YEARLY(Entry)'!$1:$1048576,4,0) -> #REF! | E6: =VLOOKUP($A6,'HALF YEARLY(Entry)'!$1:$1048576,5,0) -> #REF! | F6: =VLOOKUP($A6,'HALF YEARLY(Entry)'!$1:$1048576,6,0) -> #REF! | G6: =VLOOKUP($A6,'HALF YEARLY(Entry)'!$1:$1048576,7,0) -> #REF! | H6: =VLOOKUP($A6,'HALF YEARLY(Entry)'!$1:$1048576,8,0) -> #REF! | I6: =VLOOKUP($A6,'HALF YEARLY(Entry)'!$1:$1048576,9,0) -> #REF! | J6: =VLOOKUP($A6,'HALF YEARLY(Entry)'!$1:$1048576,10,0) -> #REF! | K6: =VLOOKUP($A6,'HALF YEARLY(Entry)'!$1:$1048576,11,0) -> #REF! | L6: =VLOOKUP($A6,'HALF YEARLY(Entry)'!$1:$1048576,12,0) -> #REF! | M6: =VLOOKUP($A6,'HALF YEARLY(Entry)'!$1:$1048576,13,0) -> #REF! | N6: =VLOOKUP($A6,'HALF YEARLY(Entry)'!$1:$1048576,14,0) -> #REF! | O6: =VLOOKUP($A6,'HALF YEARLY(Entry)'!$1:$1048576,15,0) -> #REF! | P6: =SUM(C6:H6) -> #REF! | Q6: =ROUND(P6/6,2)&" %" -> #REF!
A7: =DETAILS!#REF! -> #REF! | B7: =DETAILS!#REF! -> #REF! | C7: =VLOOKUP($A7,'HALF YEARLY(Entry)'!$1:$1048576,3,0) -> #REF! | D7: =VLOOKUP($A7,'HALF YEARLY(Entry)'!$1:$1048576,4,0) -> #REF! | E7: =VLOOKUP($A7,'HALF YEARLY(Entry)'!$1:$1048576,5,0) -> #REF! | F7: =VLOOKUP($A7,'HALF YEARLY(Entry)'!$1:$1048576,6,0) -> #REF! | G7: =VLOOKUP($A7,'HALF YEARLY(Entry)'!$1:$1048576,7,0) -> #REF! | H7: =VLOOKUP($A7,'HALF YEARLY(Entry)'!$1:$1048576,8,0) -> #REF! | I7: =VLOOKUP($A7,'HALF YEARLY(Entry)'!$1:$1048576,9,0) -> #REF! | J7: =VLOOKUP($A7,'HALF YEARLY(Entry)'!$1:$1048576,10,0) -> #REF! | K7: =VLOOKUP($A7,'HALF YEARLY(Entry)'!$1:$1048576,11,0) -> #REF! | L7: =VLOOKUP($A7,'HALF YEARLY(Entry)'!$1:$1048576,12,0) -> #REF! | M7: =VLOOKUP($A7,'HALF YEARLY(Entry)'!$1:$1048576,13,0) -> #REF! | N7: =VLOOKUP($A7,'HALF YEARLY(Entry)'!$1:$1048576,14,0) -> #REF! | O7: =VLOOKUP($A7,'HALF YEARLY(Entry)'!$1:$1048576,15,0) -> #REF! | P7: =SUM(C7:H7) -> #REF! | Q7: =ROUND(P7/6,2)&" %" -> #REF!
A8: =DETAILS!#REF! -> #REF! | B8: =DETAILS!#REF! -> #REF! | C8: =VLOOKUP($A8,'HALF YEARLY(Entry)'!$1:$1048576,3,0) -> #REF! | D8: =VLOOKUP($A8,'HALF YEARLY(Entry)'!$1:$1048576,4,0) -> #REF! | E8: =VLOOKUP($A8,'HALF YEARLY(Entry)'!$1:$1048576,5,0) -> #REF! | F8: =VLOOKUP($A8,'HALF YEARLY(Entry)'!$1:$1048576,6,0) -> #REF! | G8: =VLOOKUP($A8,'HALF YEARLY(Entry)'!$1:$1048576,7,0) -> #REF! | H8: =VLOOKUP($A8,'HALF YEARLY(Entry)'!$1:$1048576,8,0) -> #REF! | I8: =VLOOKUP($A8,'HALF YEARLY(Entry)'!$1:$1048576,9,0) -> #REF! | J8: =VLOOKUP($A8,'HALF YEARLY(Entry)'!$1:$1048576,10,0) -> #REF! | K8: =VLOOKUP($A8,'HALF YEARLY(Entry)'!$1:$1048576,11,0) -> #REF! | L8: =VLOOKUP($A8,'HALF YEARLY(Entry)'!$1:$1048576,12,0) -> #REF! | M8: =VLOOKUP($A8,'HALF YEARLY(Entry)'!$1:$1048576,13,0) -> #REF! | N8: =VLOOKUP($A8,'HALF YEARLY(Entry)'!$1:$1048576,14,0) -> #REF! | O8: =VLOOKUP($A8,'HALF YEARLY(Entry)'!$1:$1048576,15,0) -> #REF! | P8: =SUM(C8:H8) -> #REF! | Q8: =ROUND(P8/6,2)&" %" -> #REF!
A9: =DETAILS!#REF! -> #REF! | B9: =DETAILS!#REF! -> #REF! | C9: =VLOOKUP($A9,'HALF YEARLY(Entry)'!$1:$1048576,3,0) -> #REF! | D9: =VLOOKUP($A9,'HALF YEARLY(Entry)'!$1:$1048576,4,0) -> #REF! | E9: =VLOOKUP($A9,'HALF YEARLY(Entry)'!$1:$1048576,5,0) -> #REF! | F9: =VLOOKUP($A9,'HALF YEARLY(Entry)'!$1:$1048576,6,0) -> #REF! | G9: =VLOOKUP($A9,'HALF YEARLY(Entry)'!$1:$1048576,7,0) -> #REF! | H9: =VLOOKUP($A9,'HALF YEARLY(Entry)'!$1:$1048576,8,0) -> #REF! | I9: =VLOOKUP($A9,'HALF YEARLY(Entry)'!$1:$1048576,9,0) -> #REF! | J9: =VLOOKUP($A9,'HALF YEARLY(Entry)'!$1:$1048576,10,0) -> #REF! | K9: =VLOOKUP($A9,'HALF YEARLY(Entry)'!$1:$1048576,11,0) -> #REF! | L9: =VLOOKUP($A9,'HALF YEARLY(Entry)'!$1:$1048576,12,0) -> #REF! | M9: =VLOOKUP($A9,'HALF YEARLY(Entry)'!$1:$1048576,13,0) -> #REF! | N9: =VLOOKUP($A9,'HALF YEARLY(Entry)'!$1:$1048576,14,0) -> #REF! | O9: =VLOOKUP($A9,'HALF YEARLY(Entry)'!$1:$1048576,15,0) -> #REF! | P9: =SUM(C9:H9) -> #REF! | Q9: =ROUND(P9/6,2)&" %" -> #REF!
A10: =DETAILS!#REF! -> #REF! | B10: =DETAILS!#REF! -> #REF! | C10: =VLOOKUP($A10,'HALF YEARLY(Entry)'!$1:$1048576,3,0) -> #REF! | D10: =VLOOKUP($A10,'HALF YEARLY(Entry)'!$1:$1048576,4,0) -> #REF! | E10: =VLOOKUP($A10,'HALF YEARLY(Entry)'!$1:$1048576,5,0) -> #REF! | F10: =VLOOKUP($A10,'HALF YEARLY(Entry)'!$1:$1048576,6,0) -> #REF! | G10: =VLOOKUP($A10,'HALF YEARLY(Entry)'!$1:$1048576,7,0) -> #REF! | H10: =VLOOKUP($A10,'HALF YEARLY(Entry)'!$1:$1048576,8,0) -> #REF! | I10: =VLOOKUP($A10,'HALF YEARLY(Entry)'!$1:$1048576,9,0) -> #REF! | J10: =VLOOKUP($A10,'HALF YEARLY(Entry)'!$1:$1048576,10,0) -> #REF! | K10: =VLOOKUP($A10,'HALF YEARLY(Entry)'!$1:$1048576,11,0) -> #REF! | L10: =VLOOKUP($A10,'HALF YEARLY(Entry)'!$1:$1048576,12,0) -> #REF! | M10: =VLOOKUP($A10,'HALF YEARLY(Entry)'!$1:$1048576,13,0) -> #REF! | N10: =VLOOKUP($A10,'HALF YEARLY(Entry)'!$1:$1048576,14,0) -> #REF! | O10: =VLOOKUP($A10,'HALF YEARLY(Entry)'!$1:$1048576,15,0) -> #REF! | P10: =SUM(C10:H10) -> #REF! | Q10: =ROUND(P10/6,2)&" %" -> #REF!
A11: =DETAILS!#REF! -> #REF! | B11: =DETAILS!#REF! -> #REF! | C11: =VLOOKUP($A11,'HALF YEARLY(Entry)'!$1:$1048576,3,0) -> #REF! | D11: =VLOOKUP($A11,'HALF YEARLY(Entry)'!$1:$1048576,4,0) -> #REF! | E11: =VLOOKUP($A11,'HALF YEARLY(Entry)'!$1:$1048576,5,0) -> #REF! | F11: =VLOOKUP($A11,'HALF YEARLY(Entry)'!$1:$1048576,6,0) -> #REF! | G11: =VLOOKUP($A11,'HALF YEARLY(Entry)'!$1:$1048576,7,0) -> #REF! | H11: =VLOOKUP($A11,'HALF YEARLY(Entry)'!$1:$1048576,8,0) -> #REF! | I11: =VLOOKUP($A11,'HALF YEARLY(Entry)'!$1:$1048576,9,0) -> #REF! | J11: =VLOOKUP($A11,'HALF YEARLY(Entry)'!$1:$1048576,10,0) -> #REF! | K11: =VLOOKUP($A11,'HALF YEARLY(Entry)'!$1:$1048576,11,0) -> #REF! | L11: =VLOOKUP($A11,'HALF YEARLY(Entry)'!$1:$1048576,12,0) -> #REF! | M11: =VLOOKUP($A11,'HALF YEARLY(Entry)'!$1:$1048576,13,0) -> #REF! | N11: =VLOOKUP($A11,'HALF YEARLY(Entry)'!$1:$1048576,14,0) -> #REF! | O11: =VLOOKUP($A11,'HALF YEARLY(Entry)'!$1:$1048576,15,0) -> #REF! | P11: =SUM(C11:H11) -> #REF! | Q11: =ROUND(P11/6,2)&" %" -> #REF!
A12: =DETAILS!#REF! -> #REF! | B12: =DETAILS!#REF! -> #REF! | C12: =VLOOKUP($A12,'HALF YEARLY(Entry)'!$1:$1048576,3,0) -> #REF! | D12: =VLOOKUP($A12,'HALF YEARLY(Entry)'!$1:$1048576,4,0) -> #REF! | E12: =VLOOKUP($A12,'HALF YEARLY(Entry)'!$1:$1048576,5,0) -> #REF! | F12: =VLOOKUP($A12,'HALF YEARLY(Entry)'!$1:$1048576,6,0) -> #REF! | G12: =VLOOKUP($A12,'HALF YEARLY(Entry)'!$1:$1048576,7,0) -> #REF! | H12: =VLOOKUP($A12,'HALF YEARLY(Entry)'!$1:$1048576,8,0) -> #REF! | I12: =VLOOKUP($A12,'HALF YEARLY(Entry)'!$1:$1048576,9,0) -> #REF! | J12: =VLOOKUP($A12,'HALF YEARLY(Entry)'!$1:$1048576,10,0) -> #REF! | K12: =VLOOKUP($A12,'HALF YEARLY(Entry)'!$1:$1048576,11,0) -> #REF! | L12: =VLOOKUP($A12,'HALF YEARLY(Entry)'!$1:$1048576,12,0) -> #REF! | M12: =VLOOKUP($A12,'HALF YEARLY(Entry)'!$1:$1048576,13,0) -> #REF! | N12: =VLOOKUP($A12,'HALF YEARLY(Entry)'!$1:$1048576,14,0) -> #REF! | O12: =VLOOKUP($A12,'HALF YEARLY(Entry)'!$1:$1048576,15,0) -> #REF! | P12: =SUM(C12:H12) -> #REF! | Q12: =ROUND(P12/6,2)&" %" -> #REF!
A13: =DETAILS!#REF! -> #REF! | B13: =DETAILS!#REF! -> #REF! | C13: =VLOOKUP($A13,'HALF YEARLY(Entry)'!$1:$1048576,3,0) -> #REF! | D13: =VLOOKUP($A13,'HALF YEARLY(Entry)'!$1:$1048576,4,0) -> #REF! | E13: =VLOOKUP($A13,'HALF YEARLY(Entry)'!$1:$1048576,5,0) -> #REF! | F13: =VLOOKUP($A13,'HALF YEARLY(Entry)'!$1:$1048576,6,0) -> #REF! | G13: =VLOOKUP($A13,'HALF YEARLY(Entry)'!$1:$1048576,7,0) -> #REF! | H13: =VLOOKUP($A13,'HALF YEARLY(Entry)'!$1:$1048576,8,0) -> #REF! | I13: =VLOOKUP($A13,'HALF YEARLY(Entry)'!$1:$1048576,9,0) -> #REF! | J13: =VLOOKUP($A13,'HALF YEARLY(Entry)'!$1:$1048576,10,0) -> #REF! | K13: =VLOOKUP($A13,'HALF YEARLY(Entry)'!$1:$1048576,11,0) -> #REF! | L13: =VLOOKUP($A13,'HALF YEARLY(Entry)'!$1:$1048576,12,0) -> #REF! | M13: =VLOOKUP($A13,'HALF YEARLY(Entry)'!$1:$1048576,13,0) -> #REF! | N13: =VLOOKUP($A13,'HALF YEARLY(Entry)'!$1:$1048576,14,0) -> #REF! | O13: =VLOOKUP($A13,'HALF YEARLY(Entry)'!$1:$1048576,15,0) -> #REF! | P13: =SUM(C13:H13) -> #REF! | Q13: =ROUND(P13/6,2)&" %" -> #REF!
A14: =DETAILS!#REF! -> #REF! | B14: =DETAILS!#REF! -> #REF! | C14: =VLOOKUP($A14,'HALF YEARLY(Entry)'!$1:$1048576,3,0) -> #REF! | D14: =VLOOKUP($A14,'HALF YEARLY(Entry)'!$1:$1048576,4,0) -> #REF! | E14: =VLOOKUP($A14,'HALF YEARLY(Entry)'!$1:$1048576,5,0) -> #REF! | F14: =VLOOKUP($A14,'HALF YEARLY(Entry)'!$1:$1048576,6,0) -> #REF! | G14: =VLOOKUP($A14,'HALF YEARLY(Entry)'!$1:$1048576,7,0) -> #REF! | H14: =VLOOKUP($A14,'HALF YEARLY(Entry)'!$1:$1048576,8,0) -> #REF! | I14: =VLOOKUP($A14,'HALF YEARLY(Entry)'!$1:$1048576,9,0) -> #REF! | J14: =VLOOKUP($A14,'HALF YEARLY(Entry)'!$1:$1048576,10,0) -> #REF! | K14: =VLOOKUP($A14,'HALF YEARLY(Entry)'!$1:$1048576,11,0) -> #REF! | L14: =VLOOKUP($A14,'HALF YEARLY(Entry)'!$1:$1048576,12,0) -> #REF! | M14: =VLOOKUP($A14,'HALF YEARLY(Entry)'!$1:$1048576,13,0) -> #REF! | N14: =VLOOKUP($A14,'HALF YEARLY(Entry)'!$1:$1048576,14,0) -> #REF! | O14: =VLOOKUP($A14,'HALF YEARLY(Entry)'!$1:$1048576,15,0) -> #REF! | P14: =SUM(C14:H14) -> #REF! | Q14: =ROUND(P14/6,2)&" %" -> #REF!
A15: =DETAILS!#REF! -> #REF! | B15: =DETAILS!#REF! -> #REF! | C15: =VLOOKUP($A15,'HALF YEARLY(Entry)'!$1:$1048576,3,0) -> #REF! | D15: =VLOOKUP($A15,'HALF YEARLY(Entry)'!$1:$1048576,4,0) -> #REF! | E15: =VLOOKUP($A15,'HALF YEARLY(Entry)'!$1:$1048576,5,0) -> #REF! | F15: =VLOOKUP($A15,'HALF YEARLY(Entry)'!$1:$1048576,6,0) -> #REF! | G15: =VLOOKUP($A15,'HALF YEARLY(Entry)'!$1:$1048576,7,0) -> #REF! | H15: =VLOOKUP($A15,'HALF YEARLY(Entry)'!$1:$1048576,8,0) -> #REF! | I15: =VLOOKUP($A15,'HALF YEARLY(Entry)'!$1:$1048576,9,0) -> #REF! | J15: =VLOOKUP($A15,'HALF YEARLY(Entry)'!$1:$1048576,10,0) -> #REF! | K15: =VLOOKUP($A15,'HALF YEARLY(Entry)'!$1:$1048576,11,0) -> #REF! | L15: =VLOOKUP($A15,'HALF YEARLY(Entry)'!$1:$1048576,12,0) -> #REF! | M15: =VLOOKUP($A15,'HALF YEARLY(Entry)'!$1:$1048576,13,0) -> #REF! | N15: =VLOOKUP($A15,'HALF YEARLY(Entry)'!$1:$1048576,14,0) -> #REF! | O15: =VLOOKUP($A15,'HALF YEARLY(Entry)'!$1:$1048576,15,0) -> #REF! | P15: =SUM(C15:H15) -> #REF! | Q15: =ROUND(P15/6,2)&" %" -> #REF!
A16: =DETAILS!#REF! -> #REF! | B16: =DETAILS!#REF! -> #REF! | C16: =VLOOKUP($A16,'HALF YEARLY(Entry)'!$1:$1048576,3,0) -> #REF! | D16: =VLOOKUP($A16,'HALF YEARLY(Entry)'!$1:$1048576,4,0) -> #REF! | E16: =VLOOKUP($A16,'HALF YEARLY(Entry)'!$1:$1048576,5,0) -> #REF! | F16: =VLOOKUP($A16,'HALF YEARLY(Entry)'!$1:$1048576,6,0) -> #REF! | G16: =VLOOKUP($A16,'HALF YEARLY(Entry)'!$1:$1048576,7,0) -> #REF! | H16: =VLOOKUP($A16,'HALF YEARLY(Entry)'!$1:$1048576,8,0) -> #REF! | I16: =VLOOKUP($A16,'HALF YEARLY(Entry)'!$1:$1048576,9,0) -> #REF! | J16: =VLOOKUP($A16,'HALF YEARLY(Entry)'!$1:$1048576,10,0) -> #REF! | K16: =VLOOKUP($A16,'HALF YEARLY(Entry)'!$1:$1048576,11,0) -> #REF! | L16: =VLOOKUP($A16,'HALF YEARLY(Entry)'!$1:$1048576,12,0) -> #REF! | M16: =VLOOKUP($A16,'HALF YEARLY(Entry)'!$1:$1048576,13,0) -> #REF! | N16: =VLOOKUP($A16,'HALF YEARLY(Entry)'!$1:$1048576,14,0) -> #REF! | O16: =VLOOKUP($A16,'HALF YEARLY(Entry)'!$1:$1048576,15,0) -> #REF! | P16: =SUM(C16:H16) -> #REF! | Q16: =ROUND(P16/6,2)&" %" -> #REF!
... A41: =DETAILS!#REF! -> #REF! | B41: =DETAILS!#REF! -> #REF! | C41: =VLOOKUP($A41,'HALF YEARLY(Entry)'!$1:$1048576,3,0) -> #REF! | D41: =VLOOKUP($A41,'HALF YEARLY(Entry)'!$1:$1048576,4,0) -> #REF! | E41: =VLOOKUP($A41,'HALF YEARLY(Entry)'!$1:$1048576,5,0) -> #REF! | F41: =VLOOKUP($A41,'HALF YEARLY(Entry)'!$1:$1048576,6,0) -> #REF! | G41: =VLOOKUP($A41,'HALF YEARLY(Entry)'!$1:$1048576,7,0) -> #REF! | H41: =VLOOKUP($A41,'HALF YEARLY(Entry)'!$1:$1048576,8,0) -> #REF! | I41: =VLOOKUP($A41,'HALF YEARLY(Entry)'!$1:$1048576,9,0) -> #REF! | J41: =VLOOKUP($A41,'HALF YEARLY(Entry)'!$1:$1048576,10,0) -> #REF! | K41: =VLOOKUP($A41,'HALF YEARLY(Entry)'!$1:$1048576,11,0) -> #REF! | L41: =VLOOKUP($A41,'HALF YEARLY(Entry)'!$1:$1048576,12,0) -> #REF! | M41: =VLOOKUP($A41,'HALF YEARLY(Entry)'!$1:$1048576,13,0) -> #REF! | N41: =VLOOKUP($A41,'HALF YEARLY(Entry)'!$1:$1048576,14,0) -> #REF! | O41: =VLOOKUP($A41,'HALF YEARLY(Entry)'!$1:$1048576,15,0) -> #REF! | P41: =SUM(C41:H41) -> #REF! | Q41: =ROUND(P41/6,2)&" %" -> #REF!

Sheet Grade 50
A2: 50 | B2: A
A3: 49 | B3: A
A4: 48 | B4: A
A5: 47 | B5: A
A6: 46 | B6: A
A7: 45 | B7: A
A8: 44 | B8: A
A9: 43 | B9: A
A10: 42 | B10: A
A11: 41 | B11: A
A12: 40 | B12: B
A13: 39 | B13: B
... A52: 0 | B52: E

Sheet HY Compile
A1: Half Yearly Compile Report (2025-26) Class - XI-Human
A2: Half Yearly Compile Report (2025-26) Class - XI-Human | B2: Student's Name | C2: ENGLISH | F2: HINDI/CS | I2: HISTORY | L2: POLITICAL SCIENCE | O2: GEOGRAPHY | R2: PHYSICAL EDUCATION | U2: WORK EDUCATION | V2: ART EDUCATION | W2: HEALTH & PHYSICAL EDUCATION | X2: DISCIPLINE | Y2: TOTAL PRESENT | Z2: TORAL WORKING DAY | AA2: CLASS TEACHER'S REAMRK
C3: UT-I | D3: HY | E3: Total | F3: UT-I | G3: HY | H3: Total | I3: UT-I | J3: HY | K3: Total | L3: UT-I | M3: HY | N3: Total | O3: UT-I | P3: HY | Q3: Total | R3: UT-I | S3: HY | T3: Total
A4: =DETAILS!A3 -> 1925 | B4: =DETAILS!B3 -> ARYAN GUPTA | C4: =VLOOKUP($A4,'UT-I '!$1:$1048576,3,0) -> 0 | D4: =IFERROR(ROUND(VLOOKUP($A4,'HALF YEARLY'!$1:$1048576,3,0)*0.8,0),VLOOKUP($A4,'HALF YEARLY'!$1:$1048576,3,0)) -> 0 | E4: =SUM(C4:D4) -> 0 | F4: =VLOOKUP($A4,'UT-I '!$1:$1048576,4,0) -> 0 | G4: =IFERROR(ROUND(VLOOKUP($A4,'HALF YEARLY'!$1:$1048576,4,0)*0.8,0),VLOOKUP($A4,'HALF YEARLY'!$1:$1048576,4,0)) -> 0 | H4: =SUM(F4:G4) -> 0 | I4: =VLOOKUP($A4,'UT-I '!$1:$1048576,5,0) -> 0 | J4: =IFERROR(ROUND(VLOOKUP($A4,'HALF YEARLY'!$1:$1048576,5,0)*0.8,0),VLOOKUP($A4,'HALF YEARLY'!$1:$1048576,5,0)) -> 0 | K4: =SUM(I4:J4) -> 0 | L4: =VLOOKUP($A4,'UT-I '!$1:$1048576,6,0) -> 0 | M4: =IFERROR(ROUND(VLOOKUP($A4,'HALF YEARLY'!$1:$1048576,6,0)*0.8,0),VLOOKUP($A4,'HALF YEARLY'!$1:$1048576,6,0)) -> 0 | N4: =SUM(L4:M4) -> 0 | O4: =VLOOKUP($A4,'UT-I '!$1:$1048576,7,0) -> 0 | P4: =IFERROR(ROUND(VLOOKUP($A4,'HALF YEARLY'!$1:$1048576,7,0)*0.8,0),VLOOKUP($A4,'HALF YEARLY'!$1:$1048576,7,0)) -> 0 | Q4: =SUM(O4:P4) -> 0 | R4: =VLOOKUP($A4,'UT-I '!$1:$1048576,8,0) -> 0 | S4: =IFERROR(ROUND(VLOOKUP($A4,'HALF YEARLY'!$1:$1048576,8,0)*0.8,0),VLOOKUP($A4,'HALF YEARLY'!$1:$1048576,8,0)) -> 0 | T4: =SUM(R4:S4) -> 0 | U4: =VLOOKUP($A4,'HALF YEARLY'!$1:$1048576,9,0) -> 0 | V4: =VLOOKUP($A4,'HALF YEARLY'!$1:$1048576,10,0) -> 0 | W4: =VLOOKUP($A4,'HALF YEARLY'!$1:$1048576,11,0) -> 0 | X4: =VLOOKUP($A4,'HALF YEARLY'!$1:$1048576,12,0) -> 0 | Y4: =VLOOKUP($A4,'HALF YEARLY'!$1:$1048576,13,0) -> 0 | Z4: =VLOOKUP($A4,'HALF YEARLY'!$1:$1048576,14,0) -> 0 | AA4: =VLOOKUP($A4,'HALF YEARLY'!$1:$1048576,15,0) -> 0
A5: =DETAILS!A4 -> 1918 | B5: =DETAILS!B4 -> SANJANA PATEL | C5: =VLOOKUP($A5,'UT-I '!$1:$1048576,3,0) -> 0 | D5: =IFERROR(ROUND(VLOOKUP($A5,'HALF YEARLY'!$1:$1048576,3,0)*0.8,0),VLOOKUP($A5,'HALF YEARLY'!$1:$1048576,3,0)) -> 0 | E5: =SUM(C5:D5) -> 0 | F5: =VLOOKUP($A5,'UT-I '!$1:$1048576,4,0) -> 0 | G5: =IFERROR(ROUND(VLOOKUP($A5,'HALF YEARLY'!$1:$1048576,4,0)*0.8,0),VLOOKUP($A5,'HALF YEARLY'!$1:$1048576,4,0)) -> 0 | H5: =SUM(F5:G5) -> 0 | I5: =VLOOKUP($A5,'UT-I '!$1:$1048576,5,0) -> 0 | J5: =IFERROR(ROUND(VLOOKUP($A5,'HALF YEARLY'!$1:$1048576,5,0)*0.8,0),VLOOKUP($A5,'HALF YEARLY'!$1:$1048576,5,0)) -> 0 | K5: =SUM(I5:J5) -> 0 | L5: =VLOOKUP($A5,'UT-I '!$1:$1048576,6,0) -> 0 | M5: =IFERROR(ROUND(VLOOKUP($A5,'HALF YEARLY'!$1:$1048576,6,0)*0.8,0),VLOOKUP($A5,'HALF YEARLY'!$1:$1048576,6,0)) -> 0 | N5: =SUM(L5:M5) -> 0 | O5: =VLOOKUP($A5,'UT-I '!$1:$1048576,7,0) -> 0 | P5: =IFERROR(ROUND(VLOOKUP($A5,'HALF YEARLY'!$1:$1048576,7,0)*0.8,0),VLOOKUP($A5,'HALF YEARLY'!$1:$1048576,7,0)) -> 0 | Q5: =SUM(O5:P5) -> 0 | R5: =VLOOKUP($A5,'UT-I '!$1:$1048576,8,0) -> 0 | S5: =IFERROR(ROUND(VLOOKUP($A5,'HALF YEARLY'!$1:$1048576,8,0)*0.8,0),VLOOKUP($A5,'HALF YEARLY'!$1:$1048576,8,0)) -> 0 | T5: =SUM(R5:S5) -> 0 | U5: =VLOOKUP($A5,'HALF YEARLY'!$1:$1048576,9,0) -> 0 | V5: =VLOOKUP($A5,'HALF YEARLY'!$1:$1048576,10,0) -> 0 | W5: =VLOOKUP($A5,'HALF YEARLY'!$1:$1048576,11,0) -> 0 | X5: =VLOOKUP($A5,'HALF YEARLY'!$1:$1048576,12,0) -> 0 | Y5: =VLOOKUP($A5,'HALF YEARLY'!$1:$1048576,13,0) -> 0 | Z5: =VLOOKUP($A5,'HALF YEARLY'!$1:$1048576,14,0) -> 0 | AA5: =VLOOKUP($A5,'HALF YEARLY'!$1:$1048576,15,0) -> 0
A6: =DETAILS!#REF! -> #REF! | B6: =DETAILS!#REF! -> #REF! | C6: =VLOOKUP($A6,'UT-I '!$1:$1048576,3,0) -> #REF! | D6: =IFERROR(ROUND(VLOOKUP($A6,'HALF YEARLY'!$1:$1048576,3,0)*0.8,0),VLOOKUP($A6,'HALF YEARLY'!$1:$1048576,3,0)) -> #REF! | E6: =SUM(C6:D6) -> #REF! | F6: =VLOOKUP($A6,'UT-I '!$1:$1048576,4,0) -> #REF! | G6: =IFERROR(ROUND(VLOOKUP($A6,'HALF YEARLY'!$1:$1048576,4,0)*0.8,0),VLOOKUP($A6,'HALF YEARLY'!$1:$1048576,4,0)) -> #REF! | H6: =SUM(F6:G6) -> #REF! | I6: =VLOOKUP($A6,'UT-I '!$1:$1048576,5,0) -> #REF! | J6: =IFERROR(ROUND(VLOOKUP($A6,'HALF YEARLY'!$1:$1048576,5,0)*0.8,0),VLOOKUP($A6,'HALF YEARLY'!$1:$1048576,5,0)) -> #REF! | K6: =SUM(I6:J6) -> #REF! | L6: =VLOOKUP($A6,'UT-I '!$1:$1048576,6,0) -> #REF! | M6: =IFERROR(ROUND(VLOOKUP($A6,'HALF YEARLY'!$1:$1048576,6,0)*0.8,0),VLOOKUP($A6,'HALF YEARLY'!$1:$1048576,6,0)) -> #REF! | N6: =SUM(L6:M6) -> #REF! | O6: =VLOOKUP($A6,'UT-I '!$1:$1048576,7,0) -> #REF! | P6: =IFERROR(ROUND(VLOOKUP($A6,'HALF YEARLY'!$1:$1048576,7,0)*0.8,0),VLOOKUP($A6,'HALF YEARLY'!$1:$1048576,7,0)) -> #REF! | Q6: =SUM(O6:P6) -> #REF! | R6: =VLOOKUP($A6,'UT-I '!$1:$1048576,8,0) -> #REF! | S6: =IFERROR(ROUND(VLOOKUP($A6,'HALF YEARLY'!$1:$1048576,8,0)*0.8,0),VLOOKUP($A6,'HALF YEARLY'!$1:$1048576,8,0)) -> #REF! | T6: =SUM(R6:S6) -> #REF! | U6: =VLOOKUP($A6,'HALF YEARLY'!$1:$1048576,9,0) -> #REF! | V6: =VLOOKUP($A6,'HALF YEARLY'!$1:$1048576,10,0) -> #REF! | W6: =VLOOKUP($A6,'HALF YEARLY'!$1:$1048576,11,0) -> #REF! | X6: =VLOOKUP($A6,'HALF YEARLY'!$1:$1048576,12,0) -> #REF! | Y6: =VLOOKUP($A6,'HALF YEARLY'!$1:$1048576,13,0) -> #REF! | Z6: =VLOOKUP($A6,'HALF YEARLY'!$1:$1048576,14,0) -> #REF! | AA6: =VLOOKUP($A6,'HALF YEARLY'!$1:$1048576,15,0) -> #REF!
A7: =DETAILS!#REF! -> #REF! | B7: =DETAILS!#REF! -> #REF! | C7: =VLOOKUP($A7,'UT-I '!$1:$1048576,3,0) -> #REF! | D7: =IFERROR(ROUND(VLOOKUP($A7,'HALF YEARLY'!$1:$1048576,3,0)*0.8,0),VLOOKUP($A7,'HALF YEARLY'!$1:$1048576,3,0)) -> #REF! | E7: =SUM(C7:D7) -> #REF! | F7: =VLOOKUP($A7,'UT-I '!$1:$1048576,4,0) -> #REF! | G7: =IFERROR(ROUND(VLOOKUP($A7,'HALF YEARLY'!$1:$1048576,4,0)*0.8,0),VLOOKUP($A7,'HALF YEARLY'!$1:$1048576,4,0)) -> #REF! | H7: =SUM(F7:G7) -> #REF! | I7: =VLOOKUP($A7,'UT-I '!$1:$1048576,5,0) -> #REF! | J7: =IFERROR(ROUND(VLOOKUP($A7,'HALF YEARLY'!$1:$1048576,5,0)*0.8,0),VLOOKUP($A7,'HALF YEARLY'!$1:$1048576,5,0)) -> #REF! | K7: =SUM(I7:J7) -> #REF! | L7: =VLOOKUP($A7,'UT-I '!$1:$1048576,6,0) -> #REF! | M7: =IFERROR(ROUND(VLOOKUP($A7,'HALF YEARLY'!$1:$1048576,6,0)*0.8,0),VLOOKUP($A7,'HALF YEARLY'!$1:$1048576,6,0)) -> #REF! | N7: =SUM(L7:M7) -> #REF! | O7: =VLOOKUP($A7,'UT-I '!$1:$1048576,7,0) -> #REF! | P7: =IFERROR(ROUND(VLOOKUP($A7,'HALF YEARLY'!$1:$1048576,7,0)*0.8,0),VLOOKUP($A7,'HALF YEARLY'!$1:$1048576,7,0)) -> #REF! | Q7: =SUM(O7:P7) -> #REF! | R7: =VLOOKUP($A7,'UT-I '!$1:$1048576,8,0) -> #REF! | S7: =IFERROR(ROUND(VLOOKUP($A7,'HALF YEARLY'!$1:$1048576,8,0)*0.8,0),VLOOKUP($A7,'HALF YEARLY'!$1:$1048576,8,0)) -> #REF! | T7: =SUM(R7:S7) -> #REF! | U7: =VLOOKUP($A7,'HALF YEARLY'!$1:$1048576,9,0) -> #REF! | V7: =VLOOKUP($A7,'HALF YEARLY'!$1:$1048576,10,0) -> #REF! | W7: =VLOOKUP($A7,'HALF YEARLY'!$1:$1048576,11,0) -> #REF! | X7: =VLOOKUP($A7,'HALF YEARLY'!$1:$1048576,12,0) -> #REF! | Y7: =VLOOKUP($A7,'HALF YEARLY'!$1:$1048576,13,0) -> #REF! | Z7: =VLOOKUP($A7,'HALF YEARLY'!$1:$1048576,14,0) -> #REF! | AA7: =VLOOKUP($A7,'HALF YEARLY'!$1:$1048576,15,0) -> #REF!
A8: =DETAILS!#REF! -> #REF! | B8: =DETAILS!#REF! -> #REF! | C8: =VLOOKUP($A8,'UT-I '!$1:$1048576,3,0) -> #REF! | D8: =IFERROR(ROUND(VLOOKUP($A8,'HALF YEARLY'!$1:$1048576,3,0)*0.8,0),VLOOKUP($A8,'HALF YEARLY'!$1:$1048576,3,0)) -> #REF! | E8: =SUM(C8:D8) -> #REF! | F8: =VLOOKUP($A8,'UT-I '!$1:$1048576,4,0) -> #REF! | G8: =IFERROR(ROUND(VLOOKUP($A8,'HALF YEARLY'!$1:$1048576,4,0)*0.8,0),VLOOKUP($A8,'HALF YEARLY'!$1:$1048576,4,0)) -> #REF! | H8: =SUM(F8:G8) -> #REF! | I8: =VLOOKUP($A8,'UT-I '!$1:$1048576,5,0) -> #REF! | J8: =IFERROR(ROUND(VLOOKUP($A8,'HALF YEARLY'!$1:$1048576,5,0)*0.8,0),VLOOKUP($A8,'HALF YEARLY'!$1:$1048576,5,0)) -> #REF! | K8: =SUM(I8:J8) -> #REF! | L8: =VLOOKUP($A8,'UT-I '!$1:$1048576,6,0) -> #REF! | M8: =IFERROR(ROUND(VLOOKUP($A8,'HALF YEARLY'!$1:$1048576,6,0)*0.8,0),VLOOKUP($A8,'HALF YEARLY'!$1:$1048576,6,0)) -> #REF! | N8: =SUM(L8:M8) -> #REF! | O8: =VLOOKUP($A8,'UT-I '!$1:$1048576,7,0) -> #REF! | P8: =IFERROR(ROUND(VLOOKUP($A8,'HALF YEARLY'!$1:$1048576,7,0)*0.8,0),VLOOKUP($A8,'HALF YEARLY'!$1:$1048576,7,0)) -> #REF! | Q8: =SUM(O8:P8) -> #REF! | R8: =VLOOKUP($A8,'UT-I '!$1:$1048576,8,0) -> #REF! | S8: =IFERROR(ROUND(VLOOKUP($A8,'HALF YEARLY'!$1:$1048576,8,0)*0.8,0),VLOOKUP($A8,'HALF YEARLY'!$1:$1048576,8,0)) -> #REF! | T8: =SUM(R8:S8) -> #REF! | U8: =VLOOKUP($A8,'HALF YEARLY'!$1:$1048576,9,0) -> #REF! | V8: =VLOOKUP($A8,'HALF YEARLY'!$1:$1048576,10,0) -> #REF! | W8: =VLOOKUP($A8,'HALF YEARLY'!$1:$1048576,11,0) -> #REF! | X8: =VLOOKUP($A8,'HALF YEARLY'!$1:$1048576,12,0) -> #REF! | Y8: =VLOOKUP($A8,'HALF YEARLY'!$1:$1048576,13,0) -> #REF! | Z8: =VLOOKUP($A8,'HALF YEARLY'!$1:$1048576,14,0) -> #REF! | AA8: =VLOOKUP($A8,'HALF YEARLY'!$1:$1048576,15,0) -> #REF!
A9: =DETAILS!#REF! -> #REF! | B9: =DETAILS!#REF! -> #REF! | C9: =VLOOKUP($A9,'UT-I '!$1:$1048576,3,0) -> #REF! | D9: =IFERROR(ROUND(VLOOKUP($A9,'HALF YEARLY'!$1:$1048576,3,0)*0.8,0),VLOOKUP($A9,'HALF YEARLY'!$1:$1048576,3,0)) -> #REF! | E9: =SUM(C9:D9) -> #REF! | F9: =VLOOKUP($A9,'UT-I '!$1:$1048576,4,0) -> #REF! | G9: =IFERROR(ROUND(VLOOKUP($A9,'HALF YEARLY'!$1:$1048576,4,0)*0.8,0),VLOOKUP($A9,'HALF YEARLY'!$1:$1048576,4,0)) -> #REF! | H9: =SUM(F9:G9) -> #REF! | I9: =VLOOKUP($A9,'UT-I '!$1:$1048576,5,0) -> #REF! | J9: =IFERROR(ROUND(VLOOKUP($A9,'HALF YEARLY'!$1:$1048576,5,0)*0.8,0),VLOOKUP($A9,'HALF YEARLY'!$1:$1048576,5,0)) -> #REF! | K9: =SUM(I9:J9) -> #REF! | L9: =VLOOKUP($A9,'UT-I '!$1:$1048576,6,0) -> #REF! | M9: =IFERROR(ROUND(VLOOKUP($A9,'HALF YEARLY'!$1:$1048576,6,0)*0.8,0),VLOOKUP($A9,'HALF YEARLY'!$1:$1048576,6,0)) -> #REF! | N9: =SUM(L9:M9) -> #REF! | O9: =VLOOKUP($A9,'UT-I '!$1:$1048576,7,0) -> #REF! | P9: =IFERROR(ROUND(VLOOKUP($A9,'HALF YEARLY'!$1:$1048576,7,0)*0.8,0),VLOOKUP($A9,'HALF YEARLY'!$1:$1048576,7,0)) -> #REF! | Q9: =SUM(O9:P9) -> #REF! | R9: =VLOOKUP($A9,'UT-I '!$1:$1048576,8,0) -> #REF! | S9: =IFERROR(ROUND(VLOOKUP($A9,'HALF YEARLY'!$1:$1048576,8,0)*0.8,0),VLOOKUP($A9,'HALF YEARLY'!$1:$1048576,8,0)) -> #REF! | T9: =SUM(R9:S9) -> #REF! | U9: =VLOOKUP($A9,'HALF YEARLY'!$1:$1048576,9,0) -> #REF! | V9: =VLOOKUP($A9,'HALF YEARLY'!$1:$1048576,10,0) -> #REF! | W9: =VLOOKUP($A9,'HALF YEARLY'!$1:$1048576,11,0) -> #REF! | X9: =VLOOKUP($A9,'HALF YEARLY'!$1:$1048576,12,0) -> #REF! | Y9: =VLOOKUP($A9,'HALF YEARLY'!$1:$1048576,13,0) -> #REF! | Z9: =VLOOKUP($A9,'HALF YEARLY'!$1:$1048576,14,0) -> #REF! | AA9: =VLOOKUP($A9,'HALF YEARLY'!$1:$1048576,15,0) -> #REF!
A10: =DETAILS!#REF! -> #REF! | B10: =DETAILS!#REF! -> #REF! | C10: =VLOOKUP($A10,'UT-I '!$1:$1048576,3,0) -> #REF! | D10: =IFERROR(ROUND(VLOOKUP($A10,'HALF YEARLY'!$1:$1048576,3,0)*0.8,0),VLOOKUP($A10,'HALF YEARLY'!$1:$1048576,3,0)) -> #REF! | E10: =SUM(C10:D10) -> #REF! | F10: =VLOOKUP($A10,'UT-I '!$1:$1048576,4,0) -> #REF! | G10: =IFERROR(ROUND(VLOOKUP($A10,'HALF YEARLY'!$1:$1048576,4,0)*0.8,0),VLOOKUP($A10,'HALF YEARLY'!$1:$1048576,4,0)) -> #REF! | H10: =SUM(F10:G10) -> #REF! | I10: =VLOOKUP($A10,'UT-I '!$1:$1048576,5,0) -> #REF! | J10: =IFERROR(ROUND(VLOOKUP($A10,'HALF YEARLY'!$1:$1048576,5,0)*0.8,0),VLOOKUP($A10,'HALF YEARLY'!$1:$1048576,5,0)) -> #REF! | K10: =SUM(I10:J10) -> #REF! | L10: =VLOOKUP($A10,'UT-I '!$1:$1048576,6,0) -> #REF! | M10: =IFERROR(ROUND(VLOOKUP($A10,'HALF YEARLY'!$1:$1048576,6,0)*0.8,0),VLOOKUP($A10,'HALF YEARLY'!$1:$1048576,6,0)) -> #REF! | N10: =SUM(L10:M10) -> #REF! | O10: =VLOOKUP($A10,'UT-I '!$1:$1048576,7,0) -> #REF! | P10: =IFERROR(ROUND(VLOOKUP($A10,'HALF YEARLY'!$1:$1048576,7,0)*0.8,0),VLOOKUP($A10,'HALF YEARLY'!$1:$1048576,7,0)) -> #REF! | Q10: =SUM(O10:P10) -> #REF! | R10: =VLOOKUP($A10,'UT-I '!$1:$1048576,8,0) -> #REF! | S10: =IFERROR(ROUND(VLOOKUP($A10,'HALF YEARLY'!$1:$1048576,8,0)*0.8,0),VLOOKUP($A10,'HALF YEARLY'!$1:$1048576,8,0)) -> #REF! | T10: =SUM(R10:S10) -> #REF! | U10: =VLOOKUP($A10,'HALF YEARLY'!$1:$1048576,9,0) -> #REF! | V10: =VLOOKUP($A10,'HALF YEARLY'!$1:$1048576,10,0) -> #REF! | W10: =VLOOKUP($A10,'HALF YEARLY'!$1:$1048576,11,0) -> #REF! | X10: =VLOOKUP($A10,'HALF YEARLY'!$1:$1048576,12,0) -> #REF! | Y10: =VLOOKUP($A10,'HALF YEARLY'!$1:$1048576,13,0) -> #REF! | Z10: =VLOOKUP($A10,'HALF YEARLY'!$1:$1048576,14,0) -> #REF! | AA10: =VLOOKUP($A10,'HALF YEARLY'!$1:$1048576,15,0) -> #REF!
A11: =DETAILS!#REF! -> #REF! | B11: =DETAILS!#REF! -> #REF! | C11: =VLOOKUP($A11,'UT-I '!$1:$1048576,3,0) -> #REF! | D11: =IFERROR(ROUND(VLOOKUP($A11,'HALF YEARLY'!$1:$1048576,3,0)*0.8,0),VLOOKUP($A11,'HALF YEARLY'!$1:$1048576,3,0)) -> #REF! | E11: =SUM(C11:D11) -> #REF! | F11: =VLOOKUP($A11,'UT-I '!$1:$1048576,4,0) -> #REF! | G11: =IFERROR(ROUND(VLOOKUP($A11,'HALF YEARLY'!$1:$1048576,4,0)*0.8,0),VLOOKUP($A11,'HALF YEARLY'!$1:$1048576,4,0)) -> #REF! | H11: =SUM(F11:G11) -> #REF! | I11: =VLOOKUP($A11,'UT-I '!$1:$1048576,5,0) -> #REF! | J11: =IFERROR(ROUND(VLOOKUP($A11,'HALF YEARLY'!$1:$1048576,5,0)*0.8,0),VLOOKUP($A11,'HALF YEARLY'!$1:$1048576,5,0)) -> #REF! | K11: =SUM(I11:J11) -> #REF! | L11: =VLOOKUP($A11,'UT-I '!$1:$1048576,6,0) -> #REF! | M11: =IFERROR(ROUND(VLOOKUP($A11,'HALF YEARLY'!$1:$1048576,6,0)*0.8,0),VLOOKUP($A11,'HALF YEARLY'!$1:$1048576,6,0)) -> #REF! | N11: =SUM(L11:M11) -> #REF! | O11: =VLOOKUP($A11,'UT-I '!$1:$1048576,7,0) -> #REF! | P11: =IFERROR(ROUND(VLOOKUP($A11,'HALF YEARLY'!$1:$1048576,7,0)*0.8,0),VLOOKUP($A11,'HALF YEARLY'!$1:$1048576,7,0)) -> #REF! | Q11: =SUM(O11:P11) -> #REF! | R11: =VLOOKUP($A11,'UT-I '!$1:$1048576,8,0) -> #REF! | S11: =IFERROR(ROUND(VLOOKUP($A11,'HALF YEARLY'!$1:$1048576,8,0)*0.8,0),VLOOKUP($A11,'HALF YEARLY'!$1:$1048576,8,0)) -> #REF! | T11: =SUM(R11:S11) -> #REF! | U11: =VLOOKUP($A11,'HALF YEARLY'!$1:$1048576,9,0) -> #REF! | V11: =VLOOKUP($A11,'HALF YEARLY'!$1:$1048576,10,0) -> #REF! | W11: =VLOOKUP($A11,'HALF YEARLY'!$1:$1048576,11,0) -> #REF! | X11: =VLOOKUP($A11,'HALF YEARLY'!$1:$1048576,12,0) -> #REF! | Y11: =VLOOKUP($A11,'HALF YEARLY'!$1:$1048576,13,0) -> #REF! | Z11: =VLOOKUP($A11,'HALF YEARLY'!$1:$1048576,14,0) -> #REF! | AA11: =VLOOKUP($A11,'HALF YEARLY'!$1:$1048576,15,0) -> #REF!
A12: =DETAILS!#REF! -> #REF! | B12: =DETAILS!#REF! -> #REF! | C12: =VLOOKUP($A12,'UT-I '!$1:$1048576,3,0) -> #REF! | D12: =IFERROR(ROUND(VLOOKUP($A12,'HALF YEARLY'!$1:$1048576,3,0)*0.8,0),VLOOKUP($A12,'HALF YEARLY'!$1:$1048576,3,0)) -> #REF! | E12: =SUM(C12:D12) -> #REF! | F12: =VLOOKUP($A12,'UT-I '!$1:$1048576,4,0) -> #REF! | G12: =IFERROR(ROUND(VLOOKUP($A12,'HALF YEARLY'!$1:$1048576,4,0)*0.8,0),VLOOKUP($A12,'HALF YEARLY'!$1:$1048576,4,0)) -> #REF! | H12: =SUM(F12:G12) -> #REF! | I12: =VLOOKUP($A12,'UT-I '!$1:$1048576,5,0) -> #REF! | J12: =IFERROR(ROUND(VLOOKUP($A12,'HALF YEARLY'!$1:$1048576,5,0)*0.8,0),VLOOKUP($A12,'HALF YEARLY'!$1:$1048576,5,0)) -> #REF! | K12: =SUM(I12:J12) -> #REF! | L12: =VLOOKUP($A12,'UT-I '!$1:$1048576,6,0) -> #REF! | M12: =IFERROR(ROUND(VLOOKUP($A12,'HALF YEARLY'!$1:$1048576,6,0)*0.8,0),VLOOKUP($A12,'HALF YEARLY'!$1:$1048576,6,0)) -> #REF! | N12: =SUM(L12:M12) -> #REF! | O12: =VLOOKUP($A12,'UT-I '!$1:$1048576,7,0) -> #REF! | P12: =IFERROR(ROUND(VLOOKUP($A12,'HALF YEARLY'!$1:$1048576,7,0)*0.8,0),VLOOKUP($A12,'HALF YEARLY'!$1:$1048576,7,0)) -> #REF! | Q12: =SUM(O12:P12) -> #REF! | R12: =VLOOKUP($A12,'UT-I '!$1:$1048576,8,0) -> #REF! | S12: =IFERROR(ROUND(VLOOKUP($A12,'HALF YEARLY'!$1:$1048576,8,0)*0.8,0),VLOOKUP($A12,'HALF YEARLY'!$1:$1048576,8,0)) -> #REF! | T12: =SUM(R12:S12) -> #REF! | U12: =VLOOKUP($A12,'HALF YEARLY'!$1:$1048576,9,0) -> #REF! | V12: =VLOOKUP($A12,'HALF YEARLY'!$1:$1048576,10,0) -> #REF! | W12: =VLOOKUP($A12,'HALF YEARLY'!$1:$1048576,11,0) -> #REF! | X12: =VLOOKUP($A12,'HALF YEARLY'!$1:$1048576,12,0) -> #REF! | Y12: =VLOOKUP($A12,'HALF YEARLY'!$1:$1048576,13,0) -> #REF! | Z12: =VLOOKUP($A12,'HALF YEARLY'!$1:$1048576,14,0) -> #REF! | AA12: =VLOOKUP($A12,'HALF YEARLY'!$1:$1048576,15,0) -> #REF!
A13: =DETAILS!#REF! -> #REF! | B13: =DETAILS!#REF! -> #REF! | C13: =VLOOKUP($A13,'UT-I '!$1:$1048576,3,0) -> #REF! | D13: =IFERROR(ROUND(VLOOKUP($A13,'HALF YEARLY'!$1:$1048576,3,0)*0.8,0),VLOOKUP($A13,'HALF YEARLY'!$1:$1048576,3,0)) -> #REF! | E13: =SUM(C13:D13) -> #REF! | F13: =VLOOKUP($A13,'UT-I '!$1:$1048576,4,0) -> #REF! | G13: =IFERROR(ROUND(VLOOKUP($A13,'HALF YEARLY'!$1:$1048576,4,0)*0.8,0),VLOOKUP($A13,'HALF YEARLY'!$1:$1048576,4,0)) -> #REF! | H13: =SUM(F13:G13) -> #REF! | I13: =VLOOKUP($A13,'UT-I '!$1:$1048576,5,0) -> #REF! | J13: =IFERROR(ROUND(VLOOKUP($A13,'HALF YEARLY'!$1:$1048576,5,0)*0.8,0),VLOOKUP($A13,'HALF YEARLY'!$1:$1048576,5,0)) -> #REF! | K13: =SUM(I13:J13) -> #REF! | L13: =VLOOKUP($A13,'UT-I '!$1:$1048576,6,0) -> #REF! | M13: =IFERROR(ROUND(VLOOKUP($A13,'HALF YEARLY'!$1:$1048576,6,0)*0.8,0),VLOOKUP($A13,'HALF YEARLY'!$1:$1048576,6,0)) -> #REF! | N13: =SUM(L13:M13) -> #REF! | O13: =VLOOKUP($A13,'UT-I '!$1:$1048576,7,0) -> #REF! | P13: =IFERROR(ROUND(VLOOKUP($A13,'HALF YEARLY'!$1:$1048576,7,0)*0.8,0),VLOOKUP($A13,'HALF YEARLY'!$1:$1048576,7,0)) -> #REF! | Q13: =SUM(O13:P13) -> #REF! | R13: =VLOOKUP($A13,'UT-I '!$1:$1048576,8,0) -> #REF! | S13: =IFERROR(ROUND(VLOOKUP($A13,'HALF YEARLY'!$1:$1048576,8,0)*0.8,0),VLOOKUP($A13,'HALF YEARLY'!$1:$1048576,8,0)) -> #REF! | T13: =SUM(R13:S13) -> #REF! | U13: =VLOOKUP($A13,'HALF YEARLY'!$1:$1048576,9,0) -> #REF! | V13: =VLOOKUP($A13,'HALF YEARLY'!$1:$1048576,10,0) -> #REF! | W13: =VLOOKUP($A13,'HALF YEARLY'!$1:$1048576,11,0) -> #REF! | X13: =VLOOKUP($A13,'HALF YEARLY'!$1:$1048576,12,0) -> #REF! | Y13: =VLOOKUP($A13,'HALF YEARLY'!$1:$1048576,13,0) -> #REF! | Z13: =VLOOKUP($A13,'HALF YEARLY'!$1:$1048576,14,0) -> #REF! | AA13: =VLOOKUP($A13,'HALF YEARLY'!$1:$1048576,15,0) -> #REF!
A14: =DETAILS!#REF! -> #REF! | B14: =DETAILS!#REF! -> #REF! | C14: =VLOOKUP($A14,'UT-I '!$1:$1048576,3,0) -> #REF! | D14: =IFERROR(ROUND(VLOOKUP($A14,'HALF YEARLY'!$1:$1048576,3,0)*0.8,0),VLOOKUP($A14,'HALF YEARLY'!$1:$1048576,3,0)) -> #REF! | E14: =SUM(C14:D14) -> #REF! | F14: =VLOOKUP($A14,'UT-I '!$1:$1048576,4,0) -> #REF! | G14: =IFERROR(ROUND(VLOOKUP($A14,'HALF YEARLY'!$1:$1048576,4,0)*0.8,0),VLOOKUP($A14,'HALF YEARLY'!$1:$1048576,4,0)) -> #REF! | H14: =SUM(F14:G14) -> #REF! | I14: =VLOOKUP($A14,'UT-I '!$1:$1048576,5,0) -> #REF! | J14: =IFERROR(ROUND(VLOOKUP($A14,'HALF YEARLY'!$1:$1048576,5,0)*0.8,0),VLOOKUP($A14,'HALF YEARLY'!$1:$1048576,5,0)) -> #REF! | K14: =SUM(I14:J14) -> #REF! | L14: =VLOOKUP($A14,'UT-I '!$1:$1048576,6,0) -> #REF! | M14: =IFERROR(ROUND(VLOOKUP($A14,'HALF YEARLY'!$1:$1048576,6,0)*0.8,0),VLOOKUP($A14,'HALF YEARLY'!$1:$1048576,6,0)) -> #REF! | N14: =SUM(L14:M14) -> #REF! | O14: =VLOOKUP($A14,'UT-I '!$1:$1048576,7,0) -> #REF! | P14: =IFERROR(ROUND(VLOOKUP($A14,'HALF YEARLY'!$1:$1048576,7,0)*0.8,0),VLOOKUP($A14,'HALF YEARLY'!$1:$1048576,7,0)) -> #REF! | Q14: =SUM(O14:P14) -> #REF! | R14: =VLOOKUP($A14,'UT-I '!$1:$1048576,8,0) -> #REF! | S14: =IFERROR(ROUND(VLOOKUP($A14,'HALF YEARLY'!$1:$1048576,8,0)*0.8,0),VLOOKUP($A14,'HALF YEARLY'!$1:$1048576,8,0)) -> #REF! | T14: =SUM(R14:S14) -> #REF! | U14: =VLOOKUP($A14,'HALF YEARLY'!$1:$1048576,9,0) -> #REF! | V14: =VLOOKUP($A14,'HALF YEARLY'!$1:$1048576,10,0) -> #REF! | W14: =VLOOKUP($A14,'HALF YEARLY'!$1:$1048576,11,0) -> #REF! | X14: =VLOOKUP($A14,'HALF YEARLY'!$1:$1048576,12,0) -> #REF! | Y14: =VLOOKUP($A14,'HALF YEARLY'!$1:$1048576,13,0) -> #REF! | Z14: =VLOOKUP($A14,'HALF YEARLY'!$1:$1048576,14,0) -> #REF! | AA14: =VLOOKUP($A14,'HALF YEARLY'!$1:$1048576,15,0) -> #REF!
A15: =DETAILS!#REF! -> #REF! | B15: =DETAILS!#REF! -> #REF! | C15: =VLOOKUP($A15,'UT-I '!$1:$1048576,3,0) -> #REF! | D15: =IFERROR(ROUND(VLOOKUP($A15,'HALF YEARLY'!$1:$1048576,3,0)*0.8,0),VLOOKUP($A15,'HALF YEARLY'!$1:$1048576,3,0)) -> #REF! | E15: =SUM(C15:D15) -> #REF! | F15: =VLOOKUP($A15,'UT-I '!$1:$1048576,4,0) -> #REF! | G15: =IFERROR(ROUND(VLOOKUP($A15,'HALF YEARLY'!$1:$1048576,4,0)*0.8,0),VLOOKUP($A15,'HALF YEARLY'!$1:$1048576,4,0)) -> #REF! | H15: =SUM(F15:G15) -> #REF! | I15: =VLOOKUP($A15,'UT-I '!$1:$1048576,5,0) -> #REF! | J15: =IFERROR(ROUND(VLOOKUP($A15,'HALF YEARLY'!$1:$1048576,5,0)*0.8,0),VLOOKUP($A15,'HALF YEARLY'!$1:$1048576,5,0)) -> #REF! | K15: =SUM(I15:J15) -> #REF! | L15: =VLOOKUP($A15,'UT-I '!$1:$1048576,6,0) -> #REF! | M15: =IFERROR(ROUND(VLOOKUP($A15,'HALF YEARLY'!$1:$1048576,6,0)*0.8,0),VLOOKUP($A15,'HALF YEARLY'!$1:$1048576,6,0)) -> #REF! | N15: =SUM(L15:M15) -> #REF! | O15: =VLOOKUP($A15,'UT-I '!$1:$1048576,7,0) -> #REF! | P15: =IFERROR(ROUND(VLOOKUP($A15,'HALF YEARLY'!$1:$1048576,7,0)*0.8,0),VLOOKUP($A15,'HALF YEARLY'!$1:$1048576,7,0)) -> #REF! | Q15: =SUM(O15:P15) -> #REF! | R15: =VLOOKUP($A15,'UT-I '!$1:$1048576,8,0) -> #REF! | S15: =IFERROR(ROUND(VLOOKUP($A15,'HALF YEARLY'!$1:$1048576,8,0)*0.8,0),VLOOKUP($A15,'HALF YEARLY'!$1:$1048576,8,0)) -> #REF! | T15: =SUM(R15:S15) -> #REF! | U15: =VLOOKUP($A15,'HALF YEARLY'!$1:$1048576,9,0) -> #REF! | V15: =VLOOKUP($A15,'HALF YEARLY'!$1:$1048576,10,0) -> #REF! | W15: =VLOOKUP($A15,'HALF YEARLY'!$1:$1048576,11,0) -> #REF! | X15: =VLOOKUP($A15,'HALF YEARLY'!$1:$1048576,12,0) -> #REF! | Y15: =VLOOKUP($A15,'HALF YEARLY'!$1:$1048576,13,0) -> #REF! | Z15: =VLOOKUP($A15,'HALF YEARLY'!$1:$1048576,14,0) -> #REF! | AA15: =VLOOKUP($A15,'HALF YEARLY'!$1:$1048576,15,0) -> #REF!
A16: =DETAILS!#REF! -> #REF! | B16: =DETAILS!#REF! -> #REF! | C16: =VLOOKUP($A16,'UT-I '!$1:$1048576,3,0) -> #REF! | D16: =IFERROR(ROUND(VLOOKUP($A16,'HALF YEARLY'!$1:$1048576,3,0)*0.8,0),VLOOKUP($A16,'HALF YEARLY'!$1:$1048576,3,0)) -> #REF! | E16: =SUM(C16:D16) -> #REF! | F16: =VLOOKUP($A16,'UT-I '!$1:$1048576,4,0) -> #REF! | G16: =IFERROR(ROUND(VLOOKUP($A16,'HALF YEARLY'!$1:$1048576,4,0)*0.8,0),VLOOKUP($A16,'HALF YEARLY'!$1:$1048576,4,0)) -> #REF! | H16: =SUM(F16:G16) -> #REF! | I16: =VLOOKUP($A16,'UT-I '!$1:$1048576,5,0) -> #REF! | J16: =IFERROR(ROUND(VLOOKUP($A16,'HALF YEARLY'!$1:$1048576,5,0)*0.8,0),VLOOKUP($A16,'HALF YEARLY'!$1:$1048576,5,0)) -> #REF! | K16: =SUM(I16:J16) -> #REF! | L16: =VLOOKUP($A16,'UT-I '!$1:$1048576,6,0) -> #REF! | M16: =IFERROR(ROUND(VLOOKUP($A16,'HALF YEARLY'!$1:$1048576,6,0)*0.8,0),VLOOKUP($A16,'HALF YEARLY'!$1:$1048576,6,0)) -> #REF! | N16: =SUM(L16:M16) -> #REF! | O16: =VLOOKUP($A16,'UT-I '!$1:$1048576,7,0) -> #REF! | P16: =IFERROR(ROUND(VLOOKUP($A16,'HALF YEARLY'!$1:$1048576,7,0)*0.8,0),VLOOKUP($A16,'HALF YEARLY'!$1:$1048576,7,0)) -> #REF! | Q16: =SUM(O16:P16) -> #REF! | R16: =VLOOKUP($A16,'UT-I '!$1:$1048576,8,0) -> #REF! | S16: =IFERROR(ROUND(VLOOKUP($A16,'HALF YEARLY'!$1:$1048576,8,0)*0.8,0),VLOOKUP($A16,'HALF YEARLY'!$1:$1048576,8,0)) -> #REF! | T16: =SUM(R16:S16) -> #REF! | U16: =VLOOKUP($A16,'HALF YEARLY'!$1:$1048576,9,0) -> #REF! | V16: =VLOOKUP($A16,'HALF YEARLY'!$1:$1048576,10,0) -> #REF! | W16: =VLOOKUP($A16,'HALF YEARLY'!$1:$1048576,11,0) -> #REF! | X16: =VLOOKUP($A16,'HALF YEARLY'!$1:$1048576,12,0) -> #REF! | Y16: =VLOOKUP($A16,'HALF YEARLY'!$1:$1048576,13,0) -> #REF! | Z16: =VLOOKUP($A16,'HALF YEARLY'!$1:$1048576,14,0) -> #REF! | AA16: =VLOOKUP($A16,'HALF YEARLY'!$1:$1048576,15,0) -> #REF!
A17: =DETAILS!#REF! -> #REF! | B17: =DETAILS!#REF! -> #REF! | C17: =VLOOKUP($A17,'UT-I '!$1:$1048576,3,0) -> #REF! | D17: =IFERROR(ROUND(VLOOKUP($A17,'HALF YEARLY'!$1:$1048576,3,0)*0.8,0),VLOOKUP($A17,'HALF YEARLY'!$1:$1048576,3,0)) -> #REF! | E17: =SUM(C17:D17) -> #REF! | F17: =VLOOKUP($A17,'UT-I '!$1:$1048576,4,0) -> #REF! | G17: =IFERROR(ROUND(VLOOKUP($A17,'HALF YEARLY'!$1:$1048576,4,0)*0.8,0),VLOOKUP($A17,'HALF YEARLY'!$1:$1048576,4,0)) -> #REF! | H17: =SUM(F17:G17) -> #REF! | I17: =VLOOKUP($A17,'UT-I '!$1:$1048576,5,0) -> #REF! | J17: =IFERROR(ROUND(VLOOKUP($A17,'HALF YEARLY'!$1:$1048576,5,0)*0.8,0),VLOOKUP($A17,'HALF YEARLY'!$1:$1048576,5,0)) -> #REF! | K17: =SUM(I17:J17) -> #REF! | L17: =VLOOKUP($A17,'UT-I '!$1:$1048576,6,0) -> #REF! | M17: =IFERROR(ROUND(VLOOKUP($A17,'HALF YEARLY'!$1:$1048576,6,0)*0.8,0),VLOOKUP($A17,'HALF YEARLY'!$1:$1048576,6,0)) -> #REF! | N17: =SUM(L17:M17) -> #REF! | O17: =VLOOKUP($A17,'UT-I '!$1:$1048576,7,0) -> #REF! | P17: =IFERROR(ROUND(VLOOKUP($A17,'HALF YEARLY'!$1:$1048576,7,0)*0.8,0),VLOOKUP($A17,'HALF YEARLY'!$1:$1048576,7,0)) -> #REF! | Q17: =SUM(O17:P17) -> #REF! | R17: =VLOOKUP($A17,'UT-I '!$1:$1048576,8,0) -> #REF! | S17: =IFERROR(ROUND(VLOOKUP($A17,'HALF YEARLY'!$1:$1048576,8,0)*0.8,0),VLOOKUP($A17,'HALF YEARLY'!$1:$1048576,8,0)) -> #REF! | T17: =SUM(R17:S17) -> #REF! | U17: =VLOOKUP($A17,'HALF YEARLY'!$1:$1048576,9,0) -> #REF! | V17: =VLOOKUP($A17,'HALF YEARLY'!$1:$1048576,10,0) -> #REF! | W17: =VLOOKUP($A17,'HALF YEARLY'!$1:$1048576,11,0) -> #REF! | X17: =VLOOKUP($A17,'HALF YEARLY'!$1:$1048576,12,0) -> #REF! | Y17: =VLOOKUP($A17,'HALF YEARLY'!$1:$1048576,13,0) -> #REF! | Z17: =VLOOKUP($A17,'HALF YEARLY'!$1:$1048576,14,0) -> #REF! | AA17: =VLOOKUP($A17,'HALF YEARLY'!$1:$1048576,15,0) -> #REF!
... A41: =DETAILS!#REF! -> #REF! | B41: =DETAILS!#REF! -> #REF! | C41: =VLOOKUP($A41,'UT-I '!$1:$1048576,3,0) -> #REF! | D41: =IFERROR(ROUND(VLOOKUP($A41,'HALF YEARLY'!$1:$1048576,3,0)*0.8,0),VLOOKUP($A41,'HALF YEARLY'!$1:$1048576,3,0)) -> #REF! | E41: =SUM(C41:D41) -> #REF! | F41: =VLOOKUP($A41,'UT-I '!$1:$1048576,4,0) -> #REF! | G41: =IFERROR(ROUND(VLOOKUP($A41,'HALF YEARLY'!$1:$1048576,4,0)*0.8,0),VLOOKUP($A41,'HALF YEARLY'!$1:$1048576,4,0)) -> #REF! | H41: =SUM(F41:G41) -> #REF! | I41: =VLOOKUP($A41,'UT-I '!$1:$1048576,5,0) -> #REF! | J41: =IFERROR(ROUND(VLOOKUP($A41,'HALF YEARLY'!$1:$1048576,5,0)*0.8,0),VLOOKUP($A41,'HALF YEARLY'!$1:$1048576,5,0)) -> #REF! | K41: =SUM(I41:J41) -> #REF! | L41: =VLOOKUP($A41,'UT-I '!$1:$1048576,6,0) -> #REF! | M41: =IFERROR(ROUND(VLOOKUP($A41,'HALF YEARLY'!$1:$1048576,6,0)*0.8,0),VLOOKUP($A41,'HALF YEARLY'!$1:$1048576,6,0)) -> #REF! | N41: =SUM(L41:M41) -> #REF! | O41: =VLOOKUP($A41,'UT-I '!$1:$1048576,7,0) -> #REF! | P41: =IFERROR(ROUND(VLOOKUP($A41,'HALF YEARLY'!$1:$1048576,7,0)*0.8,0),VLOOKUP($A41,'HALF YEARLY'!$1:$1048576,7,0)) -> #REF! | Q41: =SUM(O41:P41) -> #REF! | R41: =VLOOKUP($A41,'UT-I '!$1:$1048576,8,0) -> #REF! | S41: =IFERROR(ROUND(VLOOKUP($A41,'HALF YEARLY'!$1:$1048576,8,0)*0.8,0),VLOOKUP($A41,'HALF YEARLY'!$1:$1048576,8,0)) -> #REF! | T41: =SUM(R41:S41) -> #REF! | U41: =VLOOKUP($A41,'HALF YEARLY'!$1:$1048576,9,0) -> #REF! | V41: =VLOOKUP($A41,'HALF YEARLY'!$1:$1048576,10,0) -> #REF! | W41: =VLOOKUP($A41,'HALF YEARLY'!$1:$1048576,11,0) -> #REF! | X41: =VLOOKUP($A41,'HALF YEARLY'!$1:$1048576,12,0) -> #REF! | Y41: =VLOOKUP($A41,'HALF YEARLY'!$1:$1048576,13,0) -> #REF! | Z41: =VLOOKUP($A41,'HALF YEARLY'!$1:$1048576,14,0) -> #REF! | AA41: =VLOOKUP($A41,'HALF YEARLY'!$1:$1048576,15,0) -> #REF!

Sheet HY Report
B2: SAINIK PUBLIC SCHOOL
B3: (Affiliated to C.B.S.E. New Delhi- Reg. No. : 2131299)
B4: Building No. VB1893, Vikas Bhawan Ward,
B5: Nagar Palika Parishad, Nawabganj, Barabanki
B6: HALF YEARLY REPORT CARD
B7: SESSION 2025-26
B8: STUDENT PROFILE
B9: Student's Name | C9: =": "&VLOOKUP($K$9,DETAILS!$1:$1048576,2,0) -> #N/A | I9: Admission No. : | K9: 1
B10: Mother's Name | C10: =": "&VLOOKUP($K$9,DETAILS!$1:$1048576,3,0) -> #N/A | I10: Class & Sec. : | K10: =VLOOKUP($K$9,DETAILS!$1:$1048576,6,0) -> #N/A
B11: Father's Name | C11: =": "&VLOOKUP($K$9,DETAILS!$1:$1048576,4,0) -> #N/A | I11: Date of Birth : | K11: =VLOOKUP($K$9,DETAILS!$1:$1048576,5,0) -> #N/A
B13: PART-1 : ACADEMIC PERFORMANCE-SCHOLASTIC AREAS
B14: SUBJECT | D14: UNIT TEST - I (20) | G14: HALF YEARLY (80) | K14: TOTAL (100)
B15: ENGLISH CORE | D15: =VLOOKUP($K$9,'HY Compile'!$1:$1048576,3,0) -> #N/A | G15: =VLOOKUP($K$9,'HY Compile'!$1:$1048576,4,0) -> #N/A | K15: =SUM(D15:J15) -> #N/A
B16: =VLOOKUP($K$9,DETAILS!$1:$1048576,7,0) -> #N/A | D16: =VLOOKUP($K$9,'HY Compile'!$1:$1048576,6,0) -> #N/A | G16: =VLOOKUP($K$9,'HY Compile'!$1:$1048576,7,0) -> #N/A | K16: =SUM(D16:J16) -> #N/A
B17: HISTORY | D17: =VLOOKUP($K$9,'HY Compile'!$1:$1048576,9,0) -> #N/A | G17: =VLOOKUP($K$9,'HY Compile'!$1:$1048576,10,0) -> #N/A | K17: =SUM(D17:J17) -> #N/A
B18: POLITICAL SCIENCE | D18: =VLOOKUP($K$9,'HY Compile'!$1:$1048576,12,0) -> #N/A | G18: =VLOOKUP($K$9,'HY Compile'!$1:$1048576,13,0) -> #N/A | K18: =SUM(D18:J18) -> #N/A
B19: GEOGRAPHY | D19: =VLOOKUP($K$9,'HY Compile'!$1:$1048576,15,0) -> #N/A | G19: =VLOOKUP($K$9,'HY Compile'!$1:$1048576,16,0) -> #N/A | K19: =SUM(D19:J19) -> #N/A
B20: PHYSICAL EDUCATION | D20: =VLOOKUP($K$9,'HY Compile'!$1:$1048576,18,0) -> #N/A | G20: =VLOOKUP($K$9,'HY Compile'!$1:$1048576,19,0) -> #N/A | K20: =SUM(D20:J20) -> #N/A
B22: Attendance | C22: =VLOOKUP($K$9,'HY Compile'!$1:$1048576,25,0) -> #N/A | D22: =VLOOKUP($K$9,'HY Compile'!$1:$1048576,26,0) -> #N/A | J22: Percentage : | L22: =ROUND(SUM(K15:M20)/6,2)&" %" -> #N/A
C23: =VLOOKUP($K$9,'HY Compile'!$1:$1048576,38,0) -> #N/A | D23: =VLOOKUP($K$9,'HY Compile'!$1:$1048576,38,0) -> #N/A | J23: Grand Total : | L23: =SUM(K15:M20)& "/600" -> #N/A
B26: PART-2:CO-SCHOLASTIC AREAS | K26: GRADE
B27: Work Education | K27: =VLOOKUP($K$9,'HY Compile'!$1:$1048576,21,0) -> #N/A
B28: Art Education | K28: =VLOOKUP($K$9,'HY Compile'!$1:$1048576,22,0) -> #N/A
B29: Health & Physical Education | K29: =VLOOKUP($K$9,'HY Compile'!$1:$1048576,23,0) -> #N/A
B30: Discipline | K30: =VLOOKUP($K$9,'HY Compile'!$1:$1048576,24,0) -> #N/A
B32: Mark Range | D32: 100-81 | F32: 80-61 | H32: 60-41 | J32: 40-33 | L32: 32-0
B33: Grade | D33: A | F33: B | H33: C | J33: D | L33: E
B36: ="Class Teacher's Remark: "&VLOOKUP($K$9,'HY Compile'!$1:$1048576,27,0) -> #N/A
B38: Issue Date: 10.10.2025
B41: Class Teacher's Signature | J41: Principal's Signature

Sheet UT-2(Entry)
A1: UNIT TEST-II (2025-26) CLASS - XI-Human
A2: SR. NO. | B2: NAME | C2: ENGLISH | D2: HINDI/CS | E2: HISTORY | F2: POLITICAL SCIENCE | G2: GEOGRAPHY | H2: PHYSICAL EDUCATION | I2: Attendance
I3: Present | J3: Working Day
A4: =DETAILS!A3 -> 1925 | B4: =DETAILS!B3 -> ARYAN GUPTA
A5: =DETAILS!A4 -> 1918 | B5: =DETAILS!B4 -> SANJANA PATEL
A6: =DETAILS!#REF! -> #REF! | B6: =DETAILS!#REF! -> #REF!
A7: =DETAILS!#REF! -> #REF! | B7: =DETAILS!#REF! -> #REF!
A8: =DETAILS!#REF! -> #REF! | B8: =DETAILS!#REF! -> #REF!
A9: =DETAILS!#REF! -> #REF! | B9: =DETAILS!#REF! -> #REF!
A10: =DETAILS!#REF! -> #REF! | B10: =DETAILS!#REF! -> #REF!
A11: =DETAILS!#REF! -> #REF! | B11: =DETAILS!#REF! -> #REF!
A12: =DETAILS!#REF! -> #REF! | B12: =DETAILS!#REF! -> #REF!
A13: =DETAILS!#REF! -> #REF! | B13: =DETAILS!#REF! -> #REF!
A14: =DETAILS!#REF! -> #REF! | B14: =DETAILS!#REF! -> #REF!
A15: =DETAILS!#REF! -> #REF! | B15: =DETAILS!#REF! -> #REF!
A16: =DETAILS!#REF! -> #REF! | B16: =DETAILS!#REF! -> #REF!
A17: =DETAILS!#REF! -> #REF! | B17: =DETAILS!#REF! -> #REF!
... A42: =DETAILS!#REF! -> #REF! | B42: =DETAILS!#REF! -> #REF!

Sheet UT-2
A1: UNIT TEST-II (2025-26) CLASS - XI-Human
A2: SR. NO. | B2: NAME | C2: ENGLISH | D2: HINDI/CS | E2: HISTORY | F2: POLITICAL SCIENCE | G2: GEOGRAPHY | H2: PHYSICAL EDUCATION | I2: TOTAL | J2: PERCENTAGE | K2: Attendance
K3: Present | L3: Working Day
A4: =DETAILS!A3 -> 1925 | B4: =DETAILS!B3 -> ARYAN GUPTA | C4: =IFERROR(ROUND((VLOOKUP(A4,'UT-2(Entry)'!$1:$1048576,3,0))/2.5,0),VLOOKUP(A4,'UT-2(Entry)'!$1:$1048576,3,0)) -> 0 | D4: =IFERROR(ROUND((VLOOKUP(A4,'UT-2(Entry)'!$1:$1048576,4,0))/2.5,0),VLOOKUP(A4,'UT-2(Entry)'!$1:$1048576,4,0)) -> 0 | E4: =IFERROR(ROUND((VLOOKUP(A4,'UT-2(Entry)'!$1:$1048576,5,0))/2.5,0),VLOOKUP(A4,'UT-2(Entry)'!$1:$1048576,5,0)) -> 0 | F4: =IFERROR(ROUND((VLOOKUP(A4,'UT-2(Entry)'!$1:$1048576,6,0))/2.5,0),VLOOKUP(A4,'UT-2(Entry)'!$1:$1048576,6,0)) -> 0 | G4: =IFERROR(ROUND((VLOOKUP($A4,'UT-2(Entry)'!$1:$1048576,7,0))/2.5,0),VLOOKUP($A4,'UT-2(Entry)'!$1:$1048576,7,0)) -> 0 | H4: =IFERROR(ROUND((VLOOKUP($A4,'UT-2(Entry)'!$1:$1048576,8,0))/2.5,0),VLOOKUP($A4,'UT-2(Entry)'!$1:$1048576,8,0)) -> 0 | I4: =SUM(C4:H4) -> 0 | J4: =ROUND(I4/1.2,2)&" %" -> 0 % | K4: =VLOOKUP(A4,'UT-2(Entry)'!$1:$1048576,9,0) -> 0 | L4: =VLOOKUP(A4,'UT-2(Entry)'!$1:$1048576,10,0) -> 0
A5: =DETAILS!A4 -> 1918 | B5: =DETAILS!B4 -> SANJANA PATEL | C5: =IFERROR(ROUND((VLOOKUP(A5,'UT-2(Entry)'!$1:$1048576,3,0))/2.5,0),VLOOKUP(A5,'UT-2(Entry)'!$1:$1048576,3,0)) -> 0 | D5: =IFERROR(ROUND((VLOOKUP(A5,'UT-2(Entry)'!$1:$1048576,4,0))/2.5,0),VLOOKUP(A5,'UT-2(Entry)'!$1:$1048576,4,0)) -> 0 | E5: =IFERROR(ROUND((VLOOKUP(A5,'UT-2(Entry)'!$1:$1048576,5,0))/2.5,0),VLOOKUP(A5,'UT-2(Entry)'!$1:$1048576,5,0)) -> 0 | F5: =IFERROR(ROUND((VLOOKUP(A5,'UT-2(Entry)'!$1:$1048576,6,0))/2.5,0),VLOOKUP(A5,'UT-2(Entry)'!$1:$1048576,6,0)) -> 0 | G5: =IFERROR(ROUND((VLOOKUP($A5,'UT-2(Entry)'!$1:$1048576,7,0))/2.5,0),VLOOKUP($A5,'UT-2(Entry)'!$1:$1048576,7,0)) -> 0 | H5: =IFERROR(ROUND((VLOOKUP($A5,'UT-2(Entry)'!$1:$1048576,8,0))/2.5,0),VLOOKUP($A5,'UT-2(Entry)'!$1:$1048576,8,0)) -> 0 | I5: =SUM(C5:H5) -> 0 | J5: =ROUND(I5/1.2,2)&" %" -> 0 % | K5: =VLOOKUP(A5,'UT-2(Entry)'!$1:$1048576,9,0) -> 0 | L5: =VLOOKUP(A5,'UT-2(Entry)'!$1:$1048576,10,0) -> 0
A6: =DETAILS!#REF! -> #REF! | B6: =DETAILS!#REF! -> #REF! | C6: =IFERROR(ROUND((VLOOKUP(A6,'UT-2(Entry)'!$1:$1048576,3,0))/2.5,0),VLOOKUP(A6,'UT-2(Entry)'!$1:$1048576,3,0)) -> #REF! | D6: =IFERROR(ROUND((VLOOKUP(A6,'UT-2(Entry)'!$1:$1048576,4,0))/2.5,0),VLOOKUP(A6,'UT-2(Entry)'!$1:$1048576,4,0)) -> #REF! | E6: =IFERROR(ROUND((VLOOKUP(A6,'UT-2(Entry)'!$1:$1048576,5,0))/2.5,0),VLOOKUP(A6,'UT-2(Entry)'!$1:$1048576,5,0)) -> #REF! | F6: =IFERROR(ROUND((VLOOKUP(A6,'UT-2(Entry)'!$1:$1048576,6,0))/2.5,0),VLOOKUP(A6,'UT-2(Entry)'!$1:$1048576,6,0)) -> #REF! | G6: =IFERROR(ROUND((VLOOKUP($A6,'UT-2(Entry)'!$1:$1048576,7,0))/2.5,0),VLOOKUP($A6,'UT-2(Entry)'!$1:$1048576,7,0)) -> #REF! | H6: =IFERROR(ROUND((VLOOKUP($A6,'UT-2(Entry)'!$1:$1048576,8,0))/2.5,0),VLOOKUP($A6,'UT-2(Entry)'!$1:$1048576,8,0)) -> #REF! | I6: =SUM(C6:H6) -> #REF! | J6: =ROUND(I6/1.2,2)&" %" -> #REF! | K6: =VLOOKUP(A6,'UT-2(Entry)'!$1:$1048576,9,0) -> #REF! | L6: =VLOOKUP(A6,'UT-2(Entry)'!$1:$1048576,10,0) -> #REF!
A7: =DETAILS!#REF! -> #REF! | B7: =DETAILS!#REF! -> #REF! | C7: =IFERROR(ROUND((VLOOKUP(A7,'UT-2(Entry)'!$1:$1048576,3,0))/2.5,0),VLOOKUP(A7,'UT-2(Entry)'!$1:$1048576,3,0)) -> #REF! | D7: =IFERROR(ROUND((VLOOKUP(A7,'UT-2(Entry)'!$1:$1048576,4,0))/2.5,0),VLOOKUP(A7,'UT-2(Entry)'!$1:$1048576,4,0)) -> #REF! | E7: =IFERROR(ROUND((VLOOKUP(A7,'UT-2(Entry)'!$1:$1048576,5,0))/2.5,0),VLOOKUP(A7,'UT-2(Entry)'!$1:$1048576,5,0)) -> #REF! | F7: =IFERROR(ROUND((VLOOKUP(A7,'UT-2(Entry)'!$1:$1048576,6,0))/2.5,0),VLOOKUP(A7,'UT-2(Entry)'!$1:$1048576,6,0)) -> #REF! | G7: =IFERROR(ROUND((VLOOKUP($A7,'UT-2(Entry)'!$1:$1048576,7,0))/2.5,0),VLOOKUP($A7,'UT-2(Entry)'!$1:$1048576,7,0)) -> #REF! | H7: =IFERROR(ROUND((VLOOKUP($A7,'UT-2(Entry)'!$1:$1048576,8,0))/2.5,0),VLOOKUP($A7,'UT-2(Entry)'!$1:$1048576,8,0)) -> #REF! | I7: =SUM(C7:H7) -> #REF! | J7: =ROUND(I7/1.2,2)&" %" -> #REF! | K7: =VLOOKUP(A7,'UT-2(Entry)'!$1:$1048576,9,0) -> #REF! | L7: =VLOOKUP(A7,'UT-2(Entry)'!$1:$1048576,10,0) -> #REF!
A8: =DETAILS!#REF! -> #REF! | B8: =DETAILS!#REF! -> #REF! | C8: =IFERROR(ROUND((VLOOKUP(A8,'UT-2(Entry)'!$1:$1048576,3,0))/2.5,0),VLOOKUP(A8,'UT-2(Entry)'!$1:$1048576,3,0)) -> #REF! | D8: =IFERROR(ROUND((VLOOKUP(A8,'UT-2(Entry)'!$1:$1048576,4,0))/2.5,0),VLOOKUP(A8,'UT-2(Entry)'!$1:$1048576,4,0)) -> #REF! | E8: =IFERROR(ROUND((VLOOKUP(A8,'UT-2(Entry)'!$1:$1048576,5,0))/2.5,0),VLOOKUP(A8,'UT-2(Entry)'!$1:$1048576,5,0)) -> #REF! | F8: =IFERROR(ROUND((VLOOKUP(A8,'UT-2(Entry)'!$1:$1048576,6,0))/2.5,0),VLOOKUP(A8,'UT-2(Entry)'!$1:$1048576,6,0)) -> #REF! | G8: =IFERROR(ROUND((VLOOKUP($A8,'UT-2(Entry)'!$1:$1048576,7,0))/2.5,0),VLOOKUP($A8,'UT-2(Entry)'!$1:$1048576,7,0)) -> #REF! | H8: =IFERROR(ROUND((VLOOKUP($A8,'UT-2(Entry)'!$1:$1048576,8,0))/2.5,0),VLOOKUP($A8,'UT-2(Entry)'!$1:$1048576,8,0)) -> #REF! | I8: =SUM(C8:H8) -> #REF! | J8: =ROUND(I8/1.2,2)&" %" -> #REF! | K8: =VLOOKUP(A8,'UT-2(Entry)'!$1:$1048576,9,0) -> #REF! | L8: =VLOOKUP(A8,'UT-2(Entry)'!$1:$1048576,10,0) -> #REF!
A9: =DETAILS!#REF! -> #REF! | B9: =DETAILS!#REF! -> #REF! | C9: =IFERROR(ROUND((VLOOKUP(A9,'UT-2(Entry)'!$1:$1048576,3,0))/2.5,0),VLOOKUP(A9,'UT-2(Entry)'!$1:$1048576,3,0)) -> #REF! | D9: =IFERROR(ROUND((VLOOKUP(A9,'UT-2(Entry)'!$1:$1048576,4,0))/2.5,0),VLOOKUP(A9,'UT-2(Entry)'!$1:$1048576,4,0)) -> #REF! | E9: =IFERROR(ROUND((VLOOKUP(A9,'UT-2(Entry)'!$1:$1048576,5,0))/2.5,0),VLOOKUP(A9,'UT-2(Entry)'!$1:$1048576,5,0)) -> #REF! | F9: =IFERROR(ROUND((VLOOKUP(A9,'UT-2(Entry)'!$1:$1048576,6,0))/2.5,0),VLOOKUP(A9,'UT-2(Entry)'!$1:$1048576,6,0)) -> #REF! | G9: =IFERROR(ROUND((VLOOKUP($A9,'UT-2(Entry)'!$1:$1048576,7,0))/2.5,0),VLOOKUP($A9,'UT-2(Entry)'!$1:$1048576,7,0)) -> #REF! | H9: =IFERROR(ROUND((VLOOKUP($A9,'UT-2(Entry)'!$1:$1048576,8,0))/2.5,0),VLOOKUP($A9,'UT-2(Entry)'!$1:$1048576,8,0)) -> #REF! | I9: =SUM(C9:H9) -> #REF! | J9: =ROUND(I9/1.2,2)&" %" -> #REF! | K9: =VLOOKUP(A9,'UT-2(Entry)'!$1:$1048576,9,0) -> #REF! | L9: =VLOOKUP(A9,'UT-2(Entry)'!$1:$1048576,10,0) -> #REF!
A10: =DETAILS!#REF! -> #REF! | B10: =DETAILS!#REF! -> #REF! | C10: =IFERROR(ROUND((VLOOKUP(A10,'UT-2(Entry)'!$1:$1048576,3,0))/2.5,0),VLOOKUP(A10,'UT-2(Entry)'!$1:$1048576,3,0)) -> #REF! | D10: =IFERROR(ROUND((VLOOKUP(A10,'UT-2(Entry)'!$1:$1048576,4,0))/2.5,0),VLOOKUP(A10,'UT-2(Entry)'!$1:$1048576,4,0)) -> #REF! | E10: =IFERROR(ROUND((VLOOKUP(A10,'UT-2(Entry)'!$1:$1048576,5,0))/2.5,0),VLOOKUP(A10,'UT-2(Entry)'!$1:$1048576,5,0)) -> #REF! | F10: =IFERROR(ROUND((VLOOKUP(A10,'UT-2(Entry)'!$1:$1048576,6,0))/2.5,0),VLOOKUP(A10,'UT-2(Entry)'!$1:$1048576,6,0)) -> #REF! | G10: =IFERROR(ROUND((VLOOKUP($A10,'UT-2(Entry)'!$1:$1048576,7,0))/2.5,0),VLOOKUP($A10,'UT-2(Entry)'!$1:$1048576,7,0)) -> #REF! | H10: =IFERROR(ROUND((VLOOKUP($A10,'UT-2(Entry)'!$1:$1048576,8,0))/2.5,0),VLOOKUP($A10,'UT-2(Entry)'!$1:$1048576,8,0)) -> #REF! | I10: =SUM(C10:H10) -> #REF! | J10: =ROUND(I10/1.2,2)&" %" -> #REF! | K10: =VLOOKUP(A10,'UT-2(Entry)'!$1:$1048576,9,0) -> #REF! | L10: =VLOOKUP(A10,'UT-2(Entry)'!$1:$1048576,10,0) -> #REF!
A11: =DETAILS!#REF! -> #REF! | B11: =DETAILS!#REF! -> #REF! | C11: =IFERROR(ROUND((VLOOKUP(A11,'UT-2(Entry)'!$1:$1048576,3,0))/2.5,0),VLOOKUP(A11,'UT-2(Entry)'!$1:$1048576,3,0)) -> #REF! | D11: =IFERROR(ROUND((VLOOKUP(A11,'UT-2(Entry)'!$1:$1048576,4,0))/2.5,0),VLOOKUP(A11,'UT-2(Entry)'!$1:$1048576,4,0)) -> #REF! | E11: =IFERROR(ROUND((VLOOKUP(A11,'UT-2(Entry)'!$1:$1048576,5,0))/2.5,0),VLOOKUP(A11,'UT-2(Entry)'!$1:$1048576,5,0)) -> #REF! | F11: =IFERROR(ROUND((VLOOKUP(A11,'UT-2(Entry)'!$1:$1048576,6,0))/2.5,0),VLOOKUP(A11,'UT-2(Entry)'!$1:$1048576,6,0)) -> #REF! | G11: =IFERROR(ROUND((VLOOKUP($A11,'UT-2(Entry)'!$1:$1048576,7,0))/2.5,0),VLOOKUP($A11,'UT-2(Entry)'!$1:$1048576,7,0)) -> #REF! | H11: =IFERROR(ROUND((VLOOKUP($A11,'UT-2(Entry)'!$1:$1048576,8,0))/2.5,0),VLOOKUP($A11,'UT-2(Entry)'!$1:$1048576,8,0)) -> #REF! | I11: =SUM(C11:H11) -> #REF! | J11: =ROUND(I11/1.2,2)&" %" -> #REF! | K11: =VLOOKUP(A11,'UT-2(Entry)'!$1:$1048576,9,0) -> #REF! | L11: =VLOOKUP(A11,'UT-2(Entry)'!$1:$1048576,10,0) -> #REF!
